Workbook

Sheet 401
A1: BT401
A2: Faculty Name: | C2: Prof. Neetu Verma
A3: Subject Name : | C3: M-III
A4: Subject Code : | C4: BT401
A5: Start Date | C5: 46104
A6: End Date
H7: 1 | I7: 2 | J7: 3 | K7: 4 | L7: 5 | O7: 1 | P7: 2 | Q7: 3 | R7: 4 | S7: 5 | T7: 6 | U7: 7 | V7: 8 | W7: 9 | X7: 10 | Y7: 11 | Z7: 12 | AA7: 13 | AB7: 14 | AC7: 15 | AD7: 16 | AE7: 17 | AF7: 18 | AG7: 19 | AH7: 20 | AI7: 21 | AL7: 1 | AM7: 2 | AN7: 3 | AO7: 4 | AP7: 5 | AQ7: 6 | AR7: 7 | AS7: 8 | AT7: 9 | AU7: 10 | AV7: 11 | AW7: 12 | AX7: 13 | AY7: 14 | AZ7: 15 | BA7: 16 | BB7: 17 | BC7: 18 | BD7: 19 | BE7: 20 | BF7: 21 | BI7: 1 | BJ7: 2 | BK7: 3 | BL7: 4 | BM7: 5 | BN7: 6 | BO7: 7 | BP7: 8 | BQ7: 9 | BR7: 10 | BS7: 11 | BT7: 12 | BU7: 13 | BV7: 14 | BW7: 15 | BX7: 16 | BY7: 17 | BZ7: 18 | CA7: 19 | CB7: 20 | CC7: 21 | CD7: 22 | CG7: 1 | CH7: 2 | CI7: 3 | CJ7: 4 | CK7: 5 | CL7: 6 | CM7: 7 | CN7: 8 | CO7: 9 | CP7: 10 | CQ7: 11 | CR7: 12 | CS7: 13 | CT7: 14 | CU7: 15 | CV7: 16
D8: Total Class | E8: OverAll Att. % | F8: Att. 50% | G8: Att. 30% | H8: 46104 | I8: 46105 | J8: 46106 | K8: 46107 | L8: 46111 | M8: MAR CLASS | N8: MARCH % | O8: 46113 | P8: 46114 | Q8: 46115 | R8: 46118 | S8: 46119 | T8: 46120 | U8: 46121 | V8: 46122 | W8: 46125 | X8: 46127 | Y8: 46128 | Z8: 46129 | AA8: 46132 | AB8: 46133 | AC8: 46134 | AD8: 46135 | AE8: 46136 | AF8: 46139 | AG8: 46140 | AH8: 46141 | AI8: 46142 | AJ8: APRIL CLASS | AK8: APRIL % | AL8: 46143 | AM8: 46146 | AN8: 46147 | AO8: 46148 | AP8: 46149 | AQ8: 46150 | AR8: 46153 | AS8: 46154 | AT8: 46155 | AU8: 46156 | AV8: 46157 | AW8: 46160 | AX8: 46161 | AY8: 46162 | AZ8: 46163 | BA8: 46164 | BB8: 46167 | BC8: 46168 | BD8: 46169 | BE8: 46170 | BF8: 46171 | BG8: MAY CLASS | BH8: MAY% | BI8: 46174 | BJ8: 46175 | BK8: 46176 | BL8: 46177 | BM8: 46178 | BN8: 46181 | BO8: 46182 | BP8: 46183 | BQ8: 46184 | BR8: 46185 | BS8: 46188 | BT8: 46189 | BU8: 46190 | BV8: 46191 | BW8: 46192 | BX8: 46195 | BY8: 46196 | BZ8: 46197 | CA8: 46198 | CB8: 46199 | CC8: 46202 | CD8: 46203 | CE8: JUNE CLASS | CF8: JUNE % | CG8: 46205 | CH8: 46209 | CI8: 46210 | CW8: JULY CLASS | CX8: JULY% | DK8: AUG CLASS | DL8: AUG%
A9: s.no. | B9: Enrollment NO. | C9: Student Name | D9: =SUM(M9+AJ9+BG9+CE9+CW9+DK9) -> 44 | H9: =SUM(H11:H92) -> 4 | I9: =SUM(I11:I92) -> 3 | J9: =SUM(J11:J92) -> 3 | K9: =SUM(K11:K92) -> 3 | L9: =SUM(L11:L92) -> 0 | M9: =COUNTIF(H9:L9,">0") -> 4 | N9: =COUNTIF(H9:K9,">0") -> 4 | O9: =SUM(O11:O92) -> 3 | P9: =SUM(P11:P92) -> 5 | Q9: =SUM(Q11:Q92) -> 0 | R9: =SUM(R11:R92) -> 0 | S9: =SUM(S11:S92) -> 0 | T9: =SUM(T11:T92) -> 0 | U9: =SUM(U11:U92) -> 0 | V9: =SUM(V11:V92) -> 0 | ... AI9: =SUM(AI11:AI92) -> 44 | AJ9: =COUNTIF(O9:AI9,">0") -> 13 | AK9: =SUM(M9+AJ9) -> 17 | AL9: =SUM(AL11:AL92) -> 0 | AM9: =SUM(AM12:AM92) -> 45 | AN9: =SUM(AN12:AN92) -> 42 | AO9: =SUM(AO12:AO92) -> 39 | AP9: =SUM(AP12:AP92) -> 52 | AQ9: =SUM(AQ11:AQ92) -> 0 | AR9: =SUM(AR11:AR92) -> 44 | AS9: =SUM(AS11:AS92) -> 28 | AT9: =SUM(AT11:AT92) -> 35 | AU9: =SUM(AU11:AU92) -> 48 | AV9: =SUM(AV11:AV92) -> 0 | AW9: =SUM(AW11:AW92) -> 0 | AX9: =SUM(AX11:AX92) -> 0 | ... BF9: =SUM(BF11:BF92) -> 0 | BG9: =COUNTIF(AM9:BF9,">0") -> 12 | BH9: =SUM(AK9+BG9) -> 29 | BI9: =SUM(BI11:BI92) -> 41 | BJ9: =SUM(BJ11:BJ92) -> 49 | BK9: =SUM(BK11:BK92) -> 0 | BL9: =SUM(BL11:BL92) -> 50 | BM9: =SUM(BM11:BM92) -> 0 | BN9: =SUM(BN11:BN92) -> 0 | BO9: =SUM(BO11:BO92) -> 49 | BP9: =SUM(BP11:BP92) -> 58 | ... CD9: =SUM(CD11:CD92) -> 0 | CE9: =COUNTIF(BI9:CD9,">0") -> 13 | CF9: =SUM(BH9+CE9) -> 42 | CH9: =SUM(CH11:CH85) -> 15 | CI9: =SUM(CI11:CI85) -> 17 | CJ9: =SUM(CJ11:CJ85) -> 0 | CK9: =SUM(CK11:CK85) -> 0 | CL9: =SUM(CL11:CL85) -> 0 | CM9: =SUM(CM11:CM85) -> 0 | CN9: =SUM(CN11:CN85) -> 0 | CO9: =SUM(CO11:CO85) -> 0 | ... CR9: =SUM(CR11:CR85) -> 0 | CS9: =SUM(CS10:CS92) -> 0 | CT9: =SUM(CT10:CT92) -> 0 | CU9: =SUM(CU11:CU92) -> 0 | CV9: =SUM(CV11:CV85) -> 0 | CW9: =COUNTIF(CG9:CV9,">0") -> 2 | CX9: =SUM(CF9+CW9) -> 44 | CY9: =SUM(CY11:CY85) -> 0 | CZ9: =SUM(CZ11:CZ85) -> 0 | DA9: =SUM(DA11:DA85) -> 0 | DB9: =SUM(DB11:DB85) -> 0 | DC9: =SUM(DC11:DC85) -> 0 | DD9: =SUM(DD11:DD85) -> 0 | DE9: =SUM(DE11:DE85) -> 0 | DF9: =SUM(DF11:DF85) -> 0 | ... DJ9: =SUM(DJ11:DJ85) -> 0 | DK9: =COUNTIF(CY9:DJ9,">0") -> 0 | DL9: =SUM(CX9+DK9) -> 44
A10: 1 | B10: 0827CI231006 | C10: ABHINAV KOURAV | D10: =SUM(M10+AJ10+BG10+CE10+CW10+DK10) -> 0 | E10: =(D10)/D$9*100 -> 0 | F10: =IF(E10<50,E10, " ") -> 0 | G10: =IF(E10<30,E10, " ") -> 0 | M10: =SUM(H10:L10) -> 0 | N10: =M10/M$9*100 -> 0 | AJ10: =SUM(O10:AI10) -> 0 | AK10: =AJ10/AJ$9*100 -> 0 | BG10: =SUM(AM10:BF10) -> 0 | BH10: =BG10/BG$9*100 -> 0 | CE10: =SUM(BI10:CD10) -> 0 | CF10: =CE10/CE$9*100 -> 0 | CW10: =SUM(CG10:CV10) -> 0 | CX10: =CW10/CW$9*100 -> 0 | DK10: =SUM(CY10:DJ10) -> 0 | DL10: =DK10/DK$9*100 -> #DIV/0!
A11: 2 | B11: 0827CI241001 | C11: AANCHAL GUTA | D11: =SUM(M11+AJ11+BG11+CE11+CW11+DK11) -> 29 | E11: =(D11)/D$9*100 -> 65.909091 | F11: =IF(E11<50,E11, " ") | G11: =IF(E11<30,E11, " ") | M11: =SUM(H11:L11) -> 0 | N11: =M11/M$9*100 -> 0 | W11: 1 | X11: 1 | Y11: 1 | AB11: 1 | AD11: 1 | AF11: 1 | AG11: 1 | AH11: 1 | AI11: 1 | AJ11: =SUM(O11:AI11) -> 9 | AK11: =AJ11/AJ$9*100 -> 69.230769 | AM11: 1 | AN11: 1 | AP11: 1 | AR11: 1 | AT11: 1 | BB11: 1 | BD11: 1 | BE11: 1 | BG11: =SUM(AM11:BF11) -> 8 | BH11: =BG11/BG$9*100 -> 66.666667 | BI11: 1 | BJ11: 1 | BL11: 1 | BP11: 1 | BS11: 1 | BT11: 1 | BU11: 1 | BV11: 1 | BX11: 1 | BY11: 1 | CA11: 1 | CE11: =SUM(BI11:CD11) -> 11 | CF11: =CE11/CE$9*100 -> 84.615385 | CI11: 1 | CW11: =SUM(CG11:CV11) -> 1 | CX11: =CW11/CW$9*100 -> 50 | DK11: =SUM(CY11:DJ11) -> 0 | DL11: =DK11/DK$9*100 -> #DIV/0!
A12: 3 | B12: 0827CI241002 | C12: AARDRA TRIVEDI | D12: =SUM(M12+AJ12+BG12+CE12+CW12+DK12) -> 18 | E12: =(D12)/D$9*100 -> 40.909091 | F12: =IF(E12<50,E12, " ") -> 40.909091 | G12: =IF(E12<30,E12, " ") | M12: =SUM(H12:L12) -> 0 | N12: =M12/M$9*100 -> 0 | X12: 1 | Y12: 1 | AA12: 1 | AB12: 1 | AC12: 1 | AF12: 1 | AH12: 1 | AJ12: =SUM(O12:AI12) -> 7 | AK12: =AJ12/AJ$9*100 -> 53.846154 | AM12: 1 | AN12: 1 | AO12: 1 | AP12: 1 | AR12: 1 | AU12: 1 | BG12: =SUM(AM12:BF12) -> 6 | BH12: =BG12/BG$9*100 -> 50 | BL12: 1 | BP12: 1 | BT12: 1 | BU12: 1 | BV12: 1 | CE12: =SUM(BI12:CD12) -> 5 | CF12: =CE12/CE$9*100 -> 38.461538 | CW12: =SUM(CG12:CV12) -> 0 | CX12: =CW12/CW$9*100 -> 0 | DK12: =SUM(CY12:DJ12) -> 0 | DL12: =DK12/DK$9*100 -> #DIV/0!
A13: 4 | B13: 0827CI241003 | C13: AARNA DUBEY | D13: =SUM(M13+AJ13+BG13+CE13+CW13+DK13) -> 24 | E13: =(D13)/D$9*100 -> 54.545455 | F13: =IF(E13<50,E13, " ") | G13: =IF(E13<30,E13, " ") | M13: =SUM(H13:L13) -> 0 | N13: =M13/M$9*100 -> 0 | Y13: 1 | AB13: 1 | AC13: 1 | AD13: 1 | AF13: 1 | AG13: 1 | AH13: 1 | AJ13: =SUM(O13:AI13) -> 7 | AK13: =AJ13/AJ$9*100 -> 53.846154 | AM13: 1 | AN13: 1 | AO13: 1 | AP13: 1 | AR13: 1 | AU13: 1 | BB13: 1 | BC13: 1 | BD13: 1 | BE13: 1 | BG13: =SUM(AM13:BF13) -> 10 | BH13: =BG13/BG$9*100 -> 83.333333 | BJ13: 1 | BL13: 1 | BP13: 1 | BT13: 1 | BU13: 1 | BV13: 1 | BY13: 1 | CE13: =SUM(BI13:CD13) -> 7 | CF13: =CE13/CE$9*100 -> 53.846154 | CW13: =SUM(CG13:CV13) -> 0 | CX13: =CW13/CW$9*100 -> 0 | DK13: =SUM(CY13:DJ13) -> 0 | DL13: =DK13/DK$9*100 -> #DIV/0!
A14: 5 | B14: 0827CI241004 | C14: AASHI BINDAL | D14: =SUM(M14+AJ14+BG14+CE14+CW14+DK14) -> 26 | E14: =(D14)/D$9*100 -> 59.090909 | F14: =IF(E14<50,E14, " ") | G14: =IF(E14<30,E14, " ") | M14: =SUM(H14:L14) -> 0 | N14: =M14/M$9*100 -> 0 | W14: 1 | Y14: 1 | AA14: 1 | AB14: 1 | AC14: 1 | AF14: 1 | AG14: 1 | AH14: 1 | AI14: 1 | AJ14: =SUM(O14:AI14) -> 9 | AK14: =AJ14/AJ$9*100 -> 69.230769 | AM14: 1 | AT14: 1 | AU14: 1 | BC14: 1 | BD14: 1 | BE14: 1 | BG14: =SUM(AM14:BF14) -> 6 | BH14: =BG14/BG$9*100 -> 50 | BI14: 1 | BJ14: 1 | BL14: 1 | BO14: 1 | BP14: 1 | BS14: 1 | BT14: 1 | BU14: 1 | BX14: 1 | BY14: 1 | CE14: =SUM(BI14:CD14) -> 10 | CF14: =CE14/CE$9*100 -> 76.923077 | CH14: 1 | CW14: =SUM(CG14:CV14) -> 1 | CX14: =CW14/CW$9*100 -> 50 | DK14: =SUM(CY14:DJ14) -> 0 | DL14: =DK14/DK$9*100 -> #DIV/0!
A15: 6 | B15: 0827CI241005 | C15: AASHI SAJJAN | D15: =SUM(M15+AJ15+BG15+CE15+CW15+DK15) -> 28 | E15: =(D15)/D$9*100 -> 63.636364 | F15: =IF(E15<50,E15, " ") | G15: =IF(E15<30,E15, " ") | M15: =SUM(H15:L15) -> 0 | N15: =M15/M$9*100 -> 0 | X15: 1 | Y15: 1 | AA15: 1 | AB15: 1 | AC15: 1 | AD15: 1 | AF15: 1 | AG15: 1 | AH15: 1 | AI15: 1 | AJ15: =SUM(O15:AI15) -> 10 | AK15: =AJ15/AJ$9*100 -> 76.923077 | AM15: 1 | AN15: 1 | AP15: 1 | AR15: 1 | AT15: 1 | AU15: 1 | BD15: 1 | BG15: =SUM(AM15:BF15) -> 7 | BH15: =BG15/BG$9*100 -> 58.333333 | BI15: 1 | BJ15: 1 | BL15: 1 | BO15: 1 | BP15: 1 | BS15: 1 | BU15: 1 | BV15: 1 | BY15: 1 | CE15: =SUM(BI15:CD15) -> 9 | CF15: =CE15/CE$9*100 -> 69.230769 | CH15: 1 | CI15: 1 | CW15: =SUM(CG15:CV15) -> 2 | CX15: =CW15/CW$9*100 -> 100 | DK15: =SUM(CY15:DJ15) -> 0 | DL15: =DK15/DK$9*100 -> #DIV/0!
A16: 7 | B16: 0827CI241006 | C16: AAYUSH DHAKAD | D16: =SUM(M16+AJ16+BG16+CE16+CW16+DK16) -> 8 | E16: =(D16)/D$9*100 -> 18.181818 | F16: =IF(E16<50,E16, " ") -> 18.181818 | G16: =IF(E16<30,E16, " ") -> 18.181818 | M16: =SUM(H16:L16) -> 0 | N16: =M16/M$9*100 -> 0 | X16: 1 | Y16: 1 | AB16: 1 | AC16: 1 | AJ16: =SUM(O16:AI16) -> 4 | AK16: =AJ16/AJ$9*100 -> 30.769231 | AM16: 1 | AO16: 1 | BG16: =SUM(AM16:BF16) -> 2 | BH16: =BG16/BG$9*100 -> 16.666667 | BT16: 1 | BV16: 1 | CE16: =SUM(BI16:CD16) -> 2 | CF16: =CE16/CE$9*100 -> 15.384615 | CW16: =SUM(CG16:CV16) -> 0 | CX16: =CW16/CW$9*100 -> 0 | DK16: =SUM(CY16:DJ16) -> 0 | DL16: =DK16/DK$9*100 -> #DIV/0!
A17: 8 | B17: 0827CI241007 | C17: ADARSH PATHADE | D17: =SUM(M17+AJ17+BG17+CE17+CW17+DK17) -> 17 | E17: =(D17)/D$9*100 -> 38.636364 | F17: =IF(E17<50,E17, " ") -> 38.636364 | G17: =IF(E17<30,E17, " ") | M17: =SUM(H17:L17) -> 0 | N17: =M17/M$9*100 -> 0 | X17: 1 | Y17: 1 | AB17: 1 | AC17: 1 | AD17: 1 | AF17: 1 | AH17: 1 | AI17: 1 | AJ17: =SUM(O17:AI17) -> 8 | AK17: =AJ17/AJ$9*100 -> 61.538462 | AU17: 1 | BG17: =SUM(AM17:BF17) -> 1 | BH17: =BG17/BG$9*100 -> 8.3333333 | BI17: 1 | BJ17: 1 | BP17: 1 | BT17: 1 | BY17: 1 | CA17: 1 | CE17: =SUM(BI17:CD17) -> 6 | CF17: =CE17/CE$9*100 -> 46.153846 | CG17: 1 | CH17: 1 | CW17: =SUM(CG17:CV17) -> 2 | CX17: =CW17/CW$9*100 -> 100 | DK17: =SUM(CY17:DJ17) -> 0 | DL17: =DK17/DK$9*100 -> #DIV/0!
A18: 9 | B18: 0827CI241008 | C18: ADITI MISHRA | D18: =SUM(M18+AJ18+BG18+CE18+CW18+DK18) -> 20 | E18: =(D18)/D$9*100 -> 45.454545 | F18: =IF(E18<50,E18, " ") -> 45.454545 | G18: =IF(E18<30,E18, " ") | M18: =SUM(H18:L18) -> 0 | N18: =M18/M$9*100 -> 0 | X18: 1 | Y18: 1 | AA18: 1 | AC18: 1 | AD18: 1 | AG18: 1 | AI18: 1 | AJ18: =SUM(O18:AI18) -> 7 | AK18: =AJ18/AJ$9*100 -> 53.846154 | AM18: 1 | AO18: 1 | AP18: 1 | AR18: 1 | AU18: 1 | BG18: =SUM(AM18:BF18) -> 5 | BH18: =BG18/BG$9*100 -> 41.666667 | BI18: 1 | BL18: 1 | BO18: 1 | BS18: 1 | BV18: 1 | BY18: 1 | CE18: =SUM(BI18:CD18) -> 6 | CF18: =CE18/CE$9*100 -> 46.153846 | CG18: 1 | CI18: 1 | CW18: =SUM(CG18:CV18) -> 2 | CX18: =CW18/CW$9*100 -> 100 | DK18: =SUM(CY18:DJ18) -> 0 | DL18: =DK18/DK$9*100 -> #DIV/0!
A19: 10 | B19: 0827CI241009 | C19: ADITYA TRIPATHI | D19: =SUM(M19+AJ19+BG19+CE19+CW19+DK19) -> 26 | E19: =(D19)/D$9*100 -> 59.090909 | F19: =IF(E19<50,E19, " ") | G19: =IF(E19<30,E19, " ") | M19: =SUM(H19:L19) -> 0 | N19: =M19/M$9*100 -> 0 | X19: 1 | Y19: 1 | AA19: 1 | AB19: 1 | AC19: 1 | AD19: 1 | AF19: 1 | AG19: 1 | AH19: 1 | AI19: 1 | AJ19: =SUM(O19:AI19) -> 10 | AK19: =AJ19/AJ$9*100 -> 76.923077 | AM19: 1 | AN19: 1 | AO19: 1 | AP19: 1 | AR19: 1 | AS19: 1 | BC19: 1 | BD19: 1 | BG19: =SUM(AM19:BF19) -> 8 | BH19: =BG19/BG$9*100 -> 66.666667 | BO19: 1 | BP19: 1 | BS19: 1 | BT19: 1 | BU19: 1 | BX19: 1 | BY19: 1 | CE19: =SUM(BI19:CD19) -> 7 | CF19: =CE19/CE$9*100 -> 53.846154 | CI19: 1 | CW19: =SUM(CG19:CV19) -> 1 | CX19: =CW19/CW$9*100 -> 50 | DK19: =SUM(CY19:DJ19) -> 0 | DL19: =DK19/DK$9*100 -> #DIV/0!
A20: 11 | B20: 0827CI241010 | C20: ADWITIYA VERMA | D20: =SUM(M20+AJ20+BG20+CE20+CW20+DK20) -> 35 | E20: =(D20)/D$9*100 -> 79.545455 | F20: =IF(E20<50,E20, " ") | G20: =IF(E20<30,E20, " ") | M20: =SUM(H20:L20) -> 0 | N20: =M20/M$9*100 -> 0 | P20: 1 | W20: 1 | X20: 1 | Y20: 1 | AA20: 1 | AB20: 1 | AC20: 1 | AD20: 1 | AF20: 1 | AG20: 1 | AH20: 1 | AI20: 1 | AJ20: =SUM(O20:AI20) -> 12 | AK20: =AJ20/AJ$9*100 -> 92.307692 | AM20: 1 | AO20: 1 | AP20: 1 | AR20: 1 | AS20: 1 | AT20: 1 | AU20: 1 | BC20: 1 | BD20: 1 | BE20: 1 | BG20: =SUM(AM20:BF20) -> 10 | BH20: =BG20/BG$9*100 -> 83.333333 | BI20: 1 | BJ20: 1 | BL20: 1 | BO20: 1 | BP20: 1 | BS20: 1 | BT20: 1 | BU20: 1 | BV20: 1 | BX20: 1 | BY20: 1 | CE20: =SUM(BI20:CD20) -> 11 | CF20: =CE20/CE$9*100 -> 84.615385 | CG20: 1 | CI20: 1 | CW20: =SUM(CG20:CV20) -> 2 | CX20: =CW20/CW$9*100 -> 100 | DK20: =SUM(CY20:DJ20) -> 0 | DL20: =DK20/DK$9*100 -> #DIV/0!
A21: 12 | B21: 0827CI241011 | C21: AKSHADA ANDHALE | D21: =SUM(M21+AJ21+BG21+CE21+CW21+DK21) -> 19 | E21: =(D21)/D$9*100 -> 43.181818 | F21: =IF(E21<50,E21, " ") -> 43.181818 | G21: =IF(E21<30,E21, " ") | M21: =SUM(H21:L21) -> 0 | N21: =M21/M$9*100 -> 0 | W21: 1 | X21: 1 | Y21: 1 | AB21: 1 | AC21: 1 | AD21: 1 | AF21: 1 | AG21: 1 | AH21: 1 | AJ21: =SUM(O21:AI21) -> 9 | AK21: =AJ21/AJ$9*100 -> 69.230769 | AM21: 1 | AO21: 1 | AP21: 1 | AT21: 1 | AU21: 1 | BG21: =SUM(AM21:BF21) -> 5 | BH21: =BG21/BG$9*100 -> 41.666667 | BO21: 1 | BP21: 1 | BS21: 1 | BY21: 1 | CE21: =SUM(BI21:CD21) -> 4 | CF21: =CE21/CE$9*100 -> 30.769231 | CI21: 1 | CW21: =SUM(CG21:CV21) -> 1 | CX21: =CW21/CW$9*100 -> 50 | DK21: =SUM(CY21:DJ21) -> 0 | DL21: =DK21/DK$9*100 -> #DIV/0!
A22: 13 | B22: 0827CI241012 | C22: AKSHARA MANDLIYA | D22: =SUM(M22+AJ22+BG22+CE22+CW22+DK22) -> 22 | E22: =(D22)/D$9*100 -> 50 | F22: =IF(E22<50,E22, " ") | G22: =IF(E22<30,E22, " ") | M22: =SUM(H22:L22) -> 0 | N22: =M22/M$9*100 -> 0 | X22: 1 | Y22: 1 | AA22: 1 | AC22: 1 | AD22: 1 | AG22: 1 | AI22: 1 | AJ22: =SUM(O22:AI22) -> 7 | AK22: =AJ22/AJ$9*100 -> 53.846154 | AM22: 1 | AO22: 1 | AP22: 1 | AR22: 1 | AU22: 1 | BG22: =SUM(AM22:BF22) -> 5 | BH22: =BG22/BG$9*100 -> 41.666667 | BI22: 1 | BJ22: 1 | BL22: 1 | BO22: 1 | BP22: 1 | BS22: 1 | BT22: 1 | BY22: 1 | CE22: =SUM(BI22:CD22) -> 8 | CF22: =CE22/CE$9*100 -> 61.538462 | CG22: 1 | CI22: 1 | CW22: =SUM(CG22:CV22) -> 2 | CX22: =CW22/CW$9*100 -> 100 | DK22: =SUM(CY22:DJ22) -> 0 | DL22: =DK22/DK$9*100 -> #DIV/0!
A23: 14 | B23: 0827CI241013 | C23: ALOK KUMAWAT | D23: =SUM(M23+AJ23+BG23+CE23+CW23+DK23) -> 15 | E23: =(D23)/D$9*100 -> 34.090909 | F23: =IF(E23<50,E23, " ") -> 34.090909 | G23: =IF(E23<30,E23, " ") | M23: =SUM(H23:L23) -> 0 | N23: =M23/M$9*100 -> 0 | X23: 1 | AA23: 1 | AB23: 1 | AD23: 1 | AF23: 1 | AI23: 1 | AJ23: =SUM(O23:AI23) -> 6 | AK23: =AJ23/AJ$9*100 -> 46.153846 | AM23: 1 | AT23: 1 | AU23: 1 | BC23: 1 | BG23: =SUM(AM23:BF23) -> 4 | BH23: =BG23/BG$9*100 -> 33.333333 | BJ23: 1 | BL23: 1 | BX23: 1 | BY23: 1 | CE23: =SUM(BI23:CD23) -> 4 | CF23: =CE23/CE$9*100 -> 30.769231 | CG23: 1 | CW23: =SUM(CG23:CV23) -> 1 | CX23: =CW23/CW$9*100 -> 50 | DK23: =SUM(CY23:DJ23) -> 0 | DL23: =DK23/DK$9*100 -> #DIV/0!
A24: 15 | B24: 0827CI241014 | C24: ANANYA AGRAWAL | D24: =SUM(M24+AJ24+BG24+CE24+CW24+DK24) -> 17 | E24: =(D24)/D$9*100 -> 38.636364 | F24: =IF(E24<50,E24, " ") -> 38.636364 | G24: =IF(E24<30,E24, " ") | M24: =SUM(H24:L24) -> 0 | N24: =M24/M$9*100 -> 0 | Y24: 1 | AB24: 1 | AC24: 1 | AD24: 1 | AG24: 1 | AH24: 1 | AI24: 1 | AJ24: =SUM(O24:AI24) -> 7 | AK24: =AJ24/AJ$9*100 -> 53.846154 | AM24: 1 | AO24: 1 | AT24: 1 | AU24: 1 | BG24: =SUM(AM24:BF24) -> 4 | BH24: =BG24/BG$9*100 -> 33.333333 | BO24: 1 | BP24: 1 | BS24: 1 | BY24: 1 | CE24: =SUM(BI24:CD24) -> 4 | CF24: =CE24/CE$9*100 -> 30.769231 | CG24: 1 | CI24: 1 | CW24: =SUM(CG24:CV24) -> 2 | CX24: =CW24/CW$9*100 -> 100 | DK24: =SUM(CY24:DJ24) -> 0 | DL24: =DK24/DK$9*100 -> #DIV/0!
A25: 16 | B25: 0827CI241015 | C25: ANANYA YADAV | D25: =SUM(M25+AJ25+BG25+CE25+CW25+DK25) -> 21 | E25: =(D25)/D$9*100 -> 47.727273 | F25: =IF(E25<50,E25, " ") -> 47.727273 | G25: =IF(E25<30,E25, " ") | M25: =SUM(H25:L25) -> 0 | N25: =M25/M$9*100 -> 0 | X25: 1 | Y25: 1 | AA25: 1 | AB25: 1 | AC25: 1 | AD25: 1 | AF25: 1 | AG25: 1 | AJ25: =SUM(O25:AI25) -> 8 | AK25: =AJ25/AJ$9*100 -> 61.538462 | AM25: 1 | AP25: 1 | AR25: 1 | AT25: 1 | AU25: 1 | BG25: =SUM(AM25:BF25) -> 5 | BH25: =BG25/BG$9*100 -> 41.666667 | BI25: 1 | BJ25: 1 | BO25: 1 | BP25: 1 | BX25: 1 | BY25: 1 | CE25: =SUM(BI25:CD25) -> 6 | CF25: =CE25/CE$9*100 -> 46.153846 | CG25: 1 | CI25: 1 | CW25: =SUM(CG25:CV25) -> 2 | CX25: =CW25/CW$9*100 -> 100 | DK25: =SUM(CY25:DJ25) -> 0 | DL25: =DK25/DK$9*100 -> #DIV/0!
A26: 17 | B26: 0827CI241016 | C26: ANJALI KHANDELWAL | D26: =SUM(M26+AJ26+BG26+CE26+CW26+DK26) -> 22 | E26: =(D26)/D$9*100 -> 50 | F26: =IF(E26<50,E26, " ") | G26: =IF(E26<30,E26, " ") | M26: =SUM(H26:L26) -> 0 | N26: =M26/M$9*100 -> 0 | W26: 1 | X26: 1 | Y26: 1 | AB26: 1 | AC26: 1 | AD26: 1 | AI26: 1 | AJ26: =SUM(O26:AI26) -> 7 | AK26: =AJ26/AJ$9*100 -> 53.846154 | AR26: 1 | AS26: 1 | AT26: 1 | AU26: 1 | BC26: 1 | BD26: 1 | BE26: 1 | BG26: =SUM(AM26:BF26) -> 7 | BH26: =BG26/BG$9*100 -> 58.333333 | BI26: 1 | BJ26: 1 | BP26: 1 | BS26: 1 | BU26: 1 | BX26: 1 | BY26: 1 | CA26: 1 | CE26: =SUM(BI26:CD26) -> 8 | CF26: =CE26/CE$9*100 -> 61.538462 | CW26: =SUM(CG26:CV26) -> 0 | CX26: =CW26/CW$9*100 -> 0 | DK26: =SUM(CY26:DJ26) -> 0 | DL26: =DK26/DK$9*100 -> #DIV/0!
A27: 18 | B27: 0827CI241017 | C27: ANMOL MANDLAWADIA | D27: =SUM(M27+AJ27+BG27+CE27+CW27+DK27) -> 20 | E27: =(D27)/D$9*100 -> 45.454545 | F27: =IF(E27<50,E27, " ") -> 45.454545 | G27: =IF(E27<30,E27, " ") | M27: =SUM(H27:L27) -> 0 | N27: =M27/M$9*100 -> 0 | X27: 1 | Y27: 1 | AB27: 1 | AC27: 1 | AF27: 1 | AG27: 1 | AH27: 1 | AJ27: =SUM(O27:AI27) -> 7 | AK27: =AJ27/AJ$9*100 -> 53.846154 | AM27: 1 | AR27: 1 | BG27: =SUM(AM27:BF27) -> 2 | BH27: =BG27/BG$9*100 -> 16.666667 | BI27: 1 | BL27: 1 | BO27: 1 | BP27: 1 | BS27: 1 | BT27: 1 | BU27: 1 | BV27: 1 | BX27: 1 | BZ27: 1 | CE27: =SUM(BI27:CD27) -> 10 | CF27: =CE27/CE$9*100 -> 76.923077 | CG27: 1 | CW27: =SUM(CG27:CV27) -> 1 | CX27: =CW27/CW$9*100 -> 50 | DK27: =SUM(CY27:DJ27) -> 0 | DL27: =DK27/DK$9*100 -> #DIV/0!
A28: 19 | B28: 0827CI241018 | C28: ANMOL SINGH BASSAN | D28: =SUM(M28+AJ28+BG28+CE28+CW28+DK28) -> 25 | E28: =(D28)/D$9*100 -> 56.818182 | F28: =IF(E28<50,E28, " ") | G28: =IF(E28<30,E28, " ") | M28: =SUM(H28:L28) -> 0 | N28: =M28/M$9*100 -> 0 | AA28: 1 | AD28: 1 | AF28: 1 | AG28: 1 | AH28: 1 | AI28: 1 | AJ28: =SUM(O28:AI28) -> 6 | AK28: =AJ28/AJ$9*100 -> 46.153846 | AM28: 1 | AN28: 1 | AO28: 1 | AP28: 1 | AT28: 1 | AU28: 1 | BC28: 1 | BD28: 1 | BG28: =SUM(AM28:BF28) -> 8 | BH28: =BG28/BG$9*100 -> 66.666667 | BJ28: 1 | BL28: 1 | BO28: 1 | BP28: 1 | BS28: 1 | BT28: 1 | BV28: 1 | BX28: 1 | BY28: 1 | CE28: =SUM(BI28:CD28) -> 9 | CF28: =CE28/CE$9*100 -> 69.230769 | CG28: 1 | CI28: 1 | CW28: =SUM(CG28:CV28) -> 2 | CX28: =CW28/CW$9*100 -> 100 | DK28: =SUM(CY28:DJ28) -> 0 | DL28: =DK28/DK$9*100 -> #DIV/0!
A29: 20 | B29: 0827CI241019 | C29: ANSHIKA KHARE | D29: =SUM(M29+AJ29+BG29+CE29+CW29+DK29) -> 22 | E29: =(D29)/D$9*100 -> 50 | F29: =IF(E29<50,E29, " ") | G29: =IF(E29<30,E29, " ") | M29: =SUM(H29:L29) -> 0 | N29: =M29/M$9*100 -> 0 | X29: 1 | Y29: 1 | AA29: 1 | AB29: 1 | AC29: 1 | AD29: 1 | AF29: 1 | AI29: 1 | AJ29: =SUM(O29:AI29) -> 8 | AK29: =AJ29/AJ$9*100 -> 61.538462 | AM29: 1 | AO29: 1 | AP29: 1 | AS29: 1 | AU29: 1 | BC29: 1 | BG29: =SUM(AM29:BF29) -> 6 | BH29: =BG29/BG$9*100 -> 50 | BI29: 1 | BJ29: 1 | BO29: 1 | BP29: 1 | BT29: 1 | BV29: 1 | BX29: 1 | BY29: 1 | CE29: =SUM(BI29:CD29) -> 8 | CF29: =CE29/CE$9*100 -> 61.538462 | CW29: =SUM(CG29:CV29) -> 0 | CX29: =CW29/CW$9*100 -> 0 | DK29: =SUM(CY29:DJ29) -> 0 | DL29: =DK29/DK$9*100 -> #DIV/0!
A30: 21 | B30: 0827CI241020 | C30: ANSHIKA SHRIVASTAV | D30: =SUM(M30+AJ30+BG30+CE30+CW30+DK30) -> 0 | E30: =(D30)/D$9*100 -> 0 | F30: =IF(E30<50,E30, " ") -> 0 | G30: =IF(E30<30,E30, " ") -> 0 | M30: =SUM(H30:L30) -> 0 | N30: =M30/M$9*100 -> 0 | AJ30: =SUM(O30:AI30) -> 0 | AK30: =AJ30/AJ$9*100 -> 0 | BG30: =SUM(AM30:BF30) -> 0 | BH30: =BG30/BG$9*100 -> 0 | CE30: =SUM(BI30:CD30) -> 0 | CF30: =CE30/CE$9*100 -> 0 | CW30: =SUM(CG30:CV30) -> 0 | CX30: =CW30/CW$9*100 -> 0 | DK30: =SUM(CY30:DJ30) -> 0 | DL30: =DK30/DK$9*100 -> #DIV/0!
A31: 22 | B31: 0827CI241021 | C31: ANUJ MALVIYA | D31: =SUM(M31+AJ31+BG31+CE31+CW31+DK31) -> 18 | E31: =(D31)/D$9*100 -> 40.909091 | F31: =IF(E31<50,E31, " ") -> 40.909091 | G31: =IF(E31<30,E31, " ") | M31: =SUM(H31:L31) -> 0 | N31: =M31/M$9*100 -> 0 | X31: 1 | AH31: 1 | AI31: 1 | AJ31: =SUM(O31:AI31) -> 3 | AK31: =AJ31/AJ$9*100 -> 23.076923 | AN31: 1 | AP31: 1 | AR31: 1 | AS31: 1 | AU31: 1 | BG31: =SUM(AM31:BF31) -> 5 | BH31: =BG31/BG$9*100 -> 41.666667 | BJ31: 1 | BL31: 1 | BO31: 1 | BP31: 1 | BT31: 1 | BV31: 1 | BX31: 1 | BZ31: 1 | CE31: =SUM(BI31:CD31) -> 8 | CF31: =CE31/CE$9*100 -> 61.538462 | CG31: 1 | CI31: 1 | CW31: =SUM(CG31:CV31) -> 2 | CX31: =CW31/CW$9*100 -> 100 | DK31: =SUM(CY31:DJ31) -> 0 | DL31: =DK31/DK$9*100 -> #DIV/0!
A32: 23 | B32: 0827CI241022 | C32: ANURAG CHOUDHARY | D32: =SUM(M32+AJ32+BG32+CE32+CW32+DK32) -> 23 | E32: =(D32)/D$9*100 -> 52.272727 | F32: =IF(E32<50,E32, " ") | G32: =IF(E32<30,E32, " ") | M32: =SUM(H32:L32) -> 0 | N32: =M32/M$9*100 -> 0 | W32: 1 | X32: 1 | Y32: 1 | AB32: 1 | AC32: 1 | AD32: 1 | AF32: 1 | AG32: 1 | AH32: 1 | AJ32: =SUM(O32:AI32) -> 9 | AK32: =AJ32/AJ$9*100 -> 69.230769 | AM32: 1 | AP32: 1 | AR32: 1 | BD32: 1 | BE32: 1 | BG32: =SUM(AM32:BF32) -> 5 | BH32: =BG32/BG$9*100 -> 41.666667 | BI32: 1 | BL32: 1 | BP32: 1 | BS32: 1 | BT32: 1 | BU32: 1 | BV32: 1 | BX32: 1 | BZ32: 1 | CE32: =SUM(BI32:CD32) -> 9 | CF32: =CE32/CE$9*100 -> 69.230769 | CW32: =SUM(CG32:CV32) -> 0 | CX32: =CW32/CW$9*100 -> 0 | DK32: =SUM(CY32:DJ32) -> 0 | DL32: =DK32/DK$9*100 -> #DIV/0!
A33: 24 | B33: 0827CI241023 | C33: ANUSHKA SISODIYA | D33: =SUM(M33+AJ33+BG33+CE33+CW33+DK33) -> 20 | E33: =(D33)/D$9*100 -> 45.454545 | F33: =IF(E33<50,E33, " ") -> 45.454545 | G33: =IF(E33<30,E33, " ") | M33: =SUM(H33:L33) -> 0 | N33: =M33/M$9*100 -> 0 | X33: 1 | Y33: 1 | AA33: 1 | AB33: 1 | AC33: 1 | AF33: 1 | AG33: 1 | AH33: 1 | AJ33: =SUM(O33:AI33) -> 8 | AK33: =AJ33/AJ$9*100 -> 61.538462 | AM33: 1 | AN33: 1 | AO33: 1 | AP33: 1 | AR33: 1 | AU33: 1 | BG33: =SUM(AM33:BF33) -> 6 | BH33: =BG33/BG$9*100 -> 50 | BL33: 1 | BO33: 1 | BP33: 1 | BT33: 1 | BV33: 1 | BY33: 1 | CE33: =SUM(BI33:CD33) -> 6 | CF33: =CE33/CE$9*100 -> 46.153846 | CW33: =SUM(CG33:CV33) -> 0 | CX33: =CW33/CW$9*100 -> 0 | DK33: =SUM(CY33:DJ33) -> 0 | DL33: =DK33/DK$9*100 -> #DIV/0!
A34: 25 | B34: 0827CI241024 | C34: ARNAV TIWARI | D34: =SUM(M34+AJ34+BG34+CE34+CW34+DK34) -> 30 | E34: =(D34)/D$9*100 -> 68.181818 | F34: =IF(E34<50,E34, " ") | G34: =IF(E34<30,E34, " ") | M34: =SUM(H34:L34) -> 0 | N34: =M34/M$9*100 -> 0 | W34: 1 | Y34: 1 | AA34: 1 | AB34: 1 | AC34: 1 | AD34: 1 | AF34: 1 | AG34: 1 | AH34: 1 | AI34: 1 | AJ34: =SUM(O34:AI34) -> 10 | AK34: =AJ34/AJ$9*100 -> 76.923077 | AM34: 1 | AN34: 1 | AO34: 1 | AP34: 1 | AR34: 1 | AT34: 1 | AU34: 1 | BC34: 1 | BG34: =SUM(AM34:BF34) -> 8 | BH34: =BG34/BG$9*100 -> 66.666667 | BI34: 1 | BJ34: 1 | BL34: 1 | BO34: 1 | BP34: 1 | BS34: 1 | BT34: 1 | BV34: 1 | BY34: 1 | BZ34: 1 | CE34: =SUM(BI34:CD34) -> 10 | CF34: =CE34/CE$9*100 -> 76.923077 | CG34: 1 | CI34: 1 | CW34: =SUM(CG34:CV34) -> 2 | CX34: =CW34/CW$9*100 -> 100 | DK34: =SUM(CY34:DJ34) -> 0 | DL34: =DK34/DK$9*100 -> #DIV/0!
A35: 26 | B35: 0827CI241025 | C35: ARVIND RUHELA | D35: =SUM(M35+AJ35+BG35+CE35+CW35+DK35) -> 18 | E35: =(D35)/D$9*100 -> 40.909091 | F35: =IF(E35<50,E35, " ") -> 40.909091 | G35: =IF(E35<30,E35, " ") | M35: =SUM(H35:L35) -> 0 | N35: =M35/M$9*100 -> 0 | W35: 1 | X35: 1 | Y35: 1 | AB35: 1 | AC35: 1 | AF35: 1 | AH35: 1 | AJ35: =SUM(O35:AI35) -> 7 | AK35: =AJ35/AJ$9*100 -> 53.846154 | AR35: 1 | BD35: 1 | BE35: 1 | BG35: =SUM(AM35:BF35) -> 3 | BH35: =BG35/BG$9*100 -> 25 | BI35: 1 | BL35: 1 | BP35: 1 | BS35: 1 | BT35: 1 | BU35: 1 | BX35: 1 | BZ35: 1 | CE35: =SUM(BI35:CD35) -> 8 | CF35: =CE35/CE$9*100 -> 61.538462 | CW35: =SUM(CG35:CV35) -> 0 | CX35: =CW35/CW$9*100 -> 0 | DK35: =SUM(CY35:DJ35) -> 0 | DL35: =DK35/DK$9*100 -> #DIV/0!
A36: 27 | B36: 0827CI241026 | C36: ASHU GARG | D36: =SUM(M36+AJ36+BG36+CE36+CW36+DK36) -> 26 | E36: =(D36)/D$9*100 -> 59.090909 | F36: =IF(E36<50,E36, " ") | G36: =IF(E36<30,E36, " ") | M36: =SUM(H36:L36) -> 0 | N36: =M36/M$9*100 -> 0 | Y36: 1 | AA36: 1 | AB36: 1 | AC36: 1 | AD36: 1 | AF36: 1 | AG36: 1 | AH36: 1 | AI36: 1 | AJ36: =SUM(O36:AI36) -> 9 | AK36: =AJ36/AJ$9*100 -> 69.230769 | AM36: 1 | AN36: 1 | AO36: 1 | AP36: 1 | AR36: 1 | AS36: 1 | BC36: 1 | BD36: 1 | BE36: 1 | BG36: =SUM(AM36:BF36) -> 9 | BH36: =BG36/BG$9*100 -> 75 | BI36: 1 | BO36: 1 | BP36: 1 | BS36: 1 | BT36: 1 | BU36: 1 | BX36: 1 | BY36: 1 | CE36: =SUM(BI36:CD36) -> 8 | CF36: =CE36/CE$9*100 -> 61.538462 | CW36: =SUM(CG36:CV36) -> 0 | CX36: =CW36/CW$9*100 -> 0 | DK36: =SUM(CY36:DJ36) -> 0 | DL36: =DK36/DK$9*100 -> #DIV/0!
A37: 28 | B37: 0827CI241027 | C37: ASHWIN PATEL | D37: =SUM(M37+AJ37+BG37+CE37+CW37+DK37) -> 13 | E37: =(D37)/D$9*100 -> 29.545455 | F37: =IF(E37<50,E37, " ") -> 29.545455 | G37: =IF(E37<30,E37, " ") -> 29.545455 | M37: =SUM(H37:L37) -> 0 | N37: =M37/M$9*100 -> 0 | AH37: 1 | AI37: 1 | AJ37: =SUM(O37:AI37) -> 2 | AK37: =AJ37/AJ$9*100 -> 15.384615 | AN37: 1 | AO37: 1 | AP37: 1 | AT37: 1 | AU37: 1 | BC37: 1 | BD37: 1 | BG37: =SUM(AM37:BF37) -> 7 | BH37: =BG37/BG$9*100 -> 58.333333 | BL37: 1 | BO37: 1 | BP37: 1 | BV37: 1 | CE37: =SUM(BI37:CD37) -> 4 | CF37: =CE37/CE$9*100 -> 30.769231 | CW37: =SUM(CG37:CV37) -> 0 | CX37: =CW37/CW$9*100 -> 0 | DK37: =SUM(CY37:DJ37) -> 0 | DL37: =DK37/DK$9*100 -> #DIV/0!
A38: 29 | B38: 0827CI241028 | C38: AYUSH CHOUHAN | D38: =SUM(M38+AJ38+BG38+CE38+CW38+DK38) -> 22 | E38: =(D38)/D$9*100 -> 50 | F38: =IF(E38<50,E38, " ") | G38: =IF(E38<30,E38, " ") | M38: =SUM(H38:L38) -> 0 | N38: =M38/M$9*100 -> 0 | AB38: 1 | AC38: 1 | AD38: 1 | AF38: 1 | AG38: 1 | AH38: 1 | AI38: 1 | AJ38: =SUM(O38:AI38) -> 7 | AK38: =AJ38/AJ$9*100 -> 53.846154 | AM38: 1 | AN38: 1 | AO38: 1 | AP38: 1 | AR38: 1 | AT38: 1 | AU38: 1 | BG38: =SUM(AM38:BF38) -> 7 | BH38: =BG38/BG$9*100 -> 58.333333 | BS38: 1 | BT38: 1 | BU38: 1 | BX38: 1 | BY38: 1 | BZ38: 1 | CE38: =SUM(BI38:CD38) -> 6 | CF38: =CE38/CE$9*100 -> 46.153846 | CG38: 1 | CI38: 1 | CW38: =SUM(CG38:CV38) -> 2 | CX38: =CW38/CW$9*100 -> 100 | DK38: =SUM(CY38:DJ38) -> 0 | DL38: =DK38/DK$9*100 -> #DIV/0!
A39: 30 | B39: 0827CI241029 | C39: AYUSHI DOSHI | D39: =SUM(M39+AJ39+BG39+CE39+CW39+DK39) -> 29 | E39: =(D39)/D$9*100 -> 65.909091 | F39: =IF(E39<50,E39, " ") | G39: =IF(E39<30,E39, " ") | M39: =SUM(H39:L39) -> 0 | N39: =M39/M$9*100 -> 0 | X39: 1 | Y39: 1 | AF39: 1 | AG39: 1 | AH39: 1 | AI39: 1 | AJ39: =SUM(O39:AI39) -> 6 | AK39: =AJ39/AJ$9*100 -> 46.153846 | AM39: 1 | AN39: 1 | AO39: 1 | AP39: 1 | AR39: 1 | AS39: 1 | AT39: 1 | AU39: 1 | BB39: 1 | BD39: 1 | BG39: =SUM(AM39:BF39) -> 10 | BH39: =BG39/BG$9*100 -> 83.333333 | BI39: 1 | BJ39: 1 | BL39: 1 | BO39: 1 | BS39: 1 | BT39: 1 | BU39: 1 | BV39: 1 | BY39: 1 | BZ39: 1 | CA39: 1 | CE39: =SUM(BI39:CD39) -> 11 | CF39: =CE39/CE$9*100 -> 84.615385 | CG39: 1 | CI39: 1 | CW39: =SUM(CG39:CV39) -> 2 | CX39: =CW39/CW$9*100 -> 100 | DK39: =SUM(CY39:DJ39) -> 0 | DL39: =DK39/DK$9*100 -> #DIV/0!
A40: 31 | B40: 0827CI241030 | C40: BHAGYESH JAIN | D40: =SUM(M40+AJ40+BG40+CE40+CW40+DK40) -> 23 | E40: =(D40)/D$9*100 -> 52.272727 | F40: =IF(E40<50,E40, " ") | G40: =IF(E40<30,E40, " ") | M40: =SUM(H40:L40) -> 0 | N40: =M40/M$9*100 -> 0 | W40: 1 | AA40: 1 | AB40: 1 | AD40: 1 | AF40: 1 | AG40: 1 | AH40: 1 | AI40: 1 | AJ40: =SUM(O40:AI40) -> 8 | AK40: =AJ40/AJ$9*100 -> 61.538462 | AP40: 1 | AR40: 1 | BE40: 1 | BG40: =SUM(AM40:BF40) -> 3 | BH40: =BG40/BG$9*100 -> 25 | BI40: 1 | BJ40: 1 | BL40: 1 | BO40: 1 | BP40: 1 | BS40: 1 | BT40: 1 | BU40: 1 | BX40: 1 | BY40: 1 | CA40: 1 | CE40: =SUM(BI40:CD40) -> 11 | CF40: =CE40/CE$9*100 -> 84.615385 | CG40: 1 | CW40: =SUM(CG40:CV40) -> 1 | CX40: =CW40/CW$9*100 -> 50 | DK40: =SUM(CY40:DJ40) -> 0 | DL40: =DK40/DK$9*100 -> #DIV/0!
...

Sheet 402
A1: CSIT-402
A2: Faculty Name: | C2: Dr. Asmita Rajawat
A3: Subject Name : | C3: Analog and Digital Communication
A4: Subject Code : | C4: CSIT-402
A5: Start Date | C5: 46104
A6: End Date
H7: 1 | I7: 2 | J7: 3 | K7: 4 | L7: 5 | O7: 1 | P7: 2 | Q7: 3 | R7: 4 | S7: 5 | T7: 6 | U7: 7 | V7: 8 | W7: 9 | X7: 10 | Y7: 11 | Z7: 12 | AA7: 13 | AB7: 14 | AC7: 15 | AD7: 16 | AE7: 17 | AF7: 18 | AG7: 19 | AH7: 20 | AI7: 21 | AL7: 1 | AM7: 2 | AN7: 3 | AO7: 4 | AP7: 5 | AQ7: 6 | AR7: 7 | AS7: 8 | AT7: 9 | AU7: 10 | AV7: 11 | AW7: 12 | AX7: 13 | AY7: 14 | AZ7: 15 | BA7: 16 | BB7: 17 | BC7: 18 | BD7: 19 | BE7: 20 | BF7: 21 | BI7: 1 | BJ7: 2 | BK7: 3 | BL7: 4 | BM7: 5 | BN7: 6 | BO7: 7 | BP7: 8 | BQ7: 9 | BR7: 10 | BS7: 11 | BT7: 12 | BU7: 13 | BV7: 14 | BW7: 15 | BX7: 16 | BY7: 17 | BZ7: 18 | CA7: 19 | CB7: 20 | CC7: 21 | CD7: 22 | CG7: 1 | CH7: 2 | CI7: 3 | CJ7: 4 | CK7: 5 | CL7: 6 | CM7: 7 | CN7: 8 | CO7: 9 | CP7: 10 | CQ7: 11 | CR7: 12 | CS7: 13 | CT7: 14 | CU7: 15 | CV7: 16
D8: Total Class | E8: OverAll Att. % | F8: Att. 50% | G8: Att. 30% | H8: 46104 | I8: 46105 | J8: 46106 | K8: 46107 | L8: 46111 | M8: MAR CLASS | N8: MARCH % | O8: 46113 | P8: 46114 | Q8: 46115 | R8: 46118 | S8: 46119 | T8: 46120 | U8: 46121 | V8: 46122 | W8: 46125 | X8: 46127 | Y8: 46128 | Z8: 46129 | AA8: 46132 | AB8: 46133 | AC8: 46134 | AD8: 46135 | AE8: 46136 | AF8: 46139 | AG8: 46140 | AH8: 46141 | AI8: 46142 | AJ8: APRIL CLASS | AK8: APRIL % | AL8: 46143 | AM8: 46146 | AN8: 46147 | AO8: 46148 | AP8: 46148 | AQ8: 46150 | AR8: 46153 | AS8: 46154 | AT8: 46155 | AU8: 46156 | AV8: 46157 | AW8: 46160 | AX8: 46161 | AY8: 46162 | AZ8: 46163 | BA8: 46164 | BB8: 46167 | BC8: 46168 | BD8: 46169 | BE8: 46170 | BF8: 46171 | BG8: MAY CLASS | BH8: MAY% | BI8: 46174 | BJ8: 46175 | BK8: 46176 | BL8: 46177 | BM8: 46178 | BN8: 46181 | BO8: 46182 | BP8: 46183 | BQ8: 46184 | BR8: 46185 | BS8: 46188 | BT8: 46189 | BU8: 46190 | BV8: 46191 | BW8: 46192 | BX8: 46195 | BY8: 46196 | BZ8: 46197 | CA8: 46198 | CB8: 46199 | CC8: 46202 | CD8: 46203 | CE8: JUNE CLASS | CF8: JUNE % | CG8: 46204 | CH8: 46206 | CI8: 46223 | CW8: JULY CLASS | CX8: JULY% | DK8: AUG CLASS | DL8: AUG%
A9: s.no. | B9: Enrollment NO. | C9: Student Name | D9: =SUM(M9+AJ9+BG9+CE9+CW9+DK9) -> 38 | H9: =SUM(H11:H92) -> 0 | I9: =SUM(I11:I92) -> 0 | J9: =SUM(J11:J92) -> 0 | K9: =SUM(K11:K92) -> 0 | L9: =SUM(L11:L92) -> 0 | M9: =COUNTIF(H9:L9,">0") -> 0 | N9: =COUNTIF(H9:K9,">0") -> 0 | O9: =SUM(O11:O92) -> 0 | P9: =SUM(P11:P92) -> 0 | Q9: =SUM(Q11:Q92) -> 0 | R9: =SUM(R11:R92) -> 0 | S9: =SUM(S11:S92) -> 0 | T9: =SUM(T11:T92) -> 0 | U9: =SUM(U11:U92) -> 0 | V9: =SUM(V11:V92) -> 0 | ... AI9: =SUM(AI11:AI92) -> 0 | AJ9: =COUNTIF(O9:AI9,">0") -> 7 | AK9: =SUM(M9+AJ9) -> 7 | AL9: =SUM(AL11:AL92) -> 0 | AM9: =SUM(AM11:AM92) -> 41 | AN9: =SUM(AN11:AN92) -> 33 | AO9: =SUM(AO11:AO92) -> 36 | AP9: =SUM(AP11:AP92) -> 38 | AQ9: =SUM(AQ11:AQ92) -> 15 | AR9: =SUM(AR11:AR92) -> 39 | AS9: =SUM(AS11:AS92) -> 37 | ... BF9: =SUM(BF11:BF92) -> 29 | BG9: =COUNTIF(AM9:BF9,">0") -> 14 | BH9: =SUM(AK9+BG9) -> 21 | BI9: =SUM(BI11:BI92) -> 36 | BJ9: =SUM(BJ11:BJ92) -> 46 | BK9: =SUM(BK11:BK92) -> 0 | BL9: =SUM(BL11:BL92) -> 0 | BM9: =SUM(BM11:BM92) -> 0 | BN9: =SUM(BN11:BN92) -> 0 | BO9: =SUM(BO11:BO92) -> 44 | BP9: =SUM(BP11:BP92) -> 0 | ... CD9: =SUM(CD11:CD92) -> 58 | CE9: =COUNTIF(BI9:CD9,">0") -> 14 | CF9: =SUM(BH9+CE9) -> 35 | CG9: =SUM(CG11:CG85) -> 38 | CH9: =SUM(CH11:CH85) -> 11 | CI9: =SUM(CI11:CI85) -> 2 | CJ9: =SUM(CJ11:CJ85) -> 0 | CK9: =SUM(CK11:CK85) -> 0 | CL9: =SUM(CL11:CL85) -> 0 | CM9: =SUM(CM11:CM85) -> 0 | CN9: =SUM(CN11:CN85) -> 0 | ... CR9: =SUM(CR11:CR85) -> 0 | CS9: =SUM(CS10:CS92) -> 0 | CT9: =SUM(CT10:CT92) -> 0 | CU9: =SUM(CU11:CU92) -> 0 | CV9: =SUM(CV11:CV85) -> 0 | CW9: =COUNTIF(CG9:CV9,">0") -> 3 | CX9: =SUM(CF9+CW9) -> 38 | CY9: =SUM(CY11:CY85) -> 0 | CZ9: =SUM(CZ11:CZ85) -> 0 | DA9: =SUM(DA11:DA85) -> 0 | DB9: =SUM(DB11:DB85) -> 0 | DC9: =SUM(DC11:DC85) -> 0 | DD9: =SUM(DD11:DD85) -> 0 | DE9: =SUM(DE11:DE85) -> 0 | DF9: =SUM(DF11:DF85) -> 0 | ... DJ9: =SUM(DJ11:DJ85) -> 0 | DK9: =COUNTIF(CY9:DJ9,">0") -> 0 | DL9: =SUM(CX9+DK9) -> 38
A10: 1 | B10: 0827CI231006 | C10: ABHINAV KOURAV | D10: =SUM(M10+AJ10+BG10+CE10+CW10+DK10) -> 0 | E10: =(D10)/D$9*100 -> 0 | F10: =IF(E10<50,E10, " ") -> 0 | G10: =IF(E10<30,E10, " ") -> 0 | M10: =SUM(H10:L10) -> 0 | N10: =M10/M$9*100 -> #DIV/0! | AJ10: =SUM(O10:AI10) -> 0 | AK10: =AJ10/AJ$9*100 -> 0 | BG10: =SUM(AM10:BF10) -> 0 | BH10: =BG10/BG$9*100 -> 0 | CE10: =SUM(BI10:CD10) -> 0 | CF10: =CE10/CE$9*100 -> 0 | CW10: =SUM(CG10:CV10) -> 0 | CX10: =CW10/CW$9*100 -> 0 | DK10: =SUM(CY10:DJ10) -> 0 | DL10: =DK10/DK$9*100 -> #DIV/0!
A11: 2 | B11: 0827CI241001 | C11: AANCHAL GUTA | D11: =SUM(M11+AJ11+BG11+CE11+CW11+DK11) -> 27 | E11: =(D11)/D$9*100 -> 71.052632 | F11: =IF(E11<50,E11, " ") | G11: =IF(E11<30,E11, " ") | M11: =SUM(H11:L11) -> 0 | N11: =M11/M$9*100 -> #DIV/0! | W11: 1 | Z11: 1 | AA11: 1 | AB11: 1 | AF11: 1 | AG11: 1 | AJ11: =SUM(O11:AI11) -> 6 | AK11: =AJ11/AJ$9*100 -> 85.714286 | AM11: 1 | AR11: 1 | AX11: 1 | BA11: 1 | BB11: 1 | BD11: 1 | BF11: 1 | BG11: =SUM(AM11:BF11) -> 7 | BH11: =BG11/BG$9*100 -> 50 | BI11: 1 | BJ11: 1 | BO11: 1 | BR11: 1 | BS11: 1 | BT11: 1 | BU11: 1 | BW11: 1 | BX11: 1 | BY11: 1 | CB11: 1 | CC11: 1 | CD11: 1 | CE11: =SUM(BI11:CD11) -> 13 | CF11: =CE11/CE$9*100 -> 92.857143 | CH11: 1 | CW11: =SUM(CG11:CV11) -> 1 | CX11: =CW11/CW$9*100 -> 33.333333 | DK11: =SUM(CY11:DJ11) -> 0 | DL11: =DK11/DK$9*100 -> #DIV/0!
A12: 3 | B12: 0827CI241002 | C12: AARDRA TRIVEDI | D12: =SUM(M12+AJ12+BG12+CE12+CW12+DK12) -> 15 | E12: =(D12)/D$9*100 -> 39.473684 | F12: =IF(E12<50,E12, " ") -> 39.473684 | G12: =IF(E12<30,E12, " ") | M12: =SUM(H12:L12) -> 0 | N12: =M12/M$9*100 -> #DIV/0! | Z12: 1 | AA12: 1 | AB12: 1 | AF12: 1 | AJ12: =SUM(O12:AI12) -> 4 | AK12: =AJ12/AJ$9*100 -> 57.142857 | AM12: 1 | AN12: 1 | AO12: 1 | AP12: 1 | AS12: 1 | AX12: 1 | BA12: 1 | BG12: =SUM(AM12:BF12) -> 7 | BH12: =BG12/BG$9*100 -> 50 | BT12: 1 | BU12: 1 | BY12: 1 | CD12: 1 | CE12: =SUM(BI12:CD12) -> 4 | CF12: =CE12/CE$9*100 -> 28.571429 | CW12: =SUM(CG12:CV12) -> 0 | CX12: =CW12/CW$9*100 -> 0 | DK12: =SUM(CY12:DJ12) -> 0 | DL12: =DK12/DK$9*100 -> #DIV/0!
A13: 4 | B13: 0827CI241003 | C13: AARNA DUBEY | D13: =SUM(M13+AJ13+BG13+CE13+CW13+DK13) -> 18 | E13: =(D13)/D$9*100 -> 47.368421 | F13: =IF(E13<50,E13, " ") -> 47.368421 | G13: =IF(E13<30,E13, " ") | M13: =SUM(H13:L13) -> 0 | N13: =M13/M$9*100 -> #DIV/0! | Z13: 1 | AA13: 1 | AB13: 1 | AF13: 1 | AJ13: =SUM(O13:AI13) -> 4 | AK13: =AJ13/AJ$9*100 -> 57.142857 | AM13: 1 | AN13: 1 | AO13: 1 | AP13: 1 | AS13: 1 | AX13: 1 | BA13: 1 | BF13: 1 | BG13: =SUM(AM13:BF13) -> 8 | BH13: =BG13/BG$9*100 -> 57.142857 | BJ13: 1 | BO13: 1 | BT13: 1 | BU13: 1 | BY13: 1 | CD13: 1 | CE13: =SUM(BI13:CD13) -> 6 | CF13: =CE13/CE$9*100 -> 42.857143 | CW13: =SUM(CG13:CV13) -> 0 | CX13: =CW13/CW$9*100 -> 0 | DK13: =SUM(CY13:DJ13) -> 0 | DL13: =DK13/DK$9*100 -> #DIV/0!
A14: 5 | B14: 0827CI241004 | C14: AASHI BINDAL | D14: =SUM(M14+AJ14+BG14+CE14+CW14+DK14) -> 21 | E14: =(D14)/D$9*100 -> 55.263158 | F14: =IF(E14<50,E14, " ") | G14: =IF(E14<30,E14, " ") | M14: =SUM(H14:L14) -> 0 | N14: =M14/M$9*100 -> #DIV/0! | W14: 1 | AA14: 1 | AB14: 1 | AC14: 1 | AF14: 1 | AG14: 1 | AJ14: =SUM(O14:AI14) -> 6 | AK14: =AJ14/AJ$9*100 -> 85.714286 | AV14: 1 | AX14: 1 | BA14: 1 | BB14: 1 | BC14: 1 | BD14: 1 | BG14: =SUM(AM14:BF14) -> 6 | BH14: =BG14/BG$9*100 -> 42.857143 | BI14: 1 | BJ14: 1 | BO14: 1 | BS14: 1 | BT14: 1 | BX14: 1 | BY14: 1 | CD14: 1 | CE14: =SUM(BI14:CD14) -> 8 | CF14: =CE14/CE$9*100 -> 57.142857 | CG14: 1 | CW14: =SUM(CG14:CV14) -> 1 | CX14: =CW14/CW$9*100 -> 33.333333 | DK14: =SUM(CY14:DJ14) -> 0 | DL14: =DK14/DK$9*100 -> #DIV/0!
A15: 6 | B15: 0827CI241005 | C15: AASHI SAJJAN | D15: =SUM(M15+AJ15+BG15+CE15+CW15+DK15) -> 20 | E15: =(D15)/D$9*100 -> 52.631579 | F15: =IF(E15<50,E15, " ") | G15: =IF(E15<30,E15, " ") | M15: =SUM(H15:L15) -> 0 | N15: =M15/M$9*100 -> #DIV/0! | AA15: 1 | AB15: 1 | AC15: 1 | AF15: 1 | AG15: 1 | AJ15: =SUM(O15:AI15) -> 5 | AK15: =AJ15/AJ$9*100 -> 71.428571 | AV15: 1 | AX15: 1 | BA15: 1 | BC15: 1 | BD15: 1 | BG15: =SUM(AM15:BF15) -> 5 | BH15: =BG15/BG$9*100 -> 35.714286 | BI15: 1 | BJ15: 1 | BO15: 1 | BR15: 1 | BS15: 1 | BT15: 1 | BX15: 1 | CB15: 1 | CD15: 1 | CE15: =SUM(BI15:CD15) -> 9 | CF15: =CE15/CE$9*100 -> 64.285714 | CG15: 1 | CW15: =SUM(CG15:CV15) -> 1 | CX15: =CW15/CW$9*100 -> 33.333333 | DK15: =SUM(CY15:DJ15) -> 0 | DL15: =DK15/DK$9*100 -> #DIV/0!
A16: 7 | B16: 0827CI241006 | C16: AAYUSH DHAKAD | D16: =SUM(M16+AJ16+BG16+CE16+CW16+DK16) -> 7 | E16: =(D16)/D$9*100 -> 18.421053 | F16: =IF(E16<50,E16, " ") -> 18.421053 | G16: =IF(E16<30,E16, " ") -> 18.421053 | M16: =SUM(H16:L16) -> 0 | N16: =M16/M$9*100 -> #DIV/0! | AB16: 1 | AC16: 1 | AJ16: =SUM(O16:AI16) -> 2 | AK16: =AJ16/AJ$9*100 -> 28.571429 | AM16: 1 | AO16: 1 | AP16: 1 | BA16: 1 | BD16: 1 | BG16: =SUM(AM16:BF16) -> 5 | BH16: =BG16/BG$9*100 -> 35.714286 | CE16: =SUM(BI16:CD16) -> 0 | CF16: =CE16/CE$9*100 -> 0 | CW16: =SUM(CG16:CV16) -> 0 | CX16: =CW16/CW$9*100 -> 0 | DK16: =SUM(CY16:DJ16) -> 0 | DL16: =DK16/DK$9*100 -> #DIV/0!
A17: 8 | B17: 0827CI241007 | C17: ADARSH PATHADE | D17: =SUM(M17+AJ17+BG17+CE17+CW17+DK17) -> 11 | E17: =(D17)/D$9*100 -> 28.947368 | F17: =IF(E17<50,E17, " ") -> 28.947368 | G17: =IF(E17<30,E17, " ") -> 28.947368 | M17: =SUM(H17:L17) -> 0 | N17: =M17/M$9*100 -> #DIV/0! | AB17: 1 | AC17: 1 | AJ17: =SUM(O17:AI17) -> 2 | AK17: =AJ17/AJ$9*100 -> 28.571429 | BA17: 1 | BG17: =SUM(AM17:BF17) -> 1 | BH17: =BG17/BG$9*100 -> 7.1428571 | BJ17: 1 | BR17: 1 | BT17: 1 | BW17: 1 | BY17: 1 | CB17: 1 | CD17: 1 | CE17: =SUM(BI17:CD17) -> 7 | CF17: =CE17/CE$9*100 -> 50 | CG17: 1 | CW17: =SUM(CG17:CV17) -> 1 | CX17: =CW17/CW$9*100 -> 33.333333 | DK17: =SUM(CY17:DJ17) -> 0 | DL17: =DK17/DK$9*100 -> #DIV/0!
A18: 9 | B18: 0827CI241008 | C18: ADITI MISHRA | D18: =SUM(M18+AJ18+BG18+CE18+CW18+DK18) -> 14 | E18: =(D18)/D$9*100 -> 36.842105 | F18: =IF(E18<50,E18, " ") -> 36.842105 | G18: =IF(E18<30,E18, " ") | M18: =SUM(H18:L18) -> 0 | N18: =M18/M$9*100 -> #DIV/0! | AC18: 1 | AG18: 1 | AJ18: =SUM(O18:AI18) -> 2 | AK18: =AJ18/AJ$9*100 -> 28.571429 | AM18: 1 | AO18: 1 | AP18: 1 | AR18: 1 | BA18: 1 | BG18: =SUM(AM18:BF18) -> 5 | BH18: =BG18/BG$9*100 -> 35.714286 | BI18: 1 | BO18: 1 | BS18: 1 | BY18: 1 | CB18: 1 | CD18: 1 | CE18: =SUM(BI18:CD18) -> 6 | CF18: =CE18/CE$9*100 -> 42.857143 | CG18: 1 | CW18: =SUM(CG18:CV18) -> 1 | CX18: =CW18/CW$9*100 -> 33.333333 | DK18: =SUM(CY18:DJ18) -> 0 | DL18: =DK18/DK$9*100 -> #DIV/0!
A19: 10 | B19: 0827CI241009 | C19: ADITYA TRIPATHI | D19: =SUM(M19+AJ19+BG19+CE19+CW19+DK19) -> 22 | E19: =(D19)/D$9*100 -> 57.894737 | F19: =IF(E19<50,E19, " ") | G19: =IF(E19<30,E19, " ") | M19: =SUM(H19:L19) -> 0 | N19: =M19/M$9*100 -> #DIV/0! | AB19: 1 | AC19: 1 | AG19: 1 | AJ19: =SUM(O19:AI19) -> 3 | AK19: =AJ19/AJ$9*100 -> 42.857143 | AM19: 1 | AN19: 1 | AO19: 1 | AP19: 1 | AR19: 1 | AS19: 1 | AV19: 1 | AX19: 1 | BA19: 1 | BB19: 1 | BC19: 1 | BG19: =SUM(AM19:BF19) -> 11 | BH19: =BG19/BG$9*100 -> 78.571429 | BO19: 1 | BR19: 1 | BS19: 1 | BT19: 1 | BU19: 1 | BX19: 1 | BY19: 1 | CD19: 1 | CE19: =SUM(BI19:CD19) -> 8 | CF19: =CE19/CE$9*100 -> 57.142857 | CW19: =SUM(CG19:CV19) -> 0 | CX19: =CW19/CW$9*100 -> 0 | DK19: =SUM(CY19:DJ19) -> 0 | DL19: =DK19/DK$9*100 -> #DIV/0!
A20: 11 | B20: 0827CI241010 | C20: ADWITIYA VERMA | D20: =SUM(M20+AJ20+BG20+CE20+CW20+DK20) -> 28 | E20: =(D20)/D$9*100 -> 73.684211 | F20: =IF(E20<50,E20, " ") | G20: =IF(E20<30,E20, " ") | M20: =SUM(H20:L20) -> 0 | N20: =M20/M$9*100 -> #DIV/0! | W20: 1 | Z20: 1 | AA20: 1 | AB20: 1 | AC20: 1 | AF20: 1 | AG20: 1 | AJ20: =SUM(O20:AI20) -> 7 | AK20: =AJ20/AJ$9*100 -> 100 | AM20: 1 | AO20: 1 | AP20: 1 | AR20: 1 | AS20: 1 | AX20: 1 | BA20: 1 | BC20: 1 | BD20: 1 | BG20: =SUM(AM20:BF20) -> 9 | BH20: =BG20/BG$9*100 -> 64.285714 | BI20: 1 | BJ20: 1 | BO20: 1 | BR20: 1 | BS20: 1 | BT20: 1 | BU20: 1 | BX20: 1 | BY20: 1 | CC20: 1 | CD20: 1 | CE20: =SUM(BI20:CD20) -> 11 | CF20: =CE20/CE$9*100 -> 78.571429 | CG20: 1 | CW20: =SUM(CG20:CV20) -> 1 | CX20: =CW20/CW$9*100 -> 33.333333 | DK20: =SUM(CY20:DJ20) -> 0 | DL20: =DK20/DK$9*100 -> #DIV/0!
A21: 12 | B21: 0827CI241011 | C21: AKSHADA ANDHALE | D21: =SUM(M21+AJ21+BG21+CE21+CW21+DK21) -> 16 | E21: =(D21)/D$9*100 -> 42.105263 | F21: =IF(E21<50,E21, " ") -> 42.105263 | G21: =IF(E21<30,E21, " ") | M21: =SUM(H21:L21) -> 0 | N21: =M21/M$9*100 -> #DIV/0! | W21: 1 | Z21: 1 | AG21: 1 | AJ21: =SUM(O21:AI21) -> 3 | AK21: =AJ21/AJ$9*100 -> 42.857143 | AM21: 1 | AO21: 1 | AP21: 1 | AQ21: 1 | AX21: 1 | BA21: 1 | BG21: =SUM(AM21:BF21) -> 6 | BH21: =BG21/BG$9*100 -> 42.857143 | BJ21: 1 | BO21: 1 | BS21: 1 | BX21: 1 | BY21: 1 | CD21: 1 | CE21: =SUM(BI21:CD21) -> 6 | CF21: =CE21/CE$9*100 -> 42.857143 | CG21: 1 | CW21: =SUM(CG21:CV21) -> 1 | CX21: =CW21/CW$9*100 -> 33.333333 | DK21: =SUM(CY21:DJ21) -> 0 | DL21: =DK21/DK$9*100 -> #DIV/0!
A22: 13 | B22: 0827CI241012 | C22: AKSHARA MANDLIYA | D22: =SUM(M22+AJ22+BG22+CE22+CW22+DK22) -> 18 | E22: =(D22)/D$9*100 -> 47.368421 | F22: =IF(E22<50,E22, " ") -> 47.368421 | G22: =IF(E22<30,E22, " ") | M22: =SUM(H22:L22) -> 0 | N22: =M22/M$9*100 -> #DIV/0! | AC22: 1 | AG22: 1 | AJ22: =SUM(O22:AI22) -> 2 | AK22: =AJ22/AJ$9*100 -> 28.571429 | AM22: 1 | AO22: 1 | AP22: 1 | AR22: 1 | BA22: 1 | BG22: =SUM(AM22:BF22) -> 5 | BH22: =BG22/BG$9*100 -> 35.714286 | BI22: 1 | BJ22: 1 | BO22: 1 | BR22: 1 | BS22: 1 | BT22: 1 | BY22: 1 | CB22: 1 | CC22: 1 | CD22: 1 | CE22: =SUM(BI22:CD22) -> 10 | CF22: =CE22/CE$9*100 -> 71.428571 | CG22: 1 | CW22: =SUM(CG22:CV22) -> 1 | CX22: =CW22/CW$9*100 -> 33.333333 | DK22: =SUM(CY22:DJ22) -> 0 | DL22: =DK22/DK$9*100 -> #DIV/0!
A23: 14 | B23: 0827CI241013 | C23: ALOK KUMAWAT | D23: =SUM(M23+AJ23+BG23+CE23+CW23+DK23) -> 10 | E23: =(D23)/D$9*100 -> 26.315789 | F23: =IF(E23<50,E23, " ") -> 26.315789 | G23: =IF(E23<30,E23, " ") -> 26.315789 | M23: =SUM(H23:L23) -> 0 | N23: =M23/M$9*100 -> #DIV/0! | AG23: 1 | AJ23: =SUM(O23:AI23) -> 1 | AK23: =AJ23/AJ$9*100 -> 14.285714 | AM23: 1 | BA23: 1 | BC23: 1 | BD23: 1 | BG23: =SUM(AM23:BF23) -> 4 | BH23: =BG23/BG$9*100 -> 28.571429 | BJ23: 1 | BX23: 1 | BY23: 1 | CE23: =SUM(BI23:CD23) -> 3 | CF23: =CE23/CE$9*100 -> 21.428571 | CG23: 1 | CH23: 1 | CW23: =SUM(CG23:CV23) -> 2 | CX23: =CW23/CW$9*100 -> 66.666667 | DK23: =SUM(CY23:DJ23) -> 0 | DL23: =DK23/DK$9*100 -> #DIV/0!
A24: 15 | B24: 0827CI241014 | C24: ANANYA AGRAWAL | D24: =SUM(M24+AJ24+BG24+CE24+CW24+DK24) -> 12 | E24: =(D24)/D$9*100 -> 31.578947 | F24: =IF(E24<50,E24, " ") -> 31.578947 | G24: =IF(E24<30,E24, " ") | M24: =SUM(H24:L24) -> 0 | N24: =M24/M$9*100 -> #DIV/0! | AJ24: =SUM(O24:AI24) -> 0 | AK24: =AJ24/AJ$9*100 -> 0 | AM24: 1 | AO24: 1 | AP24: 1 | AX24: 1 | BA24: 1 | BG24: =SUM(AM24:BF24) -> 5 | BH24: =BG24/BG$9*100 -> 35.714286 | BJ24: 1 | BO24: 1 | BS24: 1 | BX24: 1 | BY24: 1 | CD24: 1 | CE24: =SUM(BI24:CD24) -> 6 | CF24: =CE24/CE$9*100 -> 42.857143 | CG24: 1 | CW24: =SUM(CG24:CV24) -> 1 | CX24: =CW24/CW$9*100 -> 33.333333 | DK24: =SUM(CY24:DJ24) -> 0 | DL24: =DK24/DK$9*100 -> #DIV/0!
A25: 16 | B25: 0827CI241015 | C25: ANANYA YADAV | D25: =SUM(M25+AJ25+BG25+CE25+CW25+DK25) -> 14 | E25: =(D25)/D$9*100 -> 36.842105 | F25: =IF(E25<50,E25, " ") -> 36.842105 | G25: =IF(E25<30,E25, " ") | M25: =SUM(H25:L25) -> 0 | N25: =M25/M$9*100 -> #DIV/0! | AC25: 1 | AG25: 1 | AJ25: =SUM(O25:AI25) -> 2 | AK25: =AJ25/AJ$9*100 -> 28.571429 | AM25: 1 | AR25: 1 | BA25: 1 | BG25: =SUM(AM25:BF25) -> 3 | BH25: =BG25/BG$9*100 -> 21.428571 | BI25: 1 | BJ25: 1 | BO25: 1 | BR25: 1 | BX25: 1 | BY25: 1 | CB25: 1 | CD25: 1 | CE25: =SUM(BI25:CD25) -> 8 | CF25: =CE25/CE$9*100 -> 57.142857 | CG25: 1 | CW25: =SUM(CG25:CV25) -> 1 | CX25: =CW25/CW$9*100 -> 33.333333 | DK25: =SUM(CY25:DJ25) -> 0 | DL25: =DK25/DK$9*100 -> #DIV/0!
A26: 17 | B26: 0827CI241016 | C26: ANJALI KHANDELWAL | D26: =SUM(M26+AJ26+BG26+CE26+CW26+DK26) -> 23 | E26: =(D26)/D$9*100 -> 60.526316 | F26: =IF(E26<50,E26, " ") | G26: =IF(E26<30,E26, " ") | M26: =SUM(H26:L26) -> 0 | N26: =M26/M$9*100 -> #DIV/0! | W26: 1 | Z26: 1 | AB26: 1 | AF26: 1 | AG26: 1 | AJ26: =SUM(O26:AI26) -> 5 | AK26: =AJ26/AJ$9*100 -> 71.428571 | AR26: 1 | AS26: 1 | AV26: 1 | AX26: 1 | BA26: 1 | BC26: 1 | BD26: 1 | BF26: 1 | BG26: =SUM(AM26:BF26) -> 8 | BH26: =BG26/BG$9*100 -> 57.142857 | BI26: 1 | BJ26: 1 | BS26: 1 | BT26: 1 | BU26: 1 | BX26: 1 | BY26: 1 | CB26: 1 | CC26: 1 | CD26: 1 | CE26: =SUM(BI26:CD26) -> 10 | CF26: =CE26/CE$9*100 -> 71.428571 | CW26: =SUM(CG26:CV26) -> 0 | CX26: =CW26/CW$9*100 -> 0 | DK26: =SUM(CY26:DJ26) -> 0 | DL26: =DK26/DK$9*100 -> #DIV/0!
A27: 18 | B27: 0827CI241017 | C27: ANMOL MANDLAWADIA | D27: =SUM(M27+AJ27+BG27+CE27+CW27+DK27) -> 16 | E27: =(D27)/D$9*100 -> 42.105263 | F27: =IF(E27<50,E27, " ") -> 42.105263 | G27: =IF(E27<30,E27, " ") | M27: =SUM(H27:L27) -> 0 | N27: =M27/M$9*100 -> #DIV/0! | AF27: 1 | AJ27: =SUM(O27:AI27) -> 1 | AK27: =AJ27/AJ$9*100 -> 14.285714 | AM27: 1 | AR27: 1 | BA27: 1 | BF27: 1 | BG27: =SUM(AM27:BF27) -> 4 | BH27: =BG27/BG$9*100 -> 28.571429 | BI27: 1 | BO27: 1 | BS27: 1 | BU27: 1 | BX27: 1 | BZ27: 1 | CC27: 1 | CD27: 1 | CE27: =SUM(BI27:CD27) -> 8 | CF27: =CE27/CE$9*100 -> 57.142857 | CG27: 1 | CH27: 1 | CI27: 1 | CW27: =SUM(CG27:CV27) -> 3 | CX27: =CW27/CW$9*100 -> 100 | DK27: =SUM(CY27:DJ27) -> 0 | DL27: =DK27/DK$9*100 -> #DIV/0!
A28: 19 | B28: 0827CI241018 | C28: ANMOL SINGH BASSAN | D28: =SUM(M28+AJ28+BG28+CE28+CW28+DK28) -> 17 | E28: =(D28)/D$9*100 -> 44.736842 | F28: =IF(E28<50,E28, " ") -> 44.736842 | G28: =IF(E28<30,E28, " ") | M28: =SUM(H28:L28) -> 0 | N28: =M28/M$9*100 -> #DIV/0! | AB28: 1 | AG28: 1 | AJ28: =SUM(O28:AI28) -> 2 | AK28: =AJ28/AJ$9*100 -> 28.571429 | AM28: 1 | AN28: 1 | AO28: 1 | AP28: 1 | AV28: 1 | BA28: 1 | BC28: 1 | BD28: 1 | BG28: =SUM(AM28:BF28) -> 8 | BH28: =BG28/BG$9*100 -> 57.142857 | BJ28: 1 | BO28: 1 | BS28: 1 | BW28: 1 | BX28: 1 | CE28: =SUM(BI28:CD28) -> 5 | CF28: =CE28/CE$9*100 -> 35.714286 | CG28: 1 | CH28: 1 | CW28: =SUM(CG28:CV28) -> 2 | CX28: =CW28/CW$9*100 -> 66.666667 | DK28: =SUM(CY28:DJ28) -> 0 | DL28: =DK28/DK$9*100 -> #DIV/0!
A29: 20 | B29: 0827CI241019 | C29: ANSHIKA KHARE | D29: =SUM(M29+AJ29+BG29+CE29+CW29+DK29) -> 16 | E29: =(D29)/D$9*100 -> 42.105263 | F29: =IF(E29<50,E29, " ") -> 42.105263 | G29: =IF(E29<30,E29, " ") | M29: =SUM(H29:L29) -> 0 | N29: =M29/M$9*100 -> #DIV/0! | AC29: 1 | AG29: 1 | AJ29: =SUM(O29:AI29) -> 2 | AK29: =AJ29/AJ$9*100 -> 28.571429 | AO29: 1 | AP29: 1 | AS29: 1 | BA29: 1 | BC29: 1 | BG29: =SUM(AM29:BF29) -> 5 | BH29: =BG29/BG$9*100 -> 35.714286 | BI29: 1 | BJ29: 1 | BO29: 1 | BR29: 1 | BT29: 1 | BX29: 1 | BY29: 1 | CD29: 1 | CE29: =SUM(BI29:CD29) -> 8 | CF29: =CE29/CE$9*100 -> 57.142857 | CG29: 1 | CW29: =SUM(CG29:CV29) -> 1 | CX29: =CW29/CW$9*100 -> 33.333333 | DK29: =SUM(CY29:DJ29) -> 0 | DL29: =DK29/DK$9*100 -> #DIV/0!
A30: 21 | B30: 0827CI241020 | C30: ANSHIKA SHRIVASTAV | D30: =SUM(M30+AJ30+BG30+CE30+CW30+DK30) -> 1 | E30: =(D30)/D$9*100 -> 2.6315789 | F30: =IF(E30<50,E30, " ") -> 2.6315789 | G30: =IF(E30<30,E30, " ") -> 2.6315789 | M30: =SUM(H30:L30) -> 0 | N30: =M30/M$9*100 -> #DIV/0! | AJ30: =SUM(O30:AI30) -> 0 | AK30: =AJ30/AJ$9*100 -> 0 | BG30: =SUM(AM30:BF30) -> 0 | BH30: =BG30/BG$9*100 -> 0 | BY30: 1 | CE30: =SUM(BI30:CD30) -> 1 | CF30: =CE30/CE$9*100 -> 7.1428571 | CW30: =SUM(CG30:CV30) -> 0 | CX30: =CW30/CW$9*100 -> 0 | DK30: =SUM(CY30:DJ30) -> 0 | DL30: =DK30/DK$9*100 -> #DIV/0!
A31: 22 | B31: 0827CI241021 | C31: ANUJ MALVIYA | D31: =SUM(M31+AJ31+BG31+CE31+CW31+DK31) -> 15 | E31: =(D31)/D$9*100 -> 39.473684 | F31: =IF(E31<50,E31, " ") -> 39.473684 | G31: =IF(E31<30,E31, " ") | M31: =SUM(H31:L31) -> 0 | N31: =M31/M$9*100 -> #DIV/0! | AJ31: =SUM(O31:AI31) -> 0 | AK31: =AJ31/AJ$9*100 -> 0 | AN31: 1 | AR31: 1 | AS31: 1 | AX31: 1 | BA31: 1 | BF31: 1 | BG31: =SUM(AM31:BF31) -> 6 | BH31: =BG31/BG$9*100 -> 42.857143 | BJ31: 1 | BO31: 1 | BT31: 1 | BW31: 1 | BX31: 1 | BZ31: 1 | CB31: 1 | CD31: 1 | CE31: =SUM(BI31:CD31) -> 8 | CF31: =CE31/CE$9*100 -> 57.142857 | CG31: 1 | CW31: =SUM(CG31:CV31) -> 1 | CX31: =CW31/CW$9*100 -> 33.333333 | DK31: =SUM(CY31:DJ31) -> 0 | DL31: =DK31/DK$9*100 -> #DIV/0!
A32: 23 | B32: 0827CI241022 | C32: ANURAG CHOUDHARY | D32: =SUM(M32+AJ32+BG32+CE32+CW32+DK32) -> 19 | E32: =(D32)/D$9*100 -> 50 | F32: =IF(E32<50,E32, " ") | G32: =IF(E32<30,E32, " ") | M32: =SUM(H32:L32) -> 0 | N32: =M32/M$9*100 -> #DIV/0! | W32: 1 | AB32: 1 | AC32: 1 | AF32: 1 | AG32: 1 | AJ32: =SUM(O32:AI32) -> 5 | AK32: =AJ32/AJ$9*100 -> 71.428571 | AM32: 1 | AP32: 1 | AR32: 1 | BA32: 1 | BD32: 1 | BG32: =SUM(AM32:BF32) -> 5 | BH32: =BG32/BG$9*100 -> 35.714286 | BI32: 1 | BS32: 1 | BW32: 1 | BX32: 1 | BZ32: 1 | CC32: 1 | CD32: 1 | CE32: =SUM(BI32:CD32) -> 7 | CF32: =CE32/CE$9*100 -> 50 | CG32: 1 | CH32: 1 | CW32: =SUM(CG32:CV32) -> 2 | CX32: =CW32/CW$9*100 -> 66.666667 | DK32: =SUM(CY32:DJ32) -> 0 | DL32: =DK32/DK$9*100 -> #DIV/0!
A33: 24 | B33: 0827CI241023 | C33: ANUSHKA SISODIYA | D33: =SUM(M33+AJ33+BG33+CE33+CW33+DK33) -> 16 | E33: =(D33)/D$9*100 -> 42.105263 | F33: =IF(E33<50,E33, " ") -> 42.105263 | G33: =IF(E33<30,E33, " ") | M33: =SUM(H33:L33) -> 0 | N33: =M33/M$9*100 -> #DIV/0! | Z33: 1 | AA33: 1 | AB33: 1 | AF33: 1 | AG33: 1 | AJ33: =SUM(O33:AI33) -> 5 | AK33: =AJ33/AJ$9*100 -> 71.428571 | AM33: 1 | AN33: 1 | AO33: 1 | AP33: 1 | AS33: 1 | AX33: 1 | BA33: 1 | BG33: =SUM(AM33:BF33) -> 7 | BH33: =BG33/BG$9*100 -> 50 | BO33: 1 | BT33: 1 | BY33: 1 | CD33: 1 | CE33: =SUM(BI33:CD33) -> 4 | CF33: =CE33/CE$9*100 -> 28.571429 | CW33: =SUM(CG33:CV33) -> 0 | CX33: =CW33/CW$9*100 -> 0 | DK33: =SUM(CY33:DJ33) -> 0 | DL33: =DK33/DK$9*100 -> #DIV/0!
A34: 25 | B34: 0827CI241024 | C34: ARNAV TIWARI | D34: =SUM(M34+AJ34+BG34+CE34+CW34+DK34) -> 23 | E34: =(D34)/D$9*100 -> 60.526316 | F34: =IF(E34<50,E34, " ") | G34: =IF(E34<30,E34, " ") | M34: =SUM(H34:L34) -> 0 | N34: =M34/M$9*100 -> #DIV/0! | W34: 1 | AA34: 1 | AB34: 1 | AC34: 1 | AF34: 1 | AG34: 1 | AJ34: =SUM(O34:AI34) -> 6 | AK34: =AJ34/AJ$9*100 -> 85.714286 | AM34: 1 | AN34: 1 | AO34: 1 | AP34: 1 | AR34: 1 | BA34: 1 | BB34: 1 | BC34: 1 | BF34: 1 | BG34: =SUM(AM34:BF34) -> 9 | BH34: =BG34/BG$9*100 -> 64.285714 | BI34: 1 | BJ34: 1 | BO34: 1 | BS34: 1 | BT34: 1 | BY34: 1 | BZ34: 1 | CD34: 1 | CE34: =SUM(BI34:CD34) -> 8 | CF34: =CE34/CE$9*100 -> 57.142857 | CW34: =SUM(CG34:CV34) -> 0 | CX34: =CW34/CW$9*100 -> 0 | DK34: =SUM(CY34:DJ34) -> 0 | DL34: =DK34/DK$9*100 -> #DIV/0!
A35: 26 | B35: 0827CI241025 | C35: ARVIND RUHELA | D35: =SUM(M35+AJ35+BG35+CE35+CW35+DK35) -> 17 | E35: =(D35)/D$9*100 -> 44.736842 | F35: =IF(E35<50,E35, " ") -> 44.736842 | G35: =IF(E35<30,E35, " ") | M35: =SUM(H35:L35) -> 0 | N35: =M35/M$9*100 -> #DIV/0! | W35: 1 | AB35: 1 | AC35: 1 | AF35: 1 | AJ35: =SUM(O35:AI35) -> 4 | AK35: =AJ35/AJ$9*100 -> 57.142857 | AR35: 1 | BA35: 1 | BD35: 1 | BG35: =SUM(AM35:BF35) -> 3 | BH35: =BG35/BG$9*100 -> 21.428571 | BI35: 1 | BU35: 1 | BW35: 1 | BX35: 1 | BZ35: 1 | CC35: 1 | CD35: 1 | CE35: =SUM(BI35:CD35) -> 7 | CF35: =CE35/CE$9*100 -> 50 | CG35: 1 | CH35: 1 | CI35: 1 | CW35: =SUM(CG35:CV35) -> 3 | CX35: =CW35/CW$9*100 -> 100 | DK35: =SUM(CY35:DJ35) -> 0 | DL35: =DK35/DK$9*100 -> #DIV/0!
A36: 27 | B36: 0827CI241026 | C36: ASHU GARG | D36: =SUM(M36+AJ36+BG36+CE36+CW36+DK36) -> 25 | E36: =(D36)/D$9*100 -> 65.789474 | F36: =IF(E36<50,E36, " ") | G36: =IF(E36<30,E36, " ") | M36: =SUM(H36:L36) -> 0 | N36: =M36/M$9*100 -> #DIV/0! | AA36: 1 | AB36: 1 | AC36: 1 | AG36: 1 | AJ36: =SUM(O36:AI36) -> 4 | AK36: =AJ36/AJ$9*100 -> 57.142857 | AM36: 1 | AN36: 1 | AO36: 1 | AP36: 1 | AR36: 1 | AS36: 1 | AV36: 1 | AX36: 1 | BA36: 1 | BB36: 1 | BC36: 1 | BD36: 1 | BG36: =SUM(AM36:BF36) -> 12 | BH36: =BG36/BG$9*100 -> 85.714286 | BI36: 1 | BO36: 1 | BR36: 1 | BS36: 1 | BT36: 1 | BU36: 1 | BX36: 1 | BY36: 1 | CD36: 1 | CE36: =SUM(BI36:CD36) -> 9 | CF36: =CE36/CE$9*100 -> 64.285714 | CW36: =SUM(CG36:CV36) -> 0 | CX36: =CW36/CW$9*100 -> 0 | DK36: =SUM(CY36:DJ36) -> 0 | DL36: =DK36/DK$9*100 -> #DIV/0!
A37: 28 | B37: 0827CI241027 | C37: ASHWIN PATEL | D37: =SUM(M37+AJ37+BG37+CE37+CW37+DK37) -> 9 | E37: =(D37)/D$9*100 -> 23.684211 | F37: =IF(E37<50,E37, " ") -> 23.684211 | G37: =IF(E37<30,E37, " ") -> 23.684211 | M37: =SUM(H37:L37) -> 0 | N37: =M37/M$9*100 -> #DIV/0! | AJ37: =SUM(O37:AI37) -> 0 | AK37: =AJ37/AJ$9*100 -> 0 | AN37: 1 | AO37: 1 | AP37: 1 | AV37: 1 | BA37: 1 | BC37: 1 | BD37: 1 | BG37: =SUM(AM37:BF37) -> 7 | BH37: =BG37/BG$9*100 -> 50 | BO37: 1 | BW37: 1 | CE37: =SUM(BI37:CD37) -> 2 | CF37: =CE37/CE$9*100 -> 14.285714 | CW37: =SUM(CG37:CV37) -> 0 | CX37: =CW37/CW$9*100 -> 0 | DK37: =SUM(CY37:DJ37) -> 0 | DL37: =DK37/DK$9*100 -> #DIV/0!
A38: 29 | B38: 0827CI241028 | C38: AYUSH CHOUHAN | D38: =SUM(M38+AJ38+BG38+CE38+CW38+DK38) -> 18 | E38: =(D38)/D$9*100 -> 47.368421 | F38: =IF(E38<50,E38, " ") -> 47.368421 | G38: =IF(E38<30,E38, " ") | M38: =SUM(H38:L38) -> 0 | N38: =M38/M$9*100 -> #DIV/0! | AB38: 1 | AC38: 1 | AF38: 1 | AG38: 1 | AJ38: =SUM(O38:AI38) -> 4 | AK38: =AJ38/AJ$9*100 -> 57.142857 | AM38: 1 | AN38: 1 | AO38: 1 | AP38: 1 | AR38: 1 | BG38: =SUM(AM38:BF38) -> 5 | BH38: =BG38/BG$9*100 -> 35.714286 | BS38: 1 | BT38: 1 | BU38: 1 | BW38: 1 | BY38: 1 | BZ38: 1 | CC38: 1 | CD38: 1 | CE38: =SUM(BI38:CD38) -> 8 | CF38: =CE38/CE$9*100 -> 57.142857 | CG38: 1 | CW38: =SUM(CG38:CV38) -> 1 | CX38: =CW38/CW$9*100 -> 33.333333 | DK38: =SUM(CY38:DJ38) -> 0 | DL38: =DK38/DK$9*100 -> #DIV/0!
A39: 30 | B39: 0827CI241029 | C39: AYUSHI DOSHI | D39: =SUM(M39+AJ39+BG39+CE39+CW39+DK39) -> 23 | E39: =(D39)/D$9*100 -> 60.526316 | F39: =IF(E39<50,E39, " ") | G39: =IF(E39<30,E39, " ") | M39: =SUM(H39:L39) -> 0 | N39: =M39/M$9*100 -> #DIV/0! | AF39: 1 | AG39: 1 | AJ39: =SUM(O39:AI39) -> 2 | AK39: =AJ39/AJ$9*100 -> 28.571429 | AM39: 1 | AN39: 1 | AO39: 1 | AP39: 1 | AR39: 1 | AS39: 1 | BA39: 1 | BB39: 1 | BD39: 1 | BG39: =SUM(AM39:BF39) -> 9 | BH39: =BG39/BG$9*100 -> 64.285714 | BI39: 1 | BJ39: 1 | BO39: 1 | BS39: 1 | BT39: 1 | BU39: 1 | BY39: 1 | BZ39: 1 | CB39: 1 | CC39: 1 | CD39: 1 | CE39: =SUM(BI39:CD39) -> 11 | CF39: =CE39/CE$9*100 -> 78.571429 | CG39: 1 | CW39: =SUM(CG39:CV39) -> 1 | CX39: =CW39/CW$9*100 -> 33.333333 | DK39: =SUM(CY39:DJ39) -> 0 | DL39: =DK39/DK$9*100 -> #DIV/0!
A40: 31 | B40: 0827CI241030 | C40: BHAGYESH JAIN | D40: =SUM(M40+AJ40+BG40+CE40+CW40+DK40) -> 20 | E40: =(D40)/D$9*100 -> 52.631579 | F40: =IF(E40<50,E40, " ") | G40: =IF(E40<30,E40, " ") | M40: =SUM(H40:L40) -> 0 | N40: =M40/M$9*100 -> #DIV/0! | W40: 1 | Z40: 1 | AA40: 1 | AB40: 1 | AF40: 1 | AG40: 1 | AJ40: =SUM(O40:AI40) -> 6 | AK40: =AJ40/AJ$9*100 -> 85.714286 | AM40: 1 | AR40: 1 | AS40: 1 | BA40: 1 | BF40: 1 | BG40: =SUM(AM40:BF40) -> 5 | BH40: =BG40/BG$9*100 -> 35.714286 | BI40: 1 | BO40: 1 | BR40: 1 | BS40: 1 | BW40: 1 | CB40: 1 | CD40: 1 | CE40: =SUM(BI40:CD40) -> 7 | CF40: =CE40/CE$9*100 -> 50 | CG40: 1 | CH40: 1 | CW40: =SUM(CG40:CV40) -> 2 | CX40: =CW40/CW$9*100 -> 66.666667 | DK40: =SUM(CY40:DJ40) -> 0 | DL40: =DK40/DK$9*100 -> #DIV/0!
...

Sheet 402 L
A1: CSIT-402 L
A2: Faculty Name: | C2: Dr. Asmita Rajawat
A3: Subject Name : | C3: Analog and Digital Communication
A4: Subject Code : | C4: CSIT-402
A5: Start Date | C5: 46104
A6: End Date
H7: 1 | I7: 2 | J7: 3 | K7: 4 | L7: 5 | O7: 1 | P7: 2 | Q7: 3 | R7: 4 | S7: 5 | T7: 6 | U7: 7 | V7: 8 | W7: 9 | X7: 10 | Y7: 11 | Z7: 12 | AA7: 13 | AB7: 14 | AC7: 15 | AD7: 16 | AE7: 17 | AF7: 18 | AG7: 19 | AH7: 20 | AI7: 21 | AL7: 1 | AM7: 2 | AN7: 3 | AO7: 4 | AP7: 5 | AQ7: 6 | AR7: 7 | AS7: 8 | AT7: 9 | AU7: 10 | AV7: 11 | AW7: 12 | AX7: 13 | AY7: 14 | AZ7: 15 | BA7: 16 | BB7: 17 | BC7: 18 | BD7: 19 | BE7: 20 | BF7: 21 | BI7: 1 | BJ7: 2 | BK7: 3 | BL7: 4 | BM7: 5 | BN7: 6 | BO7: 7 | BP7: 8 | BQ7: 9 | BR7: 10 | BS7: 11 | BT7: 12 | BU7: 13 | BV7: 14 | BW7: 15 | BX7: 16 | BY7: 17 | BZ7: 18 | CA7: 19 | CB7: 20 | CD7: 21 | CG7: 1 | CH7: 2 | CI7: 3 | CJ7: 4 | CK7: 5 | CL7: 6 | CM7: 7 | CN7: 8 | CO7: 9 | CP7: 10 | CQ7: 11 | CR7: 12
D8: Total Class | E8: OverAll Att. % | F8: Att. 50% | G8: Att. 30% | H8: 46104 | I8: 46105 | J8: 46106 | K8: 46107 | L8: 46111 | M8: MARCH CLASS | N8: MAR % | O8: 46113 | P8: 46114 | Q8: 46115 | R8: 46118 | S8: 46119 | T8: 46120 | U8: 46121 | V8: 46122 | W8: 46125 | X8: 46127 | Y8: 46128 | Z8: 46129 | AA8: 46132 | AB8: 46133 | AC8: 46134 | AD8: 46135 | AE8: 46136 | AF8: 46139 | AG8: 46140 | AH8: 46141 | AI8: 46142 | AJ8: APRIL CLASS | AK8: APRIL % | AL8: 46143 | AM8: 46146 | AN8: 46147 | AO8: 46148 | AP8: 46149 | AQ8: 46150 | AR8: 46153 | AS8: 46154 | AT8: 46155 | AU8: 46156 | AV8: 46157 | AW8: 46160 | AX8: 46161 | AY8: 46162 | AZ8: 46163 | BA8: 46164 | BB8: 46167 | BC8: 46168 | BD8: 46169 | BE8: 46170 | BF8: 46171 | BG8: MAY CLASS | BH8: MAY % | BI8: 46174 | BJ8: 46175 | BK8: 46176 | BL8: 46177 | BM8: 46178 | BN8: 46181 | BO8: 46182 | BP8: 46183 | BQ8: 46184 | BR8: 46185 | BS8: 46188 | BT8: 46189 | BU8: 46190 | BV8: 46191 | BW8: 46192 | BX8: 46195 | BY8: 46196 | BZ8: 46197 | CA8: 46198 | CB8: 46199 | CC8: 46202 | CD8: 46203 | CE8: JUNE CLASS | CF8: JUNE % | CG8: 46204 | CS8: DEC CLASS | CT8: DEC %
A9: S.No. | B9: Enrollment No. | C9: Student Name | D9: =SUM(M9+AJ9+BG9+CE9+CS9) -> 7 | H9: =SUM(H10:H51) -> 0 | I9: =SUM(I10:I51) -> 0 | J9: =SUM(J10:J51) -> 0 | K9: =SUM(K10:K51) -> 0 | L9: =SUM(L10:L51) -> 0 | M9: =COUNTIF(H9:L9,">0") -> 0 | N9: =COUNTIF(H9:L9,">0") -> 0 | O9: =SUM(O10:O51) -> 0 | P9: =SUM(P10:P51) -> 0 | Q9: =SUM(Q10:Q51) -> 0 | R9: =SUM(R10:R51) -> 0 | S9: =SUM(S10:S51) -> 0 | T9: =SUM(T10:T51) -> 0 | U9: =SUM(U10:U51) -> 0 | V9: =SUM(V10:V51) -> 0 | ... AI9: =SUM(AI10:AI51) -> 24 | AJ9: =COUNTIF(O9:AI9,">0") -> 1 | AK9: =SUM(M9+AJ9) -> 1 | AL9: =SUM(AL10:AL51) -> 0 | AM9: =SUM(AM10:AM51) -> 0 | AN9: =SUM(AN10:AN51) -> 0 | AO9: =SUM(AO10:AO51) -> 0 | AP9: =SUM(AP10:AP51) -> 27 | AQ9: =SUM(AQ10:AQ51) -> 0 | AR9: =SUM(AR10:AR51) -> 0 | AS9: =SUM(AS10:AS51) -> 0 | ... BF9: =SUM(BF10:BF51) -> 0 | BG9: =COUNTIF(AL9:BF9,">0") -> 3 | BH9: =SUM(AK9+BG9) -> 4 | BI9: =SUM(BI10:BI51) -> 0 | BJ9: =SUM(BJ10:BJ51) -> 0 | BK9: =SUM(BK10:BK51) -> 0 | BL9: =SUM(BL10:BL51) -> 22 | BM9: =SUM(BM10:BM51) -> 0 | BN9: =SUM(BN10:BN51) -> 0 | BO9: =SUM(BO10:BO51) -> 0 | BP9: =SUM(BP10:BP51) -> 0 | ... CB9: =SUM(CB10:CB51) -> 0 | CC9: =SUM('402'!CC10:CC51) -> 13 | CD9: =SUM(CD10:CD51) -> 0 | CE9: =COUNTIF(BI9:CD9,">0") -> 2 | CF9: =SUM(BH9+CE9) -> 6 | CG9: =SUM(CG11:CG51) -> 32 | CH9: =SUM(CH11:CH51) -> 0 | CI9: =SUM(CI11:CI51) -> 0 | CJ9: =SUM(CJ11:CJ51) -> 0 | CK9: =SUM(CK11:CK51) -> 0 | CL9: =SUM(CL11:CL51) -> 0 | CM9: =SUM(CM11:CM51) -> 0 | CN9: =SUM(CN11:CN51) -> 0 | ... CR9: =SUM(CR11:CR51) -> 0 | CS9: =COUNTIF(CG9:CR9,">0") -> 1 | CT9: =SUM(CF9+CS9) -> 7
A10: 1 | B10: 0827CI231006 | C10: ABHINAV KOURAV | D10: =SUM(M10+AJ10+BG10+CE10+CS10) -> 0 | E10: =(D10)/D$9*100 -> 0 | F10: =IF(E10<50,E10, " ") -> 0 | G10: =IF(E10<30,E10, " ") -> 0 | M10: =SUM(H10:L10) -> 0 | N10: =M10/M$9*100 -> #DIV/0! | AJ10: =SUM(O10:AI10) -> 0 | AK10: =AJ10/AJ$9*100 -> 0 | BG10: =SUM(AL10:BF10) -> 0 | BH10: =BG10/BG$9*100 -> 0 | CE10: =SUM(BI10:CD10) -> 0 | CF10: =CE10/CE$9*100 -> 0 | CS10: =SUM(CG10:CR10) -> 0 | CT10: =CS10/CS$9*100 -> 0
A11: 2 | B11: 0827CI241001 | C11: AANCHAL GUPTA | D11: =SUM(M11+AJ11+BG11+CE11+CS11) -> 5 | E11: =(D11)/D$9*100 -> 71.428571 | F11: =IF(E11<50,E11, " ") | G11: =IF(E11<30,E11, " ") | M11: =SUM(H11:L11) -> 0 | N11: =M11/M$9*100 -> #DIV/0! | AI11: 1 | AJ11: =SUM(O11:AI11) -> 1 | AK11: =AJ11/AJ$9*100 -> 100 | AP11: 1 | BB11: 1 | BG11: =SUM(AL11:BF11) -> 2 | BH11: =BG11/BG$9*100 -> 66.666667 | BL11: 1 | CE11: =SUM(BI11:CD11) -> 1 | CF11: =CE11/CE$9*100 -> 50 | CG11: 1 | CS11: =SUM(CG11:CR11) -> 1 | CT11: =CS11/CS$9*100 -> 100
A12: 3 | B12: 0827CI241002 | C12: AARDRA TRIVEDI | D12: =SUM(M12+AJ12+BG12+CE12+CS12) -> 4 | E12: =(D12)/D$9*100 -> 57.142857 | F12: =IF(E12<50,E12, " ") | G12: =IF(E12<30,E12, " ") | M12: =SUM(H12:L12) -> 0 | N12: =M12/M$9*100 -> #DIV/0! | AJ12: =SUM(O12:AI12) -> 0 | AK12: =AJ12/AJ$9*100 -> 0 | AP12: 1 | AU12: 1 | BG12: =SUM(AL12:BF12) -> 2 | BH12: =BG12/BG$9*100 -> 66.666667 | BL12: 1 | CE12: =SUM(BI12:CD12) -> 1 | CF12: =CE12/CE$9*100 -> 50 | CG12: 1 | CS12: =SUM(CG12:CR12) -> 1 | CT12: =CS12/CS$9*100 -> 100
