Workbook

Sheet 601
A1: CSIT-601
A2: Faculty Name: | C2: Prof. Amrita Jain
A3: Subject Name : | C3: Software Engineering & Agile
A4: Subject Code :
A5: Start Date | C5: 46069
A6: End Date
H7: 1
D8: Total Class | E8: OverAll Att. % | F8: Att. 50% | G8: Att. 30% | H8: 46069 | I8: 46070 | J8: 46071 | K8: 46072 | L8: 46076 | M8: 46077 | N8: 46078 | O8: 46079 | P8: 46080 | Q8: 46081 | R8: FEB CLASS | S8: FEB% | T8: 46085 | U8: 46086 | V8: 46087 | W8: 46090 | X8: 46091 | Y8: 46092 | Z8: 46093 | AA8: 46094 | AB8: 46097 | AC8: 46098 | AD8: 46099 | AE8: 46100 | AF8: 46101 | AG8: 46104 | AH8: 46105 | AI8: 46106 | AJ8: 46107 | AK8: 46111 | AL8: MAR CLASS | AM8: MAR% | AN8: 46113 | AO8: 46114 | AP8: 46115 | AQ8: 46118 | AR8: 46119 | AS8: 46120 | AT8: 46121 | AU8: 46122 | AV8: 46125 | AW8: 46127 | AX8: 46128 | AY8: 46129 | AZ8: 46132 | BA8: 46133 | BB8: 46134 | BC8: 46135 | BD8: 46136 | BE8: 46139 | BF8: 46140 | BG8: 46141 | BH8: 46142 | BI8: APRIL CLASS | BJ8: APRIL % | BK8: 46143 | BL8: 46146 | BM8: 46147 | BN8: 46148 | BO8: 46149 | BP8: 46150 | BQ8: 46153 | BR8: 46154 | BS8: 46155 | BT8: 46156 | BU8: 46157 | BV8: 46160 | BW8: 46161 | BX8: 46162 | BY8: 46163 | BZ8: 46164 | CA8: 46167 | CB8: 46168 | CC8: 46169 | CD8: 46170 | CE8: 46171 | CF8: MAY CLASS | CG8: MAY % | CH8: 46174 | CI8: 46175 | CJ8: 46176 | CK8: 46177 | CL8: 46178 | CM8: 46181 | CN8: 46182 | CO8: 46183 | CP8: 46184 | CQ8: 46185 | CR8: 46186 | CS8: JUNE CLASS | CT8: JUNE% | CU8: SPECIAL LEAVE | CV8: OVER ALL % | CW8: TOTAL CLASS | CX8: REMARK
A9: s.no. | B9: Enrollment NO. | C9: Student Name | D9: =SUM(R9+AL9+BI9+CF9+CS9) -> 27 | H9: =SUM(H10:H92) -> 0 | I9: =SUM(I10:I92) -> 0 | J9: =SUM(J10:J92) -> 0 | K9: =SUM(K10:K92) -> 9 | L9: =SUM(L10:L92) -> 0 | M9: =SUM(M10:M92) -> 31 | N9: =SUM(N10:N92) -> 0 | O9: =SUM(O10:O92) -> 0 | ... Q9: =SUM(Q10:Q92) -> 0 | R9: =COUNTIF(H9:Q9,">0") -> 2 | S9: =COUNTIF(H9:I9,">0") -> 0 | T9: =SUM(T10:T92) -> 0 | U9: =SUM(U10:U92) -> 0 | V9: =SUM(V10:V92) -> 0 | W9: =SUM(W10:W92) -> 0 | X9: =SUM(X10:X92) -> 0 | Y9: =SUM(Y10:Y92) -> 33 | Z9: =SUM(Z10:Z92) -> 0 | AA9: =SUM(AA10:AA92) -> 12 | ... AK9: =SUM(AK10:AK92) -> 0 | AL9: =COUNTIF(T9:AK9,">0") -> 8 | AM9: =SUM(R9+AL9) -> 10 | AN9: =SUM(AN10:AN91) -> 0 | AO9: =SUM(AO10:AO91) -> 0 | AP9: =SUM(AP10:AP91) -> 0 | AQ9: =SUM(AQ10:AQ91) -> 0 | AR9: =SUM(AR10:AR91) -> 0 | AS9: =SUM(AS10:AS91) -> 43 | AT9: =SUM(AT10:AT91) -> 0 | AU9: =SUM(AU10:AU91) -> 0 | ... BH9: =SUM(BH10:BH91) -> 0 | BI9: =COUNTIF(AN9:BH9,">0") -> 8 | BJ9: =SUM(AM9+BI9) -> 18 | BK9: =SUM(BK10:BK91) -> 8 | BL9: =SUM(BL10:BL91) -> 25 | BM9: =SUM(BM10:BM91) -> 26 | BN9: =SUM(BN10:BN91) -> 0 | BO9: =SUM(BO10:BO91) -> 0 | BP9: =SUM(BP10:BP91) -> 22 | BQ9: =SUM(BQ10:BQ91) -> 25 | BR9: =SUM(BR10:BR91) -> 48 | ... BW9: =SUM(BW10:BW91) -> 0 | CF9: =COUNTIF(BK9:CE9,">0") -> 9 | CG9: =SUM(BJ9+CF9) -> 27 | CH9: =SUM(CH10:CH84) -> 0 | CI9: =SUM(CI10:CI84) -> 0 | CJ9: =SUM(CJ10:CJ84) -> 0 | CK9: =SUM(CK10:CK69) -> 0 | CL9: =SUM(CL10:CL69) -> 0 | CM9: =SUM(CM10:CM69) -> 0 | CN9: =SUM(CN10:CN69) -> 0 | CO9: =SUM(CO10:CO84) -> 0 | CP9: =SUM(CP10:CP69) -> 0 | CQ9: =SUM(CQ10:CQ69) -> 0 | CR9: =SUM(CR10:CR69) -> 0 | CS9: =COUNTIF(CH9:CR9,">0") -> 0 | CT9: =SUM(CG9+CS9) -> 27 | CV9: =SUM(R9+AL9+BI9+CF9+CS9+CU9) -> 27 | CW9: =SUM(R9+AL9+BI9+CF9+CS9+CU9) -> 27
A10: 1 | B10: 0827CI231001 | C10: AADARSH GARHEWAL | D10: =SUM(R10+AL10+BI10+CF10+CS10+CU10) -> 3 | E10: =(D10)/D$9*100 -> 11.111111 | F10: =IF(E10<50,E10, " ") -> 11.111111 | G10: =IF(E10<30,E10, " ") -> 11.111111 | R10: =SUM(H10:Q10) -> 0 | S10: =R10/R$9*100 -> 0 | AB10: 1 | AH10: 1 | AL10: =SUM(T10:AK10) -> 2 | AM10: =AL10/AL$9*100 -> 25 | BI10: =SUM(AN10:BH10) -> 0 | BJ10: =BI10/BI$9*100 -> 0 | BR10: 1 | CF10: =SUM(BK10:BW10) -> 1 | CG10: =CF10/CF$9*100 -> 11.111111 | CS10: =SUM(CH10:CR10) -> 0 | CT10: =CS10/CS$9*100 -> #DIV/0! | CV10: =(D10)/D$9*100 -> 11.111111 | CW10: =SUM(R10+AL10+BI10+CF10+CS10+CU10) -> 3
A11: 2 | B11: 0827CI231002 | C11: AYUSH PATEL | D11: =SUM(R11+AL11+BI11+CF11+CS11+CU11) -> 19 | E11: =(D11)/D$9*100 -> 70.37037 | F11: =IF(E11<50,E11, " ") | G11: =IF(E11<30,E11, " ") | M11: 1 | R11: =SUM(H11:Q11) -> 1 | S11: =R11/R$9*100 -> 50 | Y11: 1 | AA11: 1 | AB11: 1 | AC11: 1 | AD11: 1 | AH11: 1 | AI11: 1 | AL11: =SUM(T11:AK11) -> 7 | AM11: =AL11/AL$9*100 -> 87.5 | AS11: 1 | BE11: 1 | BF11: 1 | BG11: 1 | BI11: =SUM(AN11:BH11) -> 4 | BJ11: =BI11/BI$9*100 -> 50 | BL11: 1 | BM11: 1 | BQ11: 1 | BR11: 1 | BS11: 1 | BU11: 1 | BV11: 1 | CF11: =SUM(BK11:BW11) -> 7 | CG11: =CF11/CF$9*100 -> 77.777778 | CS11: =SUM(CH11:CR11) -> 0 | CT11: =CS11/CS$9*100 -> #DIV/0! | CV11: =(D11)/D$9*100 -> 70.37037 | CW11: =SUM(R11+AL11+BI11+CF11+CS11+CU11) -> 19
A12: 3 | B12: 0827CI231003 | C12: ABHAY DUGAYA | D12: =SUM(R12+AL12+BI12+CF12+CS12+CU12) -> 6 | E12: =(D12)/D$9*100 -> 22.222222 | F12: =IF(E12<50,E12, " ") -> 22.222222 | G12: =IF(E12<30,E12, " ") -> 22.222222 | R12: =SUM(H12:Q12) -> 0 | S12: =R12/R$9*100 -> 0 | AB12: 1 | AC12: 1 | AH12: 1 | AL12: =SUM(T12:AK12) -> 3 | AM12: =AL12/AL$9*100 -> 37.5 | BF12: 1 | BI12: =SUM(AN12:BH12) -> 1 | BJ12: =BI12/BI$9*100 -> 12.5 | BR12: 1 | BS12: 1 | CF12: =SUM(BK12:BW12) -> 2 | CG12: =CF12/CF$9*100 -> 22.222222 | CS12: =SUM(CH12:CR12) -> 0 | CT12: =CS12/CS$9*100 -> #DIV/0! | CV12: =(D12)/D$9*100 -> 22.222222 | CW12: =SUM(R12+AL12+BI12+CF12+CS12+CU12) -> 6
A13: 4 | B13: 0827CI231004 | C13: ABHISHEK JAISWAL | D13: =SUM(R13+AL13+BI13+CF13+CS13+CU13) -> 13 | E13: =(D13)/D$9*100 -> 48.148148 | F13: =IF(E13<50,E13, " ") -> 48.148148 | G13: =IF(E13<30,E13, " ") | R13: =SUM(H13:Q13) -> 0 | S13: =R13/R$9*100 -> 0 | AB13: 1 | AC13: 1 | AH13: 1 | AI13: 1 | AL13: =SUM(T13:AK13) -> 4 | AM13: =AL13/AL$9*100 -> 50 | AS13: 1 | BA13: 1 | BF13: 1 | BI13: =SUM(AN13:BH13) -> 3 | BJ13: =BI13/BI$9*100 -> 37.5 | BL13: 1 | BM13: 1 | BQ13: 1 | BR13: 1 | BS13: 1 | BU13: 1 | CF13: =SUM(BK13:BW13) -> 6 | CG13: =CF13/CF$9*100 -> 66.666667 | CS13: =SUM(CH13:CR13) -> 0 | CT13: =CS13/CS$9*100 -> #DIV/0! | CV13: =(D13)/D$9*100 -> 48.148148 | CW13: =SUM(R13+AL13+BI13+CF13+CS13+CU13) -> 13
A14: 5 | B14: 0827CI231005 | C14: ABHISHEK VERMA | D14: =SUM(R14+AL14+BI14+CF14+CS14+CU14) -> 16 | E14: =(D14)/D$9*100 -> 59.259259 | F14: =IF(E14<50,E14, " ") | G14: =IF(E14<30,E14, " ") | K14: 1 | M14: 1 | R14: =SUM(H14:Q14) -> 2 | S14: =R14/R$9*100 -> 100 | AB14: 1 | AD14: 1 | AF14: 1 | AI14: 1 | AL14: =SUM(T14:AK14) -> 4 | AM14: =AL14/AL$9*100 -> 50 | AS14: 1 | BE14: 1 | BF14: 1 | BI14: =SUM(AN14:BH14) -> 3 | BJ14: =BI14/BI$9*100 -> 37.5 | BK14: 1 | BL14: 1 | BP14: 1 | BQ14: 1 | BR14: 1 | BS14: 1 | BU14: 1 | CF14: =SUM(BK14:BW14) -> 7 | CG14: =CF14/CF$9*100 -> 77.777778 | CS14: =SUM(CH14:CR14) -> 0 | CT14: =CS14/CS$9*100 -> #DIV/0! | CV14: =(D14)/D$9*100 -> 59.259259 | CW14: =SUM(R14+AL14+BI14+CF14+CS14+CU14) -> 16
A15: 6 | B15: 0827CI231006 | C15: ABINAV KOURAV | D15: =SUM(R15+AL15+BI15+CF15+CS15+CU15) -> 0 | E15: =(D15)/D$9*100 -> 0 | F15: =IF(E15<50,E15, " ") -> 0 | G15: =IF(E15<30,E15, " ") -> 0 | R15: =SUM(H15:Q15) -> 0 | S15: =R15/R$9*100 -> 0 | AL15: =SUM(T15:AK15) -> 0 | AM15: =AL15/AL$9*100 -> 0 | BI15: =SUM(AN15:BH15) -> 0 | BJ15: =BI15/BI$9*100 -> 0 | CF15: =SUM(BK15:BW15) -> 0 | CG15: =CF15/CF$9*100 -> 0 | CS15: =SUM(CH15:CR15) -> 0 | CT15: =CS15/CS$9*100 -> #DIV/0! | CV15: =(D15)/D$9*100 -> 0 | CW15: =SUM(R15+AL15+BI15+CF15+CS15+CU15) -> 0
A16: 7 | B16: 0827CI231007 | C16: ADARSH PRATAP SINGH GURJAR | D16: =SUM(R16+AL16+BI16+CF16+CS16+CU16) -> 9 | E16: =(D16)/D$9*100 -> 33.333333 | F16: =IF(E16<50,E16, " ") -> 33.333333 | G16: =IF(E16<30,E16, " ") | R16: =SUM(H16:Q16) -> 0 | S16: =R16/R$9*100 -> 0 | AH16: 1 | AL16: =SUM(T16:AK16) -> 1 | AM16: =AL16/AL$9*100 -> 12.5 | AS16: 1 | BB16: 1 | BF16: 1 | BI16: =SUM(AN16:BH16) -> 3 | BJ16: =BI16/BI$9*100 -> 37.5 | BM16: 1 | BP16: 1 | BQ16: 1 | BR16: 1 | BV16: 1 | CF16: =SUM(BK16:BW16) -> 5 | CG16: =CF16/CF$9*100 -> 55.555556 | CS16: =SUM(CH16:CR16) -> 0 | CT16: =CS16/CS$9*100 -> #DIV/0! | CV16: =(D16)/D$9*100 -> 33.333333 | CW16: =SUM(R16+AL16+BI16+CF16+CS16+CU16) -> 9
A17: 8 | B17: 0827CI231008 | C17: ADITI VISHWAKARMA | D17: =SUM(R17+AL17+BI17+CF17+CS17+CU17) -> 15 | E17: =(D17)/D$9*100 -> 55.555556 | F17: =IF(E17<50,E17, " ") | G17: =IF(E17<30,E17, " ") | M17: 1 | R17: =SUM(H17:Q17) -> 1 | S17: =R17/R$9*100 -> 50 | AB17: 1 | AC17: 1 | AD17: 1 | AF17: 1 | AI17: 1 | AL17: =SUM(T17:AK17) -> 5 | AM17: =AL17/AL$9*100 -> 62.5 | AS17: 1 | BE17: 1 | BF17: 1 | BI17: =SUM(AN17:BH17) -> 3 | BJ17: =BI17/BI$9*100 -> 37.5 | BK17: 1 | BL17: 1 | BP17: 1 | BQ17: 1 | BR17: 1 | BS17: 1 | CF17: =SUM(BK17:BW17) -> 6 | CG17: =CF17/CF$9*100 -> 66.666667 | CS17: =SUM(CH17:CR17) -> 0 | CT17: =CS17/CS$9*100 -> #DIV/0! | CV17: =(D17)/D$9*100 -> 55.555556 | CW17: =SUM(R17+AL17+BI17+CF17+CS17+CU17) -> 15
A18: 9 | B18: 0827CI231009 | C18: ADITYA TIWARI | D18: =SUM(R18+AL18+BI18+CF18+CS18+CU18) -> 9 | E18: =(D18)/D$9*100 -> 33.333333 | F18: =IF(E18<50,E18, " ") -> 33.333333 | G18: =IF(E18<30,E18, " ") | M18: 1 | R18: =SUM(H18:Q18) -> 1 | S18: =R18/R$9*100 -> 50 | AH18: 1 | AI18: 1 | AL18: =SUM(T18:AK18) -> 2 | AM18: =AL18/AL$9*100 -> 25 | AS18: 1 | BF18: 1 | BG18: 1 | BI18: =SUM(AN18:BH18) -> 3 | BJ18: =BI18/BI$9*100 -> 37.5 | BM18: 1 | BR18: 1 | BS18: 1 | CF18: =SUM(BK18:BW18) -> 3 | CG18: =CF18/CF$9*100 -> 33.333333 | CS18: =SUM(CH18:CR18) -> 0 | CT18: =CS18/CS$9*100 -> #DIV/0! | CV18: =(D18)/D$9*100 -> 33.333333 | CW18: =SUM(R18+AL18+BI18+CF18+CS18+CU18) -> 9
A19: 10 | B19: 0827CI231010 | C19: AKASH BARASKAR | D19: =SUM(R19+AL19+BI19+CF19+CS19+CU19) -> 10 | E19: =(D19)/D$9*100 -> 37.037037 | F19: =IF(E19<50,E19, " ") -> 37.037037 | G19: =IF(E19<30,E19, " ") | R19: =SUM(H19:Q19) -> 0 | S19: =R19/R$9*100 -> 0 | AC19: 1 | AD19: 1 | AL19: =SUM(T19:AK19) -> 2 | AM19: =AL19/AL$9*100 -> 25 | AZ19: 1 | BA19: 1 | BB19: 1 | BE19: 1 | BF19: 1 | BI19: =SUM(AN19:BH19) -> 5 | BJ19: =BI19/BI$9*100 -> 62.5 | BS19: 1 | BU19: 1 | BV19: 1 | CF19: =SUM(BK19:BW19) -> 3 | CG19: =CF19/CF$9*100 -> 33.333333 | CS19: =SUM(CH19:CR19) -> 0 | CT19: =CS19/CS$9*100 -> #DIV/0! | CV19: =(D19)/D$9*100 -> 37.037037 | CW19: =SUM(R19+AL19+BI19+CF19+CS19+CU19) -> 10
A20: 11 | B20: 0827CI231011 | C20: AKSHAT KARODE | D20: =SUM(R20+AL20+BI20+CF20+CS20+CU20) -> 8 | E20: =(D20)/D$9*100 -> 29.62963 | F20: =IF(E20<50,E20, " ") -> 29.62963 | G20: =IF(E20<30,E20, " ") -> 29.62963 | R20: =SUM(H20:Q20) -> 0 | S20: =R20/R$9*100 -> 0 | AB20: 1 | AC20: 1 | AI20: 1 | AL20: =SUM(T20:AK20) -> 3 | AM20: =AL20/AL$9*100 -> 37.5 | AS20: 1 | BF20: 1 | BI20: =SUM(AN20:BH20) -> 2 | BJ20: =BI20/BI$9*100 -> 25 | BP20: 1 | BR20: 1 | BS20: 1 | CF20: =SUM(BK20:BW20) -> 3 | CG20: =CF20/CF$9*100 -> 33.333333 | CS20: =SUM(CH20:CR20) -> 0 | CT20: =CS20/CS$9*100 -> #DIV/0! | CV20: =(D20)/D$9*100 -> 29.62963 | CW20: =SUM(R20+AL20+BI20+CF20+CS20+CU20) -> 8
A21: 12 | B21: 0827CI231012 | C21: AKSHAY KHANNA | D21: =SUM(R21+AL21+BI21+CF21+CS21+CU21) -> 10 | E21: =(D21)/D$9*100 -> 37.037037 | F21: =IF(E21<50,E21, " ") -> 37.037037 | G21: =IF(E21<30,E21, " ") | M21: 1 | R21: =SUM(H21:Q21) -> 1 | S21: =R21/R$9*100 -> 50 | AB21: 1 | AL21: =SUM(T21:AK21) -> 1 | AM21: =AL21/AL$9*100 -> 12.5 | AS21: 1 | BA21: 1 | BF21: 1 | BG21: 1 | BI21: =SUM(AN21:BH21) -> 4 | BJ21: =BI21/BI$9*100 -> 50 | BM21: 1 | BQ21: 1 | BR21: 1 | BS21: 1 | CF21: =SUM(BK21:BW21) -> 4 | CG21: =CF21/CF$9*100 -> 44.444444 | CS21: =SUM(CH21:CR21) -> 0 | CT21: =CS21/CS$9*100 -> #DIV/0! | CV21: =(D21)/D$9*100 -> 37.037037 | CW21: =SUM(R21+AL21+BI21+CF21+CS21+CU21) -> 10
A22: 13 | B22: 0827CI231013 | C22: AMAY MISHRA | D22: =SUM(R22+AL22+BI22+CF22+CS22+CU22) -> 10 | E22: =(D22)/D$9*100 -> 37.037037 | F22: =IF(E22<50,E22, " ") -> 37.037037 | G22: =IF(E22<30,E22, " ") | R22: =SUM(H22:Q22) -> 0 | S22: =R22/R$9*100 -> 0 | Y22: 1 | AB22: 1 | AI22: 1 | AL22: =SUM(T22:AK22) -> 3 | AM22: =AL22/AL$9*100 -> 37.5 | AS22: 1 | BE22: 1 | BF22: 1 | BG22: 1 | BI22: =SUM(AN22:BH22) -> 4 | BJ22: =BI22/BI$9*100 -> 50 | BP22: 1 | BQ22: 1 | BR22: 1 | CF22: =SUM(BK22:BW22) -> 3 | CG22: =CF22/CF$9*100 -> 33.333333 | CS22: =SUM(CH22:CR22) -> 0 | CT22: =CS22/CS$9*100 -> #DIV/0! | CV22: =(D22)/D$9*100 -> 37.037037 | CW22: =SUM(R22+AL22+BI22+CF22+CS22+CU22) -> 10
A23: 14 | B23: 0827CI231014 | C23: AMBAR YADAV | D23: =SUM(R23+AL23+BI23+CF23+CS23+CU23) -> 5 | E23: =(D23)/D$9*100 -> 18.518519 | F23: =IF(E23<50,E23, " ") -> 18.518519 | G23: =IF(E23<30,E23, " ") -> 18.518519 | R23: =SUM(H23:Q23) -> 0 | S23: =R23/R$9*100 -> 0 | AI23: 1 | AL23: =SUM(T23:AK23) -> 1 | AM23: =AL23/AL$9*100 -> 12.5 | AS23: 1 | BI23: =SUM(AN23:BH23) -> 1 | BJ23: =BI23/BI$9*100 -> 12.5 | BP23: 1 | BQ23: 1 | BR23: 1 | CF23: =SUM(BK23:BW23) -> 3 | CG23: =CF23/CF$9*100 -> 33.333333 | CS23: =SUM(CH23:CR23) -> 0 | CT23: =CS23/CS$9*100 -> #DIV/0! | CV23: =(D23)/D$9*100 -> 18.518519 | CW23: =SUM(R23+AL23+BI23+CF23+CS23+CU23) -> 5
A24: 15 | B24: 0827CI231015 | C24: AMIT YADAV | D24: =SUM(R24+AL24+BI24+CF24+CS24+CU24) -> 6 | E24: =(D24)/D$9*100 -> 22.222222 | F24: =IF(E24<50,E24, " ") -> 22.222222 | G24: =IF(E24<30,E24, " ") -> 22.222222 | R24: =SUM(H24:Q24) -> 0 | S24: =R24/R$9*100 -> 0 | Y24: 1 | AB24: 1 | AC24: 1 | AL24: =SUM(T24:AK24) -> 3 | AM24: =AL24/AL$9*100 -> 37.5 | BF24: 1 | BI24: =SUM(AN24:BH24) -> 1 | BJ24: =BI24/BI$9*100 -> 12.5 | BR24: 1 | BS24: 1 | CF24: =SUM(BK24:BW24) -> 2 | CG24: =CF24/CF$9*100 -> 22.222222 | CS24: =SUM(CH24:CR24) -> 0 | CT24: =CS24/CS$9*100 -> #DIV/0! | CV24: =(D24)/D$9*100 -> 22.222222 | CW24: =SUM(R24+AL24+BI24+CF24+CS24+CU24) -> 6
A25: 16 | B25: 0827CI231016 | C25: ANIRUDDH CHATURVEDI | D25: =SUM(R25+AL25+BI25+CF25+CS25+CU25) -> 7 | E25: =(D25)/D$9*100 -> 25.925926 | F25: =IF(E25<50,E25, " ") -> 25.925926 | G25: =IF(E25<30,E25, " ") -> 25.925926 | M25: 1 | R25: =SUM(H25:Q25) -> 1 | S25: =R25/R$9*100 -> 50 | Y25: 1 | AB25: 1 | AD25: 1 | AL25: =SUM(T25:AK25) -> 3 | AM25: =AL25/AL$9*100 -> 37.5 | BI25: =SUM(AN25:BH25) -> 0 | BJ25: =BI25/BI$9*100 -> 0 | BK25: 1 | BS25: 1 | BU25: 1 | CF25: =SUM(BK25:BW25) -> 3 | CG25: =CF25/CF$9*100 -> 33.333333 | CS25: =SUM(CH25:CR25) -> 0 | CT25: =CS25/CS$9*100 -> #DIV/0! | CV25: =(D25)/D$9*100 -> 25.925926 | CW25: =SUM(R25+AL25+BI25+CF25+CS25+CU25) -> 7
A26: 17 | B26: 0827CI231017 | C26: ANIRUDDHA SHARMA | D26: =SUM(R26+AL26+BI26+CF26+CS26+CU26) -> 3 | E26: =(D26)/D$9*100 -> 11.111111 | F26: =IF(E26<50,E26, " ") -> 11.111111 | G26: =IF(E26<30,E26, " ") -> 11.111111 | M26: 1 | R26: =SUM(H26:Q26) -> 1 | S26: =R26/R$9*100 -> 50 | AA26: 1 | AL26: =SUM(T26:AK26) -> 1 | AM26: =AL26/AL$9*100 -> 12.5 | BI26: =SUM(AN26:BH26) -> 0 | BJ26: =BI26/BI$9*100 -> 0 | BS26: 1 | CF26: =SUM(BK26:BW26) -> 1 | CG26: =CF26/CF$9*100 -> 11.111111 | CS26: =SUM(CH26:CR26) -> 0 | CT26: =CS26/CS$9*100 -> #DIV/0! | CV26: =(D26)/D$9*100 -> 11.111111 | CW26: =SUM(R26+AL26+BI26+CF26+CS26+CU26) -> 3
A27: 18 | B27: 0827CI231018 | C27: ANSH RATHORE | D27: =SUM(R27+AL27+BI27+CF27+CS27+CU27) -> 6 | E27: =(D27)/D$9*100 -> 22.222222 | F27: =IF(E27<50,E27, " ") -> 22.222222 | G27: =IF(E27<30,E27, " ") -> 22.222222 | M27: 1 | R27: =SUM(H27:Q27) -> 1 | S27: =R27/R$9*100 -> 50 | Y27: 1 | AH27: 1 | AI27: 1 | AL27: =SUM(T27:AK27) -> 3 | AM27: =AL27/AL$9*100 -> 37.5 | AS27: 1 | BF27: 1 | BI27: =SUM(AN27:BH27) -> 2 | BJ27: =BI27/BI$9*100 -> 25 | CF27: =SUM(BK27:BW27) -> 0 | CG27: =CF27/CF$9*100 -> 0 | CS27: =SUM(CH27:CR27) -> 0 | CT27: =CS27/CS$9*100 -> #DIV/0! | CV27: =(D27)/D$9*100 -> 22.222222 | CW27: =SUM(R27+AL27+BI27+CF27+CS27+CU27) -> 6
A28: 19 | B28: 0827CI231019 | C28: ANSH VAISHNAV | D28: =SUM(R28+AL28+BI28+CF28+CS28+CU28) -> 5 | E28: =(D28)/D$9*100 -> 18.518519 | F28: =IF(E28<50,E28, " ") -> 18.518519 | G28: =IF(E28<30,E28, " ") -> 18.518519 | M28: 1 | R28: =SUM(H28:Q28) -> 1 | S28: =R28/R$9*100 -> 50 | Y28: 1 | AC28: 1 | AL28: =SUM(T28:AK28) -> 2 | AM28: =AL28/AL$9*100 -> 25 | BI28: =SUM(AN28:BH28) -> 0 | BJ28: =BI28/BI$9*100 -> 0 | BR28: 1 | BS28: 1 | CF28: =SUM(BK28:BW28) -> 2 | CG28: =CF28/CF$9*100 -> 22.222222 | CS28: =SUM(CH28:CR28) -> 0 | CT28: =CS28/CS$9*100 -> #DIV/0! | CV28: =(D28)/D$9*100 -> 18.518519 | CW28: =SUM(R28+AL28+BI28+CF28+CS28+CU28) -> 5
A29: 20 | B29: 0827CI231020 | C29: ANSHU BILAWLIYA | D29: =SUM(R29+AL29+BI29+CF29+CS29+CU29) -> 23 | E29: =(D29)/D$9*100 -> 85.185185 | F29: =IF(E29<50,E29, " ") | G29: =IF(E29<30,E29, " ") | K29: 1 | M29: 1 | R29: =SUM(H29:Q29) -> 2 | S29: =R29/R$9*100 -> 100 | Y29: 1 | AA29: 1 | AB29: 1 | AC29: 1 | AD29: 1 | AH29: 1 | AI29: 1 | AL29: =SUM(T29:AK29) -> 7 | AM29: =AL29/AL$9*100 -> 87.5 | AS29: 1 | AZ29: 1 | BA29: 1 | BB29: 1 | BE29: 1 | BF29: 1 | BG29: 1 | BI29: =SUM(AN29:BH29) -> 7 | BJ29: =BI29/BI$9*100 -> 87.5 | BL29: 1 | BM29: 1 | BQ29: 1 | BR29: 1 | BS29: 1 | BU29: 1 | BV29: 1 | CF29: =SUM(BK29:BW29) -> 7 | CG29: =CF29/CF$9*100 -> 77.777778 | CS29: =SUM(CH29:CR29) -> 0 | CT29: =CS29/CS$9*100 -> #DIV/0! | CV29: =(D29)/D$9*100 -> 85.185185 | CW29: =SUM(R29+AL29+BI29+CF29+CS29+CU29) -> 23
A30: 21 | B30: 0827CI231021 | C30: ANUJ MALVIYA | D30: =SUM(R30+AL30+BI30+CF30+CS30+CU30) -> 6 | E30: =(D30)/D$9*100 -> 22.222222 | F30: =IF(E30<50,E30, " ") -> 22.222222 | G30: =IF(E30<30,E30, " ") -> 22.222222 | R30: =SUM(H30:Q30) -> 0 | S30: =R30/R$9*100 -> 0 | AL30: =SUM(T30:AK30) -> 0 | AM30: =AL30/AL$9*100 -> 0 | AS30: 1 | BF30: 1 | BG30: 1 | BI30: =SUM(AN30:BH30) -> 3 | BJ30: =BI30/BI$9*100 -> 37.5 | BP30: 1 | BR30: 1 | BS30: 1 | CF30: =SUM(BK30:BW30) -> 3 | CG30: =CF30/CF$9*100 -> 33.333333 | CS30: =SUM(CH30:CR30) -> 0 | CT30: =CS30/CS$9*100 -> #DIV/0! | CV30: =(D30)/D$9*100 -> 22.222222 | CW30: =SUM(R30+AL30+BI30+CF30+CS30+CU30) -> 6
A31: 22 | B31: 0827CI231022 | C31: ANVESH TRIVEDI | D31: =SUM(R31+AL31+BI31+CF31+CS31+CU31) -> 12 | E31: =(D31)/D$9*100 -> 44.444444 | F31: =IF(E31<50,E31, " ") -> 44.444444 | G31: =IF(E31<30,E31, " ") | M31: 1 | R31: =SUM(H31:Q31) -> 1 | S31: =R31/R$9*100 -> 50 | AC31: 1 | AH31: 1 | AI31: 1 | AL31: =SUM(T31:AK31) -> 3 | AM31: =AL31/AL$9*100 -> 37.5 | AS31: 1 | BA31: 1 | BF31: 1 | BG31: 1 | BI31: =SUM(AN31:BH31) -> 4 | BJ31: =BI31/BI$9*100 -> 50 | BM31: 1 | BQ31: 1 | BR31: 1 | BS31: 1 | CF31: =SUM(BK31:BW31) -> 4 | CG31: =CF31/CF$9*100 -> 44.444444 | CS31: =SUM(CH31:CR31) -> 0 | CT31: =CS31/CS$9*100 -> #DIV/0! | CV31: =(D31)/D$9*100 -> 44.444444 | CW31: =SUM(R31+AL31+BI31+CF31+CS31+CU31) -> 12
A32: 23 | B32: 0827CI231023 | C32: ANYA JAIN | D32: =SUM(R32+AL32+BI32+CF32+CS32+CU32) -> 14 | E32: =(D32)/D$9*100 -> 51.851852 | F32: =IF(E32<50,E32, " ") | G32: =IF(E32<30,E32, " ") | K32: 1 | R32: =SUM(H32:Q32) -> 1 | S32: =R32/R$9*100 -> 50 | AB32: 1 | AC32: 1 | AD32: 1 | AH32: 1 | AL32: =SUM(T32:AK32) -> 4 | AM32: =AL32/AL$9*100 -> 50 | AS32: 1 | BA32: 1 | BE32: 1 | BF32: 1 | BI32: =SUM(AN32:BH32) -> 4 | BJ32: =BI32/BI$9*100 -> 50 | BM32: 1 | BQ32: 1 | BR32: 1 | BS32: 1 | BU32: 1 | CF32: =SUM(BK32:BW32) -> 5 | CG32: =CF32/CF$9*100 -> 55.555556 | CS32: =SUM(CH32:CR32) -> 0 | CT32: =CS32/CS$9*100 -> #DIV/0! | CV32: =(D32)/D$9*100 -> 51.851852 | CW32: =SUM(R32+AL32+BI32+CF32+CS32+CU32) -> 14
A33: 24 | B33: 0827CI231024 | C33: ARYAN SINGH BHADORIA | D33: =SUM(R33+AL33+BI33+CF33+CS33+CU33) -> 13 | E33: =(D33)/D$9*100 -> 48.148148 | F33: =IF(E33<50,E33, " ") -> 48.148148 | G33: =IF(E33<30,E33, " ") | M33: 1 | R33: =SUM(H33:Q33) -> 1 | S33: =R33/R$9*100 -> 50 | AB33: 1 | AC33: 1 | AH33: 1 | AI33: 1 | AL33: =SUM(T33:AK33) -> 4 | AM33: =AL33/AL$9*100 -> 50 | AS33: 1 | BA33: 1 | BF33: 1 | BG33: 1 | BI33: =SUM(AN33:BH33) -> 4 | BJ33: =BI33/BI$9*100 -> 50 | BM33: 1 | BQ33: 1 | BR33: 1 | BS33: 1 | CF33: =SUM(BK33:BW33) -> 4 | CG33: =CF33/CF$9*100 -> 44.444444 | CS33: =SUM(CH33:CR33) -> 0 | CT33: =CS33/CS$9*100 -> #DIV/0! | CV33: =(D33)/D$9*100 -> 48.148148 | CW33: =SUM(R33+AL33+BI33+CF33+CS33+CU33) -> 13
A34: 25 | B34: 0827CI231025 | C34: ASHWIN CARPENTER | D34: =SUM(R34+AL34+BI34+CF34+CS34+CU34) -> 5 | E34: =(D34)/D$9*100 -> 18.518519 | F34: =IF(E34<50,E34, " ") -> 18.518519 | G34: =IF(E34<30,E34, " ") -> 18.518519 | R34: =SUM(H34:Q34) -> 0 | S34: =R34/R$9*100 -> 0 | Y34: 1 | AC34: 1 | AL34: =SUM(T34:AK34) -> 2 | AM34: =AL34/AL$9*100 -> 25 | AS34: 1 | BI34: =SUM(AN34:BH34) -> 1 | BJ34: =BI34/BI$9*100 -> 12.5 | BL34: 1 | BV34: 1 | CF34: =SUM(BK34:BW34) -> 2 | CG34: =CF34/CF$9*100 -> 22.222222 | CS34: =SUM(CH34:CR34) -> 0 | CT34: =CS34/CS$9*100 -> #DIV/0! | CV34: =(D34)/D$9*100 -> 18.518519 | CW34: =SUM(R34+AL34+BI34+CF34+CS34+CU34) -> 5
A35: 26 | B35: 0827CI231026 | C35: AVI KEDARE | D35: =SUM(R35+AL35+BI35+CF35+CS35+CU35) -> 17 | E35: =(D35)/D$9*100 -> 62.962963 | F35: =IF(E35<50,E35, " ") | G35: =IF(E35<30,E35, " ") | K35: 1 | M35: 1 | R35: =SUM(H35:Q35) -> 2 | S35: =R35/R$9*100 -> 100 | Y35: 1 | AA35: 1 | AB35: 1 | AC35: 1 | AD35: 1 | AL35: =SUM(T35:AK35) -> 5 | AM35: =AL35/AL$9*100 -> 62.5 | AS35: 1 | BE35: 1 | BF35: 1 | BG35: 1 | BI35: =SUM(AN35:BH35) -> 4 | BJ35: =BI35/BI$9*100 -> 50 | BL35: 1 | BQ35: 1 | BR35: 1 | BS35: 1 | BU35: 1 | BV35: 1 | CF35: =SUM(BK35:BW35) -> 6 | CG35: =CF35/CF$9*100 -> 66.666667 | CS35: =SUM(CH35:CR35) -> 0 | CT35: =CS35/CS$9*100 -> #DIV/0! | CV35: =(D35)/D$9*100 -> 62.962963 | CW35: =SUM(R35+AL35+BI35+CF35+CS35+CU35) -> 17
A36: 27 | B36: 0827CI231027 | C36: AYUSH CHOUDHARY | D36: =SUM(R36+AL36+BI36+CF36+CS36+CU36) -> 0 | E36: =(D36)/D$9*100 -> 0 | F36: =IF(E36<50,E36, " ") -> 0 | G36: =IF(E36<30,E36, " ") -> 0 | R36: =SUM(H36:Q36) -> 0 | S36: =R36/R$9*100 -> 0 | AL36: =SUM(T36:AK36) -> 0 | AM36: =AL36/AL$9*100 -> 0 | BI36: =SUM(AN36:BH36) -> 0 | BJ36: =BI36/BI$9*100 -> 0 | CF36: =SUM(BK36:BW36) -> 0 | CG36: =CF36/CF$9*100 -> 0 | CS36: =SUM(CH36:CR36) -> 0 | CT36: =CS36/CS$9*100 -> #DIV/0! | CV36: =(D36)/D$9*100 -> 0 | CW36: =SUM(R36+AL36+BI36+CF36+CS36+CU36) -> 0
A37: 28 | B37: 0827CI231028 | C37: AYUSH CHOURASIYA | D37: =SUM(R37+AL37+BI37+CF37+CS37+CU37) -> 7 | E37: =(D37)/D$9*100 -> 25.925926 | F37: =IF(E37<50,E37, " ") -> 25.925926 | G37: =IF(E37<30,E37, " ") -> 25.925926 | K37: 1 | R37: =SUM(H37:Q37) -> 1 | S37: =R37/R$9*100 -> 50 | Y37: 1 | AB37: 1 | AC37: 1 | AD37: 1 | AL37: =SUM(T37:AK37) -> 4 | AM37: =AL37/AL$9*100 -> 50 | BA37: 1 | BE37: 1 | BI37: =SUM(AN37:BH37) -> 2 | BJ37: =BI37/BI$9*100 -> 25 | CF37: =SUM(BK37:BW37) -> 0 | CG37: =CF37/CF$9*100 -> 0 | CS37: =SUM(CH37:CR37) -> 0 | CT37: =CS37/CS$9*100 -> #DIV/0! | CV37: =(D37)/D$9*100 -> 25.925926 | CW37: =SUM(R37+AL37+BI37+CF37+CS37+CU37) -> 7
A38: 29 | B38: 0827CI231029 | C38: CHIRAG | D38: =SUM(R38+AL38+BI38+CF38+CS38+CU38) -> 4 | E38: =(D38)/D$9*100 -> 14.814815 | F38: =IF(E38<50,E38, " ") -> 14.814815 | G38: =IF(E38<30,E38, " ") -> 14.814815 | R38: =SUM(H38:Q38) -> 0 | S38: =R38/R$9*100 -> 0 | AH38: 1 | AL38: =SUM(T38:AK38) -> 1 | AM38: =AL38/AL$9*100 -> 12.5 | BF38: 1 | BI38: =SUM(AN38:BH38) -> 1 | BJ38: =BI38/BI$9*100 -> 12.5 | BR38: 1 | BS38: 1 | CF38: =SUM(BK38:BW38) -> 2 | CG38: =CF38/CF$9*100 -> 22.222222 | CS38: =SUM(CH38:CR38) -> 0 | CT38: =CS38/CS$9*100 -> #DIV/0! | CV38: =(D38)/D$9*100 -> 14.814815 | CW38: =SUM(R38+AL38+BI38+CF38+CS38+CU38) -> 4
A39: 30 | B39: 0827CI231030 | C39: DARSHIL JAIN | D39: =SUM(R39+AL39+BI39+CF39+CS39+CU39) -> 3 | E39: =(D39)/D$9*100 -> 11.111111 | F39: =IF(E39<50,E39, " ") -> 11.111111 | G39: =IF(E39<30,E39, " ") -> 11.111111 | R39: =SUM(H39:Q39) -> 0 | S39: =R39/R$9*100 -> 0 | AL39: =SUM(T39:AK39) -> 0 | AM39: =AL39/AL$9*100 -> 0 | BI39: =SUM(AN39:BH39) -> 0 | BJ39: =BI39/BI$9*100 -> 0 | BM39: 1 | BR39: 1 | BS39: 1 | CF39: =SUM(BK39:BW39) -> 3 | CG39: =CF39/CF$9*100 -> 33.333333 | CS39: =SUM(CH39:CR39) -> 0 | CT39: =CS39/CS$9*100 -> #DIV/0! | CV39: =(D39)/D$9*100 -> 11.111111 | CW39: =SUM(R39+AL39+BI39+CF39+CS39+CU39) -> 3
A40: 31 | B40: 0827CI231031 | C40: DARSHIT JAIN | D40: =SUM(R40+AL40+BI40+CF40+CS40+CU40) -> 8 | E40: =(D40)/D$9*100 -> 29.62963 | F40: =IF(E40<50,E40, " ") -> 29.62963 | G40: =IF(E40<30,E40, " ") -> 29.62963 | M40: 1 | R40: =SUM(H40:Q40) -> 1 | S40: =R40/R$9*100 -> 50 | Y40: 1 | AC40: 1 | AL40: =SUM(T40:AK40) -> 2 | AM40: =AL40/AL$9*100 -> 25 | AS40: 1 | BF40: 1 | BI40: =SUM(AN40:BH40) -> 2 | BJ40: =BI40/BI$9*100 -> 25 | BM40: 1 | BQ40: 1 | BS40: 1 | CF40: =SUM(BK40:BW40) -> 3 | CG40: =CF40/CF$9*100 -> 33.333333 | CS40: =SUM(CH40:CR40) -> 0 | CT40: =CS40/CS$9*100 -> #DIV/0! | CV40: =(D40)/D$9*100 -> 29.62963 | CW40: =SUM(R40+AL40+BI40+CF40+CS40+CU40) -> 8
...

Sheet 601 L
A1: CSIT-601 L
A2: Faculty Name: | C2: Prof. Amrita Jain
A3: Subject Name : | C3: Software Engineering & Agile
A4: Subject Code :
A5: Start Date | C5: 46069
A6: End Date
BK7: 1 | BL7: 2 | BM7: 3 | BN7: 4 | BO7: 5 | BP7: 6 | BQ7: 7 | BR7: 8 | BS7: 9 | BT7: 10 | BU7: 11 | BV7: 12 | BW7: 13 | BX7: 14 | BY7: 15 | BZ7: 16 | CA7: 17 | CB7: 18 | CC7: 19 | CD7: 20 | CE7: 21 | CH7: 1 | CI7: 2 | CJ7: 3 | CK7: 4 | CL7: 5 | CM7: 6 | CN7: 7 | CO7: 8 | CP7: 9 | CQ7: 10 | CR7: 11 | CS7: 12
D8: Total Class | E8: OverAll Att. % | F8: Att. 50% | G8: Att. 30% | H8: 46069 | I8: 46070 | J8: 46071 | K8: 46072 | L8: 46076 | M8: 46077 | N8: 46078 | O8: 46079 | P8: 46080 | Q8: 46081 | R8: FEB CLASS | S8: FEB% | T8: 46085 | U8: 46086 | V8: 46087 | W8: 46090 | X8: 46091 | Y8: 46092 | Z8: 46093 | AA8: 46094 | AB8: 46097 | AC8: 46098 | AD8: 46099 | AE8: 46100 | AF8: 46101 | AG8: 46104 | AH8: 46105 | AI8: 46106 | AJ8: 46107 | AK8: 46111 | AL8: MAR CLASS | AM8: MAR % | AN8: 46113 | AO8: 46114 | AP8: 46115 | AQ8: 46118 | AR8: 46119 | AS8: 46120 | AT8: 46121 | AU8: 46122 | AV8: 46125 | AW8: 46127 | AX8: 46128 | AY8: 46129 | AZ8: 46132 | BA8: 46133 | BB8: 46134 | BC8: 46135 | BD8: 46136 | BE8: 46139 | BF8: 46140 | BG8: 46141 | BH8: 46142 | BI8: APRIL CLASS | BJ8: APRIL % | BK8: 46143 | BL8: 46146 | BM8: 46147 | BN8: 46148 | BO8: 46149 | BP8: 46150 | BQ8: 46153 | BR8: 46154 | BS8: 46155 | BT8: 46156 | BU8: 46157 | BV8: 46160 | BW8: 46161 | BX8: 46162 | BY8: 46163 | BZ8: 46164 | CA8: 46167 | CB8: 46168 | CC8: 46169 | CD8: 46170 | CE8: 46171 | CF8: MAY CLASS | CG8: MAY % | CH8: 46174 | CI8: 46175 | CJ8: 46176 | CK8: 46177 | CL8: 46178 | CM8: 46181 | CN8: 46182 | CO8: 46183 | CP8: 46184 | CQ8: 46185 | CR8: 46186 | CS8: 46188 | CT8: DEC CLASS | CU8: DEC % | CV8: SPECIAL LEAVE | CW8: OVER ALL % | CX8: TOTAL CLASS | CY8: REMARK
A9: S.No. | B9: Enrollment No. | C9: Student Name | D9: =SUM(R9+AL9+BI9+CF9+CT9) -> 14 | H9: =SUM(H10:H93) -> 0 | I9: =SUM(I10:I93) -> 5 | J9: =SUM(J10:J93) -> 0 | K9: =SUM(K10:K93) -> 0 | L9: =SUM(L10:L93) -> 0 | M9: =SUM(M10:M93) -> 30 | N9: =SUM(N10:N93) -> 0 | O9: =SUM(O10:O93) -> 0 | ... Q9: =SUM(Q10:Q93) -> 0 | R9: =COUNTIF(H9:Q9,">0") -> 2 | S9: =COUNTIF(H9:K9,">0") -> 1 | T9: =SUM(T10:T93) -> 0 | U9: =SUM(U10:U93) -> 0 | V9: =SUM(V10:V93) -> 0 | W9: =SUM(W10:W93) -> 0 | X9: =SUM(X10:X93) -> 0 | Y9: =SUM(Y10:Y93) -> 36 | Z9: =SUM(Z10:Z93) -> 37 | AA9: =SUM(AA10:AA93) -> 0 | ... AK9: =SUM(AK10:AK93) -> 0 | AL9: =COUNTIF(T9:AK9,">0") -> 5 | AM9: =SUM(R9+AL9) -> 7 | AN9: =SUM(AN10:AN48) -> 0 | AO9: =SUM(AO10:AO48) -> 0 | AP9: =SUM(AP10:AP48) -> 0 | AQ9: =SUM(AQ10:AQ48) -> 0 | AR9: =SUM(AR10:AR48) -> 0 | AS9: =SUM(AS10:AS48) -> 0 | AT9: =SUM(AT10:AT48) -> 0 | AU9: =SUM(AU10:AU48) -> 0 | ... BH9: =SUM(BH10:BH48) -> 11 | BI9: =COUNTIF(AN9:BH9,">0") -> 4 | BJ9: =SUM(AM9+BI9) -> 11 | BK9: =SUM(BK10:BK48) -> 0 | BL9: =SUM(BL10:BL48) -> 0 | BM9: =SUM(BM10:BM48) -> 0 | BN9: =SUM(BN10:BN48) -> 21 | BO9: =SUM(BO10:BO48) -> 0 | BP9: =SUM(BP10:BP48) -> 25 | BQ9: =SUM(BQ10:BQ48) -> 0 | BR9: =SUM(BR10:BR48) -> 0 | ... CE9: =SUM(CE10:CE48) -> 0 | CF9: =COUNTIF(BK9:CE9,">0") -> 3 | CG9: =SUM(BJ9+CF9) -> 14 | CH9: =SUM(CH10:CH48) -> 0 | CI9: =SUM(CI10:CI48) -> 0 | CJ9: =SUM(CJ10:CJ48) -> 0 | CK9: =SUM(CK10:CK48) -> 0 | CL9: =SUM(CL10:CL48) -> 0 | CM9: =SUM(CM10:CM48) -> 0 | CN9: =SUM(CN10:CN48) -> 0 | CO9: =SUM(CO10:CO48) -> 0 | ... CS9: =SUM(CS10:CS48) -> 0 | CT9: =COUNTIF(CH9:CS9,">0") -> 0 | CU9: =SUM(CG9+CT9) -> 14 | CW9: =SUM(R9+AL9+BI9+CF9+CT9+CV9) -> 14 | CX9: =SUM(R9+AL9+BI9+CF9+CT9+CV9) -> 14
A10: 1 | B10: 0827CI231001 | C10: AADARSH GARHEWAL | D10: =SUM(R10+AL10+BI10+CF10+CT10+CV10) -> 0 | E10: =(D10)/D$9*100 -> 0 | F10: =IF(E10<50,E10, " ") -> 0 | G10: =IF(E10<30,E10, " ") -> 0 | R10: =SUM(H10:Q10) -> 0 | S10: =R10/R$9*100 -> 0 | AL10: =SUM(T10:AK10) -> 0 | AM10: =AL10/AL$9*100 -> 0 | BI10: =SUM(AN10:BH10) -> 0 | BJ10: =BI10/BI$9*100 -> 0 | CF10: =SUM(BK10:CE10) -> 0 | CG10: =CF10/CF$9*100 -> 0 | CT10: =SUM(CH10:CS10) -> 0 | CU10: =CT10/CT$9*100 -> #DIV/0! | CW10: =(D10)/D$9*100 -> 0 | CX10: =SUM(R10+AL10+BI10+CF10+CT10+CV10) -> 0
A11: 2 | B11: 0827CI231002 | C11: AYUSH PATEL | D11: =SUM(R11+AL11+BI11+CF11+CT11+CV11) -> 12 | E11: =(D11)/D$9*100 -> 85.714286 | F11: =IF(E11<50,E11, " ") | G11: =IF(E11<30,E11, " ") | M11: 1 | R11: =SUM(H11:Q11) -> 1 | S11: =R11/R$9*100 -> 50 | Y11: 1 | Z11: 1 | AD11: 1 | AE11: 1 | AI11: 1 | AL11: =SUM(T11:AK11) -> 5 | AM11: =AL11/AL$9*100 -> 100 | AX11: 1 | BG11: 1 | BH11: 1 | BI11: =SUM(AN11:BH11) -> 3 | BJ11: =BI11/BI$9*100 -> 75 | BN11: 1 | BP11: 1 | BT11: 1 | CF11: =SUM(BK11:CE11) -> 3 | CG11: =CF11/CF$9*100 -> 100 | CT11: =SUM(CH11:CS11) -> 0 | CU11: =CT11/CT$9*100 -> #DIV/0! | CW11: =(D11)/D$9*100 -> 85.714286 | CX11: =SUM(R11+AL11+BI11+CF11+CT11+CV11) -> 12
A12: 3 | B12: 0827CI231003 | C12: ABHAY DUGAYA | D12: =SUM(R12+AL12+BI12+CF12+CT12+CV12) -> 2 | E12: =(D12)/D$9*100 -> 14.285714 | F12: =IF(E12<50,E12, " ") -> 14.285714 | G12: =IF(E12<30,E12, " ") -> 14.285714 | R12: =SUM(H12:Q12) -> 0 | S12: =R12/R$9*100 -> 0 | AL12: =SUM(T12:AK12) -> 0 | AM12: =AL12/AL$9*100 -> 0 | BI12: =SUM(AN12:BH12) -> 0 | BJ12: =BI12/BI$9*100 -> 0 | BN12: 1 | BT12: 1 | CF12: =SUM(BK12:CE12) -> 2 | CG12: =CF12/CF$9*100 -> 66.666667 | CT12: =SUM(CH12:CS12) -> 0 | CU12: =CT12/CT$9*100 -> #DIV/0! | CW12: =(D12)/D$9*100 -> 14.285714 | CX12: =SUM(R12+AL12+BI12+CF12+CT12+CV12) -> 2
A13: 4 | B13: 0827CI231004 | C13: ABHISHEK JAISWAL | D13: =SUM(R13+AL13+BI13+CF13+CT13+CV13) -> 5 | E13: =(D13)/D$9*100 -> 35.714286 | F13: =IF(E13<50,E13, " ") -> 35.714286 | G13: =IF(E13<30,E13, " ") | R13: =SUM(H13:Q13) -> 0 | S13: =R13/R$9*100 -> 0 | AI13: 1 | AL13: =SUM(T13:AK13) -> 1 | AM13: =AL13/AL$9*100 -> 20 | AX13: 1 | BH13: 1 | BI13: =SUM(AN13:BH13) -> 2 | BJ13: =BI13/BI$9*100 -> 50 | BP13: 1 | BT13: 1 | CF13: =SUM(BK13:CE13) -> 2 | CG13: =CF13/CF$9*100 -> 66.666667 | CT13: =SUM(CH13:CS13) -> 0 | CU13: =CT13/CT$9*100 -> #DIV/0! | CW13: =(D13)/D$9*100 -> 35.714286 | CX13: =SUM(R13+AL13+BI13+CF13+CT13+CV13) -> 5
A14: 5 | B14: 0827CI231005 | C14: ABHISHEK VERMA | D14: =SUM(R14+AL14+BI14+CF14+CT14+CV14) -> 6 | E14: =(D14)/D$9*100 -> 42.857143 | F14: =IF(E14<50,E14, " ") -> 42.857143 | G14: =IF(E14<30,E14, " ") | M14: 1 | R14: =SUM(H14:Q14) -> 1 | S14: =R14/R$9*100 -> 50 | Y14: 1 | AD14: 1 | AI14: 1 | AL14: =SUM(T14:AK14) -> 3 | AM14: =AL14/AL$9*100 -> 60 | BI14: =SUM(AN14:BH14) -> 0 | BJ14: =BI14/BI$9*100 -> 0 | BN14: 1 | BP14: 1 | CF14: =SUM(BK14:CE14) -> 2 | CG14: =CF14/CF$9*100 -> 66.666667 | CT14: =SUM(CH14:CS14) -> 0 | CU14: =CT14/CT$9*100 -> #DIV/0! | CW14: =(D14)/D$9*100 -> 42.857143 | CX14: =SUM(R14+AL14+BI14+CF14+CT14+CV14) -> 6
A15: 6 | B15: 0827CI231006 | C15: ABINAV KOURAV | D15: =SUM(R15+AL15+BI15+CF15+CT15+CV15) -> 0 | E15: =(D15)/D$9*100 -> 0 | F15: =IF(E15<50,E15, " ") -> 0 | G15: =IF(E15<30,E15, " ") -> 0 | R15: =SUM(H15:Q15) -> 0 | S15: =R15/R$9*100 -> 0 | AL15: =SUM(T15:AK15) -> 0 | AM15: =AL15/AL$9*100 -> 0 | BI15: =SUM(AN15:BH15) -> 0 | BJ15: =BI15/BI$9*100 -> 0 | CF15: =SUM(BK15:CE15) -> 0 | CG15: =CF15/CF$9*100 -> 0 | CT15: =SUM(CH15:CS15) -> 0 | CU15: =CT15/CT$9*100 -> #DIV/0! | CW15: =(D15)/D$9*100 -> 0 | CX15: =SUM(R15+AL15+BI15+CF15+CT15+CV15) -> 0
A16: 7 | B16: 0827CI231007 | C16: ADARSH PRATAP SINGH GURJAR | D16: =SUM(R16+AL16+BI16+CF16+CT16+CV16) -> 4 | E16: =(D16)/D$9*100 -> 28.571429 | F16: =IF(E16<50,E16, " ") -> 28.571429 | G16: =IF(E16<30,E16, " ") -> 28.571429 | R16: =SUM(H16:Q16) -> 0 | S16: =R16/R$9*100 -> 0 | AL16: =SUM(T16:AK16) -> 0 | AM16: =AL16/AL$9*100 -> 0 | BB16: 1 | BH16: 1 | BI16: =SUM(AN16:BH16) -> 2 | BJ16: =BI16/BI$9*100 -> 50 | BP16: 1 | BT16: 1 | CF16: =SUM(BK16:CE16) -> 2 | CG16: =CF16/CF$9*100 -> 66.666667 | CT16: =SUM(CH16:CS16) -> 0 | CU16: =CT16/CT$9*100 -> #DIV/0! | CW16: =(D16)/D$9*100 -> 28.571429 | CX16: =SUM(R16+AL16+BI16+CF16+CT16+CV16) -> 4
A17: 8 | B17: 0827CI231008 | C17: ADITI VISHWAKARMA | D17: =SUM(R17+AL17+BI17+CF17+CT17+CV17) -> 5 | E17: =(D17)/D$9*100 -> 35.714286 | F17: =IF(E17<50,E17, " ") -> 35.714286 | G17: =IF(E17<30,E17, " ") | M17: 1 | R17: =SUM(H17:Q17) -> 1 | S17: =R17/R$9*100 -> 50 | Y17: 1 | AD17: 1 | AI17: 1 | AL17: =SUM(T17:AK17) -> 3 | AM17: =AL17/AL$9*100 -> 60 | BI17: =SUM(AN17:BH17) -> 0 | BJ17: =BI17/BI$9*100 -> 0 | BP17: 1 | CF17: =SUM(BK17:CE17) -> 1 | CG17: =CF17/CF$9*100 -> 33.333333 | CT17: =SUM(CH17:CS17) -> 0 | CU17: =CT17/CT$9*100 -> #DIV/0! | CW17: =(D17)/D$9*100 -> 35.714286 | CX17: =SUM(R17+AL17+BI17+CF17+CT17+CV17) -> 5
A18: 9 | B18: 0827CI231009 | C18: ADITYA TIWARI | D18: =SUM(R18+AL18+BI18+CF18+CT18+CV18) -> 5 | E18: =(D18)/D$9*100 -> 35.714286 | F18: =IF(E18<50,E18, " ") -> 35.714286 | G18: =IF(E18<30,E18, " ") | M18: 1 | R18: =SUM(H18:Q18) -> 1 | S18: =R18/R$9*100 -> 50 | AI18: 1 | AL18: =SUM(T18:AK18) -> 1 | AM18: =AL18/AL$9*100 -> 20 | BG18: 1 | BI18: =SUM(AN18:BH18) -> 1 | BJ18: =BI18/BI$9*100 -> 25 | BN18: 1 | BP18: 1 | CF18: =SUM(BK18:CE18) -> 2 | CG18: =CF18/CF$9*100 -> 66.666667 | CT18: =SUM(CH18:CS18) -> 0 | CU18: =CT18/CT$9*100 -> #DIV/0! | CW18: =(D18)/D$9*100 -> 35.714286 | CX18: =SUM(R18+AL18+BI18+CF18+CT18+CV18) -> 5
A19: 10 | B19: 0827CI231010 | C19: AKASH BARASKAR | D19: =SUM(R19+AL19+BI19+CF19+CT19+CV19) -> 3 | E19: =(D19)/D$9*100 -> 21.428571 | F19: =IF(E19<50,E19, " ") -> 21.428571 | G19: =IF(E19<30,E19, " ") -> 21.428571 | R19: =SUM(H19:Q19) -> 0 | S19: =R19/R$9*100 -> 0 | AD19: 1 | AE19: 1 | AL19: =SUM(T19:AK19) -> 2 | AM19: =AL19/AL$9*100 -> 40 | BB19: 1 | BI19: =SUM(AN19:BH19) -> 1 | BJ19: =BI19/BI$9*100 -> 25 | CF19: =SUM(BK19:CE19) -> 0 | CG19: =CF19/CF$9*100 -> 0 | CT19: =SUM(CH19:CS19) -> 0 | CU19: =CT19/CT$9*100 -> #DIV/0! | CW19: =(D19)/D$9*100 -> 21.428571 | CX19: =SUM(R19+AL19+BI19+CF19+CT19+CV19) -> 3
A20: 11 | B20: 0827CI231011 | C20: AKSHAT KARODE | D20: =SUM(R20+AL20+BI20+CF20+CT20+CV20) -> 4 | E20: =(D20)/D$9*100 -> 28.571429 | F20: =IF(E20<50,E20, " ") -> 28.571429 | G20: =IF(E20<30,E20, " ") -> 28.571429 | R20: =SUM(H20:Q20) -> 0 | S20: =R20/R$9*100 -> 0 | AI20: 1 | AL20: =SUM(T20:AK20) -> 1 | AM20: =AL20/AL$9*100 -> 20 | BH20: 1 | BI20: =SUM(AN20:BH20) -> 1 | BJ20: =BI20/BI$9*100 -> 25 | BN20: 1 | BP20: 1 | CF20: =SUM(BK20:CE20) -> 2 | CG20: =CF20/CF$9*100 -> 66.666667 | CT20: =SUM(CH20:CS20) -> 0 | CU20: =CT20/CT$9*100 -> #DIV/0! | CW20: =(D20)/D$9*100 -> 28.571429 | CX20: =SUM(R20+AL20+BI20+CF20+CT20+CV20) -> 4
A21: 12 | B21: 0827CI231012 | C21: AKSHAY KHANNA | D21: =SUM(R21+AL21+BI21+CF21+CT21+CV21) -> 4 | E21: =(D21)/D$9*100 -> 28.571429 | F21: =IF(E21<50,E21, " ") -> 28.571429 | G21: =IF(E21<30,E21, " ") -> 28.571429 | M21: 1 | R21: =SUM(H21:Q21) -> 1 | S21: =R21/R$9*100 -> 50 | AL21: =SUM(T21:AK21) -> 0 | AM21: =AL21/AL$9*100 -> 0 | BG21: 1 | BI21: =SUM(AN21:BH21) -> 1 | BJ21: =BI21/BI$9*100 -> 25 | BN21: 1 | BP21: 1 | CF21: =SUM(BK21:CE21) -> 2 | CG21: =CF21/CF$9*100 -> 66.666667 | CT21: =SUM(CH21:CS21) -> 0 | CU21: =CT21/CT$9*100 -> #DIV/0! | CW21: =(D21)/D$9*100 -> 28.571429 | CX21: =SUM(R21+AL21+BI21+CF21+CT21+CV21) -> 4
A22: 13 | B22: 0827CI231013 | C22: AMAY MISHRA | D22: =SUM(R22+AL22+BI22+CF22+CT22+CV22) -> 6 | E22: =(D22)/D$9*100 -> 42.857143 | F22: =IF(E22<50,E22, " ") -> 42.857143 | G22: =IF(E22<30,E22, " ") | R22: =SUM(H22:Q22) -> 0 | S22: =R22/R$9*100 -> 0 | Y22: 1 | Z22: 1 | AI22: 1 | AL22: =SUM(T22:AK22) -> 3 | AM22: =AL22/AL$9*100 -> 60 | BG22: 1 | BI22: =SUM(AN22:BH22) -> 1 | BJ22: =BI22/BI$9*100 -> 25 | BN22: 1 | BP22: 1 | CF22: =SUM(BK22:CE22) -> 2 | CG22: =CF22/CF$9*100 -> 66.666667 | CT22: =SUM(CH22:CS22) -> 0 | CU22: =CT22/CT$9*100 -> #DIV/0! | CW22: =(D22)/D$9*100 -> 42.857143 | CX22: =SUM(R22+AL22+BI22+CF22+CT22+CV22) -> 6
A23: 14 | B23: 0827CI231014 | C23: AMBAR YADAV | D23: =SUM(R23+AL23+BI23+CF23+CT23+CV23) -> 3 | E23: =(D23)/D$9*100 -> 21.428571 | F23: =IF(E23<50,E23, " ") -> 21.428571 | G23: =IF(E23<30,E23, " ") -> 21.428571 | I23: 1 | R23: =SUM(H23:Q23) -> 1 | S23: =R23/R$9*100 -> 50 | AI23: 1 | AL23: =SUM(T23:AK23) -> 1 | AM23: =AL23/AL$9*100 -> 20 | BI23: =SUM(AN23:BH23) -> 0 | BJ23: =BI23/BI$9*100 -> 0 | BP23: 1 | CF23: =SUM(BK23:CE23) -> 1 | CG23: =CF23/CF$9*100 -> 33.333333 | CT23: =SUM(CH23:CS23) -> 0 | CU23: =CT23/CT$9*100 -> #DIV/0! | CW23: =(D23)/D$9*100 -> 21.428571 | CX23: =SUM(R23+AL23+BI23+CF23+CT23+CV23) -> 3
A24: 15 | B24: 0827CI231015 | C24: AMIT YADAV | D24: =SUM(R24+AL24+BI24+CF24+CT24+CV24) -> 2 | E24: =(D24)/D$9*100 -> 14.285714 | F24: =IF(E24<50,E24, " ") -> 14.285714 | G24: =IF(E24<30,E24, " ") -> 14.285714 | R24: =SUM(H24:Q24) -> 0 | S24: =R24/R$9*100 -> 0 | Z24: 1 | AL24: =SUM(T24:AK24) -> 1 | AM24: =AL24/AL$9*100 -> 20 | BI24: =SUM(AN24:BH24) -> 0 | BJ24: =BI24/BI$9*100 -> 0 | BT24: 1 | CF24: =SUM(BK24:CE24) -> 1 | CG24: =CF24/CF$9*100 -> 33.333333 | CT24: =SUM(CH24:CS24) -> 0 | CU24: =CT24/CT$9*100 -> #DIV/0! | CW24: =(D24)/D$9*100 -> 14.285714 | CX24: =SUM(R24+AL24+BI24+CF24+CT24+CV24) -> 2
A25: 16 | B25: 0827CI231016 | C25: ANIRUDDH CHATURVEDI | D25: =SUM(R25+AL25+BI25+CF25+CT25+CV25) -> 7 | E25: =(D25)/D$9*100 -> 50 | F25: =IF(E25<50,E25, " ") | G25: =IF(E25<30,E25, " ") | M25: 1 | R25: =SUM(H25:Q25) -> 1 | S25: =R25/R$9*100 -> 50 | Y25: 1 | Z25: 1 | AD25: 1 | AE25: 1 | AL25: =SUM(T25:AK25) -> 4 | AM25: =AL25/AL$9*100 -> 80 | BI25: =SUM(AN25:BH25) -> 0 | BJ25: =BI25/BI$9*100 -> 0 | BN25: 1 | BT25: 1 | CF25: =SUM(BK25:CE25) -> 2 | CG25: =CF25/CF$9*100 -> 66.666667 | CT25: =SUM(CH25:CS25) -> 0 | CU25: =CT25/CT$9*100 -> #DIV/0! | CW25: =(D25)/D$9*100 -> 50 | CX25: =SUM(R25+AL25+BI25+CF25+CT25+CV25) -> 7
A26: 17 | B26: 0827CI231017 | C26: ANIRUDDHA SHARMA | D26: =SUM(R26+AL26+BI26+CF26+CT26+CV26) -> 3 | E26: =(D26)/D$9*100 -> 21.428571 | F26: =IF(E26<50,E26, " ") -> 21.428571 | G26: =IF(E26<30,E26, " ") -> 21.428571 | M26: 1 | R26: =SUM(H26:Q26) -> 1 | S26: =R26/R$9*100 -> 50 | Z26: 1 | AL26: =SUM(T26:AK26) -> 1 | AM26: =AL26/AL$9*100 -> 20 | BI26: =SUM(AN26:BH26) -> 0 | BJ26: =BI26/BI$9*100 -> 0 | BT26: 1 | CF26: =SUM(BK26:CE26) -> 1 | CG26: =CF26/CF$9*100 -> 33.333333 | CT26: =SUM(CH26:CS26) -> 0 | CU26: =CT26/CT$9*100 -> #DIV/0! | CW26: =(D26)/D$9*100 -> 21.428571 | CX26: =SUM(R26+AL26+BI26+CF26+CT26+CV26) -> 3
A27: 18 | B27: 0827CI231018 | C27: ANSH RATHORE | D27: =SUM(R27+AL27+BI27+CF27+CT27+CV27) -> 6 | E27: =(D27)/D$9*100 -> 42.857143 | F27: =IF(E27<50,E27, " ") -> 42.857143 | G27: =IF(E27<30,E27, " ") | M27: 1 | R27: =SUM(H27:Q27) -> 1 | S27: =R27/R$9*100 -> 50 | Y27: 1 | Z27: 1 | AI27: 1 | AL27: =SUM(T27:AK27) -> 3 | AM27: =AL27/AL$9*100 -> 60 | BI27: =SUM(AN27:BH27) -> 0 | BJ27: =BI27/BI$9*100 -> 0 | BN27: 1 | BP27: 1 | CF27: =SUM(BK27:CE27) -> 2 | CG27: =CF27/CF$9*100 -> 66.666667 | CT27: =SUM(CH27:CS27) -> 0 | CU27: =CT27/CT$9*100 -> #DIV/0! | CW27: =(D27)/D$9*100 -> 42.857143 | CX27: =SUM(R27+AL27+BI27+CF27+CT27+CV27) -> 6
A28: 19 | B28: 0827CI231019 | C28: ANSH VAISHNAV | D28: =SUM(R28+AL28+BI28+CF28+CT28+CV28) -> 3 | E28: =(D28)/D$9*100 -> 21.428571 | F28: =IF(E28<50,E28, " ") -> 21.428571 | G28: =IF(E28<30,E28, " ") -> 21.428571 | M28: 1 | R28: =SUM(H28:Q28) -> 1 | S28: =R28/R$9*100 -> 50 | Z28: 1 | AL28: =SUM(T28:AK28) -> 1 | AM28: =AL28/AL$9*100 -> 20 | BH28: 1 | BI28: =SUM(AN28:BH28) -> 1 | BJ28: =BI28/BI$9*100 -> 25 | CF28: =SUM(BK28:CE28) -> 0 | CG28: =CF28/CF$9*100 -> 0 | CT28: =SUM(CH28:CS28) -> 0 | CU28: =CT28/CT$9*100 -> #DIV/0! | CW28: =(D28)/D$9*100 -> 21.428571 | CX28: =SUM(R28+AL28+BI28+CF28+CT28+CV28) -> 3
A29: 20 | B29: 0827CI231020 | C29: ANSHU BILAWLIYA | D29: =SUM(R29+AL29+BI29+CF29+CT29+CV29) -> 12 | E29: =(D29)/D$9*100 -> 85.714286 | F29: =IF(E29<50,E29, " ") | G29: =IF(E29<30,E29, " ") | M29: 1 | R29: =SUM(H29:Q29) -> 1 | S29: =R29/R$9*100 -> 50 | Y29: 1 | Z29: 1 | AD29: 1 | AE29: 1 | AI29: 1 | AL29: =SUM(T29:AK29) -> 5 | AM29: =AL29/AL$9*100 -> 100 | AX29: 1 | BB29: 1 | BG29: 1 | BI29: =SUM(AN29:BH29) -> 3 | BJ29: =BI29/BI$9*100 -> 75 | BN29: 1 | BP29: 1 | BT29: 1 | CF29: =SUM(BK29:CE29) -> 3 | CG29: =CF29/CF$9*100 -> 100 | CT29: =SUM(CH29:CS29) -> 0 | CU29: =CT29/CT$9*100 -> #DIV/0! | CW29: =(D29)/D$9*100 -> 85.714286 | CX29: =SUM(R29+AL29+BI29+CF29+CT29+CV29) -> 12
A30: 21 | B30: 0827CI231021 | C30: ANUJ MALVIYA | D30: =SUM(R30+AL30+BI30+CF30+CT30+CV30) -> 3 | E30: =(D30)/D$9*100 -> 21.428571 | F30: =IF(E30<50,E30, " ") -> 21.428571 | G30: =IF(E30<30,E30, " ") -> 21.428571 | I30: 1 | R30: =SUM(H30:Q30) -> 1 | S30: =R30/R$9*100 -> 50 | AL30: =SUM(T30:AK30) -> 0 | AM30: =AL30/AL$9*100 -> 0 | BG30: 1 | BI30: =SUM(AN30:BH30) -> 1 | BJ30: =BI30/BI$9*100 -> 25 | BP30: 1 | CF30: =SUM(BK30:CE30) -> 1 | CG30: =CF30/CF$9*100 -> 33.333333 | CT30: =SUM(CH30:CS30) -> 0 | CU30: =CT30/CT$9*100 -> #DIV/0! | CW30: =(D30)/D$9*100 -> 21.428571 | CX30: =SUM(R30+AL30+BI30+CF30+CT30+CV30) -> 3
A31: 22 | B31: 0827CI231022 | C31: ANVESH TRIVEDI | D31: =SUM(R31+AL31+BI31+CF31+CT31+CV31) -> 6 | E31: =(D31)/D$9*100 -> 42.857143 | F31: =IF(E31<50,E31, " ") -> 42.857143 | G31: =IF(E31<30,E31, " ") | M31: 1 | R31: =SUM(H31:Q31) -> 1 | S31: =R31/R$9*100 -> 50 | AD31: 1 | AI31: 1 | AL31: =SUM(T31:AK31) -> 2 | AM31: =AL31/AL$9*100 -> 40 | BG31: 1 | BI31: =SUM(AN31:BH31) -> 1 | BJ31: =BI31/BI$9*100 -> 25 | BN31: 1 | BP31: 1 | CF31: =SUM(BK31:CE31) -> 2 | CG31: =CF31/CF$9*100 -> 66.666667 | CT31: =SUM(CH31:CS31) -> 0 | CU31: =CT31/CT$9*100 -> #DIV/0! | CW31: =(D31)/D$9*100 -> 42.857143 | CX31: =SUM(R31+AL31+BI31+CF31+CT31+CV31) -> 6
A32: 23 | B32: 0827CI231023 | C32: ANYA JAIN | D32: =SUM(R32+AL32+BI32+CF32+CT32+CV32) -> 4 | E32: =(D32)/D$9*100 -> 28.571429 | F32: =IF(E32<50,E32, " ") -> 28.571429 | G32: =IF(E32<30,E32, " ") -> 28.571429 | R32: =SUM(H32:Q32) -> 0 | S32: =R32/R$9*100 -> 0 | Y32: 1 | AD32: 1 | AL32: =SUM(T32:AK32) -> 2 | AM32: =AL32/AL$9*100 -> 40 | BI32: =SUM(AN32:BH32) -> 0 | BJ32: =BI32/BI$9*100 -> 0 | BN32: 1 | BP32: 1 | CF32: =SUM(BK32:CE32) -> 2 | CG32: =CF32/CF$9*100 -> 66.666667 | CT32: =SUM(CH32:CS32) -> 0 | CU32: =CT32/CT$9*100 -> #DIV/0! | CW32: =(D32)/D$9*100 -> 28.571429 | CX32: =SUM(R32+AL32+BI32+CF32+CT32+CV32) -> 4
A33: 24 | B33: 0827CI231024 | C33: ARYAN SINGH BHADORIA | D33: =SUM(R33+AL33+BI33+CF33+CT33+CV33) -> 6 | E33: =(D33)/D$9*100 -> 42.857143 | F33: =IF(E33<50,E33, " ") -> 42.857143 | G33: =IF(E33<30,E33, " ") | M33: 1 | R33: =SUM(H33:Q33) -> 1 | S33: =R33/R$9*100 -> 50 | AD33: 1 | AI33: 1 | AL33: =SUM(T33:AK33) -> 2 | AM33: =AL33/AL$9*100 -> 40 | BG33: 1 | BI33: =SUM(AN33:BH33) -> 1 | BJ33: =BI33/BI$9*100 -> 25 | BN33: 1 | BP33: 1 | CF33: =SUM(BK33:CE33) -> 2 | CG33: =CF33/CF$9*100 -> 66.666667 | CT33: =SUM(CH33:CS33) -> 0 | CU33: =CT33/CT$9*100 -> #DIV/0! | CW33: =(D33)/D$9*100 -> 42.857143 | CX33: =SUM(R33+AL33+BI33+CF33+CT33+CV33) -> 6
A34: 25 | B34: 0827CI231025 | C34: ASHWIN CARPENTER | D34: =SUM(R34+AL34+BI34+CF34+CT34+CV34) -> 2 | E34: =(D34)/D$9*100 -> 14.285714 | F34: =IF(E34<50,E34, " ") -> 14.285714 | G34: =IF(E34<30,E34, " ") -> 14.285714 | R34: =SUM(H34:Q34) -> 0 | S34: =R34/R$9*100 -> 0 | Z34: 1 | AL34: =SUM(T34:AK34) -> 1 | AM34: =AL34/AL$9*100 -> 20 | BI34: =SUM(AN34:BH34) -> 0 | BJ34: =BI34/BI$9*100 -> 0 | BP34: 1 | CF34: =SUM(BK34:CE34) -> 1 | CG34: =CF34/CF$9*100 -> 33.333333 | CT34: =SUM(CH34:CS34) -> 0 | CU34: =CT34/CT$9*100 -> #DIV/0! | CW34: =(D34)/D$9*100 -> 14.285714 | CX34: =SUM(R34+AL34+BI34+CF34+CT34+CV34) -> 2
A35: 26 | B35: 0827CI231026 | C35: AVI KEDARE | D35: =SUM(R35+AL35+BI35+CF35+CT35+CV35) -> 11 | E35: =(D35)/D$9*100 -> 78.571429 | F35: =IF(E35<50,E35, " ") | G35: =IF(E35<30,E35, " ") | M35: 1 | R35: =SUM(H35:Q35) -> 1 | S35: =R35/R$9*100 -> 50 | Y35: 1 | Z35: 1 | AD35: 1 | AE35: 1 | AL35: =SUM(T35:AK35) -> 4 | AM35: =AL35/AL$9*100 -> 80 | AX35: 1 | BG35: 1 | BH35: 1 | BI35: =SUM(AN35:BH35) -> 3 | BJ35: =BI35/BI$9*100 -> 75 | BN35: 1 | BP35: 1 | BT35: 1 | CF35: =SUM(BK35:CE35) -> 3 | CG35: =CF35/CF$9*100 -> 100 | CT35: =SUM(CH35:CS35) -> 0 | CU35: =CT35/CT$9*100 -> #DIV/0! | CW35: =(D35)/D$9*100 -> 78.571429 | CX35: =SUM(R35+AL35+BI35+CF35+CT35+CV35) -> 11
A36: 27 | B36: 0827CI231027 | C36: AYUSH CHOUDHARY | D36: =SUM(R36+AL36+BI36+CF36+CT36+CV36) -> 0 | E36: =(D36)/D$9*100 -> 0 | F36: =IF(E36<50,E36, " ") -> 0 | G36: =IF(E36<30,E36, " ") -> 0 | R36: =SUM(H36:Q36) -> 0 | S36: =R36/R$9*100 -> 0 | AL36: =SUM(T36:AK36) -> 0 | AM36: =AL36/AL$9*100 -> 0 | BI36: =SUM(AN36:BH36) -> 0 | BJ36: =BI36/BI$9*100 -> 0 | CF36: =SUM(BK36:CE36) -> 0 | CG36: =CF36/CF$9*100 -> 0 | CT36: =SUM(CH36:CS36) -> 0 | CU36: =CT36/CT$9*100 -> #DIV/0! | CW36: =(D36)/D$9*100 -> 0 | CX36: =SUM(R36+AL36+BI36+CF36+CT36+CV36) -> 0
A37: 28 | B37: 0827CI231028 | C37: AYUSH CHOURASIYA | D37: =SUM(R37+AL37+BI37+CF37+CT37+CV37) -> 4 | E37: =(D37)/D$9*100 -> 28.571429 | F37: =IF(E37<50,E37, " ") -> 28.571429 | G37: =IF(E37<30,E37, " ") -> 28.571429 | R37: =SUM(H37:Q37) -> 0 | S37: =R37/R$9*100 -> 0 | Y37: 1 | AD37: 1 | AL37: =SUM(T37:AK37) -> 2 | AM37: =AL37/AL$9*100 -> 40 | BH37: 1 | BI37: =SUM(AN37:BH37) -> 1 | BJ37: =BI37/BI$9*100 -> 25 | BN37: 1 | CF37: =SUM(BK37:CE37) -> 1 | CG37: =CF37/CF$9*100 -> 33.333333 | CT37: =SUM(CH37:CS37) -> 0 | CU37: =CT37/CT$9*100 -> #DIV/0! | CW37: =(D37)/D$9*100 -> 28.571429 | CX37: =SUM(R37+AL37+BI37+CF37+CT37+CV37) -> 4
A38: 29 | B38: 0827CI231029 | C38: CHIRAG | D38: =SUM(R38+AL38+BI38+CF38+CT38+CV38) -> 1 | E38: =(D38)/D$9*100 -> 7.1428571 | F38: =IF(E38<50,E38, " ") -> 7.1428571 | G38: =IF(E38<30,E38, " ") -> 7.1428571 | R38: =SUM(H38:Q38) -> 0 | S38: =R38/R$9*100 -> 0 | AL38: =SUM(T38:AK38) -> 0 | AM38: =AL38/AL$9*100 -> 0 | BI38: =SUM(AN38:BH38) -> 0 | BJ38: =BI38/BI$9*100 -> 0 | BT38: 1 | CF38: =SUM(BK38:CE38) -> 1 | CG38: =CF38/CF$9*100 -> 33.333333 | CT38: =SUM(CH38:CS38) -> 0 | CU38: =CT38/CT$9*100 -> #DIV/0! | CW38: =(D38)/D$9*100 -> 7.1428571 | CX38: =SUM(R38+AL38+BI38+CF38+CT38+CV38) -> 1
A39: 30 | B39: 0827CI231030 | C39: DARSHIL JAIN | D39: =SUM(R39+AL39+BI39+CF39+CT39+CV39) -> 1 | E39: =(D39)/D$9*100 -> 7.1428571 | F39: =IF(E39<50,E39, " ") -> 7.1428571 | G39: =IF(E39<30,E39, " ") -> 7.1428571 | R39: =SUM(H39:Q39) -> 0 | S39: =R39/R$9*100 -> 0 | AL39: =SUM(T39:AK39) -> 0 | AM39: =AL39/AL$9*100 -> 0 | BI39: =SUM(AN39:BH39) -> 0 | BJ39: =BI39/BI$9*100 -> 0 | BN39: 1 | CF39: =SUM(BK39:CE39) -> 1 | CG39: =CF39/CF$9*100 -> 33.333333 | CT39: =SUM(CH39:CS39) -> 0 | CU39: =CT39/CT$9*100 -> #DIV/0! | CW39: =(D39)/D$9*100 -> 7.1428571 | CX39: =SUM(R39+AL39+BI39+CF39+CT39+CV39) -> 1
A40: 31 | B40: 0827CI231031 | C40: DARSHIT JAIN | D40: =SUM(R40+AL40+BI40+CF40+CT40+CV40) -> 4 | E40: =(D40)/D$9*100 -> 28.571429 | F40: =IF(E40<50,E40, " ") -> 28.571429 | G40: =IF(E40<30,E40, " ") -> 28.571429 | M40: 1 | R40: =SUM(H40:Q40) -> 1 | S40: =R40/R$9*100 -> 50 | AE40: 1 | AL40: =SUM(T40:AK40) -> 1 | AM40: =AL40/AL$9*100 -> 20 | BH40: 1 | BI40: =SUM(AN40:BH40) -> 1 | BJ40: =BI40/BI$9*100 -> 25 | BP40: 1 | CF40: =SUM(BK40:CE40) -> 1 | CG40: =CF40/CF$9*100 -> 33.333333 | CT40: =SUM(CH40:CS40) -> 0 | CU40: =CT40/CT$9*100 -> #DIV/0! | CW40: =(D40)/D$9*100 -> 28.571429 | CX40: =SUM(R40+AL40+BI40+CF40+CT40+CV40) -> 4
...

Sheet 602
A1: CSIT-601
A2: Faculty Name: | C2: Dr. VANDANA kATE
A3: Subject Name : | C3: Machine Learning
A4: Subject Code :
A5: Start Date | C5: 46069
A6: End Date | AQ6: Annual Fest -26 | AY6: Training
J7: 3 | K7: 4 | L7: 5 | M7: 6 | N7: 7 | W7: 8 | X7: 9 | Y7: 10 | Z7: 11 | AB7: 12
D8: Total Class | E8: OverAll Att. % | F8: Att. 50% | G8: Att. 30% | H8: 46069 | I8: 46070 | J8: 46071 | K8: 46072 | L8: 46076 | M8: 46077 | N8: 46078 | O8: 46079 | P8: 46080 | Q8: 46081 | R8: FEB CLASS | S8: FEB% | T8: 46085 | U8: 46086 | V8: 46087 | W8: 46090 | X8: 46091 | Y8: 46092 | Z8: 46093 | AA8: 46094 | AB8: 46097 | AC8: 46098 | AD8: 46099 | AE8: 46100 | AF8: 46101 | AG8: 46104 | AH8: 46105 | AI8: 46106 | AJ8: 46107 | AK8: 46111 | AL8: MAR CLASS | AM8: MAR% | AN8: 46113 | AO8: 46114 | AP8: 46115 | AQ8: 46118 | AR8: 46119 | AS8: 46120 | AT8: 46121 | AU8: 46122 | AV8: 46125 | AW8: 46127 | AX8: 46128 | AY8: 46129 | AZ8: 46132 | BA8: 46133 | BB8: 46134 | BC8: 46135 | BD8: 46136 | BE8: 46139 | BF8: 46140 | BG8: 46141 | BH8: 46142 | BI8: APRIL CLASS | BJ8: APRIL % | BK8: 46143 | BL8: 46146 | BM8: 46146 | BN8: 46147 | BO8: 46148 | BP8: 46149 | BQ8: 46149 | BR8: 46150 | BS8: 46153 | BT8: 46154 | BU8: 46155 | BV8: 46156 | BW8: 46157 | BX8: 46160 | BY8: 46161 | BZ8: 46162 | CA8: 46163 | CB8: 46164 | CC8: 46167 | CD8: 46168 | CE8: 46169 | CF8: 46170 | CG8: 46171 | CH8: MAY CLASS | CI8: MAY % | CJ8: 46174 | CK8: 46175 | CL8: 46176 | CM8: 46177 | CN8: 46178 | CO8: 46181 | CP8: 46182 | CQ8: 46183 | CR8: 46184 | CS8: 46185 | CT8: 46186 | CU8: JUNE CLASS | CV8: JUNE% | CW8: SPECIAL LEAVE | CX8: OVER ALL % | CY8: TOTAL CLASS | CZ8: REMARK
A9: s.no. | B9: Enrollment NO. | C9: Student Name | D9: =SUM(R9+AL9+BI9+CH9+CU9) -> 33 | H9: =SUM(H10:H92) -> 0 | I9: =SUM(I10:I92) -> 0 | J9: =SUM(J10:J92) -> 6 | K9: =SUM(K10:K92) -> 5 | L9: =SUM(L10:L92) -> 30 | M9: =SUM(M10:M92) -> 18 | N9: =SUM(N10:N92) -> 23 | O9: =SUM(O10:O92) -> 0 | ... Q9: =SUM(Q10:Q92) -> 0 | R9: =COUNTIF(H9:Q9,">0") -> 5 | S9: =COUNTIF(H9:I9,">0") -> 0 | T9: =SUM(T10:T92) -> 0 | U9: =SUM(U10:U92) -> 0 | V9: =SUM(V10:V92) -> 0 | W9: =SUM(W10:W92) -> 35 | X9: =SUM(X10:X92) -> 29 | Y9: =SUM(Y10:Y92) -> 33 | Z9: =SUM(Z10:Z92) -> 41 | AA9: =SUM(AA10:AA92) -> 12 | ... AK9: =SUM(AK10:AK92) -> 0 | AL9: =COUNTIF(T9:AK9,">0") -> 10 | AM9: =SUM(R9+AL9) -> 15 | AN9: =SUM(AN10:AN91) -> 0 | AO9: =SUM(AO10:AO91) -> 0 | AP9: =SUM(AP10:AP91) -> 0 | AQ9: =SUM(AQ10:AQ91) -> 0 | AR9: =SUM(AR10:AR91) -> 0 | AS9: =SUM(AS10:AS91) -> 0 | AT9: =SUM(AT10:AT91) -> 0 | AU9: =SUM(AU10:AU91) -> 0 | ... BH9: =SUM(BH10:BH91) -> 32 | BI9: =COUNTIF(AN9:BH9,">0") -> 7 | BJ9: =SUM(AM9+BI9) -> 22 | BK9: =SUM(BK10:BK91) -> 8 | BL9: =SUM(BL10:BL91) -> 31 | BM9: =SUM(BM10:BM91) -> 23 | BN9: =SUM(BN10:BN91) -> 33 | BO9: =SUM(BO10:BO91) -> 40 | BP9: =SUM(BP10:BP91) -> 32 | BQ9: =SUM(BQ10:BQ91) -> 39 | BR9: =SUM(BR10:BR91) -> 0 | ... CG9: =SUM(CG10:CG91) -> 0 | CH9: =COUNTIF(BK9:CG9,">0") -> 11 | CI9: =SUM(BJ9+CH9) -> 33 | CJ9: =SUM(CJ10:CJ84) -> 0 | CK9: =SUM(CK10:CK84) -> 0 | CL9: =SUM(CL10:CL84) -> 0 | CM9: =SUM(CM10:CM69) -> 0 | CN9: =SUM(CN10:CN69) -> 0 | CO9: =SUM(CO10:CO69) -> 0 | CP9: =SUM(CP10:CP69) -> 0 | CQ9: =SUM(CQ10:CQ84) -> 0 | CR9: =SUM(CR10:CR69) -> 0 | CS9: =SUM(CS10:CS69) -> 0 | CT9: =SUM(CT10:CT69) -> 0 | CU9: =COUNTIF(CJ9:CT9,">0") -> 0 | CV9: =SUM(CI9+CU9) -> 33 | CX9: =SUM(R9+AL9+BI9+CH9+CU9+CW9) -> 33 | CY9: =SUM(R9+AL9+BI9+CH9+CU9+CW9) -> 33
A10: 1 | B10: 0827CI231001 | C10: AADARSH GARHEWAL | D10: =SUM(R10+AL10+BI10+CH10+CU10+CW10) -> 3 | E10: =(D10)/D$9*100 -> 9.0909091 | F10: =IF(E10<50,E10, " ") -> 9.0909091 | G10: =IF(E10<30,E10, " ") -> 9.0909091 | R10: =SUM(H10:Q10) -> 0 | S10: =R10/R$9*100 -> 0 | AG10: 1 | AL10: =SUM(T10:AK10) -> 1 | AM10: =AL10/AL$9*100 -> 10 | BI10: =SUM(AN10:BH10) -> 0 | BJ10: =BI10/BI$9*100 -> 0 | BL10: 1 | BT10: 1 | CH10: =SUM(BK10:CG10) -> 2 | CI10: =CH10/CH$9*100 -> 18.181818 | CU10: =SUM(CJ10:CT10) -> 0 | CV10: =CU10/CU$9*100 -> #DIV/0! | CX10: =(D10)/D$9*100 -> 9.0909091 | CY10: =SUM(R10+AL10+BI10+CH10+CU10+CW10) -> 3
A11: 2 | B11: 0827CI231002 | C11: AYUSH PATEL | D11: =SUM(R11+AL11+BI11+CH11+CU11+CW11) -> 27 | E11: =(D11)/D$9*100 -> 81.818182 | F11: =IF(E11<50,E11, " ") | G11: =IF(E11<30,E11, " ") | J11: 1 | L11: 1 | M11: 1 | R11: =SUM(H11:Q11) -> 3 | S11: =R11/R$9*100 -> 60 | W11: 1 | X11: 1 | Y11: 1 | Z11: 1 | AA11: 1 | AB11: 1 | AF11: 1 | AG11: 1 | AH11: 1 | AI11: 1 | AL11: =SUM(T11:AK11) -> 10 | AM11: =AL11/AL$9*100 -> 100 | AX11: 1 | BE11: 1 | BF11: 1 | BG11: 1 | BH11: 1 | BI11: =SUM(AN11:BH11) -> 5 | BJ11: =BI11/BI$9*100 -> 71.428571 | BL11: 1 | BM11: 1 | BN11: 1 | BO11: 1 | BQ11: 1 | BS11: 1 | BT11: 1 | BU11: 1 | BX11: 1 | CH11: =SUM(BK11:CG11) -> 9 | CI11: =CH11/CH$9*100 -> 81.818182 | CU11: =SUM(CJ11:CT11) -> 0 | CV11: =CU11/CU$9*100 -> #DIV/0! | CX11: =(D11)/D$9*100 -> 81.818182 | CY11: =SUM(R11+AL11+BI11+CH11+CU11+CW11) -> 27
A12: 3 | B12: 0827CI231003 | C12: ABHAY DUGAYA | D12: =SUM(R12+AL12+BI12+CH12+CU12+CW12) -> 3 | E12: =(D12)/D$9*100 -> 9.0909091 | F12: =IF(E12<50,E12, " ") -> 9.0909091 | G12: =IF(E12<30,E12, " ") -> 9.0909091 | R12: =SUM(H12:Q12) -> 0 | S12: =R12/R$9*100 -> 0 | AG12: 1 | AL12: =SUM(T12:AK12) -> 1 | AM12: =AL12/AL$9*100 -> 10 | BI12: =SUM(AN12:BH12) -> 0 | BJ12: =BI12/BI$9*100 -> 0 | BO12: 1 | BT12: 1 | CH12: =SUM(BK12:CG12) -> 2 | CI12: =CH12/CH$9*100 -> 18.181818 | CU12: =SUM(CJ12:CT12) -> 0 | CV12: =CU12/CU$9*100 -> #DIV/0! | CX12: =(D12)/D$9*100 -> 9.0909091 | CY12: =SUM(R12+AL12+BI12+CH12+CU12+CW12) -> 3
A13: 4 | B13: 0827CI231004 | C13: ABHISHEK JAISWAL | D13: =SUM(R13+AL13+BI13+CH13+CU13+CW13) -> 13 | E13: =(D13)/D$9*100 -> 39.393939 | F13: =IF(E13<50,E13, " ") -> 39.393939 | G13: =IF(E13<30,E13, " ") | R13: =SUM(H13:Q13) -> 0 | S13: =R13/R$9*100 -> 0 | AG13: 1 | AL13: =SUM(T13:AK13) -> 1 | AM13: =AL13/AL$9*100 -> 10 | AX13: 1 | BA13: 1 | BE13: 1 | BF13: 1 | BH13: 1 | BI13: =SUM(AN13:BH13) -> 5 | BJ13: =BI13/BI$9*100 -> 71.428571 | BL13: 1 | BM13: 1 | BN13: 1 | BP13: 1 | BQ13: 1 | BT13: 1 | BX13: 1 | CH13: =SUM(BK13:CG13) -> 7 | CI13: =CH13/CH$9*100 -> 63.636364 | CU13: =SUM(CJ13:CT13) -> 0 | CV13: =CU13/CU$9*100 -> #DIV/0! | CX13: =(D13)/D$9*100 -> 39.393939 | CY13: =SUM(R13+AL13+BI13+CH13+CU13+CW13) -> 13
A14: 5 | B14: 0827CI231005 | C14: ABHISHEK VERMA | D14: =SUM(R14+AL14+BI14+CH14+CU14+CW14) -> 21 | E14: =(D14)/D$9*100 -> 63.636364 | F14: =IF(E14<50,E14, " ") | G14: =IF(E14<30,E14, " ") | L14: 1 | M14: 1 | N14: 1 | R14: =SUM(H14:Q14) -> 3 | S14: =R14/R$9*100 -> 60 | W14: 1 | X14: 1 | AB14: 1 | AG14: 1 | AI14: 1 | AL14: =SUM(T14:AK14) -> 5 | AM14: =AL14/AL$9*100 -> 50 | AX14: 1 | BE14: 1 | BF14: 1 | BH14: 1 | BI14: =SUM(AN14:BH14) -> 4 | BJ14: =BI14/BI$9*100 -> 57.142857 | BK14: 1 | BL14: 1 | BN14: 1 | BO14: 1 | BP14: 1 | BQ14: 1 | BS14: 1 | BT14: 1 | BU14: 1 | CH14: =SUM(BK14:CG14) -> 9 | CI14: =CH14/CH$9*100 -> 81.818182 | CU14: =SUM(CJ14:CT14) -> 0 | CV14: =CU14/CU$9*100 -> #DIV/0! | CX14: =(D14)/D$9*100 -> 63.636364 | CY14: =SUM(R14+AL14+BI14+CH14+CU14+CW14) -> 21
A15: 6 | B15: 0827CI231006 | C15: ABINAV KOURAV | D15: =SUM(R15+AL15+BI15+CH15+CU15+CW15) -> 0 | E15: =(D15)/D$9*100 -> 0 | F15: =IF(E15<50,E15, " ") -> 0 | G15: =IF(E15<30,E15, " ") -> 0 | R15: =SUM(H15:Q15) -> 0 | S15: =R15/R$9*100 -> 0 | AL15: =SUM(T15:AK15) -> 0 | AM15: =AL15/AL$9*100 -> 0 | BI15: =SUM(AN15:BH15) -> 0 | BJ15: =BI15/BI$9*100 -> 0 | CH15: =SUM(BK15:CG15) -> 0 | CI15: =CH15/CH$9*100 -> 0 | CU15: =SUM(CJ15:CT15) -> 0 | CV15: =CU15/CU$9*100 -> #DIV/0! | CX15: =(D15)/D$9*100 -> 0 | CY15: =SUM(R15+AL15+BI15+CH15+CU15+CW15) -> 0
A16: 7 | B16: 0827CI231007 | C16: ADARSH PRATAP SINGH GURJAR | D16: =SUM(R16+AL16+BI16+CH16+CU16+CW16) -> 10 | E16: =(D16)/D$9*100 -> 30.30303 | F16: =IF(E16<50,E16, " ") -> 30.30303 | G16: =IF(E16<30,E16, " ") | R16: =SUM(H16:Q16) -> 0 | S16: =R16/R$9*100 -> 0 | AG16: 1 | AL16: =SUM(T16:AK16) -> 1 | AM16: =AL16/AL$9*100 -> 10 | BF16: 1 | BH16: 1 | BI16: =SUM(AN16:BH16) -> 2 | BJ16: =BI16/BI$9*100 -> 28.571429 | BN16: 1 | BO16: 1 | BP16: 1 | BQ16: 1 | BS16: 1 | BT16: 1 | BX16: 1 | CH16: =SUM(BK16:CG16) -> 7 | CI16: =CH16/CH$9*100 -> 63.636364 | CU16: =SUM(CJ16:CT16) -> 0 | CV16: =CU16/CU$9*100 -> #DIV/0! | CX16: =(D16)/D$9*100 -> 30.30303 | CY16: =SUM(R16+AL16+BI16+CH16+CU16+CW16) -> 10
A17: 8 | B17: 0827CI231008 | C17: ADITI VISHWAKARMA | D17: =SUM(R17+AL17+BI17+CH17+CU17+CW17) -> 18 | E17: =(D17)/D$9*100 -> 54.545455 | F17: =IF(E17<50,E17, " ") | G17: =IF(E17<30,E17, " ") | L17: 1 | M17: 1 | N17: 1 | R17: =SUM(H17:Q17) -> 3 | S17: =R17/R$9*100 -> 60 | W17: 1 | AB17: 1 | AG17: 1 | AI17: 1 | AL17: =SUM(T17:AK17) -> 4 | AM17: =AL17/AL$9*100 -> 40 | BE17: 1 | BF17: 1 | BI17: =SUM(AN17:BH17) -> 2 | BJ17: =BI17/BI$9*100 -> 28.571429 | BK17: 1 | BL17: 1 | BM17: 1 | BO17: 1 | BP17: 1 | BQ17: 1 | BS17: 1 | BT17: 1 | BU17: 1 | CH17: =SUM(BK17:CG17) -> 9 | CI17: =CH17/CH$9*100 -> 81.818182 | CU17: =SUM(CJ17:CT17) -> 0 | CV17: =CU17/CU$9*100 -> #DIV/0! | CX17: =(D17)/D$9*100 -> 54.545455 | CY17: =SUM(R17+AL17+BI17+CH17+CU17+CW17) -> 18
A18: 9 | B18: 0827CI231009 | C18: ADITYA TIWARI | D18: =SUM(R18+AL18+BI18+CH18+CU18+CW18) -> 14 | E18: =(D18)/D$9*100 -> 42.424242 | F18: =IF(E18<50,E18, " ") -> 42.424242 | G18: =IF(E18<30,E18, " ") | L18: 1 | R18: =SUM(H18:Q18) -> 1 | S18: =R18/R$9*100 -> 20 | AG18: 1 | AH18: 1 | AL18: =SUM(T18:AK18) -> 2 | AM18: =AL18/AL$9*100 -> 20 | AX18: 1 | BE18: 1 | BF18: 1 | BH18: 1 | BI18: =SUM(AN18:BH18) -> 4 | BJ18: =BI18/BI$9*100 -> 57.142857 | BN18: 1 | BO18: 1 | BP18: 1 | BQ18: 1 | BS18: 1 | BT18: 1 | BU18: 1 | CH18: =SUM(BK18:CG18) -> 7 | CI18: =CH18/CH$9*100 -> 63.636364 | CU18: =SUM(CJ18:CT18) -> 0 | CV18: =CU18/CU$9*100 -> #DIV/0! | CX18: =(D18)/D$9*100 -> 42.424242 | CY18: =SUM(R18+AL18+BI18+CH18+CU18+CW18) -> 14
A19: 10 | B19: 0827CI231010 | C19: AKASH BARASKAR | D19: =SUM(R19+AL19+BI19+CH19+CU19+CW19) -> 9 | E19: =(D19)/D$9*100 -> 27.272727 | F19: =IF(E19<50,E19, " ") -> 27.272727 | G19: =IF(E19<30,E19, " ") -> 27.272727 | R19: =SUM(H19:Q19) -> 0 | S19: =R19/R$9*100 -> 0 | AF19: 1 | AG19: 1 | AI19: 1 | AL19: =SUM(T19:AK19) -> 3 | AM19: =AL19/AL$9*100 -> 30 | BA19: 1 | BE19: 1 | BF19: 1 | BH19: 1 | BI19: =SUM(AN19:BH19) -> 4 | BJ19: =BI19/BI$9*100 -> 57.142857 | BU19: 1 | BX19: 1 | CH19: =SUM(BK19:CG19) -> 2 | CI19: =CH19/CH$9*100 -> 18.181818 | CU19: =SUM(CJ19:CT19) -> 0 | CV19: =CU19/CU$9*100 -> #DIV/0! | CX19: =(D19)/D$9*100 -> 27.272727 | CY19: =SUM(R19+AL19+BI19+CH19+CU19+CW19) -> 9
A20: 11 | B20: 0827CI231011 | C20: AKSHAT KARODE | D20: =SUM(R20+AL20+BI20+CH20+CU20+CW20) -> 9 | E20: =(D20)/D$9*100 -> 27.272727 | F20: =IF(E20<50,E20, " ") -> 27.272727 | G20: =IF(E20<30,E20, " ") -> 27.272727 | N20: 1 | R20: =SUM(H20:Q20) -> 1 | S20: =R20/R$9*100 -> 20 | AG20: 1 | AL20: =SUM(T20:AK20) -> 1 | AM20: =AL20/AL$9*100 -> 10 | BE20: 1 | BH20: 1 | BI20: =SUM(AN20:BH20) -> 2 | BJ20: =BI20/BI$9*100 -> 28.571429 | BN20: 1 | BO20: 1 | BP20: 1 | BQ20: 1 | BT20: 1 | CH20: =SUM(BK20:CG20) -> 5 | CI20: =CH20/CH$9*100 -> 45.454545 | CU20: =SUM(CJ20:CT20) -> 0 | CV20: =CU20/CU$9*100 -> #DIV/0! | CX20: =(D20)/D$9*100 -> 27.272727 | CY20: =SUM(R20+AL20+BI20+CH20+CU20+CW20) -> 9
A21: 12 | B21: 0827CI231012 | C21: AKSHAY KHANNA | D21: =SUM(R21+AL21+BI21+CH21+CU21+CW21) -> 14 | E21: =(D21)/D$9*100 -> 42.424242 | F21: =IF(E21<50,E21, " ") -> 42.424242 | G21: =IF(E21<30,E21, " ") | L21: 1 | N21: 1 | R21: =SUM(H21:Q21) -> 2 | S21: =R21/R$9*100 -> 40 | AB21: 1 | AL21: =SUM(T21:AK21) -> 1 | AM21: =AL21/AL$9*100 -> 10 | AX21: 1 | BE21: 1 | BF21: 1 | BH21: 1 | BI21: =SUM(AN21:BH21) -> 4 | BJ21: =BI21/BI$9*100 -> 57.142857 | BN21: 1 | BO21: 1 | BP21: 1 | BQ21: 1 | BS21: 1 | BT21: 1 | BU21: 1 | CH21: =SUM(BK21:CG21) -> 7 | CI21: =CH21/CH$9*100 -> 63.636364 | CU21: =SUM(CJ21:CT21) -> 0 | CV21: =CU21/CU$9*100 -> #DIV/0! | CX21: =(D21)/D$9*100 -> 42.424242 | CY21: =SUM(R21+AL21+BI21+CH21+CU21+CW21) -> 14
A22: 13 | B22: 0827CI231013 | C22: AMAY MISHRA | D22: =SUM(R22+AL22+BI22+CH22+CU22+CW22) -> 16 | E22: =(D22)/D$9*100 -> 48.484848 | F22: =IF(E22<50,E22, " ") -> 48.484848 | G22: =IF(E22<30,E22, " ") | L22: 1 | N22: 1 | R22: =SUM(H22:Q22) -> 2 | S22: =R22/R$9*100 -> 40 | Y22: 1 | Z22: 1 | AB22: 1 | AG22: 1 | AL22: =SUM(T22:AK22) -> 4 | AM22: =AL22/AL$9*100 -> 40 | BE22: 1 | BF22: 1 | BG22: 1 | BI22: =SUM(AN22:BH22) -> 3 | BJ22: =BI22/BI$9*100 -> 42.857143 | BL22: 1 | BM22: 1 | BO22: 1 | BP22: 1 | BQ22: 1 | BS22: 1 | BT22: 1 | CH22: =SUM(BK22:CG22) -> 7 | CI22: =CH22/CH$9*100 -> 63.636364 | CU22: =SUM(CJ22:CT22) -> 0 | CV22: =CU22/CU$9*100 -> #DIV/0! | CX22: =(D22)/D$9*100 -> 48.484848 | CY22: =SUM(R22+AL22+BI22+CH22+CU22+CW22) -> 16
