Workbook

Sheet 402
A1: CSITT-402
A2: Faculty Name: | C2: Dr. Asmita Rajawat
A3: Subject Name : | C3: Analog and Digital Communication
A4: Subject Code : | C4: CSIT-402
A5: Start Date | C5: 46104
A6: End Date
H7: 1 | I7: 2 | J7: 3 | K7: 4 | L7: 5 | O7: 1 | P7: 2 | Q7: 3 | R7: 4 | S7: 5 | T7: 6 | U7: 7 | V7: 8 | W7: 9 | X7: 10 | Y7: 11 | Z7: 12 | AA7: 13 | AB7: 14 | AC7: 15 | AD7: 16 | AE7: 17 | AF7: 18 | AG7: 19 | AH7: 20 | AI7: 21 | AL7: 1 | AM7: 2 | AN7: 3 | AO7: 4 | AP7: 5 | AQ7: 6 | AR7: 7 | AS7: 8 | AT7: 9 | AU7: 10 | AV7: 11 | AW7: 12 | AX7: 13 | AY7: 14 | AZ7: 15 | BA7: 16 | BB7: 17 | BC7: 18 | BD7: 19 | BE7: 20 | BF7: 21 | BI7: 1 | BJ7: 2 | BK7: 3 | BL7: 4 | BM7: 5 | BN7: 6 | BO7: 7 | BP7: 8 | BQ7: 9 | BR7: 10 | BS7: 11 | BT7: 12 | BU7: 13 | BV7: 14 | BW7: 15 | BX7: 16 | BY7: 17 | BZ7: 18 | CA7: 19 | CB7: 20 | CC7: 21 | CD7: 22 | CG7: 1 | CH7: 2 | CI7: 3 | CJ7: 4 | CK7: 5 | CL7: 6 | CM7: 7 | CN7: 8 | CO7: 9 | CP7: 10 | CQ7: 11 | CR7: 12 | CS7: 13 | CT7: 14 | CU7: 15 | CV7: 16 | CW7: 17 | CX7: 18 | CY7: 19
D8: Total Class | E8: OverAll Att. % | F8: Att. 50% | G8: Att. 30% | H8: 46104 | I8: 46105 | J8: 46106 | K8: 46107 | L8: 46111 | M8: MARCH CLASS | N8: MARCH% | O8: 46113 | P8: 46114 | Q8: 46115 | R8: 46118 | S8: 46119 | T8: 46120 | U8: 46121 | V8: 46122 | W8: 46125 | X8: 46127 | Y8: 46128 | Z8: 46129 | AA8: 46132 | AB8: 46133 | AC8: 46134 | AD8: 46135 | AE8: 46136 | AF8: 46139 | AG8: 46140 | AH8: 46141 | AI8: 46142 | AJ8: APRIL CLASS | AK8: APRIL% | AL8: 46143 | AM8: 46146 | AN8: 46147 | AO8: 46148 | AP8: 46149 | AQ8: 46150 | AR8: 46153 | AS8: 46154 | AT8: 46155 | AU8: 46156 | AV8: 46157 | AW8: 46160 | AX8: 46161 | AY8: 46162 | AZ8: 46163 | BA8: 46164 | BB8: 46167 | BC8: 46168 | BD8: 46169 | BE8: 46170 | BF8: 46171 | BG8: MAY CLASS | BH8: MAY % | BI8: 46174 | BJ8: 46175 | BK8: 46176 | BL8: 46177 | BM8: 46178 | BN8: 46181 | BO8: 46182 | BP8: 46183 | BQ8: 46184 | BR8: 46185 | BS8: 46188 | BT8: 46189 | BU8: 46190 | BV8: 46191 | BW8: 46192 | BX8: 46195 | BY8: 46196 | BZ8: 46197 | CA8: 46198 | CB8: 46199 | CC8: 46202 | CD8: 46203 | CE8: JUNE CLASS | CF8: JUNE% | CG8: 46204 | CH8: 46205 | CI8: 46205 | CJ8: 46206 | CK8: 46223 | CZ8: JULY CLASS | DA8: JULY% | DP8: JAN CLASS | DQ8: JAN %
A9: s.no. | B9: Enrollment NO. | C9: Student Name | D9: =SUM(M9+AJ9+BG9+CE9+CZ9) -> 36 | H9: =SUM(H10:H94) -> 0 | I9: =SUM(I10:I94) -> 0 | J9: =SUM(J10:J94) -> 0 | K9: =SUM(K10:K94) -> 0 | L9: =SUM(L10:L94) -> 0 | M9: =COUNTIF(H9:L9,">0") -> 0 | N9: =COUNTIF(H9:L9,">0") -> 0 | O9: =SUM(O10:O94) -> 0 | P9: =SUM(P10:P94) -> 0 | Q9: =SUM(Q10:Q94) -> 0 | R9: =SUM(R10:R94) -> 0 | S9: =SUM(S10:S94) -> 0 | T9: =SUM(T10:T94) -> 0 | U9: =SUM(U10:U94) -> 0 | V9: =SUM(V10:V94) -> 0 | ... AI9: =SUM(AI10:AI94) -> 36 | AJ9: =COUNTIF(O9:AI9,">0") -> 10 | AK9: =SUM(M9+AJ9) -> 10 | AL9: =SUM(AL10:AL94) -> 0 | AM9: =SUM(AM10:AM94) -> 36 | AN9: =SUM(AN10:AN94) -> 45 | AO9: =SUM(AO10:AO94) -> 42 | AP9: =SUM(AP10:AP94) -> 35 | AQ9: =SUM(AQ10:AQ94) -> 0 | AR9: =SUM(AR10:AR94) -> 25 | AS9: =SUM(AS10:AS94) -> 42 | ... BF9: =SUM(BF10:BF94) -> 0 | BG9: =COUNTIF(AL9:BF9,">0") -> 12 | BH9: =SUM(AK9+BG9) -> 22 | BI9: =SUM(BI10:BI94) -> 24 | BJ9: =SUM(BJ10:BJ94) -> 36 | BK9: =SUM(BK10:BK94) -> 0 | BL9: =SUM(BL10:BL94) -> 24 | BM9: =SUM(BM10:BM94) -> 0 | BN9: =SUM(BN10:BN94) -> 0 | BO9: =SUM(BO10:BO94) -> 40 | BP9: =SUM(BP10:BP94) -> 0 | ... CD9: =SUM(CD10:CD94) -> 33 | CE9: =COUNTIF(BI9:CD9,">0") -> 9 | CF9: =SUM(BH9+CE9) -> 31 | CG9: =SUM(CG10:CG94) -> 46 | CH9: =SUM(CH10:CH94) -> 15 | CI9: =SUM(CI10:CI94) -> 15 | CJ9: =SUM(CJ10:CJ94) -> 25 | CK9: =SUM(CK10:CK94) -> 10 | CL9: =SUM(CL10:CL94) -> 0 | CM9: =SUM(CM10:CM94) -> 0 | CN9: =SUM(CN10:CN94) -> 0 | ... CY9: =SUM(CY10:CY94) -> 0 | CZ9: =COUNTIF(CG9:CQ9,">0") -> 5 | DA9: =SUM(CF9+CZ9) -> 36 | DB9: =SUM(DB10:DB94) -> 0 | DC9: =SUM(DC10:DC94) -> 0 | DD9: =SUM(DD10:DD94) -> 0 | DE9: =SUM(DE10:DE94) -> 0 | DF9: =SUM(DF10:DF94) -> 0 | DG9: =SUM(DG10:DG94) -> 0 | DH9: =SUM(DH10:DH94) -> 0 | DI9: =SUM(DI10:DI94) -> 0 | ... DO9: =SUM(DO10:DO94) -> 0 | DP9: =COUNTIF(DB9:DO9,">0") -> 0 | DQ9: =SUM(CV9+DP9) -> 0
A10: 1 | B10: 0827CI241083 | C10: PARMEET KEVAT | D10: =SUM(M10+AJ10+BG10+CE10+CZ10) -> 23 | E10: =(D10)/D$9*100 -> 63.888889 | F10: =IF(E10<50,E10, " ") | G10: =IF(E10<30,E10, " ") | M10: =SUM(H10:L10) -> 0 | N10: =M10/M$9*100 -> #DIV/0! | W10: 1 | X10: 1 | Y10: 1 | AB10: 1 | AC10: 1 | AD10: 1 | AF10: 1 | AG10: 1 | AH10: 1 | AI10: 1 | AJ10: =SUM(O10:AI10) -> 10 | AK10: =AJ10/AJ$9*100 -> 100 | AM10: 1 | AN10: 1 | AO10: 1 | AP10: 1 | AR10: 1 | AY10: 1 | AZ10: 1 | BD10: 1 | BG10: =SUM(AL10:BF10) -> 8 | BH10: =BG10/BG$9*100 -> 66.666667 | BI10: 1 | BJ10: 1 | BL10: 1 | BO10: 1 | BS10: 1 | CE10: =SUM(BI10:CD10) -> 5 | CF10: =CE10/CE$9*100 -> 55.555556 | CZ10: =SUM(CG10:CQ10) -> 0 | DA10: =CZ10/CZ$9*100 -> 0 | DP10: =SUM(DB10:DO10) -> 0 | DQ10: =DP10/DP$9*100 -> #DIV/0!
A11: 2 | B11: 0827CI241084 | C11: PARTH SHARMA | D11: =SUM(M11+AJ11+BG11+CE11+CZ11) -> 21 | E11: =(D11)/D$9*100 -> 58.333333 | F11: =IF(E11<50,E11, " ") | G11: =IF(E11<30,E11, " ") | M11: =SUM(H11:L11) -> 0 | N11: =M11/M$9*100 -> #DIV/0! | X11: 1 | Y11: 1 | AB11: 1 | AC11: 1 | AD11: 1 | AF11: 1 | AG11: 1 | AI11: 1 | AJ11: =SUM(O11:AI11) -> 8 | AK11: =AJ11/AJ$9*100 -> 80 | AM11: 1 | AN11: 1 | AO11: 1 | AP11: 1 | AR11: 1 | AS11: 1 | AY11: 1 | AZ11: 1 | BD11: 1 | BG11: =SUM(AL11:BF11) -> 9 | BH11: =BG11/BG$9*100 -> 75 | BJ11: 1 | BO11: 1 | BT11: 1 | CE11: =SUM(BI11:CD11) -> 3 | CF11: =CE11/CE$9*100 -> 33.333333 | CG11: 1 | CZ11: =SUM(CG11:CQ11) -> 1 | DA11: =CZ11/CZ$9*100 -> 20 | DP11: =SUM(DB11:DO11) -> 0 | DQ11: =DP11/DP$9*100 -> #DIV/0!
A12: 3 | B12: 0827CI241085 | C12: PARTH SHARMA | D12: =SUM(M12+AJ12+BG12+CE12+CZ12) -> 0 | E12: =(D12)/D$9*100 -> 0 | F12: =IF(E12<50,E12, " ") -> 0 | G12: =IF(E12<30,E12, " ") -> 0 | M12: =SUM(H12:L12) -> 0 | N12: =M12/M$9*100 -> #DIV/0! | AJ12: =SUM(O12:AI12) -> 0 | AK12: =AJ12/AJ$9*100 -> 0 | BG12: =SUM(AL12:BF12) -> 0 | BH12: =BG12/BG$9*100 -> 0 | CE12: =SUM(BI12:CD12) -> 0 | CF12: =CE12/CE$9*100 -> 0 | CZ12: =SUM(CG12:CQ12) -> 0 | DA12: =CZ12/CZ$9*100 -> 0 | DP12: =SUM(DB12:DO12) -> 0 | DQ12: =DP12/DP$9*100 -> #DIV/0!
A13: 4 | B13: 0827CI241086 | C13: PARUL DEVKAR | D13: =SUM(M13+AJ13+BG13+CE13+CZ13) -> 0 | E13: =(D13)/D$9*100 -> 0 | F13: =IF(E13<50,E13, " ") -> 0 | G13: =IF(E13<30,E13, " ") -> 0 | M13: =SUM(H13:L13) -> 0 | N13: =M13/M$9*100 -> #DIV/0! | AJ13: =SUM(O13:AI13) -> 0 | AK13: =AJ13/AJ$9*100 -> 0 | BG13: =SUM(AL13:BF13) -> 0 | BH13: =BG13/BG$9*100 -> 0 | CE13: =SUM(BI13:CD13) -> 0 | CF13: =CE13/CE$9*100 -> 0 | CZ13: =SUM(CG13:CQ13) -> 0 | DA13: =CZ13/CZ$9*100 -> 0 | DP13: =SUM(DB13:DO13) -> 0 | DQ13: =DP13/DP$9*100 -> #DIV/0!
A14: 5 | B14: 0827CI241087 | C14: PAVNI SONER | D14: =SUM(M14+AJ14+BG14+CE14+CZ14) -> 16 | E14: =(D14)/D$9*100 -> 44.444444 | F14: =IF(E14<50,E14, " ") -> 44.444444 | G14: =IF(E14<30,E14, " ") | M14: =SUM(H14:L14) -> 0 | N14: =M14/M$9*100 -> #DIV/0! | X14: 1 | Y14: 1 | AB14: 1 | AG14: 1 | AH14: 1 | AJ14: =SUM(O14:AI14) -> 5 | AK14: =AJ14/AJ$9*100 -> 50 | AM14: 1 | AN14: 1 | AO14: 1 | AR14: 1 | AY14: 1 | AZ14: 1 | BG14: =SUM(AL14:BF14) -> 6 | BH14: =BG14/BG$9*100 -> 50 | BI14: 1 | CD14: 1 | CE14: =SUM(BI14:CD14) -> 2 | CF14: =CE14/CE$9*100 -> 22.222222 | CG14: 1 | CH14: 1 | CI14: 1 | CZ14: =SUM(CG14:CQ14) -> 3 | DA14: =CZ14/CZ$9*100 -> 60 | DP14: =SUM(DB14:DO14) -> 0 | DQ14: =DP14/DP$9*100 -> #DIV/0!
A15: 6 | B15: 0827CI241088 | C15: PIYUSH MANDLOI | D15: =SUM(M15+AJ15+BG15+CE15+CZ15) -> 18 | E15: =(D15)/D$9*100 -> 50 | F15: =IF(E15<50,E15, " ") | G15: =IF(E15<30,E15, " ") | M15: =SUM(H15:L15) -> 0 | N15: =M15/M$9*100 -> #DIV/0! | Y15: 1 | AD15: 1 | AG15: 1 | AH15: 1 | AI15: 1 | AJ15: =SUM(O15:AI15) -> 5 | AK15: =AJ15/AJ$9*100 -> 50 | AM15: 1 | AN15: 1 | AO15: 1 | AS15: 1 | AY15: 1 | AZ15: 1 | BG15: =SUM(AL15:BF15) -> 6 | BH15: =BG15/BG$9*100 -> 50 | BL15: 1 | BT15: 1 | CC15: 1 | CE15: =SUM(BI15:CD15) -> 3 | CF15: =CE15/CE$9*100 -> 33.333333 | CG15: 1 | CH15: 1 | CI15: 1 | CJ15: 1 | CZ15: =SUM(CG15:CQ15) -> 4 | DA15: =CZ15/CZ$9*100 -> 80 | DP15: =SUM(DB15:DO15) -> 0 | DQ15: =DP15/DP$9*100 -> #DIV/0!
A16: 7 | B16: 0827CI241089 | C16: PRAGATI VERMA | D16: =SUM(M16+AJ16+BG16+CE16+CZ16) -> 4 | E16: =(D16)/D$9*100 -> 11.111111 | F16: =IF(E16<50,E16, " ") -> 11.111111 | G16: =IF(E16<30,E16, " ") -> 11.111111 | M16: =SUM(H16:L16) -> 0 | N16: =M16/M$9*100 -> #DIV/0! | AC16: 1 | AD16: 1 | AH16: 1 | AJ16: =SUM(O16:AI16) -> 3 | AK16: =AJ16/AJ$9*100 -> 30 | BG16: =SUM(AL16:BF16) -> 0 | BH16: =BG16/BG$9*100 -> 0 | BO16: 1 | CE16: =SUM(BI16:CD16) -> 1 | CF16: =CE16/CE$9*100 -> 11.111111 | CZ16: =SUM(CG16:CQ16) -> 0 | DA16: =CZ16/CZ$9*100 -> 0 | DP16: =SUM(DB16:DO16) -> 0 | DQ16: =DP16/DP$9*100 -> #DIV/0!
A17: 8 | B17: 0827CI241090 | C17: PRANAL PATEL | D17: =SUM(M17+AJ17+BG17+CE17+CZ17) -> 6 | E17: =(D17)/D$9*100 -> 16.666667 | F17: =IF(E17<50,E17, " ") -> 16.666667 | G17: =IF(E17<30,E17, " ") -> 16.666667 | M17: =SUM(H17:L17) -> 0 | N17: =M17/M$9*100 -> #DIV/0! | AD17: 1 | AI17: 1 | AJ17: =SUM(O17:AI17) -> 2 | AK17: =AJ17/AJ$9*100 -> 20 | AP17: 1 | AY17: 1 | AZ17: 1 | BG17: =SUM(AL17:BF17) -> 3 | BH17: =BG17/BG$9*100 -> 25 | BL17: 1 | CE17: =SUM(BI17:CD17) -> 1 | CF17: =CE17/CE$9*100 -> 11.111111 | CZ17: =SUM(CG17:CQ17) -> 0 | DA17: =CZ17/CZ$9*100 -> 0 | DP17: =SUM(DB17:DO17) -> 0 | DQ17: =DP17/DP$9*100 -> #DIV/0!
A18: 9 | B18: 0827CI241091 | C18: PRANIT GURVE | D18: =SUM(M18+AJ18+BG18+CE18+CZ18) -> 21 | E18: =(D18)/D$9*100 -> 58.333333 | F18: =IF(E18<50,E18, " ") | G18: =IF(E18<30,E18, " ") | M18: =SUM(H18:L18) -> 0 | N18: =M18/M$9*100 -> #DIV/0! | W18: 1 | X18: 1 | Y18: 1 | AG18: 1 | AH18: 1 | AI18: 1 | AJ18: =SUM(O18:AI18) -> 6 | AK18: =AJ18/AJ$9*100 -> 60 | AN18: 1 | AO18: 1 | AP18: 1 | AS18: 1 | AY18: 1 | AZ18: 1 | BD18: 1 | BG18: =SUM(AL18:BF18) -> 7 | BH18: =BG18/BG$9*100 -> 58.333333 | BI18: 1 | BJ18: 1 | BT18: 1 | BX18: 1 | CD18: 1 | CE18: =SUM(BI18:CD18) -> 5 | CF18: =CE18/CE$9*100 -> 55.555556 | CG18: 1 | CH18: 1 | CJ18: 1 | CZ18: =SUM(CG18:CQ18) -> 3 | DA18: =CZ18/CZ$9*100 -> 60 | DP18: =SUM(DB18:DO18) -> 0 | DQ18: =DP18/DP$9*100 -> #DIV/0!
A19: 10 | B19: 0827CI241092 | C19: PRANSHU KUMAWAT | D19: =SUM(M19+AJ19+BG19+CE19+CZ19) -> 7 | E19: =(D19)/D$9*100 -> 19.444444 | F19: =IF(E19<50,E19, " ") -> 19.444444 | G19: =IF(E19<30,E19, " ") -> 19.444444 | M19: =SUM(H19:L19) -> 0 | N19: =M19/M$9*100 -> #DIV/0! | AF19: 1 | AG19: 1 | AH19: 1 | AI19: 1 | AJ19: =SUM(O19:AI19) -> 4 | AK19: =AJ19/AJ$9*100 -> 40 | AN19: 1 | AO19: 1 | AS19: 1 | BG19: =SUM(AL19:BF19) -> 3 | BH19: =BG19/BG$9*100 -> 25 | CE19: =SUM(BI19:CD19) -> 0 | CF19: =CE19/CE$9*100 -> 0 | CZ19: =SUM(CG19:CQ19) -> 0 | DA19: =CZ19/CZ$9*100 -> 0 | DP19: =SUM(DB19:DO19) -> 0 | DQ19: =DP19/DP$9*100 -> #DIV/0!
A20: 11 | B20: 0827CI241093 | C20: PRASHAM JAIN | D20: =SUM(M20+AJ20+BG20+CE20+CZ20) -> 26 | E20: =(D20)/D$9*100 -> 72.222222 | F20: =IF(E20<50,E20, " ") | G20: =IF(E20<30,E20, " ") | M20: =SUM(H20:L20) -> 0 | N20: =M20/M$9*100 -> #DIV/0! | W20: 1 | X20: 1 | Y20: 1 | AB20: 1 | AC20: 1 | AD20: 1 | AF20: 1 | AG20: 1 | AH20: 1 | AJ20: =SUM(O20:AI20) -> 9 | AK20: =AJ20/AJ$9*100 -> 90 | AM20: 1 | AN20: 1 | AO20: 1 | AP20: 1 | AS20: 1 | AY20: 1 | AZ20: 1 | BB20: 1 | BD20: 1 | BG20: =SUM(AL20:BF20) -> 9 | BH20: =BG20/BG$9*100 -> 75 | BI20: 1 | BJ20: 1 | BO20: 1 | BS20: 1 | BT20: 1 | BX20: 1 | CE20: =SUM(BI20:CD20) -> 6 | CF20: =CE20/CE$9*100 -> 66.666667 | CG20: 1 | CJ20: 1 | CZ20: =SUM(CG20:CQ20) -> 2 | DA20: =CZ20/CZ$9*100 -> 40 | DP20: =SUM(DB20:DO20) -> 0 | DQ20: =DP20/DP$9*100 -> #DIV/0!
A21: 12 | B21: 0827CI241094 | C21: PRATHAM BHAWSAR | D21: =SUM(M21+AJ21+BG21+CE21+CZ21) -> 26 | E21: =(D21)/D$9*100 -> 72.222222 | F21: =IF(E21<50,E21, " ") | G21: =IF(E21<30,E21, " ") | M21: =SUM(H21:L21) -> 0 | N21: =M21/M$9*100 -> #DIV/0! | W21: 1 | X21: 1 | Y21: 1 | AB21: 1 | AC21: 1 | AD21: 1 | AF21: 1 | AG21: 1 | AH21: 1 | AI21: 1 | AJ21: =SUM(O21:AI21) -> 10 | AK21: =AJ21/AJ$9*100 -> 100 | AN21: 1 | AO21: 1 | AP21: 1 | AS21: 1 | AU21: 1 | AY21: 1 | AZ21: 1 | BB21: 1 | BD21: 1 | BG21: =SUM(AL21:BF21) -> 9 | BH21: =BG21/BG$9*100 -> 75 | BJ21: 1 | BL21: 1 | BO21: 1 | BS21: 1 | BT21: 1 | CE21: =SUM(BI21:CD21) -> 5 | CF21: =CE21/CE$9*100 -> 55.555556 | CG21: 1 | CJ21: 1 | CZ21: =SUM(CG21:CQ21) -> 2 | DA21: =CZ21/CZ$9*100 -> 40 | DP21: =SUM(DB21:DO21) -> 0 | DQ21: =DP21/DP$9*100 -> #DIV/0!
A22: 13 | B22: 0827CI241095 | C22: PRATHAM BORDE | D22: =SUM(M22+AJ22+BG22+CE22+CZ22) -> 19 | E22: =(D22)/D$9*100 -> 52.777778 | F22: =IF(E22<50,E22, " ") | G22: =IF(E22<30,E22, " ") | M22: =SUM(H22:L22) -> 0 | N22: =M22/M$9*100 -> #DIV/0! | W22: 1 | X22: 1 | Y22: 1 | AD22: 1 | AF22: 1 | AG22: 1 | AH22: 1 | AJ22: =SUM(O22:AI22) -> 7 | AK22: =AJ22/AJ$9*100 -> 70 | AM22: 1 | AN22: 1 | AU22: 1 | AY22: 1 | AZ22: 1 | BE22: 1 | BG22: =SUM(AL22:BF22) -> 6 | BH22: =BG22/BG$9*100 -> 50 | BJ22: 1 | BL22: 1 | BO22: 1 | BS22: 1 | BT22: 1 | CD22: 1 | CE22: =SUM(BI22:CD22) -> 6 | CF22: =CE22/CE$9*100 -> 66.666667 | CZ22: =SUM(CG22:CQ22) -> 0 | DA22: =CZ22/CZ$9*100 -> 0 | DP22: =SUM(DB22:DO22) -> 0 | DQ22: =DP22/DP$9*100 -> #DIV/0!
A23: 14 | B23: 0827CI241096 | C23: PRATHAM KARANKAR | D23: =SUM(M23+AJ23+BG23+CE23+CZ23) -> 17 | E23: =(D23)/D$9*100 -> 47.222222 | F23: =IF(E23<50,E23, " ") -> 47.222222 | G23: =IF(E23<30,E23, " ") | M23: =SUM(H23:L23) -> 0 | N23: =M23/M$9*100 -> #DIV/0! | AB23: 1 | AC23: 1 | AG23: 1 | AH23: 1 | AI23: 1 | AJ23: =SUM(O23:AI23) -> 5 | AK23: =AJ23/AJ$9*100 -> 50 | AM23: 1 | AN23: 1 | AO23: 1 | AP23: 1 | AR23: 1 | AY23: 1 | AZ23: 1 | BD23: 1 | BG23: =SUM(AL23:BF23) -> 8 | BH23: =BG23/BG$9*100 -> 66.666667 | BO23: 1 | CE23: =SUM(BI23:CD23) -> 1 | CF23: =CE23/CE$9*100 -> 11.111111 | CG23: 1 | CH23: 1 | CI23: 1 | CZ23: =SUM(CG23:CQ23) -> 3 | DA23: =CZ23/CZ$9*100 -> 60 | DP23: =SUM(DB23:DO23) -> 0 | DQ23: =DP23/DP$9*100 -> #DIV/0!
A24: 15 | B24: 0827CI241097 | C24: PRATHMESH MANDLOI | D24: =SUM(M24+AJ24+BG24+CE24+CZ24) -> 20 | E24: =(D24)/D$9*100 -> 55.555556 | F24: =IF(E24<50,E24, " ") | G24: =IF(E24<30,E24, " ") | M24: =SUM(H24:L24) -> 0 | N24: =M24/M$9*100 -> #DIV/0! | W24: 1 | X24: 1 | Y24: 1 | AC24: 1 | AD24: 1 | AF24: 1 | AG24: 1 | AH24: 1 | AJ24: =SUM(O24:AI24) -> 8 | AK24: =AJ24/AJ$9*100 -> 80 | AM24: 1 | AO24: 1 | AP24: 1 | AR24: 1 | AY24: 1 | AZ24: 1 | BG24: =SUM(AL24:BF24) -> 6 | BH24: =BG24/BG$9*100 -> 50 | BJ24: 1 | BO24: 1 | BS24: 1 | BT24: 1 | CD24: 1 | CE24: =SUM(BI24:CD24) -> 5 | CF24: =CE24/CE$9*100 -> 55.555556 | CG24: 1 | CZ24: =SUM(CG24:CQ24) -> 1 | DA24: =CZ24/CZ$9*100 -> 20 | DP24: =SUM(DB24:DO24) -> 0 | DQ24: =DP24/DP$9*100 -> #DIV/0!
A25: 16 | B25: 0827CI241098 | C25: PRATIKSHA KUMAWAT | D25: =SUM(M25+AJ25+BG25+CE25+CZ25) -> 17 | E25: =(D25)/D$9*100 -> 47.222222 | F25: =IF(E25<50,E25, " ") -> 47.222222 | G25: =IF(E25<30,E25, " ") | M25: =SUM(H25:L25) -> 0 | N25: =M25/M$9*100 -> #DIV/0! | W25: 1 | Y25: 1 | AB25: 1 | AJ25: =SUM(O25:AI25) -> 3 | AK25: =AJ25/AJ$9*100 -> 30 | AM25: 1 | AN25: 1 | AO25: 1 | AR25: 1 | AU25: 1 | AY25: 1 | AZ25: 1 | BG25: =SUM(AL25:BF25) -> 7 | BH25: =BG25/BG$9*100 -> 58.333333 | BI25: 1 | BO25: 1 | BT25: 1 | CD25: 1 | CE25: =SUM(BI25:CD25) -> 4 | CF25: =CE25/CE$9*100 -> 44.444444 | CG25: 1 | CH25: 1 | CI25: 1 | CZ25: =SUM(CG25:CQ25) -> 3 | DA25: =CZ25/CZ$9*100 -> 60 | DP25: =SUM(DB25:DO25) -> 0 | DQ25: =DP25/DP$9*100 -> #DIV/0!
A26: 17 | B26: 0827CI241099 | C26: PRAYATI BABULGAONKAR | D26: =SUM(M26+AJ26+BG26+CE26+CZ26) -> 21 | E26: =(D26)/D$9*100 -> 58.333333 | F26: =IF(E26<50,E26, " ") | G26: =IF(E26<30,E26, " ") | M26: =SUM(H26:L26) -> 0 | N26: =M26/M$9*100 -> #DIV/0! | W26: 1 | X26: 1 | Y26: 1 | AB26: 1 | AC26: 1 | AF26: 1 | AG26: 1 | AI26: 1 | AJ26: =SUM(O26:AI26) -> 8 | AK26: =AJ26/AJ$9*100 -> 80 | AM26: 1 | AN26: 1 | AO26: 1 | AY26: 1 | AZ26: 1 | BB26: 1 | BG26: =SUM(AL26:BF26) -> 6 | BH26: =BG26/BG$9*100 -> 50 | BI26: 1 | BO26: 1 | BS26: 1 | BT26: 1 | BX26: 1 | CE26: =SUM(BI26:CD26) -> 5 | CF26: =CE26/CE$9*100 -> 55.555556 | CG26: 1 | CJ26: 1 | CZ26: =SUM(CG26:CQ26) -> 2 | DA26: =CZ26/CZ$9*100 -> 40 | DP26: =SUM(DB26:DO26) -> 0 | DQ26: =DP26/DP$9*100 -> #DIV/0!
A27: 18 | B27: 0827CI241100 | C27: PRIYANKA SAWARKAR | D27: =SUM(M27+AJ27+BG27+CE27+CZ27) -> 16 | E27: =(D27)/D$9*100 -> 44.444444 | F27: =IF(E27<50,E27, " ") -> 44.444444 | G27: =IF(E27<30,E27, " ") | M27: =SUM(H27:L27) -> 0 | N27: =M27/M$9*100 -> #DIV/0! | W27: 1 | X27: 1 | Y27: 1 | AC27: 1 | AF27: 1 | AG27: 1 | AI27: 1 | AJ27: =SUM(O27:AI27) -> 7 | AK27: =AJ27/AJ$9*100 -> 70 | AY27: 1 | AZ27: 1 | BB27: 1 | BG27: =SUM(AL27:BF27) -> 3 | BH27: =BG27/BG$9*100 -> 25 | BI27: 1 | BS27: 1 | BT27: 1 | BX27: 1 | CE27: =SUM(BI27:CD27) -> 4 | CF27: =CE27/CE$9*100 -> 44.444444 | CG27: 1 | CJ27: 1 | CZ27: =SUM(CG27:CQ27) -> 2 | DA27: =CZ27/CZ$9*100 -> 40 | DP27: =SUM(DB27:DO27) -> 0 | DQ27: =DP27/DP$9*100 -> #DIV/0!
A28: 19 | B28: 0827CI241101 | C28: RACHCHU JAISWAL | D28: =SUM(M28+AJ28+BG28+CE28+CZ28) -> 14 | E28: =(D28)/D$9*100 -> 38.888889 | F28: =IF(E28<50,E28, " ") -> 38.888889 | G28: =IF(E28<30,E28, " ") | M28: =SUM(H28:L28) -> 0 | N28: =M28/M$9*100 -> #DIV/0! | AB28: 1 | AF28: 1 | AG28: 1 | AI28: 1 | AJ28: =SUM(O28:AI28) -> 4 | AK28: =AJ28/AJ$9*100 -> 40 | AM28: 1 | AN28: 1 | AP28: 1 | AS28: 1 | BG28: =SUM(AL28:BF28) -> 4 | BH28: =BG28/BG$9*100 -> 33.333333 | BO28: 1 | BS28: 1 | BT28: 1 | BX28: 1 | CC28: 1 | CD28: 1 | CE28: =SUM(BI28:CD28) -> 6 | CF28: =CE28/CE$9*100 -> 66.666667 | CZ28: =SUM(CG28:CQ28) -> 0 | DA28: =CZ28/CZ$9*100 -> 0 | DP28: =SUM(DB28:DO28) -> 0 | DQ28: =DP28/DP$9*100 -> #DIV/0!
A29: 20 | B29: 0827CI241102 | C29: RAJ KUSHWAH | D29: =SUM(M29+AJ29+BG29+CE29+CZ29) -> 4 | E29: =(D29)/D$9*100 -> 11.111111 | F29: =IF(E29<50,E29, " ") -> 11.111111 | G29: =IF(E29<30,E29, " ") -> 11.111111 | M29: =SUM(H29:L29) -> 0 | N29: =M29/M$9*100 -> #DIV/0! | AD29: 1 | AJ29: =SUM(O29:AI29) -> 1 | AK29: =AJ29/AJ$9*100 -> 10 | AY29: 1 | AZ29: 1 | BG29: =SUM(AL29:BF29) -> 2 | BH29: =BG29/BG$9*100 -> 16.666667 | BL29: 1 | CE29: =SUM(BI29:CD29) -> 1 | CF29: =CE29/CE$9*100 -> 11.111111 | CZ29: =SUM(CG29:CQ29) -> 0 | DA29: =CZ29/CZ$9*100 -> 0 | DP29: =SUM(DB29:DO29) -> 0 | DQ29: =DP29/DP$9*100 -> #DIV/0!
A30: 21 | B30: 0827CI241103 | C30: RAJVEER MISTRI | D30: =SUM(M30+AJ30+BG30+CE30+CZ30) -> 20 | E30: =(D30)/D$9*100 -> 55.555556 | F30: =IF(E30<50,E30, " ") | G30: =IF(E30<30,E30, " ") | M30: =SUM(H30:L30) -> 0 | N30: =M30/M$9*100 -> #DIV/0! | Y30: 1 | AC30: 1 | AD30: 1 | AF30: 1 | AG30: 1 | AH30: 1 | AI30: 1 | AJ30: =SUM(O30:AI30) -> 7 | AK30: =AJ30/AJ$9*100 -> 70 | AM30: 1 | AN30: 1 | AO30: 1 | AP30: 1 | AR30: 1 | AS30: 1 | AY30: 1 | AZ30: 1 | BG30: =SUM(AL30:BF30) -> 8 | BH30: =BG30/BG$9*100 -> 66.666667 | BJ30: 1 | BL30: 1 | BO30: 1 | BT30: 1 | CE30: =SUM(BI30:CD30) -> 4 | CF30: =CE30/CE$9*100 -> 44.444444 | CG30: 1 | CZ30: =SUM(CG30:CQ30) -> 1 | DA30: =CZ30/CZ$9*100 -> 20 | DP30: =SUM(DB30:DO30) -> 0 | DQ30: =DP30/DP$9*100 -> #DIV/0!
A31: 22 | B31: 0827CI241104 | C31: REHAN SHAIKH | D31: =SUM(M31+AJ31+BG31+CE31+CZ31) -> 0 | E31: =(D31)/D$9*100 -> 0 | F31: =IF(E31<50,E31, " ") -> 0 | G31: =IF(E31<30,E31, " ") -> 0 | M31: =SUM(H31:L31) -> 0 | N31: =M31/M$9*100 -> #DIV/0! | AJ31: =SUM(O31:AI31) -> 0 | AK31: =AJ31/AJ$9*100 -> 0 | BG31: =SUM(AL31:BF31) -> 0 | BH31: =BG31/BG$9*100 -> 0 | CE31: =SUM(BI31:CD31) -> 0 | CF31: =CE31/CE$9*100 -> 0 | CZ31: =SUM(CG31:CQ31) -> 0 | DA31: =CZ31/CZ$9*100 -> 0 | DP31: =SUM(DB31:DO31) -> 0 | DQ31: =DP31/DP$9*100 -> #DIV/0!
A32: 23 | B32: 0827CI241105 | C32: RHYTHM MAHAJAN | D32: =SUM(M32+AJ32+BG32+CE32+CZ32) -> 22 | E32: =(D32)/D$9*100 -> 61.111111 | F32: =IF(E32<50,E32, " ") | G32: =IF(E32<30,E32, " ") | M32: =SUM(H32:L32) -> 0 | N32: =M32/M$9*100 -> #DIV/0! | W32: 1 | X32: 1 | Y32: 1 | AB32: 1 | AC32: 1 | AF32: 1 | AG32: 1 | AH32: 1 | AJ32: =SUM(O32:AI32) -> 8 | AK32: =AJ32/AJ$9*100 -> 80 | AM32: 1 | AN32: 1 | AO32: 1 | AR32: 1 | AS32: 1 | AY32: 1 | AZ32: 1 | BB32: 1 | BD32: 1 | BG32: =SUM(AL32:BF32) -> 9 | BH32: =BG32/BG$9*100 -> 75 | BO32: 1 | BS32: 1 | BT32: 1 | CE32: =SUM(BI32:CD32) -> 3 | CF32: =CE32/CE$9*100 -> 33.333333 | CG32: 1 | CJ32: 1 | CZ32: =SUM(CG32:CQ32) -> 2 | DA32: =CZ32/CZ$9*100 -> 40 | DP32: =SUM(DB32:DO32) -> 0 | DQ32: =DP32/DP$9*100 -> #DIV/0!
A33: 24 | B33: 0827CI241106 | C33: RIMJHIM RAWAL | D33: =SUM(M33+AJ33+BG33+CE33+CZ33) -> 19 | E33: =(D33)/D$9*100 -> 52.777778 | F33: =IF(E33<50,E33, " ") | G33: =IF(E33<30,E33, " ") | M33: =SUM(H33:L33) -> 0 | N33: =M33/M$9*100 -> #DIV/0! | X33: 1 | Y33: 1 | AC33: 1 | AF33: 1 | AG33: 1 | AH33: 1 | AJ33: =SUM(O33:AI33) -> 6 | AK33: =AJ33/AJ$9*100 -> 60 | AM33: 1 | AN33: 1 | AO33: 1 | AR33: 1 | AS33: 1 | AY33: 1 | AZ33: 1 | BD33: 1 | BG33: =SUM(AL33:BF33) -> 8 | BH33: =BG33/BG$9*100 -> 66.666667 | BI33: 1 | BS33: 1 | BT33: 1 | CE33: =SUM(BI33:CD33) -> 3 | CF33: =CE33/CE$9*100 -> 33.333333 | CG33: 1 | CJ33: 1 | CZ33: =SUM(CG33:CQ33) -> 2 | DA33: =CZ33/CZ$9*100 -> 40 | DP33: =SUM(DB33:DO33) -> 0 | DQ33: =DP33/DP$9*100 -> #DIV/0!
A34: 25 | B34: 0827CI241107 | C34: RISHABH PACHLASIYA | D34: =SUM(M34+AJ34+BG34+CE34+CZ34) -> 0 | E34: =(D34)/D$9*100 -> 0 | F34: =IF(E34<50,E34, " ") -> 0 | G34: =IF(E34<30,E34, " ") -> 0 | M34: =SUM(H34:L34) -> 0 | N34: =M34/M$9*100 -> #DIV/0! | AJ34: =SUM(O34:AI34) -> 0 | AK34: =AJ34/AJ$9*100 -> 0 | BG34: =SUM(AL34:BF34) -> 0 | BH34: =BG34/BG$9*100 -> 0 | CE34: =SUM(BI34:CD34) -> 0 | CF34: =CE34/CE$9*100 -> 0 | CZ34: =SUM(CG34:CQ34) -> 0 | DA34: =CZ34/CZ$9*100 -> 0 | DP34: =SUM(DB34:DO34) -> 0 | DQ34: =DP34/DP$9*100 -> #DIV/0!
A35: 26 | B35: 0827CI241108 | C35: RISHIKA CHOUHAN | D35: =SUM(M35+AJ35+BG35+CE35+CZ35) -> 12 | E35: =(D35)/D$9*100 -> 33.333333 | F35: =IF(E35<50,E35, " ") -> 33.333333 | G35: =IF(E35<30,E35, " ") | M35: =SUM(H35:L35) -> 0 | N35: =M35/M$9*100 -> #DIV/0! | AD35: 1 | AJ35: =SUM(O35:AI35) -> 1 | AK35: =AJ35/AJ$9*100 -> 10 | AP35: 1 | AS35: 1 | AU35: 1 | AY35: 1 | AZ35: 1 | BB35: 1 | BD35: 1 | BG35: =SUM(AL35:BF35) -> 7 | BH35: =BG35/BG$9*100 -> 58.333333 | BO35: 1 | BT35: 1 | BX35: 1 | CE35: =SUM(BI35:CD35) -> 3 | CF35: =CE35/CE$9*100 -> 33.333333 | CG35: 1 | CZ35: =SUM(CG35:CQ35) -> 1 | DA35: =CZ35/CZ$9*100 -> 20 | DP35: =SUM(DB35:DO35) -> 0 | DQ35: =DP35/DP$9*100 -> #DIV/0!
A36: 27 | B36: 0827CI241109 | C36: RISHIRAJ JHAWAR | D36: =SUM(M36+AJ36+BG36+CE36+CZ36) -> 19 | E36: =(D36)/D$9*100 -> 52.777778 | F36: =IF(E36<50,E36, " ") | G36: =IF(E36<30,E36, " ") | M36: =SUM(H36:L36) -> 0 | N36: =M36/M$9*100 -> #DIV/0! | W36: 1 | X36: 1 | Y36: 1 | AB36: 1 | AG36: 1 | AJ36: =SUM(O36:AI36) -> 5 | AK36: =AJ36/AJ$9*100 -> 50 | AM36: 1 | AN36: 1 | AO36: 1 | AP36: 1 | AZ36: 1 | BB36: 1 | BD36: 1 | BE36: 1 | BG36: =SUM(AL36:BF36) -> 8 | BH36: =BG36/BG$9*100 -> 66.666667 | BJ36: 1 | BO36: 1 | BT36: 1 | BX36: 1 | CD36: 1 | CE36: =SUM(BI36:CD36) -> 5 | CF36: =CE36/CE$9*100 -> 55.555556 | CJ36: 1 | CZ36: =SUM(CG36:CQ36) -> 1 | DA36: =CZ36/CZ$9*100 -> 20 | DP36: =SUM(DB36:DO36) -> 0 | DQ36: =DP36/DP$9*100 -> #DIV/0!
A37: 28 | B37: 0827CI241110 | C37: ROHIT PARIHAR | D37: =SUM(M37+AJ37+BG37+CE37+CZ37) -> 18 | E37: =(D37)/D$9*100 -> 50 | F37: =IF(E37<50,E37, " ") | G37: =IF(E37<30,E37, " ") | M37: =SUM(H37:L37) -> 0 | N37: =M37/M$9*100 -> #DIV/0! | W37: 1 | X37: 1 | Y37: 1 | AB37: 1 | AC37: 1 | AD37: 1 | AI37: 1 | AJ37: =SUM(O37:AI37) -> 7 | AK37: =AJ37/AJ$9*100 -> 70 | AP37: 1 | AS37: 1 | AU37: 1 | AY37: 1 | AZ37: 1 | BD37: 1 | BE37: 1 | BG37: =SUM(AL37:BF37) -> 7 | BH37: =BG37/BG$9*100 -> 58.333333 | BJ37: 1 | BL37: 1 | BS37: 1 | BT37: 1 | CE37: =SUM(BI37:CD37) -> 4 | CF37: =CE37/CE$9*100 -> 44.444444 | CZ37: =SUM(CG37:CQ37) -> 0 | DA37: =CZ37/CZ$9*100 -> 0 | DP37: =SUM(DB37:DO37) -> 0 | DQ37: =DP37/DP$9*100 -> #DIV/0!
A38: 29 | B38: 0827CI241111 | C38: SAHIL PAHUJA | D38: =SUM(M38+AJ38+BG38+CE38+CZ38) -> 19 | E38: =(D38)/D$9*100 -> 52.777778 | F38: =IF(E38<50,E38, " ") | G38: =IF(E38<30,E38, " ") | M38: =SUM(H38:L38) -> 0 | N38: =M38/M$9*100 -> #DIV/0! | W38: 1 | X38: 1 | Y38: 1 | AD38: 1 | AG38: 1 | AH38: 1 | AJ38: =SUM(O38:AI38) -> 6 | AK38: =AJ38/AJ$9*100 -> 60 | AM38: 1 | AN38: 1 | AO38: 1 | AP38: 1 | AS38: 1 | AY38: 1 | AZ38: 1 | BD38: 1 | BG38: =SUM(AL38:BF38) -> 8 | BH38: =BG38/BG$9*100 -> 66.666667 | BI38: 1 | BJ38: 1 | BO38: 1 | BS38: 1 | CE38: =SUM(BI38:CD38) -> 4 | CF38: =CE38/CE$9*100 -> 44.444444 | CG38: 1 | CZ38: =SUM(CG38:CQ38) -> 1 | DA38: =CZ38/CZ$9*100 -> 20 | DP38: =SUM(DB38:DO38) -> 0 | DQ38: =DP38/DP$9*100 -> #DIV/0!
A39: 30 | B39: 0827CI241112 | C39: SAMARTH MAHESHWARI | D39: =SUM(M39+AJ39+BG39+CE39+CZ39) -> 22 | E39: =(D39)/D$9*100 -> 61.111111 | F39: =IF(E39<50,E39, " ") | G39: =IF(E39<30,E39, " ") | M39: =SUM(H39:L39) -> 0 | N39: =M39/M$9*100 -> #DIV/0! | X39: 1 | Y39: 1 | AB39: 1 | AC39: 1 | AH39: 1 | AI39: 1 | AJ39: =SUM(O39:AI39) -> 6 | AK39: =AJ39/AJ$9*100 -> 60 | AM39: 1 | AN39: 1 | AO39: 1 | AP39: 1 | AR39: 1 | AS39: 1 | AY39: 1 | AZ39: 1 | BD39: 1 | BG39: =SUM(AL39:BF39) -> 9 | BH39: =BG39/BG$9*100 -> 75 | BI39: 1 | BJ39: 1 | BO39: 1 | BT39: 1 | CE39: =SUM(BI39:CD39) -> 4 | CF39: =CE39/CE$9*100 -> 44.444444 | CG39: 1 | CH39: 1 | CI39: 1 | CZ39: =SUM(CG39:CQ39) -> 3 | DA39: =CZ39/CZ$9*100 -> 60 | DP39: =SUM(DB39:DO39) -> 0 | DQ39: =DP39/DP$9*100 -> #DIV/0!
A40: 31 | B40: 0827CI241113 | C40: SAMRUDDHI SONGIRKAR | D40: =SUM(M40+AJ40+BG40+CE40+CZ40) -> 8 | E40: =(D40)/D$9*100 -> 22.222222 | F40: =IF(E40<50,E40, " ") -> 22.222222 | G40: =IF(E40<30,E40, " ") -> 22.222222 | M40: =SUM(H40:L40) -> 0 | N40: =M40/M$9*100 -> #DIV/0! | AB40: 1 | AD40: 1 | AJ40: =SUM(O40:AI40) -> 2 | AK40: =AJ40/AJ$9*100 -> 20 | AO40: 1 | AU40: 1 | BG40: =SUM(AL40:BF40) -> 2 | BH40: =BG40/BG$9*100 -> 16.666667 | CE40: =SUM(BI40:CD40) -> 0 | CF40: =CE40/CE$9*100 -> 0 | CG40: 1 | CH40: 1 | CI40: 1 | CK40: 1 | CZ40: =SUM(CG40:CQ40) -> 4 | DA40: =CZ40/CZ$9*100 -> 80 | DP40: =SUM(DB40:DO40) -> 0 | DQ40: =DP40/DP$9*100 -> #DIV/0!
...

Sheet 401
A1: BT-401
A2: Faculty Name: | C2: Prof. Neetu Verma
A3: Subject Name : | C3: M-III
A4: Subject Code : | C4: BT401
A5: Start Date | C5: 46104
A6: End Date
H7: 1 | I7: 2 | J7: 3 | K7: 4 | L7: 5 | O7: 1 | P7: 2 | Q7: 3 | R7: 4 | S7: 5 | T7: 6 | U7: 7 | V7: 8 | W7: 9 | X7: 10 | Y7: 11 | Z7: 12 | AA7: 13 | AB7: 14 | AC7: 15 | AD7: 16 | AE7: 17 | AF7: 18 | AG7: 19 | AH7: 20 | AI7: 21 | AL7: 1 | AM7: 2 | AN7: 3 | AO7: 4 | AP7: 5 | AQ7: 6 | AR7: 7 | AS7: 8 | AT7: 9 | AU7: 10 | AV7: 11 | AW7: 12 | AX7: 13 | AY7: 14 | AZ7: 15 | BA7: 16 | BB7: 17 | BC7: 18 | BD7: 19 | BE7: 20 | BF7: 21 | BI7: 1 | BJ7: 2 | BK7: 3 | BL7: 4 | BM7: 5 | BN7: 6 | BO7: 7 | BP7: 8 | BQ7: 9 | BR7: 10 | BS7: 11 | BT7: 12 | BU7: 13 | BV7: 14 | BW7: 15 | BX7: 16 | BY7: 17 | BZ7: 18 | CA7: 19 | CB7: 20 | CC7: 21 | CD7: 22 | CG7: 1 | CH7: 2 | CI7: 3 | CJ7: 4 | CK7: 5 | CL7: 6 | CM7: 7 | CN7: 8 | CO7: 9 | CP7: 10 | CQ7: 11 | CR7: 12 | CS7: 13 | CT7: 14 | CU7: 15 | CV7: 16 | CW7: 17 | CX7: 18 | CY7: 19
D8: Total Class | E8: OverAll Att. % | F8: 1 | G8: Att. 30% | H8: 46104 | I8: 46105 | J8: 46106 | K8: 46107 | L8: 46111 | M8: MARCH CLASS | N8: MARCH% | O8: 46113 | P8: 46114 | Q8: 46115 | R8: 46118 | S8: 46119 | T8: 46120 | U8: 46121 | V8: 46122 | W8: 46125 | X8: 46127 | Y8: 46128 | Z8: 46129 | AA8: 46132 | AB8: 46133 | AC8: 46134 | AD8: 46135 | AE8: 46136 | AF8: 46139 | AG8: 46140 | AH8: 46141 | AI8: 46142 | AJ8: APRIL CLASS | AK8: APRIL% | AL8: 46143 | AM8: 46146 | AN8: 46147 | AO8: 46148 | AP8: 46149 | AQ8: 46150 | AR8: 46153 | AS8: 46154 | AT8: 46155 | AU8: 46156 | AV8: 46157 | AW8: 46160 | AX8: 46161 | AY8: 46162 | AZ8: 46163 | BA8: 46164 | BB8: 46167 | BC8: 46168 | BD8: 46169 | BE8: 46170 | BF8: 46171 | BG8: MAY CLASS | BH8: MAY % | BI8: 46174 | BJ8: 46175 | BK8: 46176 | BL8: 46177 | BM8: 46178 | BN8: 46181 | BO8: 46182 | BP8: 46183 | BQ8: 46184 | BR8: 46185 | BS8: 46188 | BT8: 46189 | BU8: 46190 | BV8: 46191 | BW8: 46192 | BX8: 46195 | BY8: 46196 | BZ8: 46197 | CA8: 46198 | CB8: 46199 | CC8: 46202 | CD8: 46203 | CE8: JUNE CLASS | CF8: JUNE% | CG8: 46205 | CH8: 46209 | CI8: 46210 | CZ8: JULY CLASS | DA8: JULY% | DP8: JAN CLASS | DQ8: JAN %
A9: s.no. | B9: Enrollment NO. | C9: Student Name | D9: =SUM(M9+AJ9+BG9+CE9+CZ9) -> 39 | H9: =SUM(H10:H94) -> 0 | I9: =SUM(I10:I94) -> 0 | J9: =SUM(J10:J94) -> 0 | K9: =SUM(K10:K94) -> 0 | L9: =SUM(L10:L94) -> 0 | M9: =COUNTIF(H9:L9,">0") -> 0 | N9: =COUNTIF(H9:L9,">0") -> 0 | O9: =SUM(O10:O94) -> 0 | P9: =SUM(P10:P94) -> 0 | Q9: =SUM(Q10:Q94) -> 0 | R9: =SUM(R10:R94) -> 0 | S9: =SUM(S10:S94) -> 0 | T9: =SUM(T10:T94) -> 0 | U9: =SUM(U10:U94) -> 0 | V9: =SUM(V10:V94) -> 0 | ... AI9: =SUM(AI10:AI94) -> 0 | AJ9: =COUNTIF(O9:AI9,">0") -> 9 | AK9: =SUM(M9+AJ9) -> 9 | AL9: =SUM(AL10:AL94) -> 22 | AM9: =SUM(AM10:AM94) -> 0 | AN9: =SUM(AN10:AN94) -> 32 | AO9: =SUM(AO10:AO94) -> 33 | AP9: =SUM(AP10:AP94) -> 21 | AQ9: =SUM(AQ10:AQ94) -> 34 | AR9: =SUM(AR10:AR94) -> 0 | AS9: =SUM(AS10:AS94) -> 34 | ... BF9: =SUM(BF10:BF94) -> 30 | BG9: =COUNTIF(AL9:BF9,">0") -> 16 | BH9: =SUM(AK9+BG9) -> 25 | BI9: =SUM(BI10:BI94) -> 0 | BJ9: =SUM(BJ10:BJ94) -> 32 | BK9: =SUM(BK10:BK94) -> 0 | BL9: =SUM(BL10:BL94) -> 17 | BM9: =SUM(BM10:BM94) -> 0 | BN9: =SUM(BN10:BN94) -> 0 | BO9: =SUM(BO10:BO94) -> 42 | BP9: =SUM(BP10:BP94) -> 41 | ... CD9: =SUM(CD10:CD94) -> 31 | CE9: =COUNTIF(BI9:CD9,">0") -> 11 | CF9: =SUM(BH9+CE9) -> 36 | CG9: =SUM(CG10:CG94) -> 102 | CH9: =SUM(CH10:CH94) -> 14 | CI9: =SUM(CI10:CI94) -> 62 | CJ9: =SUM(CJ10:CJ94) -> 0 | CK9: =SUM(CK10:CK94) -> 0 | CL9: =SUM(CL10:CL94) -> 0 | CM9: =SUM(CM10:CM94) -> 0 | CN9: =SUM(CN10:CN94) -> 0 | ... CY9: =SUM(CY10:CY94) -> 0 | CZ9: =COUNTIF(CG9:CQ9,">0") -> 3 | DA9: =SUM(CF9+CZ9) -> 39 | DB9: =SUM(DB10:DB94) -> 0 | DC9: =SUM(DC10:DC94) -> 0 | DD9: =SUM(DD10:DD94) -> 0 | DE9: =SUM(DE10:DE94) -> 0 | DF9: =SUM(DF10:DF94) -> 0 | DG9: =SUM(DG10:DG94) -> 0 | DH9: =SUM(DH10:DH94) -> 0 | DI9: =SUM(DI10:DI94) -> 0 | ... DO9: =SUM(DO10:DO94) -> 0 | DP9: =COUNTIF(DB9:DO9,">0") -> 0 | DQ9: =SUM(CV9+DP9) -> 0
A10: 1 | B10: 0827CI241083 | C10: PARMEET KEVAT | D10: =SUM(M10+AJ10+BG10+CE10+CZ10) -> 23 | E10: =(D10)/D$9*100 -> 58.974359 | F10: =IF(E10<50,E10, " ") | G10: =IF(E10<30,E10, " ") | M10: =SUM(H10:L10) -> 0 | N10: =M10/M$9*100 -> #DIV/0! | X10: 1 | Y10: 1 | Z10: 1 | AB10: 1 | AC10: 1 | AD10: 1 | AG10: 1 | AH10: 1 | AJ10: =SUM(O10:AI10) -> 8 | AK10: =AJ10/AJ$9*100 -> 88.888889 | AN10: 1 | AO10: 1 | AP10: 1 | AQ10: 1 | AT10: 1 | AX10: 1 | AY10: 1 | AZ10: 1 | BD10: 1 | BF10: 1 | BG10: =SUM(AL10:BF10) -> 10 | BH10: =BG10/BG$9*100 -> 62.5 | BO10: 1 | BR10: 1 | BZ10: 1 | CB10: 2 | CE10: =SUM(BI10:CD10) -> 5 | CF10: =CE10/CE$9*100 -> 45.454545 | CZ10: =SUM(CG10:CQ10) -> 0 | DA10: =CZ10/CZ$9*100 -> 0 | DP10: =SUM(DB10:DO10) -> 0 | DQ10: =DP10/DP$9*100 -> #DIV/0!
A11: 2 | B11: 0827CI241084 | C11: PARTH SHARMA | D11: =SUM(M11+AJ11+BG11+CE11+CZ11) -> 28 | E11: =(D11)/D$9*100 -> 71.794872 | F11: =IF(E11<50,E11, " ") | G11: =IF(E11<30,E11, " ") | M11: =SUM(H11:L11) -> 0 | N11: =M11/M$9*100 -> #DIV/0! | X11: 1 | Y11: 1 | Z11: 1 | AB11: 1 | AC11: 1 | AD11: 1 | AE11: 2 | AG11: 1 | AH11: 1 | AJ11: =SUM(O11:AI11) -> 10 | AK11: =AJ11/AJ$9*100 -> 111.11111 | AN11: 1 | AO11: 1 | AP11: 1 | AQ11: 1 | AS11: 1 | AT11: 1 | AX11: 1 | AY11: 1 | AZ11: 1 | BD11: 1 | BG11: =SUM(AL11:BF11) -> 10 | BH11: =BG11/BG$9*100 -> 62.5 | BO11: 1 | BP11: 1 | BT11: 1 | BZ11: 1 | CB11: 2 | CE11: =SUM(BI11:CD11) -> 6 | CF11: =CE11/CE$9*100 -> 54.545455 | CG11: 2 | CZ11: =SUM(CG11:CQ11) -> 2 | DA11: =CZ11/CZ$9*100 -> 66.666667 | DP11: =SUM(DB11:DO11) -> 0 | DQ11: =DP11/DP$9*100 -> #DIV/0!
A12: 3 | B12: 0827CI241085 | C12: PARTH SHARMA | D12: =SUM(M12+AJ12+BG12+CE12+CZ12) -> 2 | E12: =(D12)/D$9*100 -> 5.1282051 | F12: =IF(E12<50,E12, " ") -> 5.1282051 | G12: =IF(E12<30,E12, " ") -> 5.1282051 | M12: =SUM(H12:L12) -> 0 | N12: =M12/M$9*100 -> #DIV/0! | AJ12: =SUM(O12:AI12) -> 0 | AK12: =AJ12/AJ$9*100 -> 0 | BG12: =SUM(AL12:BF12) -> 0 | BH12: =BG12/BG$9*100 -> 0 | CE12: =SUM(BI12:CD12) -> 0 | CF12: =CE12/CE$9*100 -> 0 | CI12: 2 | CZ12: =SUM(CG12:CQ12) -> 2 | DA12: =CZ12/CZ$9*100 -> 66.666667 | DP12: =SUM(DB12:DO12) -> 0 | DQ12: =DP12/DP$9*100 -> #DIV/0!
A13: 4 | B13: 0827CI241086 | C13: PARUL DEVKAR | D13: =SUM(M13+AJ13+BG13+CE13+CZ13) -> 0 | E13: =(D13)/D$9*100 -> 0 | F13: =IF(E13<50,E13, " ") -> 0 | G13: =IF(E13<30,E13, " ") -> 0 | M13: =SUM(H13:L13) -> 0 | N13: =M13/M$9*100 -> #DIV/0! | AJ13: =SUM(O13:AI13) -> 0 | AK13: =AJ13/AJ$9*100 -> 0 | BG13: =SUM(AL13:BF13) -> 0 | BH13: =BG13/BG$9*100 -> 0 | CE13: =SUM(BI13:CD13) -> 0 | CF13: =CE13/CE$9*100 -> 0 | CZ13: =SUM(CG13:CQ13) -> 0 | DA13: =CZ13/CZ$9*100 -> 0 | DP13: =SUM(DB13:DO13) -> 0 | DQ13: =DP13/DP$9*100 -> #DIV/0!
A14: 5 | B14: 0827CI241087 | C14: PAVNI SONER | D14: =SUM(M14+AJ14+BG14+CE14+CZ14) -> 21 | E14: =(D14)/D$9*100 -> 53.846154 | F14: =IF(E14<50,E14, " ") | G14: =IF(E14<30,E14, " ") | M14: =SUM(H14:L14) -> 0 | N14: =M14/M$9*100 -> #DIV/0! | X14: 1 | Y14: 1 | Z14: 1 | AB14: 1 | AG14: 1 | AH14: 1 | AJ14: =SUM(O14:AI14) -> 6 | AK14: =AJ14/AJ$9*100 -> 66.666667 | AN14: 1 | AO14: 1 | AQ14: 1 | AX14: 1 | AY14: 1 | AZ14: 1 | BC14: 1 | BF14: 1 | BG14: =SUM(AL14:BF14) -> 8 | BH14: =BG14/BG$9*100 -> 50 | BZ14: 1 | CB14: 2 | CD14: 1 | CE14: =SUM(BI14:CD14) -> 4 | CF14: =CE14/CE$9*100 -> 36.363636 | CG14: 2 | CH14: 1 | CZ14: =SUM(CG14:CQ14) -> 3 | DA14: =CZ14/CZ$9*100 -> 100 | DP14: =SUM(DB14:DO14) -> 0 | DQ14: =DP14/DP$9*100 -> #DIV/0!
A15: 6 | B15: 0827CI241088 | C15: PIYUSH MANDLOI | D15: =SUM(M15+AJ15+BG15+CE15+CZ15) -> 22 | E15: =(D15)/D$9*100 -> 56.410256 | F15: =IF(E15<50,E15, " ") | G15: =IF(E15<30,E15, " ") | M15: =SUM(H15:L15) -> 0 | N15: =M15/M$9*100 -> #DIV/0! | Z15: 1 | AE15: 2 | AG15: 1 | AH15: 1 | AJ15: =SUM(O15:AI15) -> 5 | AK15: =AJ15/AJ$9*100 -> 55.555556 | AL15: 1 | AN15: 1 | AQ15: 1 | AY15: 1 | AZ15: 1 | BC15: 1 | BG15: =SUM(AL15:BF15) -> 6 | BH15: =BG15/BG$9*100 -> 37.5 | BP15: 1 | BR15: 1 | BT15: 1 | CB15: 2 | CD15: 1 | CE15: =SUM(BI15:CD15) -> 6 | CF15: =CE15/CE$9*100 -> 54.545455 | CG15: 2 | CH15: 1 | CI15: 2 | CZ15: =SUM(CG15:CQ15) -> 5 | DA15: =CZ15/CZ$9*100 -> 166.66667 | DP15: =SUM(DB15:DO15) -> 0 | DQ15: =DP15/DP$9*100 -> #DIV/0!
A16: 7 | B16: 0827CI241089 | C16: PRAGATI VERMA | D16: =SUM(M16+AJ16+BG16+CE16+CZ16) -> 13 | E16: =(D16)/D$9*100 -> 33.333333 | F16: =IF(E16<50,E16, " ") -> 33.333333 | G16: =IF(E16<30,E16, " ") | M16: =SUM(H16:L16) -> 0 | N16: =M16/M$9*100 -> #DIV/0! | AB16: 1 | AC16: 1 | AD16: 1 | AH16: 1 | AJ16: =SUM(O16:AI16) -> 4 | AK16: =AJ16/AJ$9*100 -> 44.444444 | AL16: 1 | AT16: 1 | AV16: 1 | BG16: =SUM(AL16:BF16) -> 3 | BH16: =BG16/BG$9*100 -> 18.75 | BJ16: 1 | BO16: 1 | BP16: 1 | BZ16: 1 | CE16: =SUM(BI16:CD16) -> 4 | CF16: =CE16/CE$9*100 -> 36.363636 | CI16: 2 | CZ16: =SUM(CG16:CQ16) -> 2 | DA16: =CZ16/CZ$9*100 -> 66.666667 | DP16: =SUM(DB16:DO16) -> 0 | DQ16: =DP16/DP$9*100 -> #DIV/0!
A17: 8 | B17: 0827CI241090 | C17: PRANAL PATEL | D17: =SUM(M17+AJ17+BG17+CE17+CZ17) -> 7 | E17: =(D17)/D$9*100 -> 17.948718 | F17: =IF(E17<50,E17, " ") -> 17.948718 | G17: =IF(E17<30,E17, " ") -> 17.948718 | M17: =SUM(H17:L17) -> 0 | N17: =M17/M$9*100 -> #DIV/0! | X17: 1 | Y17: 1 | AB17: 1 | AJ17: =SUM(O17:AI17) -> 3 | AK17: =AJ17/AJ$9*100 -> 33.333333 | AY17: 1 | BG17: =SUM(AL17:BF17) -> 1 | BH17: =BG17/BG$9*100 -> 6.25 | BL17: 1 | CE17: =SUM(BI17:CD17) -> 1 | CF17: =CE17/CE$9*100 -> 9.0909091 | CG17: 2 | CZ17: =SUM(CG17:CQ17) -> 2 | DA17: =CZ17/CZ$9*100 -> 66.666667 | DP17: =SUM(DB17:DO17) -> 0 | DQ17: =DP17/DP$9*100 -> #DIV/0!
A18: 9 | B18: 0827CI241091 | C18: PRANIT GURVE | D18: =SUM(M18+AJ18+BG18+CE18+CZ18) -> 17 | E18: =(D18)/D$9*100 -> 43.589744 | F18: =IF(E18<50,E18, " ") -> 43.589744 | G18: =IF(E18<30,E18, " ") | M18: =SUM(H18:L18) -> 0 | N18: =M18/M$9*100 -> #DIV/0! | AE18: 2 | AJ18: =SUM(O18:AI18) -> 2 | AK18: =AJ18/AJ$9*100 -> 22.222222 | AN18: 1 | AO18: 1 | AP18: 1 | AZ18: 1 | BC18: 1 | BD18: 1 | BG18: =SUM(AL18:BF18) -> 6 | BH18: =BG18/BG$9*100 -> 37.5 | BJ18: 1 | BP18: 1 | BR18: 1 | BT18: 1 | BY18: 1 | BZ18: 1 | CD18: 1 | CE18: =SUM(BI18:CD18) -> 7 | CF18: =CE18/CE$9*100 -> 63.636364 | CI18: 2 | CZ18: =SUM(CG18:CQ18) -> 2 | DA18: =CZ18/CZ$9*100 -> 66.666667 | DP18: =SUM(DB18:DO18) -> 0 | DQ18: =DP18/DP$9*100 -> #DIV/0!
A19: 10 | B19: 0827CI241092 | C19: PRANSHU KUMAWAT | D19: =SUM(M19+AJ19+BG19+CE19+CZ19) -> 6 | E19: =(D19)/D$9*100 -> 15.384615 | F19: =IF(E19<50,E19, " ") -> 15.384615 | G19: =IF(E19<30,E19, " ") -> 15.384615 | M19: =SUM(H19:L19) -> 0 | N19: =M19/M$9*100 -> #DIV/0! | AG19: 1 | AJ19: =SUM(O19:AI19) -> 1 | AK19: =AJ19/AJ$9*100 -> 11.111111 | AL19: 1 | AS19: 1 | AT19: 1 | BG19: =SUM(AL19:BF19) -> 3 | BH19: =BG19/BG$9*100 -> 18.75 | CE19: =SUM(BI19:CD19) -> 0 | CF19: =CE19/CE$9*100 -> 0 | CG19: 2 | CZ19: =SUM(CG19:CQ19) -> 2 | DA19: =CZ19/CZ$9*100 -> 66.666667 | DP19: =SUM(DB19:DO19) -> 0 | DQ19: =DP19/DP$9*100 -> #DIV/0!
A20: 11 | B20: 0827CI241093 | C20: PRASHAM JAIN | D20: =SUM(M20+AJ20+BG20+CE20+CZ20) -> 26 | E20: =(D20)/D$9*100 -> 66.666667 | F20: =IF(E20<50,E20, " ") | G20: =IF(E20<30,E20, " ") | M20: =SUM(H20:L20) -> 0 | N20: =M20/M$9*100 -> #DIV/0! | X20: 1 | Y20: 1 | Z20: 1 | AB20: 1 | AC20: 1 | AD20: 1 | AG20: 1 | AJ20: =SUM(O20:AI20) -> 7 | AK20: =AJ20/AJ$9*100 -> 77.777778 | AN20: 1 | AO20: 1 | AP20: 1 | AQ20: 1 | AS20: 1 | AX20: 1 | AZ20: 1 | BD20: 1 | BF20: 1 | BG20: =SUM(AL20:BF20) -> 9 | BH20: =BG20/BG$9*100 -> 56.25 | BJ20: 1 | BO20: 1 | BP20: 1 | BT20: 1 | CB20: 2 | CE20: =SUM(BI20:CD20) -> 6 | CF20: =CE20/CE$9*100 -> 54.545455 | CG20: 2 | CI20: 2 | CZ20: =SUM(CG20:CQ20) -> 4 | DA20: =CZ20/CZ$9*100 -> 133.33333 | DP20: =SUM(DB20:DO20) -> 0 | DQ20: =DP20/DP$9*100 -> #DIV/0!
A21: 12 | B21: 0827CI241094 | C21: PRATHAM BHAWSAR | D21: =SUM(M21+AJ21+BG21+CE21+CZ21) -> 32 | E21: =(D21)/D$9*100 -> 82.051282 | F21: =IF(E21<50,E21, " ") | G21: =IF(E21<30,E21, " ") | M21: =SUM(H21:L21) -> 0 | N21: =M21/M$9*100 -> #DIV/0! | X21: 1 | Y21: 1 | Z21: 1 | AB21: 1 | AC21: 1 | AD21: 1 | AE21: 2 | AG21: 1 | AH21: 1 | AJ21: =SUM(O21:AI21) -> 10 | AK21: =AJ21/AJ$9*100 -> 111.11111 | AL21: 1 | AN21: 1 | AO21: 1 | AQ21: 1 | AS21: 1 | AX21: 1 | AY21: 1 | AZ21: 1 | BC21: 1 | BD21: 1 | BF21: 1 | BG21: =SUM(AL21:BF21) -> 11 | BH21: =BG21/BG$9*100 -> 68.75 | BL21: 1 | BO21: 1 | BP21: 1 | BT21: 1 | BY21: 1 | CA21: 2 | CB21: 2 | CE21: =SUM(BI21:CD21) -> 9 | CF21: =CE21/CE$9*100 -> 81.818182 | CI21: 2 | CZ21: =SUM(CG21:CQ21) -> 2 | DA21: =CZ21/CZ$9*100 -> 66.666667 | DP21: =SUM(DB21:DO21) -> 0 | DQ21: =DP21/DP$9*100 -> #DIV/0!
A22: 13 | B22: 0827CI241095 | C22: PRATHAM BORDE | D22: =SUM(M22+AJ22+BG22+CE22+CZ22) -> 25 | E22: =(D22)/D$9*100 -> 64.102564 | F22: =IF(E22<50,E22, " ") | G22: =IF(E22<30,E22, " ") | M22: =SUM(H22:L22) -> 0 | N22: =M22/M$9*100 -> #DIV/0! | X22: 1 | Y22: 1 | Z22: 1 | AB22: 1 | AE22: 2 | AH22: 1 | AJ22: =SUM(O22:AI22) -> 7 | AK22: =AJ22/AJ$9*100 -> 77.777778 | AS22: 1 | AT22: 1 | AU22: 1 | AV22: 1 | AX22: 1 | AY22: 1 | BC22: 1 | BE22: 1 | BF22: 1 | BG22: =SUM(AL22:BF22) -> 9 | BH22: =BG22/BG$9*100 -> 56.25 | BL22: 1 | BO22: 1 | BT22: 1 | BY22: 1 | BZ22: 1 | CE22: =SUM(BI22:CD22) -> 5 | CF22: =CE22/CE$9*100 -> 45.454545 | CG22: 2 | CI22: 2 | CZ22: =SUM(CG22:CQ22) -> 4 | DA22: =CZ22/CZ$9*100 -> 133.33333 | DP22: =SUM(DB22:DO22) -> 0 | DQ22: =DP22/DP$9*100 -> #DIV/0!
A23: 14 | B23: 0827CI241096 | C23: PRATHAM KARANKAR | D23: =SUM(M23+AJ23+BG23+CE23+CZ23) -> 21 | E23: =(D23)/D$9*100 -> 53.846154 | F23: =IF(E23<50,E23, " ") | G23: =IF(E23<30,E23, " ") | M23: =SUM(H23:L23) -> 0 | N23: =M23/M$9*100 -> #DIV/0! | AB23: 1 | AC23: 1 | AE23: 2 | AG23: 1 | AH23: 1 | AJ23: =SUM(O23:AI23) -> 6 | AK23: =AJ23/AJ$9*100 -> 66.666667 | AN23: 1 | AO23: 1 | AP23: 1 | AT23: 1 | AX23: 1 | AY23: 1 | AZ23: 1 | BG23: =SUM(AL23:BF23) -> 7 | BH23: =BG23/BG$9*100 -> 43.75 | BO23: 1 | BR23: 1 | BZ23: 1 | CB23: 2 | CE23: =SUM(BI23:CD23) -> 5 | CF23: =CE23/CE$9*100 -> 45.454545 | CG23: 2 | CH23: 1 | CZ23: =SUM(CG23:CQ23) -> 3 | DA23: =CZ23/CZ$9*100 -> 100 | DP23: =SUM(DB23:DO23) -> 0 | DQ23: =DP23/DP$9*100 -> #DIV/0!
A24: 15 | B24: 0827CI241097 | C24: PRATHMESH MANDLOI | D24: =SUM(M24+AJ24+BG24+CE24+CZ24) -> 15 | E24: =(D24)/D$9*100 -> 38.461538 | F24: =IF(E24<50,E24, " ") -> 38.461538 | G24: =IF(E24<30,E24, " ") | M24: =SUM(H24:L24) -> 0 | N24: =M24/M$9*100 -> #DIV/0! | X24: 1 | Y24: 1 | Z24: 1 | AB24: 1 | AC24: 1 | AG24: 1 | AH24: 1 | AJ24: =SUM(O24:AI24) -> 7 | AK24: =AJ24/AJ$9*100 -> 77.777778 | AO24: 1 | AX24: 1 | AY24: 1 | BG24: =SUM(AL24:BF24) -> 3 | BH24: =BG24/BG$9*100 -> 18.75 | BO24: 1 | BT24: 1 | BY24: 1 | CE24: =SUM(BI24:CD24) -> 3 | CF24: =CE24/CE$9*100 -> 27.272727 | CG24: 2 | CZ24: =SUM(CG24:CQ24) -> 2 | DA24: =CZ24/CZ$9*100 -> 66.666667 | DP24: =SUM(DB24:DO24) -> 0 | DQ24: =DP24/DP$9*100 -> #DIV/0!
A25: 16 | B25: 0827CI241098 | C25: PRATIKSHA KUMAWAT | D25: =SUM(M25+AJ25+BG25+CE25+CZ25) -> 19 | E25: =(D25)/D$9*100 -> 48.717949 | F25: =IF(E25<50,E25, " ") -> 48.717949 | G25: =IF(E25<30,E25, " ") | M25: =SUM(H25:L25) -> 0 | N25: =M25/M$9*100 -> #DIV/0! | Z25: 1 | AB25: 1 | AH25: 1 | AJ25: =SUM(O25:AI25) -> 3 | AK25: =AJ25/AJ$9*100 -> 33.333333 | AL25: 1 | AN25: 1 | AQ25: 1 | AX25: 1 | AY25: 1 | AZ25: 1 | BC25: 1 | BF25: 1 | BG25: =SUM(AL25:BF25) -> 8 | BH25: =BG25/BG$9*100 -> 50 | BO25: 1 | BZ25: 1 | CB25: 2 | CD25: 1 | CE25: =SUM(BI25:CD25) -> 5 | CF25: =CE25/CE$9*100 -> 45.454545 | CG25: 2 | CH25: 1 | CZ25: =SUM(CG25:CQ25) -> 3 | DA25: =CZ25/CZ$9*100 -> 100 | DP25: =SUM(DB25:DO25) -> 0 | DQ25: =DP25/DP$9*100 -> #DIV/0!
A26: 17 | B26: 0827CI241099 | C26: PRAYATI BABULGAONKAR | D26: =SUM(M26+AJ26+BG26+CE26+CZ26) -> 19 | E26: =(D26)/D$9*100 -> 48.717949 | F26: =IF(E26<50,E26, " ") -> 48.717949 | G26: =IF(E26<30,E26, " ") | M26: =SUM(H26:L26) -> 0 | N26: =M26/M$9*100 -> #DIV/0! | X26: 1 | Y26: 1 | AC26: 1 | AG26: 1 | AJ26: =SUM(O26:AI26) -> 4 | AK26: =AJ26/AJ$9*100 -> 44.444444 | AN26: 1 | AO26: 1 | AQ26: 1 | AX26: 1 | AZ26: 1 | BF26: 1 | BG26: =SUM(AL26:BF26) -> 6 | BH26: =BG26/BG$9*100 -> 37.5 | BO26: 1 | BP26: 1 | BT26: 1 | CB26: 2 | CE26: =SUM(BI26:CD26) -> 5 | CF26: =CE26/CE$9*100 -> 45.454545 | CG26: 2 | CI26: 2 | CZ26: =SUM(CG26:CQ26) -> 4 | DA26: =CZ26/CZ$9*100 -> 133.33333 | DP26: =SUM(DB26:DO26) -> 0 | DQ26: =DP26/DP$9*100 -> #DIV/0!
A27: 18 | B27: 0827CI241100 | C27: PRIYANKA SAWARKAR | D27: =SUM(M27+AJ27+BG27+CE27+CZ27) -> 16 | E27: =(D27)/D$9*100 -> 41.025641 | F27: =IF(E27<50,E27, " ") -> 41.025641 | G27: =IF(E27<30,E27, " ") | M27: =SUM(H27:L27) -> 0 | N27: =M27/M$9*100 -> #DIV/0! | X27: 1 | Y27: 1 | AC27: 1 | AG27: 1 | AJ27: =SUM(O27:AI27) -> 4 | AK27: =AJ27/AJ$9*100 -> 44.444444 | AP27: 1 | AX27: 1 | BC27: 1 | BF27: 1 | BG27: =SUM(AL27:BF27) -> 4 | BH27: =BG27/BG$9*100 -> 25 | BT27: 1 | BZ27: 1 | CB27: 2 | CE27: =SUM(BI27:CD27) -> 4 | CF27: =CE27/CE$9*100 -> 36.363636 | CG27: 2 | CI27: 2 | CZ27: =SUM(CG27:CQ27) -> 4 | DA27: =CZ27/CZ$9*100 -> 133.33333 | DP27: =SUM(DB27:DO27) -> 0 | DQ27: =DP27/DP$9*100 -> #DIV/0!
A28: 19 | B28: 0827CI241101 | C28: RACHCHU JAISWAL | D28: =SUM(M28+AJ28+BG28+CE28+CZ28) -> 11 | E28: =(D28)/D$9*100 -> 28.205128 | F28: =IF(E28<50,E28, " ") -> 28.205128 | G28: =IF(E28<30,E28, " ") -> 28.205128 | M28: =SUM(H28:L28) -> 0 | N28: =M28/M$9*100 -> #DIV/0! | AB28: 1 | AG28: 1 | AJ28: =SUM(O28:AI28) -> 2 | AK28: =AJ28/AJ$9*100 -> 22.222222 | AL28: 1 | AN28: 1 | AQ28: 1 | BG28: =SUM(AL28:BF28) -> 3 | BH28: =BG28/BG$9*100 -> 18.75 | BO28: 1 | BP28: 1 | BR28: 1 | BT28: 1 | BY28: 1 | CD28: 1 | CE28: =SUM(BI28:CD28) -> 6 | CF28: =CE28/CE$9*100 -> 54.545455 | CZ28: =SUM(CG28:CQ28) -> 0 | DA28: =CZ28/CZ$9*100 -> 0 | DP28: =SUM(DB28:DO28) -> 0 | DQ28: =DP28/DP$9*100 -> #DIV/0!
A29: 20 | B29: 0827CI241102 | C29: RAJ KUSHWAH | D29: =SUM(M29+AJ29+BG29+CE29+CZ29) -> 6 | E29: =(D29)/D$9*100 -> 15.384615 | F29: =IF(E29<50,E29, " ") -> 15.384615 | G29: =IF(E29<30,E29, " ") -> 15.384615 | M29: =SUM(H29:L29) -> 0 | N29: =M29/M$9*100 -> #DIV/0! | X29: 1 | AJ29: =SUM(O29:AI29) -> 1 | AK29: =AJ29/AJ$9*100 -> 11.111111 | AP29: 1 | AS29: 1 | AY29: 1 | AZ29: 1 | BG29: =SUM(AL29:BF29) -> 4 | BH29: =BG29/BG$9*100 -> 25 | BL29: 1 | CE29: =SUM(BI29:CD29) -> 1 | CF29: =CE29/CE$9*100 -> 9.0909091 | CZ29: =SUM(CG29:CQ29) -> 0 | DA29: =CZ29/CZ$9*100 -> 0 | DP29: =SUM(DB29:DO29) -> 0 | DQ29: =DP29/DP$9*100 -> #DIV/0!
A30: 21 | B30: 0827CI241103 | C30: RAJVEER MISTRI | D30: =SUM(M30+AJ30+BG30+CE30+CZ30) -> 21 | E30: =(D30)/D$9*100 -> 53.846154 | F30: =IF(E30<50,E30, " ") | G30: =IF(E30<30,E30, " ") | M30: =SUM(H30:L30) -> 0 | N30: =M30/M$9*100 -> #DIV/0! | AB30: 1 | AC30: 1 | AD30: 1 | AH30: 1 | AJ30: =SUM(O30:AI30) -> 4 | AK30: =AJ30/AJ$9*100 -> 44.444444 | AN30: 1 | AO30: 1 | AQ30: 1 | AX30: 1 | AY30: 1 | AZ30: 1 | BG30: =SUM(AL30:BF30) -> 6 | BH30: =BG30/BG$9*100 -> 37.5 | BL30: 1 | BO30: 1 | BP30: 1 | BR30: 1 | BT30: 1 | BY30: 1 | BZ30: 1 | CB30: 2 | CE30: =SUM(BI30:CD30) -> 9 | CF30: =CE30/CE$9*100 -> 81.818182 | CG30: 2 | CZ30: =SUM(CG30:CQ30) -> 2 | DA30: =CZ30/CZ$9*100 -> 66.666667 | DP30: =SUM(DB30:DO30) -> 0 | DQ30: =DP30/DP$9*100 -> #DIV/0!
A31: 22 | B31: 0827CI241104 | C31: REHAN SHAIKH | D31: =SUM(M31+AJ31+BG31+CE31+CZ31) -> 5 | E31: =(D31)/D$9*100 -> 12.820513 | F31: =IF(E31<50,E31, " ") -> 12.820513 | G31: =IF(E31<30,E31, " ") -> 12.820513 | M31: =SUM(H31:L31) -> 0 | N31: =M31/M$9*100 -> #DIV/0! | AJ31: =SUM(O31:AI31) -> 0 | AK31: =AJ31/AJ$9*100 -> 0 | AS31: 1 | AT31: 1 | BG31: =SUM(AL31:BF31) -> 2 | BH31: =BG31/BG$9*100 -> 12.5 | BY31: 1 | CE31: =SUM(BI31:CD31) -> 1 | CF31: =CE31/CE$9*100 -> 9.0909091 | CI31: 2 | CZ31: =SUM(CG31:CQ31) -> 2 | DA31: =CZ31/CZ$9*100 -> 66.666667 | DP31: =SUM(DB31:DO31) -> 0 | DQ31: =DP31/DP$9*100 -> #DIV/0!
A32: 23 | B32: 0827CI241105 | C32: RHYTHM MAHAJAN | D32: =SUM(M32+AJ32+BG32+CE32+CZ32) -> 25 | E32: =(D32)/D$9*100 -> 64.102564 | F32: =IF(E32<50,E32, " ") | G32: =IF(E32<30,E32, " ") | M32: =SUM(H32:L32) -> 0 | N32: =M32/M$9*100 -> #DIV/0! | X32: 1 | Y32: 1 | Z32: 1 | AB32: 1 | AC32: 1 | AG32: 1 | AH32: 1 | AJ32: =SUM(O32:AI32) -> 7 | AK32: =AJ32/AJ$9*100 -> 77.777778 | AN32: 1 | AO32: 1 | AX32: 1 | AZ32: 1 | BC32: 1 | BF32: 1 | BG32: =SUM(AL32:BF32) -> 6 | BH32: =BG32/BG$9*100 -> 37.5 | BO32: 1 | BP32: 1 | BR32: 1 | BT32: 1 | BY32: 1 | BZ32: 1 | CB32: 2 | CE32: =SUM(BI32:CD32) -> 8 | CF32: =CE32/CE$9*100 -> 72.727273 | CG32: 2 | CI32: 2 | CZ32: =SUM(CG32:CQ32) -> 4 | DA32: =CZ32/CZ$9*100 -> 133.33333 | DP32: =SUM(DB32:DO32) -> 0 | DQ32: =DP32/DP$9*100 -> #DIV/0!
A33: 24 | B33: 0827CI241106 | C33: RIMJHIM RAWAL | D33: =SUM(M33+AJ33+BG33+CE33+CZ33) -> 22 | E33: =(D33)/D$9*100 -> 56.410256 | F33: =IF(E33<50,E33, " ") | G33: =IF(E33<30,E33, " ") | M33: =SUM(H33:L33) -> 0 | N33: =M33/M$9*100 -> #DIV/0! | X33: 1 | Y33: 1 | AC33: 1 | AG33: 1 | AH33: 1 | AJ33: =SUM(O33:AI33) -> 5 | AK33: =AJ33/AJ$9*100 -> 55.555556 | AN33: 1 | AO33: 1 | AS33: 1 | AX33: 1 | AZ33: 1 | BC33: 1 | BF33: 1 | BG33: =SUM(AL33:BF33) -> 7 | BH33: =BG33/BG$9*100 -> 43.75 | BP33: 1 | BR33: 1 | BT33: 1 | BZ33: 1 | CB33: 2 | CE33: =SUM(BI33:CD33) -> 6 | CF33: =CE33/CE$9*100 -> 54.545455 | CG33: 2 | CI33: 2 | CZ33: =SUM(CG33:CQ33) -> 4 | DA33: =CZ33/CZ$9*100 -> 133.33333 | DP33: =SUM(DB33:DO33) -> 0 | DQ33: =DP33/DP$9*100 -> #DIV/0!
A34: 25 | B34: 0827CI241107 | C34: RISHABH PACHLASIYA | D34: =SUM(M34+AJ34+BG34+CE34+CZ34) -> 3 | E34: =(D34)/D$9*100 -> 7.6923077 | F34: =IF(E34<50,E34, " ") -> 7.6923077 | G34: =IF(E34<30,E34, " ") -> 7.6923077 | M34: =SUM(H34:L34) -> 0 | N34: =M34/M$9*100 -> #DIV/0! | Z34: 1 | AJ34: =SUM(O34:AI34) -> 1 | AK34: =AJ34/AJ$9*100 -> 11.111111 | AS34: 1 | BG34: =SUM(AL34:BF34) -> 1 | BH34: =BG34/BG$9*100 -> 6.25 | BY34: 1 | CE34: =SUM(BI34:CD34) -> 1 | CF34: =CE34/CE$9*100 -> 9.0909091 | CZ34: =SUM(CG34:CQ34) -> 0 | DA34: =CZ34/CZ$9*100 -> 0 | DP34: =SUM(DB34:DO34) -> 0 | DQ34: =DP34/DP$9*100 -> #DIV/0!
A35: 26 | B35: 0827CI241108 | C35: RISHIKA CHOUHAN | D35: =SUM(M35+AJ35+BG35+CE35+CZ35) -> 12 | E35: =(D35)/D$9*100 -> 30.769231 | F35: =IF(E35<50,E35, " ") -> 30.769231 | G35: =IF(E35<30,E35, " ") | M35: =SUM(H35:L35) -> 0 | N35: =M35/M$9*100 -> #DIV/0! | Y35: 1 | AJ35: =SUM(O35:AI35) -> 1 | AK35: =AJ35/AJ$9*100 -> 11.111111 | AQ35: 1 | AZ35: 1 | BC35: 1 | BD35: 1 | BF35: 1 | BG35: =SUM(AL35:BF35) -> 5 | BH35: =BG35/BG$9*100 -> 31.25 | BO35: 1 | BP35: 1 | BR35: 1 | BT35: 1 | CE35: =SUM(BI35:CD35) -> 4 | CF35: =CE35/CE$9*100 -> 36.363636 | CG35: 2 | CZ35: =SUM(CG35:CQ35) -> 2 | DA35: =CZ35/CZ$9*100 -> 66.666667 | DP35: =SUM(DB35:DO35) -> 0 | DQ35: =DP35/DP$9*100 -> #DIV/0!
A36: 27 | B36: 0827CI241109 | C36: RISHIRAJ JHAWAR | D36: =SUM(M36+AJ36+BG36+CE36+CZ36) -> 20 | E36: =(D36)/D$9*100 -> 51.282051 | F36: =IF(E36<50,E36, " ") | G36: =IF(E36<30,E36, " ") | M36: =SUM(H36:L36) -> 0 | N36: =M36/M$9*100 -> #DIV/0! | X36: 1 | Y36: 1 | AB36: 1 | AJ36: =SUM(O36:AI36) -> 3 | AK36: =AJ36/AJ$9*100 -> 33.333333 | AO36: 1 | AS36: 1 | AT36: 1 | AU36: 1 | AZ36: 1 | BC36: 1 | BD36: 1 | BG36: =SUM(AL36:BF36) -> 7 | BH36: =BG36/BG$9*100 -> 43.75 | BJ36: 1 | BO36: 1 | BP36: 1 | BT36: 1 | BZ36: 1 | CB36: 2 | CD36: 1 | CE36: =SUM(BI36:CD36) -> 8 | CF36: =CE36/CE$9*100 -> 72.727273 | CI36: 2 | CZ36: =SUM(CG36:CQ36) -> 2 | DA36: =CZ36/CZ$9*100 -> 66.666667 | DP36: =SUM(DB36:DO36) -> 0 | DQ36: =DP36/DP$9*100 -> #DIV/0!
A37: 28 | B37: 0827CI241110 | C37: ROHIT PARIHAR | D37: =SUM(M37+AJ37+BG37+CE37+CZ37) -> 25 | E37: =(D37)/D$9*100 -> 64.102564 | F37: =IF(E37<50,E37, " ") | G37: =IF(E37<30,E37, " ") | M37: =SUM(H37:L37) -> 0 | N37: =M37/M$9*100 -> #DIV/0! | X37: 1 | Y37: 1 | Z37: 1 | AB37: 1 | AC37: 1 | AD37: 1 | AE37: 2 | AJ37: =SUM(O37:AI37) -> 8 | AK37: =AJ37/AJ$9*100 -> 88.888889 | AL37: 1 | AN37: ` | AP37: 1 | AQ37: 1 | AX37: 1 | AY37: 1 | AZ37: 1 | BC37: 1 | BD37: 1 | BE37: 1 | BG37: =SUM(AL37:BF37) -> 9 | BH37: =BG37/BG$9*100 -> 56.25 | BJ37: 1 | BL37: 1 | BR37: 1 | BT37: 1 | CB37: 2 | CE37: =SUM(BI37:CD37) -> 6 | CF37: =CE37/CE$9*100 -> 54.545455 | CG37: 2 | CZ37: =SUM(CG37:CQ37) -> 2 | DA37: =CZ37/CZ$9*100 -> 66.666667 | DP37: =SUM(DB37:DO37) -> 0 | DQ37: =DP37/DP$9*100 -> #DIV/0!
A38: 29 | B38: 0827CI241111 | C38: SAHIL PAHUJA | D38: =SUM(M38+AJ38+BG38+CE38+CZ38) -> 24 | E38: =(D38)/D$9*100 -> 61.538462 | F38: =IF(E38<50,E38, " ") | G38: =IF(E38<30,E38, " ") | M38: =SUM(H38:L38) -> 0 | N38: =M38/M$9*100 -> #DIV/0! | X38: 1 | Y38: 1 | Z38: 1 | AD38: 1 | AE38: 2 | AG38: 1 | AH38: 1 | AJ38: =SUM(O38:AI38) -> 8 | AK38: =AJ38/AJ$9*100 -> 88.888889 | AN38: ` | AO38: 1 | AP38: 1 | AS38: 1 | AT38: 1 | AU38: 1 | AY38: 1 | AZ38: 1 | BD38: 1 | BE38: 1 | BG38: =SUM(AL38:BF38) -> 9 | BH38: =BG38/BG$9*100 -> 56.25 | BJ38: 1 | BO38: 1 | BP38: 1 | CB38: 2 | CE38: =SUM(BI38:CD38) -> 5 | CF38: =CE38/CE$9*100 -> 45.454545 | CG38: 2 | CZ38: =SUM(CG38:CQ38) -> 2 | DA38: =CZ38/CZ$9*100 -> 66.666667 | DP38: =SUM(DB38:DO38) -> 0 | DQ38: =DP38/DP$9*100 -> #DIV/0!
A39: 30 | B39: 0827CI241112 | C39: SAMARTH MAHESHWARI | D39: =SUM(M39+AJ39+BG39+CE39+CZ39) -> 28 | E39: =(D39)/D$9*100 -> 71.794872 | F39: =IF(E39<50,E39, " ") | G39: =IF(E39<30,E39, " ") | M39: =SUM(H39:L39) -> 0 | N39: =M39/M$9*100 -> #DIV/0! | X39: 1 | Z39: 1 | AB39: 1 | AC39: 1 | AD39: 1 | AE39: 2 | AH39: 1 | AJ39: =SUM(O39:AI39) -> 8 | AK39: =AJ39/AJ$9*100 -> 88.888889 | AO39: 1 | AP39: 1 | AS39: 1 | AT39: 1 | AV39: 1 | AX39: 1 | AY39: 1 | AZ39: 1 | BD39: 1 | BG39: =SUM(AL39:BF39) -> 9 | BH39: =BG39/BG$9*100 -> 56.25 | BJ39: 1 | BO39: 1 | BP39: 1 | BR39: 1 | BT39: 1 | BZ39: 1 | CB39: 2 | CE39: =SUM(BI39:CD39) -> 8 | CF39: =CE39/CE$9*100 -> 72.727273 | CG39: 2 | CH39: 1 | CZ39: =SUM(CG39:CQ39) -> 3 | DA39: =CZ39/CZ$9*100 -> 100 | DP39: =SUM(DB39:DO39) -> 0 | DQ39: =DP39/DP$9*100 -> #DIV/0!
A40: 31 | B40: 0827CI241113 | C40: SAMRUDDHI SONGIRKAR | D40: =SUM(M40+AJ40+BG40+CE40+CZ40) -> 10 | E40: =(D40)/D$9*100 -> 25.641026 | F40: =IF(E40<50,E40, " ") -> 25.641026 | G40: =IF(E40<30,E40, " ") -> 25.641026 | M40: =SUM(H40:L40) -> 0 | N40: =M40/M$9*100 -> #DIV/0! | X40: 1 | AB40: 1 | AD40: 1 | AJ40: =SUM(O40:AI40) -> 3 | AK40: =AJ40/AJ$9*100 -> 33.333333 | AO40: 1 | AQ40: 1 | AS40: 1 | BD40: 1 | BG40: =SUM(AL40:BF40) -> 4 | BH40: =BG40/BG$9*100 -> 25 | CE40: =SUM(BI40:CD40) -> 0 | CF40: =CE40/CE$9*100 -> 0 | CG40: 2 | CH40: 1 | CZ40: =SUM(CG40:CQ40) -> 3 | DA40: =CZ40/CZ$9*100 -> 100 | DP40: =SUM(DB40:DO40) -> 0 | DQ40: =DP40/DP$9*100 -> #DIV/0!
...

Sheet 402 L
A1: CSIT-402 L
A2: Faculty Name: | C2: Dr. Asmita Rajawat
A3: Subject Name : | C3: Analog and Digital Communication
A4: Subject Code : | C4: CSIT-402
A5: Start Date | C5: 46104
A6: End Date
H7: 1 | I7: 2 | J7: 3 | L7: 4 | O7: 1 | P7: 2 | Q7: 3 | R7: 4 | S7: 5 | T7: 6 | U7: 7 | V7: 8 | W7: 9 | X7: 10 | Y7: 11 | Z7: 12 | AA7: 13 | AB7: 14 | AC7: 15 | AD7: 16 | AE7: 17 | AF7: 18 | AG7: 19 | AH7: 20 | AI7: 21 | AL7: 1 | AM7: 2 | AN7: 3 | AO7: 4 | AP7: 5 | AQ7: 6 | AR7: 7 | AS7: 8 | AT7: 9 | AU7: 10 | AV7: 11 | AW7: 12 | AX7: 13 | AY7: 14 | AZ7: 15 | BA7: 16 | BB7: 17 | BE7: 18 | BH7: 1 | BI7: 2 | BJ7: 3 | BK7: 4 | BL7: 5 | BM7: 6 | BN7: 7 | BO7: 8 | BP7: 9 | BQ7: 10 | BR7: 11 | BS7: 12 | BT7: 13 | BU7: 14 | BV7: 15 | BW7: 16 | BX7: 17 | BY7: 18 | BZ7: 19 | CA7: 20 | CB7: 21 | CE7: 1 | CF7: 2 | CG7: 3 | CH7: 4 | CI7: 5 | CJ7: 6 | CK7: 7 | CL7: 8 | CM7: 9 | CN7: 10
D8: Total Class | E8: OverAll Att. % | F8: Att. 50% | G8: Att. 30% | H8: 46104 | I8: 46105 | J8: 46106 | K8: 46107 | L8: 46111 | M8: MAR CLASS | N8: MARCH % | O8: 46113 | P8: 46114 | Q8: 46115 | R8: 46118 | S8: 46119 | T8: 46120 | U8: 46121 | V8: 46122 | W8: 46125 | X8: 46127 | Y8: 46128 | Z8: 46129 | AA8: 46132 | AB8: 46133 | AC8: 46134 | AD8: 46135 | AE8: 46136 | AF8: 46139 | AG8: 46140 | AH8: 46141 | AI8: 46142 | AJ8: APRIL CLASS | AK8: APRIL % | AL8: 46143 | AM8: 46146 | AN8: 46147 | AO8: 46148 | AP8: 46149 | AQ8: 46150 | AR8: 46153 | AS8: 46154 | AT8: 46155 | AU8: 46156 | AV8: 46157 | AW8: 46160 | AX8: 46161 | AY8: 46162 | AZ8: 46163 | BA8: 46164 | BB8: 46167 | BC8: 46169 | BD8: 46171 | BF8: MAY CLASS | BG8: MAY % | BH8: 46174 | BI8: 46175 | BJ8: 46176 | BK8: 46177 | BL8: 46178 | BM8: 46181 | BN8: 46182 | BO8: 46183 | BP8: 46184 | BQ8: 46185 | BR8: 46188 | BS8: 46189 | BT8: 46190 | BU8: 46191 | BV8: 46192 | BW8: 46195 | BX8: 46196 | BY8: 46197 | BZ8: 46198 | CA8: 46199 | CC8: JUNE CLASS | CD8: JUNE % | CE8: 46204 | CF8: 46206 | CO8: DEC CLASS | CP8: DEC %
A9: S.No. | B9: Enrollment No. | C9: Student Name | D9: =SUM(M9+AJ9+BF9+CC9+CO9) -> 10 | H9: =SUM(H10:H50) -> 0 | I9: =SUM(I10:I50) -> 0 | J9: =SUM(J10:J50) -> 0 | K9: =SUM(K10:K50) -> 0 | L9: =SUM(L10:L50) -> 0 | M9: =COUNTIF(H9:L9,">0") -> 0 | N9: =COUNTIF(H9:L9,">0") -> 0 | O9: =SUM(O10:O50) -> 0 | P9: =SUM(P10:P50) -> 0 | Q9: =SUM(Q10:Q50) -> 0 | R9: =SUM(R10:R50) -> 0 | S9: =SUM(S10:S50) -> 0 | T9: =SUM(T10:T50) -> 0 | U9: =SUM(U10:U50) -> 0 | V9: =SUM(V10:V50) -> 0 | ... AI9: =SUM(AI10:AI50) -> 0 | AJ9: =COUNTIF(O9:AI9,">0") -> 2 | AK9: =SUM(M9+AJ9) -> 2 | AL9: =SUM(AL10:AL50) -> 8 | AM9: =SUM(AM10:AM50) -> 0 | AN9: =SUM(AN10:AN50) -> 0 | AO9: =SUM(AO10:AO50) -> 0 | AP9: =SUM(AP10:AP50) -> 0 | AQ9: =SUM(AQ10:AQ50) -> 17 | AR9: =SUM(AR10:AR50) -> 0 | AS9: =SUM(AS10:AS50) -> 0 | ... BB9: =SUM(BB10:BB50) -> 0 | BD9: =SUM(BD10:BD50) -> 15 | BE9: =SUM(BE10:BE50) -> 0 | BF9: =COUNTIF(AL9:BE9,">0") -> 4 | BG9: =SUM(AK9+BF9) -> 6 | BH9: =SUM(BH10:BH50) -> 0 | BI9: =SUM(BI10:BI50) -> 0 | BJ9: =SUM(BJ10:BJ50) -> 0 | BK9: =SUM(BK10:BK50) -> 0 | BL9: =SUM(BL10:BL50) -> 0 | BM9: =SUM(BM10:BM50) -> 0 | BN9: =SUM(BN10:BN50) -> 0 | BO9: =SUM(BO10:BO50) -> 0 | ... CB9: =SUM(CB10:CB50) -> 0 | CC9: =COUNTIF(BH9:CB9,">0") -> 3 | CD9: =SUM(BG9+CC9) -> 9 | CE9: =SUM(CE10:CE48) -> 0 | CF9: =SUM(CF10:CF48) -> 27 | CG9: =SUM(CG10:CG48) -> 0 | CH9: =SUM(CH10:CH48) -> 0 | CI9: =SUM(CI10:CI48) -> 0 | CJ9: =SUM(CJ10:CJ48) -> 0 | CK9: =SUM(CK10:CK48) -> 0 | CL9: =SUM(CL10:CL48) -> 0 | ... CN9: =SUM(CN10:CN48) -> 0 | CO9: =COUNTIF(CE9:CN9,">0") -> 1 | CP9: =SUM(CD9+CO9) -> 10
A10: 1 | B10: 0827CI241083 | C10: PARMEET KEVAT | D10: =SUM(M10+AJ10+BF10+CC10+CO10) -> 5 | E10: =(D10)/D$9*100 -> 50 | F10: =IF(E10<50,E10, " ") | G10: =IF(E10<30,E10, " ") | M10: =SUM(H10:L10) -> 0 | N10: =M10/M$9*100 -> #DIV/0! | Z10: 1 | AJ10: =SUM(O10:AI10) -> 1 | AK10: =AJ10/AJ$9*100 -> 50 | AQ10: 1 | BD10: 1 | BF10: =SUM(AL10:BE10) -> 2 | BG10: =BF10/BF$9*100 -> 50 | BQ10: 1 | CA10: 1 | CC10: =SUM(BH10:CB10) -> 2 | CD10: =CC10/CC$9*100 -> 66.666667 | CO10: =SUM(CE10:CN10) -> 0 | CP10: =CO10/CO$9*100 -> 0
A11: 2 | B11: 0827CI241084 | C11: PARTH SHARMA | D11: =SUM(M11+AJ11+BF11+CC11+CO11) -> 7 | E11: =(D11)/D$9*100 -> 70 | F11: =IF(E11<50,E11, " ") | G11: =IF(E11<30,E11, " ") | M11: =SUM(H11:L11) -> 0 | N11: =M11/M$9*100 -> #DIV/0! | Z11: 1 | AE11: 1 | AJ11: =SUM(O11:AI11) -> 2 | AK11: =AJ11/AJ$9*100 -> 100 | AQ11: 1 | BF11: =SUM(AL11:BE11) -> 1 | BG11: =BF11/BF$9*100 -> 25 | BQ11: 1 | BV11: 1 | CA11: 1 | CC11: =SUM(BH11:CB11) -> 3 | CD11: =CC11/CC$9*100 -> 100 | CF11: 1 | CO11: =SUM(CE11:CN11) -> 1 | CP11: =CO11/CO$9*100 -> 100
A12: 3 | B12: 0827CI241085 | C12: PARTH SHARMA | D12: =SUM(M12+AJ12+BF12+CC12+CO12) -> 1 | E12: =(D12)/D$9*100 -> 10 | F12: =IF(E12<50,E12, " ") -> 10 | G12: =IF(E12<30,E12, " ") -> 10 | M12: =SUM(H12:L12) -> 0 | N12: =M12/M$9*100 -> #DIV/0! | AJ12: =SUM(O12:AI12) -> 0 | AK12: =AJ12/AJ$9*100 -> 0 | BF12: =SUM(AL12:BE12) -> 0 | BG12: =BF12/BF$9*100 -> 0 | CC12: =SUM(BH12:CB12) -> 0 | CD12: =CC12/CC$9*100 -> 0 | CF12: 1 | CO12: =SUM(CE12:CN12) -> 1 | CP12: =CO12/CO$9*100 -> 100
A13: 4 | B13: 0827CI241086 | C13: PARUL DEVKAR | D13: =SUM(M13+AJ13+BF13+CC13+CO13) -> 1 | E13: =(D13)/D$9*100 -> 10 | F13: =IF(E13<50,E13, " ") -> 10 | G13: =IF(E13<30,E13, " ") -> 10 | M13: =SUM(H13:L13) -> 0 | N13: =M13/M$9*100 -> #DIV/0! | AJ13: =SUM(O13:AI13) -> 0 | AK13: =AJ13/AJ$9*100 -> 0 | AV13: 1 | BF13: =SUM(AL13:BE13) -> 1 | BG13: =BF13/BF$9*100 -> 25 | CC13: =SUM(BH13:CB13) -> 0 | CD13: =CC13/CC$9*100 -> 0 | CO13: =SUM(CE13:CN13) -> 0 | CP13: =CO13/CO$9*100 -> 0
A14: 5 | B14: 0827CI241087 | C14: PAVNI SONER | D14: =SUM(M14+AJ14+BF14+CC14+CO14) -> 6 | E14: =(D14)/D$9*100 -> 60 | F14: =IF(E14<50,E14, " ") | G14: =IF(E14<30,E14, " ") | M14: =SUM(H14:L14) -> 0 | N14: =M14/M$9*100 -> #DIV/0! | Z14: 1 | AJ14: =SUM(O14:AI14) -> 1 | AK14: =AJ14/AJ$9*100 -> 50 | AQ14: 1 | BD14: 1 | BF14: =SUM(AL14:BE14) -> 2 | BG14: =BF14/BF$9*100 -> 50 | BV14: 1 | CA14: 1 | CC14: =SUM(BH14:CB14) -> 2 | CD14: =CC14/CC$9*100 -> 66.666667 | CF14: 1 | CO14: =SUM(CE14:CN14) -> 1 | CP14: =CO14/CO$9*100 -> 100
A15: 6 | B15: 0827CI241088 | C15: PIYUSH MANDLOI | D15: =SUM(M15+AJ15+BF15+CC15+CO15) -> 7 | E15: =(D15)/D$9*100 -> 70 | F15: =IF(E15<50,E15, " ") | G15: =IF(E15<30,E15, " ") | M15: =SUM(H15:L15) -> 0 | N15: =M15/M$9*100 -> #DIV/0! | Z15: 1 | AE15: 1 | AJ15: =SUM(O15:AI15) -> 2 | AK15: =AJ15/AJ$9*100 -> 100 | AL15: 1 | AQ15: 1 | BF15: =SUM(AL15:BE15) -> 2 | BG15: =BF15/BF$9*100 -> 50 | BQ15: 1 | CA15: 1 | CC15: =SUM(BH15:CB15) -> 2 | CD15: =CC15/CC$9*100 -> 66.666667 | CF15: 1 | CO15: =SUM(CE15:CN15) -> 1 | CP15: =CO15/CO$9*100 -> 100
A16: 7 | B16: 0827CI241089 | C16: PRAGATI VERMA | D16: =SUM(M16+AJ16+BF16+CC16+CO16) -> 2 | E16: =(D16)/D$9*100 -> 20 | F16: =IF(E16<50,E16, " ") -> 20 | G16: =IF(E16<30,E16, " ") -> 20 | M16: =SUM(H16:L16) -> 0 | N16: =M16/M$9*100 -> #DIV/0! | AJ16: =SUM(O16:AI16) -> 0 | AK16: =AJ16/AJ$9*100 -> 0 | AL16: 1 | BF16: =SUM(AL16:BE16) -> 1 | BG16: =BF16/BF$9*100 -> 25 | CC16: =SUM(BH16:CB16) -> 0 | CD16: =CC16/CC$9*100 -> 0 | CF16: 1 | CO16: =SUM(CE16:CN16) -> 1 | CP16: =CO16/CO$9*100 -> 100
A17: 8 | B17: 0827CI241090 | C17: PRANAL PATEL | D17: =SUM(M17+AJ17+BF17+CC17+CO17) -> 0 | E17: =(D17)/D$9*100 -> 0 | F17: =IF(E17<50,E17, " ") -> 0 | G17: =IF(E17<30,E17, " ") -> 0 | M17: =SUM(H17:L17) -> 0 | N17: =M17/M$9*100 -> #DIV/0! | AJ17: =SUM(O17:AI17) -> 0 | AK17: =AJ17/AJ$9*100 -> 0 | BF17: =SUM(AL17:BE17) -> 0 | BG17: =BF17/BF$9*100 -> 0 | CC17: =SUM(BH17:CB17) -> 0 | CD17: =CC17/CC$9*100 -> 0 | CO17: =SUM(CE17:CN17) -> 0 | CP17: =CO17/CO$9*100 -> 0
A18: 9 | B18: 0827CI241091 | C18: PRANIT GURVE | D18: =SUM(M18+AJ18+BF18+CC18+CO18) -> 5 | E18: =(D18)/D$9*100 -> 50 | F18: =IF(E18<50,E18, " ") | G18: =IF(E18<30,E18, " ") | M18: =SUM(H18:L18) -> 0 | N18: =M18/M$9*100 -> #DIV/0! | AE18: 1 | AJ18: =SUM(O18:AI18) -> 1 | AK18: =AJ18/AJ$9*100 -> 50 | AL18: 1 | BF18: =SUM(AL18:BE18) -> 1 | BG18: =BF18/BF$9*100 -> 25 | BQ18: 1 | CA18: 1 | CC18: =SUM(BH18:CB18) -> 2 | CD18: =CC18/CC$9*100 -> 66.666667 | CF18: 1 | CO18: =SUM(CE18:CN18) -> 1 | CP18: =CO18/CO$9*100 -> 100
