Workbook

Sheet 401
A1: CY-401
A2: Faculty Name: | C2: Prof. Anita Agrawal
A3: Subject Name : | C3: Introduction To Linear Algebra | BI3: 0
A4: Subject Code : | C4: CY-401
A5: Start Date | C5: 46104
A6: End Date
H7: 1 | J7: 3 | K7: 4 | N7: 1 | O7: 2 | P7: 3 | Q7: 4 | R7: 5 | S7: 6 | T7: 7 | U7: 8 | V7: 9 | W7: 10 | X7: 11 | Y7: 12 | Z7: 13 | AA7: 15 | AB7: 16 | AC7: 17 | AD7: 18 | AE7: 19 | AF7: 20 | AG7: 21 | AJ7: 1 | AK7: 2 | AL7: 3 | AM7: 4 | AN7: 5 | AO7: 6 | AP7: 7 | AQ7: 8 | AR7: 9 | AS7: 10 | AT7: 11 | AU7: 12 | AV7: 13 | AW7: 14 | AX7: 15 | BB7: 16 | BC7: 17 | BD7: 18 | BG7: 1 | BH7: 2 | BI7: 3 | BJ7: 4 | BK7: 5 | BL7: 6 | BM7: 7 | BN7: 8 | BO7: 9 | BP7: 10 | BQ7: 11 | BR7: 12 | BS7: 13 | BT7: 14 | BU7: 15 | BV7: 16 | BW7: 17 | BX7: 18 | CB7: 19 | CE7: 1 | CF7: 2 | CG7: 3 | CH7: 4 | CI7: 5 | CJ7: 6 | CK7: 7 | CL7: 8 | CM7: 9 | CN7: 10 | CO7: 11
D8: Total Class | E8: OverAll Att. % | F8: Att. 50% | G8: Att. 30% | H8: 46104 | I8: 46106 | J8: 46107 | K8: 46111 | L8: MAR CLASS | M8: MAR % | N8: 46113 | O8: 46114 | P8: 46115 | Q8: 46118 | R8: 46119 | S8: 46120 | T8: 46121 | U8: 46122 | V8: 46125 | W8: 46127 | X8: 46128 | Y8: 46129 | Z8: 46132 | AA8: 46134 | AB8: 46135 | AC8: 46136 | AD8: 46139 | AE8: 46141 | AF8: 46142 | AH8: APRIL CLASS | AI8: APRIL % | AJ8: 46143 | AK8: 46146 | AL8: 46148 | AM8: 46150 | AN8: 46153 | AO8: 46155 | AP8: 46156 | AQ8: 46157 | AR8: 46167 | AS8: 46169 | AT8: 46170 | AU8: 46171 | BE8: MAY CLASS | BF8: MAY % | BG8: 46174 | BH8: 46177 | BI8: 46183 | BJ8: 46185 | BK8: 46186 | BL8: 46188 | BM8: 46190 | BN8: 46191 | BO8: 46192 | BP8: 46195 | BQ8: 46197 | BR8: 46198 | BS8: 46199 | BT8: 46202 | CC8: JUNE CLASS | CD8: JUNE % | CE8: 46204 | CF8: 46205 | CR8: JULY CLASS | CS8: JULY% | DL8: JAN CLASS | DM8: JAN%
A9: s.no. | B9: Enrollment NO. | C9: Student Name | D9: =SUM(L9+AH9+BE9+CC9+CR9) -> 41 | H9: =SUM(H10:H89) -> 9 | I9: =SUM(I10:I89) -> 3 | J9: =SUM(J10:J89) -> 0 | K9: =SUM(K10:K89) -> 0 | L9: =COUNTIF(H9:K9,">0") -> 2 | M9: =COUNTIF(H9:K9,">0") -> 2 | N9: =SUM(N10:N89) -> 0 | O9: =SUM(O10:O89) -> 0 | P9: =SUM(P10:P89) -> 0 | Q9: =SUM(Q10:Q89) -> 0 | R9: =SUM(R10:R89) -> 0 | S9: =SUM(S10:S89) -> 0 | T9: =SUM(T10:T89) -> 0 | U9: =SUM(U10:U89) -> 0 | ... AG9: =SUM(AG10:AG89) -> 0 | AH9: =COUNTIF(N9:AG9,">0") -> 11 | AI9: =SUM(L9+AH9) -> 13 | AJ9: =SUM(AJ10:AJ89) -> 33 | AK9: =SUM(AK10:AK89) -> 42 | AL9: =SUM(AL10:AL89) -> 40 | AM9: =SUM(AM10:AM89) -> 19 | AN9: =SUM(AN10:AN89) -> 37 | AO9: =SUM(AO10:AO89) -> 36 | AP9: =SUM(AP10:AP89) -> 32 | AQ9: =SUM(AQ10:AQ89) -> 14 | ... AX9: =SUM(AX10:AX89) -> 0 | BB9: =SUM(BB10:BB89) -> 0 | BC9: =SUM(BC10:BC89) -> 0 | BD9: =SUM(BD10:BD89) -> 0 | BE9: =COUNTIF(AJ9:BD9,">0") -> 12 | BF9: =SUM(AI9+BE9) -> 25 | BG9: =SUM(BG10:BG89) -> 32 | BH9: =SUM(BH10:BH89) -> 25 | BI9: =SUM(BI10:BI89) -> 42 | BJ9: =SUM(BJ10:BJ89) -> 36 | BK9: =SUM(BK10:BK89) -> 6 | BL9: =SUM(BL10:BL89) -> 40 | BM9: =SUM(BM10:BM89) -> 48 | BN9: =SUM(BN10:BN89) -> 31 | ... CA9: =SUM(CA10:CA89) -> 0 | CB9: =SUM(CB10:CB69) -> 0 | CC9: =COUNTIF(BG9:CB9,">0") -> 14 | CD9: =SUM(BF9+CC9) -> 39 | CE9: =SUM(CE10:CE89) -> 32 | CF9: =SUM(CF10:CF89) -> 34 | CG9: =SUM(CG10:CG89) -> 0 | CH9: =SUM(CH10:CH89) -> 0 | CI9: =SUM(CI10:CI89) -> 0 | CJ9: =SUM(CJ10:CJ89) -> 0 | CK9: =SUM(CK10:CK89) -> 0 | CL9: =SUM(CL10:CL89) -> 0 | ... CQ9: =SUM(CQ10:CQ89) -> 0 | CR9: =COUNTIF(CE9:CQ9,">0") -> 2 | CS9: =SUM(CD9+CR9) -> 41 | CT9: =SUM(CT10:CT89) -> 0 | CU9: =SUM(CU10:CU89) -> 0 | CV9: =SUM(CV10:CV89) -> 0 | CW9: =SUM(CW10:CW89) -> 0 | CX9: =SUM(CX10:CX89) -> 0 | CY9: =SUM(CY10:CY89) -> 0 | CZ9: =SUM(CZ10:CZ89) -> 0 | DA9: =SUM(DA10:DA89) -> 0 | ... DK9: =SUM(DK10:DK89) -> 0 | DL9: =COUNTIF(CT9:DK9,">0") -> 0 | DM9: =SUM(CX9+DL9) -> 0
A10: 1 | B10: 0827CY241001 | C10: AASTHA RATHORE | D10: =SUM(L10+AH10+BE10+CC10+CR10) -> 35 | E10: =(D10)/D$9*100 -> 85.365854 | F10: =IF(E10<50,E10, " ") | G10: =IF(E10<30,E10, " ") | H10: 1 | L10: =SUM(H10:K10) -> 1 | M10: =L10/L$9*100 -> 50 | V10: 1 | W10: 1 | X10: 1 | Y10: 1 | Z10: 1 | AB10: 1 | AC10: 1 | AD10: 1 | AE10: 1 | AF10: 1 | AH10: =SUM(N10:AG10) -> 10 | AI10: =AH10/AH$9*100 -> 90.909091 | AJ10: 1 | AL10: 1 | AM10: 1 | AN10: 1 | AO10: 1 | AP10: 1 | AQ10: 1 | AR10: 1 | AS10: 1 | AT10: 1 | AU10: 1 | BE10: =SUM(AJ10:BD10) -> 11 | BF10: =BE10/BE$9*100 -> 91.666667 | BG10: 1 | BI10: 1 | BJ10: 1 | BK10: 1 | BL10: 1 | BM10: 1 | BO10: 1 | BP10: 1 | BR10: 1 | BS10: 1 | BT10: 1 | CC10: =SUM(BG10:CB10) -> 11 | CD10: =CC10/CC$9*100 -> 78.571429 | CE10: 1 | CF10: 1 | CR10: =SUM(CE10:CQ10) -> 2 | CS10: =CR10/CR$9*100 -> 100 | DL10: =SUM(CT10:DK10) -> 0 | DM10: =DL10/DL$9*100 -> #DIV/0!
A11: 2 | B11: 0827CY241002 | C11: ABEER JOSHI | D11: =SUM(L11+AH11+BE11+CC11+CR11) -> 17 | E11: =(D11)/D$9*100 -> 41.463415 | F11: =IF(E11<50,E11, " ") -> 41.463415 | G11: =IF(E11<30,E11, " ") | L11: =SUM(H11:K11) -> 0 | M11: =L11/L$9*100 -> 0 | W11: 1 | X11: 1 | Y11: 1 | AA11: 1 | AF11: 1 | AH11: =SUM(N11:AG11) -> 5 | AI11: =AH11/AH$9*100 -> 45.454545 | AK11: 1 | AN11: 1 | AP11: 1 | AR11: 1 | AS11: 1 | AT11: 1 | BE11: =SUM(AJ11:BD11) -> 6 | BF11: =BE11/BE$9*100 -> 50 | BM11: 1 | BN11: 1 | BP11: 1 | BQ11: 1 | BT11: 1 | CC11: =SUM(BG11:CB11) -> 5 | CD11: =CC11/CC$9*100 -> 35.714286 | CE11: 1 | CR11: =SUM(CE11:CQ11) -> 1 | CS11: =CR11/CR$9*100 -> 50 | DL11: =SUM(CT11:DK11) -> 0 | DM11: =DL11/DL$9*100 -> #DIV/0!
A12: 3 | B12: 0827CY241003 | C12: ABHIJEET SINGH | D12: =SUM(L12+AH12+BE12+CC12+CR12) -> 16 | E12: =(D12)/D$9*100 -> 39.02439 | F12: =IF(E12<50,E12, " ") -> 39.02439 | G12: =IF(E12<30,E12, " ") | L12: =SUM(H12:K12) -> 0 | M12: =L12/L$9*100 -> 0 | W12: 1 | AA12: 1 | AB12: 1 | AC12: 1 | AH12: =SUM(N12:AG12) -> 4 | AI12: =AH12/AH$9*100 -> 36.363636 | AK12: 1 | AL12: 1 | AN12: 1 | AO12: 1 | AP12: 1 | AS12: 1 | AT12: 1 | BE12: =SUM(AJ12:BD12) -> 7 | BF12: =BE12/BE$9*100 -> 58.333333 | BG12: 1 | BH12: 1 | BL12: 1 | BN12: 1 | BT12: 1 | CC12: =SUM(BG12:CB12) -> 5 | CD12: =CC12/CC$9*100 -> 35.714286 | CR12: =SUM(CE12:CQ12) -> 0 | CS12: =CR12/CR$9*100 -> 0 | DL12: =SUM(CT12:DK12) -> 0 | DM12: =DL12/DL$9*100 -> #DIV/0!
A13: 4 | B13: 0827CY241004 | C13: ADITI CHOUDHARY | D13: =SUM(L13+AH13+BE13+CC13+CR13) -> 21 | E13: =(D13)/D$9*100 -> 51.219512 | F13: =IF(E13<50,E13, " ") | G13: =IF(E13<30,E13, " ") | L13: =SUM(H13:K13) -> 0 | M13: =L13/L$9*100 -> 0 | V13: 1 | W13: 1 | X13: 1 | Y13: 1 | Z13: 1 | AE13: 1 | AF13: 1 | AH13: =SUM(N13:AG13) -> 7 | AI13: =AH13/AH$9*100 -> 63.636364 | AK13: 1 | AM13: 1 | AO13: 1 | AU13: 1 | BE13: =SUM(AJ13:BD13) -> 4 | BF13: =BE13/BE$9*100 -> 33.333333 | BG13: 1 | BH13: 1 | BK13: 1 | BM13: 1 | BN13: 1 | BO13: 1 | BQ13: 1 | BS13: 1 | BT13: 1 | CC13: =SUM(BG13:CB13) -> 9 | CD13: =CC13/CC$9*100 -> 64.285714 | CF13: 1 | CR13: =SUM(CE13:CQ13) -> 1 | CS13: =CR13/CR$9*100 -> 50 | DL13: =SUM(CT13:DK13) -> 0 | DM13: =DL13/DL$9*100 -> #DIV/0!
A14: 5 | B14: 0827CY241005 | C14: ADITYA JAUNJAL | D14: =SUM(L14+AH14+BE14+CC14+CR14) -> 29 | E14: =(D14)/D$9*100 -> 70.731707 | F14: =IF(E14<50,E14, " ") | G14: =IF(E14<30,E14, " ") | L14: =SUM(H14:K14) -> 0 | M14: =L14/L$9*100 -> 0 | V14: 1 | W14: 1 | X14: 1 | Y14: 1 | Z14: 1 | AA14: 1 | AB14: 1 | AC14: 1 | AD14: 1 | AE14: 1 | AF14: 1 | AH14: =SUM(N14:AG14) -> 11 | AI14: =AH14/AH$9*100 -> 100 | AJ14: 1 | AK14: 1 | AL14: 1 | AN14: 1 | AO14: 1 | AP14: 1 | AQ14: 1 | AR14: 1 | BE14: =SUM(AJ14:BD14) -> 8 | BF14: =BE14/BE$9*100 -> 66.666667 | BJ14: 1 | BL14: 1 | BM14: 1 | BN14: 1 | BO14: 1 | BP14: 1 | BQ14: 1 | BR14: 1 | BT14: 1 | CC14: =SUM(BG14:CB14) -> 9 | CD14: =CC14/CC$9*100 -> 64.285714 | CE14: 1 | CR14: =SUM(CE14:CQ14) -> 1 | CS14: =CR14/CR$9*100 -> 50 | DL14: =SUM(CT14:DK14) -> 0 | DM14: =DL14/DL$9*100 -> #DIV/0!
A15: 6 | B15: 0827CY241006 | C15: AMAY NAMDEV | D15: =SUM(L15+AH15+BE15+CC15+CR15) -> 16 | E15: =(D15)/D$9*100 -> 39.02439 | F15: =IF(E15<50,E15, " ") -> 39.02439 | G15: =IF(E15<30,E15, " ") | L15: =SUM(H15:K15) -> 0 | M15: =L15/L$9*100 -> 0 | W15: 1 | X15: 1 | Y15: 1 | AA15: 1 | AC15: 1 | AH15: =SUM(N15:AG15) -> 5 | AI15: =AH15/AH$9*100 -> 45.454545 | AK15: 1 | AR15: 1 | AS15: 1 | AT15: 1 | BE15: =SUM(AJ15:BD15) -> 4 | BF15: =BE15/BE$9*100 -> 33.333333 | BH15: 1 | BJ15: 1 | BL15: 1 | BM15: 1 | BR15: 1 | CC15: =SUM(BG15:CB15) -> 5 | CD15: =CC15/CC$9*100 -> 35.714286 | CE15: 1 | CF15: 1 | CR15: =SUM(CE15:CQ15) -> 2 | CS15: =CR15/CR$9*100 -> 100 | DL15: =SUM(CT15:DK15) -> 0 | DM15: =DL15/DL$9*100 -> #DIV/0!
A16: 7 | B16: 0827CY241007 | C16: AMISHA SALVI | D16: =SUM(L16+AH16+BE16+CC16+CR16) -> 1 | E16: =(D16)/D$9*100 -> 2.4390244 | F16: =IF(E16<50,E16, " ") -> 2.4390244 | G16: =IF(E16<30,E16, " ") -> 2.4390244 | H16: 1 | L16: =SUM(H16:K16) -> 1 | M16: =L16/L$9*100 -> 50 | AH16: =SUM(N16:AG16) -> 0 | AI16: =AH16/AH$9*100 -> 0 | BE16: =SUM(AJ16:BD16) -> 0 | BF16: =BE16/BE$9*100 -> 0 | CC16: =SUM(BG16:CB16) -> 0 | CD16: =CC16/CC$9*100 -> 0 | CR16: =SUM(CE16:CQ16) -> 0 | CS16: =CR16/CR$9*100 -> 0 | DL16: =SUM(CT16:DK16) -> 0 | DM16: =DL16/DL$9*100 -> #DIV/0!
A17: 8 | B17: 0827CY241008 | C17: AMIT GANGWAL | D17: =SUM(L17+AH17+BE17+CC17+CR17) -> 0 | E17: =(D17)/D$9*100 -> 0 | F17: =IF(E17<50,E17, " ") -> 0 | G17: =IF(E17<30,E17, " ") -> 0 | L17: =SUM(H17:K17) -> 0 | M17: =L17/L$9*100 -> 0 | AH17: =SUM(N17:AG17) -> 0 | AI17: =AH17/AH$9*100 -> 0 | BE17: =SUM(AJ17:BD17) -> 0 | BF17: =BE17/BE$9*100 -> 0 | CC17: =SUM(BG17:CB17) -> 0 | CD17: =CC17/CC$9*100 -> 0 | CR17: =SUM(CE17:CQ17) -> 0 | CS17: =CR17/CR$9*100 -> 0 | DL17: =SUM(CT17:DK17) -> 0 | DM17: =DL17/DL$9*100 -> #DIV/0!
A18: 9 | B18: 0827CY241009 | C18: ANANYA SHARMA | D18: =SUM(L18+AH18+BE18+CC18+CR18) -> 23 | E18: =(D18)/D$9*100 -> 56.097561 | F18: =IF(E18<50,E18, " ") | G18: =IF(E18<30,E18, " ") | L18: =SUM(H18:K18) -> 0 | M18: =L18/L$9*100 -> 0 | V18: 1 | W18: 1 | AA18: 1 | AE18: 1 | AF18: 1 | AH18: =SUM(N18:AG18) -> 5 | AI18: =AH18/AH$9*100 -> 45.454545 | AJ18: 1 | AK18: 1 | AL18: 1 | AM18: 1 | AN18: 1 | AR18: 1 | AS18: 1 | AU18: 1 | BE18: =SUM(AJ18:BD18) -> 8 | BF18: =BE18/BE$9*100 -> 66.666667 | BH18: 1 | BI18: 1 | BL18: 1 | BM18: 1 | BO18: 1 | BP18: 1 | BQ18: 1 | BS18: 1 | CC18: =SUM(BG18:CB18) -> 8 | CD18: =CC18/CC$9*100 -> 57.142857 | CE18: 1 | CF18: 1 | CR18: =SUM(CE18:CQ18) -> 2 | CS18: =CR18/CR$9*100 -> 100 | DL18: =SUM(CT18:DK18) -> 0 | DM18: =DL18/DL$9*100 -> #DIV/0!
A19: 10 | B19: 0827CY241010 | C19: ANIKET PATEL | D19: =SUM(L19+AH19+BE19+CC19+CR19) -> 0 | E19: =(D19)/D$9*100 -> 0 | F19: =IF(E19<50,E19, " ") -> 0 | G19: =IF(E19<30,E19, " ") -> 0 | L19: =SUM(H19:K19) -> 0 | M19: =L19/L$9*100 -> 0 | AH19: =SUM(N19:AG19) -> 0 | AI19: =AH19/AH$9*100 -> 0 | BE19: =SUM(AJ19:BD19) -> 0 | BF19: =BE19/BE$9*100 -> 0 | CC19: =SUM(BG19:CB19) -> 0 | CD19: =CC19/CC$9*100 -> 0 | CR19: =SUM(CE19:CQ19) -> 0 | CS19: =CR19/CR$9*100 -> 0 | DL19: =SUM(CT19:DK19) -> 0 | DM19: =DL19/DL$9*100 -> #DIV/0!
A20: 11 | B20: 0827CY241011 | C20: ANISHA BAIRAGI | D20: =SUM(L20+AH20+BE20+CC20+CR20) -> 38 | E20: =(D20)/D$9*100 -> 92.682927 | F20: =IF(E20<50,E20, " ") | G20: =IF(E20<30,E20, " ") | H20: 1 | L20: =SUM(H20:K20) -> 1 | M20: =L20/L$9*100 -> 50 | V20: 1 | W20: 1 | X20: 1 | Y20: 1 | Z20: 1 | AA20: 1 | AB20: 1 | AC20: 1 | AD20: 1 | AE20: 1 | AF20: 1 | AH20: =SUM(N20:AG20) -> 11 | AI20: =AH20/AH$9*100 -> 100 | AJ20: 1 | AK20: 1 | AL20: 1 | AM20: 1 | AN20: 1 | AO20: 1 | AP20: 1 | AQ20: 1 | AR20: 1 | AS20: 1 | AU20: 1 | BE20: =SUM(AJ20:BD20) -> 11 | BF20: =BE20/BE$9*100 -> 91.666667 | BG20: 1 | BH20: 1 | BI20: 1 | BJ20: 1 | BK20: 1 | BL20: 1 | BM20: 1 | BN20: 1 | BP20: 1 | BQ20: 1 | BR20: 1 | BS20: 1 | BT20: 1 | CC20: =SUM(BG20:CB20) -> 13 | CD20: =CC20/CC$9*100 -> 92.857143 | CE20: 1 | CF20: 1 | CR20: =SUM(CE20:CQ20) -> 2 | CS20: =CR20/CR$9*100 -> 100 | DL20: =SUM(CT20:DK20) -> 0 | DM20: =DL20/DL$9*100 -> #DIV/0!
A21: 12 | B21: 0827CY241012 | C21: ANKUSH BAMOTRIYA | D21: =SUM(L21+AH21+BE21+CC21+CR21) -> 6 | E21: =(D21)/D$9*100 -> 14.634146 | F21: =IF(E21<50,E21, " ") -> 14.634146 | G21: =IF(E21<30,E21, " ") -> 14.634146 | L21: =SUM(H21:K21) -> 0 | M21: =L21/L$9*100 -> 0 | AH21: =SUM(N21:AG21) -> 0 | AI21: =AH21/AH$9*100 -> 0 | AP21: 1 | BE21: =SUM(AJ21:BD21) -> 1 | BF21: =BE21/BE$9*100 -> 8.3333333 | BG21: 1 | BI21: 1 | BJ21: 1 | BN21: 1 | BP21: 1 | CC21: =SUM(BG21:CB21) -> 5 | CD21: =CC21/CC$9*100 -> 35.714286 | CR21: =SUM(CE21:CQ21) -> 0 | CS21: =CR21/CR$9*100 -> 0 | DL21: =SUM(CT21:DK21) -> 0 | DM21: =DL21/DL$9*100 -> #DIV/0!
A22: 13 | B22: 0827CY241013 | C22: ANUSHKA SETHIYA | D22: =SUM(L22+AH22+BE22+CC22+CR22) -> 12 | E22: =(D22)/D$9*100 -> 29.268293 | F22: =IF(E22<50,E22, " ") -> 29.268293 | G22: =IF(E22<30,E22, " ") -> 29.268293 | L22: =SUM(H22:K22) -> 0 | M22: =L22/L$9*100 -> 0 | V22: 1 | W22: 1 | X22: 1 | Z22: 1 | AA22: 1 | AB22: 1 | AF22: 1 | AH22: =SUM(N22:AG22) -> 7 | AI22: =AH22/AH$9*100 -> 63.636364 | AL22: 1 | AP22: 1 | AR22: 1 | BE22: =SUM(AJ22:BD22) -> 3 | BF22: =BE22/BE$9*100 -> 25 | BL22: 1 | CC22: =SUM(BG22:CB22) -> 1 | CD22: =CC22/CC$9*100 -> 7.1428571 | CF22: 1 | CR22: =SUM(CE22:CQ22) -> 1 | CS22: =CR22/CR$9*100 -> 50 | DL22: =SUM(CT22:DK22) -> 0 | DM22: =DL22/DL$9*100 -> #DIV/0!
A23: 14 | B23: 0827CY241014 | C23: APOORV JAIN | D23: =SUM(L23+AH23+BE23+CC23+CR23) -> 11 | E23: =(D23)/D$9*100 -> 26.829268 | F23: =IF(E23<50,E23, " ") -> 26.829268 | G23: =IF(E23<30,E23, " ") -> 26.829268 | L23: =SUM(H23:K23) -> 0 | M23: =L23/L$9*100 -> 0 | AE23: 1 | AH23: =SUM(N23:AG23) -> 1 | AI23: =AH23/AH$9*100 -> 9.0909091 | AL23: 1 | AP23: 1 | AS23: 1 | AU23: 1 | BE23: =SUM(AJ23:BD23) -> 4 | BF23: =BE23/BE$9*100 -> 33.333333 | BI23: 1 | BM23: 1 | BN23: 1 | BQ23: 1 | BS23: 1 | CC23: =SUM(BG23:CB23) -> 5 | CD23: =CC23/CC$9*100 -> 35.714286 | CF23: 1 | CR23: =SUM(CE23:CQ23) -> 1 | CS23: =CR23/CR$9*100 -> 50 | DL23: =SUM(CT23:DK23) -> 0 | DM23: =DL23/DL$9*100 -> #DIV/0!
A24: 15 | B24: 0827CY241015 | C24: ASHMIT YADAV | D24: =SUM(L24+AH24+BE24+CC24+CR24) -> 20 | E24: =(D24)/D$9*100 -> 48.780488 | F24: =IF(E24<50,E24, " ") -> 48.780488 | G24: =IF(E24<30,E24, " ") | L24: =SUM(H24:K24) -> 0 | M24: =L24/L$9*100 -> 0 | W24: 1 | X24: 1 | Y24: 1 | AA24: 1 | AB24: 1 | AC24: 1 | AH24: =SUM(N24:AG24) -> 6 | AI24: =AH24/AH$9*100 -> 54.545455 | AL24: 1 | AN24: 1 | AO24: 1 | AP24: 1 | BE24: =SUM(AJ24:BD24) -> 4 | BF24: =BE24/BE$9*100 -> 33.333333 | BG24: 1 | BJ24: 1 | BL24: 1 | BM24: 1 | BN24: 1 | BQ24: 1 | BR24: 1 | BT24: 1 | CC24: =SUM(BG24:CB24) -> 8 | CD24: =CC24/CC$9*100 -> 57.142857 | CE24: 1 | CF24: 1 | CR24: =SUM(CE24:CQ24) -> 2 | CS24: =CR24/CR$9*100 -> 100 | DL24: =SUM(CT24:DK24) -> 0 | DM24: =DL24/DL$9*100 -> #DIV/0!
A25: 16 | B25: 0827CY241016 | C25: ASHWIN PATEL | D25: =SUM(L25+AH25+BE25+CC25+CR25) -> 0 | E25: =(D25)/D$9*100 -> 0 | F25: =IF(E25<50,E25, " ") -> 0 | G25: =IF(E25<30,E25, " ") -> 0 | L25: =SUM(H25:K25) -> 0 | M25: =L25/L$9*100 -> 0 | AH25: =SUM(N25:AG25) -> 0 | AI25: =AH25/AH$9*100 -> 0 | BE25: =SUM(AJ25:BD25) -> 0 | BF25: =BE25/BE$9*100 -> 0 | CC25: =SUM(BG25:CB25) -> 0 | CD25: =CC25/CC$9*100 -> 0 | CR25: =SUM(CE25:CQ25) -> 0 | CS25: =CR25/CR$9*100 -> 0 | DL25: =SUM(CT25:DK25) -> 0 | DM25: =DL25/DL$9*100 -> #DIV/0!
A26: 17 | B26: 0827CY241017 | C26: AYUSH SETHI | D26: =SUM(L26+AH26+BE26+CC26+CR26) -> 20 | E26: =(D26)/D$9*100 -> 48.780488 | F26: =IF(E26<50,E26, " ") -> 48.780488 | G26: =IF(E26<30,E26, " ") | L26: =SUM(H26:K26) -> 0 | M26: =L26/L$9*100 -> 0 | AF26: 1 | AH26: =SUM(N26:AG26) -> 1 | AI26: =AH26/AH$9*100 -> 9.0909091 | AJ26: 1 | AL26: 1 | AN26: 1 | AP26: 1 | AQ26: 1 | AR26: 1 | AS26: 1 | AT26: 1 | AU26: 1 | BE26: =SUM(AJ26:BD26) -> 9 | BF26: =BE26/BE$9*100 -> 75 | BI26: 1 | BJ26: 1 | BL26: 1 | BM26: 1 | BN26: 1 | BP26: 1 | BR26: 1 | BS26: 1 | BT26: 1 | CC26: =SUM(BG26:CB26) -> 9 | CD26: =CC26/CC$9*100 -> 64.285714 | CF26: 1 | CR26: =SUM(CE26:CQ26) -> 1 | CS26: =CR26/CR$9*100 -> 50 | DL26: =SUM(CT26:DK26) -> 0 | DM26: =DL26/DL$9*100 -> #DIV/0!
A27: 18 | B27: 0827CY241018 | C27: AYUSHI BAIRAGI | D27: =SUM(L27+AH27+BE27+CC27+CR27) -> 9 | E27: =(D27)/D$9*100 -> 21.95122 | F27: =IF(E27<50,E27, " ") -> 21.95122 | G27: =IF(E27<30,E27, " ") -> 21.95122 | H27: 1 | L27: =SUM(H27:K27) -> 1 | M27: =L27/L$9*100 -> 50 | W27: 1 | AD27: 1 | AH27: =SUM(N27:AG27) -> 2 | AI27: =AH27/AH$9*100 -> 18.181818 | AJ27: 1 | AL27: 1 | AR27: 1 | BE27: =SUM(AJ27:BD27) -> 3 | BF27: =BE27/BE$9*100 -> 25 | BI27: 1 | BO27: 1 | CC27: =SUM(BG27:CB27) -> 2 | CD27: =CC27/CC$9*100 -> 14.285714 | CF27: 1 | CR27: =SUM(CE27:CQ27) -> 1 | CS27: =CR27/CR$9*100 -> 50 | DL27: =SUM(CT27:DK27) -> 0 | DM27: =DL27/DL$9*100 -> #DIV/0!
A28: 19 | B28: 0827CY241019 | C28: BHUMIKA AMIN | D28: =SUM(L28+AH28+BE28+CC28+CR28) -> 26 | E28: =(D28)/D$9*100 -> 63.414634 | F28: =IF(E28<50,E28, " ") | G28: =IF(E28<30,E28, " ") | H28: 1 | L28: =SUM(H28:K28) -> 1 | M28: =L28/L$9*100 -> 50 | V28: 1 | W28: 1 | X28: 1 | Y28: 1 | AB28: 1 | AC28: 1 | AH28: =SUM(N28:AG28) -> 6 | AI28: =AH28/AH$9*100 -> 54.545455 | AJ28: 1 | AK28: 1 | AL28: 1 | AM28: 1 | AO28: 1 | AP28: 1 | AT28: 1 | AU28: 1 | BE28: =SUM(AJ28:BD28) -> 8 | BF28: =BE28/BE$9*100 -> 66.666667 | BG28: 1 | BI28: 1 | BJ28: 1 | BK28: 1 | BL28: 1 | BM28: 1 | BQ28: 1 | BS28: 1 | BT28: 1 | CC28: =SUM(BG28:CB28) -> 9 | CD28: =CC28/CC$9*100 -> 64.285714 | CE28: 1 | CF28: 1 | CR28: =SUM(CE28:CQ28) -> 2 | CS28: =CR28/CR$9*100 -> 100 | DL28: =SUM(CT28:DK28) -> 0 | DM28: =DL28/DL$9*100 -> #DIV/0!
A29: 20 | B29: 0827CY241020 | C29: CHAITANYA PARKER | D29: =SUM(L29+AH29+BE29+CC29+CR29) -> 34 | E29: =(D29)/D$9*100 -> 82.926829 | F29: =IF(E29<50,E29, " ") | G29: =IF(E29<30,E29, " ") | I29: 1 | L29: =SUM(H29:K29) -> 1 | M29: =L29/L$9*100 -> 50 | V29: 1 | W29: 1 | X29: 1 | Z29: 1 | AA29: 1 | AB29: 1 | AC29: 1 | AD29: 1 | AE29: 1 | AF29: 1 | AH29: =SUM(N29:AG29) -> 10 | AI29: =AH29/AH$9*100 -> 90.909091 | AJ29: 1 | AK29: 1 | AL29: 1 | AN29: 1 | AO29: 1 | AP29: 1 | AQ29: 1 | AR29: 1 | AS29: 1 | AT29: 1 | BE29: =SUM(AJ29:BD29) -> 10 | BF29: =BE29/BE$9*100 -> 83.333333 | BG29: 1 | BH29: 1 | BI29: 1 | BJ29: 1 | BL29: 1 | BM29: 1 | BN29: 1 | BP29: 1 | BQ29: 1 | BR29: 1 | BT29: 1 | CC29: =SUM(BG29:CB29) -> 11 | CD29: =CC29/CC$9*100 -> 78.571429 | CE29: 1 | CF29: 1 | CR29: =SUM(CE29:CQ29) -> 2 | CS29: =CR29/CR$9*100 -> 100 | DL29: =SUM(CT29:DK29) -> 0 | DM29: =DL29/DL$9*100 -> #DIV/0!
A30: 21 | B30: 0827CY241021 | C30: CHIRAG KAMARIYA | D30: =SUM(L30+AH30+BE30+CC30+CR30) -> 9 | E30: =(D30)/D$9*100 -> 21.95122 | F30: =IF(E30<50,E30, " ") -> 21.95122 | G30: =IF(E30<30,E30, " ") -> 21.95122 | L30: =SUM(H30:K30) -> 0 | M30: =L30/L$9*100 -> 0 | X30: 1 | Z30: 1 | AA30: 1 | AH30: =SUM(N30:AG30) -> 3 | AI30: =AH30/AH$9*100 -> 27.272727 | AL30: 1 | AS30: 1 | BE30: =SUM(AJ30:BD30) -> 2 | BF30: =BE30/BE$9*100 -> 16.666667 | BL30: 1 | BM30: 1 | BN30: 1 | CC30: =SUM(BG30:CB30) -> 3 | CD30: =CC30/CC$9*100 -> 21.428571 | CF30: 1 | CR30: =SUM(CE30:CQ30) -> 1 | CS30: =CR30/CR$9*100 -> 50 | DL30: =SUM(CT30:DK30) -> 0 | DM30: =DL30/DL$9*100 -> #DIV/0!
A31: 22 | B31: 0827CY241022 | C31: CHIRAYU PATIDAR | D31: =SUM(L31+AH31+BE31+CC31+CR31) -> 19 | E31: =(D31)/D$9*100 -> 46.341463 | F31: =IF(E31<50,E31, " ") -> 46.341463 | G31: =IF(E31<30,E31, " ") | L31: =SUM(H31:K31) -> 0 | M31: =L31/L$9*100 -> 0 | V31: 1 | W31: 1 | X31: 1 | Z31: 1 | AA31: 1 | AB31: 1 | AD31: 1 | AE31: 1 | AF31: 1 | AH31: =SUM(N31:AG31) -> 9 | AI31: =AH31/AH$9*100 -> 81.818182 | AK31: 1 | AL31: 1 | AO31: 1 | AP31: 1 | BE31: =SUM(AJ31:BD31) -> 4 | BF31: =BE31/BE$9*100 -> 33.333333 | BI31: 1 | BM31: 1 | BN31: 1 | BQ31: 1 | BS31: 1 | BT31: 1 | CC31: =SUM(BG31:CB31) -> 6 | CD31: =CC31/CC$9*100 -> 42.857143 | CR31: =SUM(CE31:CQ31) -> 0 | CS31: =CR31/CR$9*100 -> 0 | DL31: =SUM(CT31:DK31) -> 0 | DM31: =DL31/DL$9*100 -> #DIV/0!
A32: 23 | B32: 0827CY241023 | C32: DARSH MUNDRA | D32: =SUM(L32+AH32+BE32+CC32+CR32) -> 27 | E32: =(D32)/D$9*100 -> 65.853659 | F32: =IF(E32<50,E32, " ") | G32: =IF(E32<30,E32, " ") | L32: =SUM(H32:K32) -> 0 | M32: =L32/L$9*100 -> 0 | V32: 1 | W32: 1 | X32: 1 | Y32: 1 | Z32: 1 | AA32: 1 | AB32: 1 | AE32: 1 | AF32: 1 | AH32: =SUM(N32:AG32) -> 9 | AI32: =AH32/AH$9*100 -> 81.818182 | AJ32: 1 | AK32: 1 | AL32: 1 | AN32: 1 | AO32: 1 | AR32: 1 | AT32: 1 | AU32: 1 | BE32: =SUM(AJ32:BD32) -> 8 | BF32: =BE32/BE$9*100 -> 66.666667 | BG32: 1 | BH32: 1 | BI32: 1 | BJ32: 1 | BL32: 1 | BM32: 1 | BQ32: 1 | BR32: 1 | BS32: 1 | CC32: =SUM(BG32:CB32) -> 9 | CD32: =CC32/CC$9*100 -> 64.285714 | CF32: 1 | CR32: =SUM(CE32:CQ32) -> 1 | CS32: =CR32/CR$9*100 -> 50 | DL32: =SUM(CT32:DK32) -> 0 | DM32: =DL32/DL$9*100 -> #DIV/0!
A33: 24 | B33: 0827CY241024 | C33: DIKSHARTH HARDIYA | D33: =SUM(L33+AH33+BE33+CC33+CR33) -> 1 | E33: =(D33)/D$9*100 -> 2.4390244 | F33: =IF(E33<50,E33, " ") -> 2.4390244 | G33: =IF(E33<30,E33, " ") -> 2.4390244 | L33: =SUM(H33:K33) -> 0 | M33: =L33/L$9*100 -> 0 | Z33: 1 | AH33: =SUM(N33:AG33) -> 1 | AI33: =AH33/AH$9*100 -> 9.0909091 | BE33: =SUM(AJ33:BD33) -> 0 | BF33: =BE33/BE$9*100 -> 0 | CC33: =SUM(BG33:CB33) -> 0 | CD33: =CC33/CC$9*100 -> 0 | CR33: =SUM(CE33:CQ33) -> 0 | CS33: =CR33/CR$9*100 -> 0 | DL33: =SUM(CT33:DK33) -> 0 | DM33: =DL33/DL$9*100 -> #DIV/0!
A34: 25 | B34: 0827CY241025 | C34: FARAJ AHMED ANSARI | D34: =SUM(L34+AH34+BE34+CC34+CR34) -> 4 | E34: =(D34)/D$9*100 -> 9.7560976 | F34: =IF(E34<50,E34, " ") -> 9.7560976 | G34: =IF(E34<30,E34, " ") -> 9.7560976 | L34: =SUM(H34:K34) -> 0 | M34: =L34/L$9*100 -> 0 | V34: 1 | Z34: 1 | AE34: 1 | AH34: =SUM(N34:AG34) -> 3 | AI34: =AH34/AH$9*100 -> 27.272727 | AK34: 1 | BE34: =SUM(AJ34:BD34) -> 1 | BF34: =BE34/BE$9*100 -> 8.3333333 | CC34: =SUM(BG34:CB34) -> 0 | CD34: =CC34/CC$9*100 -> 0 | CR34: =SUM(CE34:CQ34) -> 0 | CS34: =CR34/CR$9*100 -> 0 | DL34: =SUM(CT34:DK34) -> 0 | DM34: =DL34/DL$9*100 -> #DIV/0!
A35: 26 | B35: 0827CY241026 | C35: HARSH BATHRI | D35: =SUM(L35+AH35+BE35+CC35+CR35) -> 20 | E35: =(D35)/D$9*100 -> 48.780488 | F35: =IF(E35<50,E35, " ") -> 48.780488 | G35: =IF(E35<30,E35, " ") | L35: =SUM(H35:K35) -> 0 | M35: =L35/L$9*100 -> 0 | V35: 1 | W35: 1 | X35: 1 | Y35: 1 | Z35: 1 | AA35: 1 | AH35: =SUM(N35:AG35) -> 6 | AI35: =AH35/AH$9*100 -> 54.545455 | AK35: 1 | AL35: 1 | AN35: 1 | AO35: 1 | AT35: 1 | AU35: 1 | BE35: =SUM(AJ35:BD35) -> 6 | BF35: =BE35/BE$9*100 -> 50 | BG35: 1 | BI35: 1 | BJ35: 1 | BL35: 1 | BM35: 1 | BP35: 1 | BQ35: 1 | CC35: =SUM(BG35:CB35) -> 7 | CD35: =CC35/CC$9*100 -> 50 | CF35: 1 | CR35: =SUM(CE35:CQ35) -> 1 | CS35: =CR35/CR$9*100 -> 50 | DL35: =SUM(CT35:DK35) -> 0 | DM35: =DL35/DL$9*100 -> #DIV/0!
A36: 27 | B36: 0827CY241027 | C36: HARSH PALIWAL | D36: =SUM(L36+AH36+BE36+CC36+CR36) -> 8 | E36: =(D36)/D$9*100 -> 19.512195 | F36: =IF(E36<50,E36, " ") -> 19.512195 | G36: =IF(E36<30,E36, " ") -> 19.512195 | L36: =SUM(H36:K36) -> 0 | M36: =L36/L$9*100 -> 0 | AH36: =SUM(N36:AG36) -> 0 | AI36: =AH36/AH$9*100 -> 0 | AO36: 1 | AP36: 1 | AS36: 1 | BE36: =SUM(AJ36:BD36) -> 3 | BF36: =BE36/BE$9*100 -> 25 | BI36: 1 | BJ36: 1 | BL36: 1 | BM36: 1 | BT36: 1 | CC36: =SUM(BG36:CB36) -> 5 | CD36: =CC36/CC$9*100 -> 35.714286 | CR36: =SUM(CE36:CQ36) -> 0 | CS36: =CR36/CR$9*100 -> 0 | DL36: =SUM(CT36:DK36) -> 0 | DM36: =DL36/DL$9*100 -> #DIV/0!
A37: 28 | B37: 0827CY241028 | C37: HEMANT KUMAR PATIL | D37: =SUM(L37+AH37+BE37+CC37+CR37) -> 24 | E37: =(D37)/D$9*100 -> 58.536585 | F37: =IF(E37<50,E37, " ") | G37: =IF(E37<30,E37, " ") | L37: =SUM(H37:K37) -> 0 | M37: =L37/L$9*100 -> 0 | V37: 1 | W37: 1 | X37: 1 | Z37: 1 | AA37: 1 | AB37: 1 | AD37: 1 | AE37: 1 | AF37: 1 | AH37: =SUM(N37:AG37) -> 9 | AI37: =AH37/AH$9*100 -> 81.818182 | AK37: 1 | AL37: 1 | AN37: 1 | AO37: 1 | AR37: 1 | AU37: 1 | BE37: =SUM(AJ37:BD37) -> 6 | BF37: =BE37/BE$9*100 -> 50 | BG37: 1 | BI37: 1 | BL37: 1 | BM37: 1 | BN37: 1 | BP37: 1 | BR37: 1 | BT37: 1 | CC37: =SUM(BG37:CB37) -> 8 | CD37: =CC37/CC$9*100 -> 57.142857 | CF37: 1 | CR37: =SUM(CE37:CQ37) -> 1 | CS37: =CR37/CR$9*100 -> 50 | DL37: =SUM(CT37:DK37) -> 0 | DM37: =DL37/DL$9*100 -> #DIV/0!
A38: 29 | B38: 0827CY241029 | C38: JANHAVI SINGH | D38: =SUM(L38+AH38+BE38+CC38+CR38) -> 16 | E38: =(D38)/D$9*100 -> 39.02439 | F38: =IF(E38<50,E38, " ") -> 39.02439 | G38: =IF(E38<30,E38, " ") | L38: =SUM(H38:K38) -> 0 | M38: =L38/L$9*100 -> 0 | W38: 1 | X38: 1 | Y38: 1 | AD38: 1 | AH38: =SUM(N38:AG38) -> 4 | AI38: =AH38/AH$9*100 -> 36.363636 | AK38: 1 | AN38: 1 | AO38: 1 | BE38: =SUM(AJ38:BD38) -> 3 | BF38: =BE38/BE$9*100 -> 25 | BG38: 1 | BH38: 1 | BJ38: 1 | BN38: 1 | BO38: 1 | BP38: 1 | BQ38: 1 | BR38: 1 | CC38: =SUM(BG38:CB38) -> 8 | CD38: =CC38/CC$9*100 -> 57.142857 | CE38: 1 | CR38: =SUM(CE38:CQ38) -> 1 | CS38: =CR38/CR$9*100 -> 50 | DL38: =SUM(CT38:DK38) -> 0 | DM38: =DL38/DL$9*100 -> #DIV/0!
A39: 30 | B39: 0827CY241030 | C39: JATIN PAL | D39: =SUM(L39+AH39+BE39+CC39+CR39) -> 12 | E39: =(D39)/D$9*100 -> 29.268293 | F39: =IF(E39<50,E39, " ") -> 29.268293 | G39: =IF(E39<30,E39, " ") -> 29.268293 | L39: =SUM(H39:K39) -> 0 | M39: =L39/L$9*100 -> 0 | V39: 1 | Z39: 1 | AB39: 1 | AC39: 1 | AD39: 1 | AE39: 1 | AH39: =SUM(N39:AG39) -> 6 | AI39: =AH39/AH$9*100 -> 54.545455 | AK39: 1 | AP39: 1 | AQ39: 1 | BE39: =SUM(AJ39:BD39) -> 3 | BF39: =BE39/BE$9*100 -> 25 | BI39: 1 | BJ39: 1 | BS39: 1 | CC39: =SUM(BG39:CB39) -> 3 | CD39: =CC39/CC$9*100 -> 21.428571 | CR39: =SUM(CE39:CQ39) -> 0 | CS39: =CR39/CR$9*100 -> 0 | DL39: =SUM(CT39:DK39) -> 0 | DM39: =DL39/DL$9*100 -> #DIV/0!
A40: 31 | B40: 0827CY241031 | C40: JAYSHREE CHOUHAN | D40: =SUM(L40+AH40+BE40+CC40+CR40) -> 16 | E40: =(D40)/D$9*100 -> 39.02439 | F40: =IF(E40<50,E40, " ") -> 39.02439 | G40: =IF(E40<30,E40, " ") | L40: =SUM(H40:K40) -> 0 | M40: =L40/L$9*100 -> 0 | AB40: 1 | AC40: 1 | AD40: 1 | AE40: 1 | AF40: 1 | AH40: =SUM(N40:AG40) -> 5 | AI40: =AH40/AH$9*100 -> 45.454545 | AJ40: 1 | AM40: 1 | AN40: 1 | AO40: 1 | AR40: 1 | AT40: 1 | BE40: =SUM(AJ40:BD40) -> 6 | BF40: =BE40/BE$9*100 -> 50 | BG40: 1 | BJ40: 1 | BM40: 1 | BO40: 1 | CC40: =SUM(BG40:CB40) -> 4 | CD40: =CC40/CC$9*100 -> 28.571429 | CE40: 1 | CR40: =SUM(CE40:CQ40) -> 1 | CS40: =CR40/CR$9*100 -> 50 | DL40: =SUM(CT40:DK40) -> 0 | DM40: =DL40/DL$9*100 -> #DIV/0!
...

Sheet 402
A1: CY-402
A2: Faculty Name: | C2: Prof. Nidhi Nigam
A3: Subject Name : | C3: Fundamental of Cyber Security
A4: Subject Code : | C4: CY-402
A5: Start Date | C5: 46104
A6: End Date | Y6: MG | AG6: MG | AN6: AAG | AU6: SG | BC6: SG | BO6: Vacation
H7: 1 | I7: 2 | K7: 3 | L7: 4 | O7: 1 | P7: 2 | Q7: 3 | R7: 4 | S7: 5 | T7: 6 | U7: 7 | V7: 8 | W7: 9 | X7: 10 | Y7: 11 | Z7: 12 | AA7: 13 | AB7: 14 | AC7: 15 | AD7: 16 | AE7: 17 | AF7: 18 | AG7: 19 | AH7: 20 | AI7: 21 | AL7: 1 | AM7: 2 | AN7: 3 | AO7: 4 | AP7: 5 | AQ7: 6 | AR7: 7 | AS7: 8 | AT7: 9 | AU7: 10 | AV7: 11 | AW7: 12 | AX7: 13 | AY7: 14 | AZ7: 15 | BA7: 16 | BB7: 17 | BC7: 18 | BD7: 19 | BE7: 20 | BF7: 21 | BI7: 1 | BJ7: 2 | BK7: 3 | BL7: 4 | BM7: 5 | BN7: 6 | BO7: 7 | BP7: 8 | BQ7: 9 | BR7: 10 | BS7: 11 | BT7: 12 | BU7: 13 | BV7: 14 | BW7: 15 | BX7: 16 | BY7: 17 | BZ7: 18 | CA7: 19 | CB7: 20 | CC7: 21 | CD7: 22 | CE7: 23 | CF7: 24 | CG7: 25 | CH7: 26 | CI7: 27 | CL7: 1 | CM7: 2 | CN7: 3 | CO7: 4 | CP7: 5 | CQ7: 6 | CR7: 7 | CS7: 8 | CT7: 9 | CU7: 10 | CV7: 11
D8: Total Class | E8: OverAll Att. % | F8: Att. 50% | G8: Att. 30% | H8: 46104 | I8: 46105 | J8: 46106 | K8: 46107 | L8: 46111 | M8: MAR CLASS | N8: MAR % | O8: 46113 | P8: 46114 | Q8: 46115 | R8: 46118 | S8: 46119 | T8: 46120 | U8: 46121 | V8: 46122 | W8: 46125 | X8: 46127 | Y8: 46128 | Z8: 46129 | AA8: 46132 | AB8: 46133 | AC8: 46134 | AD8: 46135 | AE8: 46136 | AF8: 46139 | AG8: 46140 | AH8: 46141 | AI8: 46142 | AJ8: APRIL CLASS | AK8: APRIL % | AL8: 46143 | AM8: 46146 | AN8: 46147 | AO8: 46148 | AP8: 46149 | AQ8: 46150 | AR8: 46153 | AS8: 46154 | AT8: 46155 | AU8: 46155 | AV8: 46157 | AW8: 46160 | AX8: 46161 | AY8: 46162 | AZ8: 46163 | BA8: 46164 | BB8: 46167 | BC8: 46168 | BD8: 46169 | BE8: 46170 | BF8: 46171 | BG8: MAY CLASS | BH8: MAY % | BI8: 46174 | BJ8: 46175 | BK8: 46176 | BL8: 46177 | BM8: 46178 | BN8: 46181 | BO8: 46182 | BP8: 46183 | BQ8: 46184 | BR8: 46185 | BS8: 46188 | BT8: 46189 | BU8: 46190 | BV8: 46191 | BW8: 46192 | BX8: 46195 | BY8: 46195 | BZ8: 46196 | CA8: 46197 | CB8: 46197 | CC8: 46198 | CD8: 46198 | CE8: 46199 | CF8: 46199 | CG8: 46202 | CH8: 46202 | CI8: 46203 | CJ8: JUNE CLASS | CK8: JUNE % | CL8: 46204 | CM8: 46204 | CN8: 46206 | CO8: 46206 | CP8: 46208 | CQ8: 46209 | CR8: 46210 | CS8: 46211 | CT8: 46212 | CU8: 46213 | CV8: 46214 | CW8: 46215 | CX8: 46216 | CY8: JULY CLASS | CZ8: JULY% | DS8: JAN CLASS | DT8: JAN%
A9: s.no. | B9: Enrollment NO. | C9: Student Name | D9: =SUM(M9+AJ9+BG9+CJ9+CY9) -> 45 | H9: =SUM(H10:H89) -> 9 | I9: =SUM(I10:I89) -> 0 | J9: =SUM(J10:J89) -> 3 | K9: =SUM(K10:K89) -> 0 | L9: =SUM(L10:L89) -> 0 | M9: =COUNTIF(H9:L9,">0") -> 2 | N9: =COUNTIF(H9:L9,">0") -> 2 | O9: =SUM(O10:O89) -> 0 | P9: =SUM(P10:P89) -> 0 | Q9: =SUM(Q10:Q89) -> 0 | R9: =SUM(R10:R89) -> 0 | S9: =SUM(S10:S89) -> 0 | T9: =SUM(T10:T89) -> 0 | U9: =SUM(U10:U89) -> 0 | V9: =SUM(V10:V89) -> 0 | ... AI9: =SUM(AI10:AI89) -> 33 | AJ9: =COUNTIF(O9:AI9,">0") -> 13 | AK9: =SUM(M9+AJ9) -> 15 | AL9: =SUM(AL10:AL89) -> 33 | AM9: =SUM(AM10:AM89) -> 43 | AN9: =SUM(AN10:AN89) -> 43 | AO9: =SUM(AO10:AO89) -> 42 | AP9: =SUM(AP10:AP89) -> 42 | AQ9: =SUM(AQ10:AQ89) -> 19 | AR9: =SUM(AR10:AR89) -> 37 | AS9: =SUM(AS10:AS89) -> 0 | ... BF9: =SUM(BF10:BF89) -> 22 | BG9: =COUNTIF(AL9:BF9,">0") -> 14 | BH9: =SUM(AK9+BG9) -> 29 | BI9: =SUM(BI10:BI69) -> 0 | BJ9: =SUM(BJ10:BJ69) -> 0 | BK9: =SUM(BK10:BK69) -> 0 | BL9: =SUM(BL10:BL69) -> 17 | BM9: =SUM(BM10:BM69) -> 0 | BN9: =SUM(BN10:BN69) -> 0 | BO9: =SUM(BO10:BO69) -> 0 | BP9: =SUM(BP10:BP69) -> 0 | BR9: =SUM(BR10:BR69) -> 0 | BS9: =SUM(BS10:BS69) -> 0 | BT9: =SUM(BT10:BT69) -> 0 | BU9: =SUM(BU10:BU69) -> 0 | BV9: =SUM(BV10:BV69) -> 0 | BW9: =SUM(BW10:BW69) -> 0 | BX9: =SUM(BX10:BX69) -> 18 | BY9: =SUM(BY10:BY69) -> 18 | ... CI9: =SUM(CI10:CI69) -> 0 | CJ9: =COUNTIF(BI9:CI9,">0") -> 11 | CK9: =SUM(BH9+CJ9) -> 40 | CL9: =SUM(CL10:CL89) -> 32 | CM9: =SUM(CM10:CM89) -> 32 | CN9: =SUM(CN10:CN89) -> 42 | CO9: =SUM(CO10:CO89) -> 42 | CP9: =SUM(CP10:CP89) -> 0 | CQ9: =SUM(CQ10:CQ89) -> 44 | CR9: =SUM(CR10:CR89) -> 0 | CS9: =SUM(CS10:CS89) -> 0 | ... CX9: =SUM(CX10:CX89) -> 0 | CY9: =COUNTIF(CL9:CX9,">0") -> 5 | CZ9: =SUM(CK9+CY9) -> 45 | DA9: =SUM(DA10:DA89) -> 0 | DB9: =SUM(DB10:DB89) -> 0 | DC9: =SUM(DC10:DC89) -> 0 | DD9: =SUM(DD10:DD89) -> 0 | DE9: =SUM(DE10:DE89) -> 0 | DF9: =SUM(DF10:DF89) -> 0 | DG9: =SUM(DG10:DG89) -> 0 | DH9: =SUM(DH10:DH89) -> 0 | ... DR9: =SUM(DR10:DR89) -> 0 | DS9: =COUNTIF(DA9:DR9,">0") -> 0 | DT9: =SUM(DE9+DS9) -> 0
A10: 1 | B10: 0827CY241001 | C10: AASTHA RATHORE | D10: =SUM(M10+AJ10+BG10+CJ10+CY10) -> 37 | E10: =(D10)/D$9*100 -> 82.222222 | F10: =IF(E10<50,E10, " ") | G10: =IF(E10<30,E10, " ") | H10: 1 | M10: =SUM(H10:L10) -> 1 | N10: =M10/M$9*100 -> 50 | W10: 1 | X10: 1 | Y10: 1 | Z10: 1 | AA10: 1 | AB10: 1 | AC10: 1 | AD10: 1 | AE10: 1 | AF10: 1 | AH10: 1 | AI10: 1 | AJ10: =SUM(O10:AI10) -> 12 | AK10: =AJ10/AJ$9*100 -> 92.307692 | AL10: 1 | AN10: 1 | AO10: 1 | AP10: 1 | AQ10: 1 | AR10: 1 | AT10: 1 | AU10: 1 | BB10: 1 | BC10: 1 | BD10: 1 | BE10: 1 | BF10: 1 | BG10: =SUM(AL10:BF10) -> 13 | BH10: =BG10/BG$9*100 -> 92.857143 | BX10: 1 | BY10: 1 | CC10: 1 | CD10: 1 | CG10: 1 | CH10: 1 | CJ10: =SUM(BI10:CI10) -> 6 | CK10: =CJ10/CJ$9*100 -> 54.545455 | CL10: 1 | CM10: 1 | CN10: 1 | CO10: 1 | CQ10: 1 | CY10: =SUM(CL10:CX10) -> 5 | CZ10: =CY10/CY$9*100 -> 100 | DS10: =SUM(DA10:DR10) -> 0 | DT10: =DS10/DS$9*100 -> #DIV/0!
A11: 2 | B11: 0827CY241002 | C11: ABEER JOSHI | D11: =SUM(M11+AJ11+BG11+CJ11+CY11) -> 22 | E11: =(D11)/D$9*100 -> 48.888889 | F11: =IF(E11<50,E11, " ") -> 48.888889 | G11: =IF(E11<30,E11, " ") | M11: =SUM(H11:L11) -> 0 | N11: =M11/M$9*100 -> 0 | X11: 1 | Z11: 1 | AB11: 1 | AC11: 1 | AG11: 1 | AI11: 1 | AJ11: =SUM(O11:AI11) -> 6 | AK11: =AJ11/AJ$9*100 -> 46.153846 | AM11: 1 | AR11: 1 | BB11: 1 | BD11: 1 | BE11: 1 | BG11: =SUM(AL11:BF11) -> 5 | BH11: =BG11/BG$9*100 -> 35.714286 | BX11: 1 | BY11: 1 | CA11: 1 | CB11: 1 | CG11: 1 | CH11: 1 | CJ11: =SUM(BI11:CI11) -> 6 | CK11: =CJ11/CJ$9*100 -> 54.545455 | CL11: 1 | CM11: 1 | CN11: 1 | CO11: 1 | CQ11: 1 | CY11: =SUM(CL11:CX11) -> 5 | CZ11: =CY11/CY$9*100 -> 100 | DS11: =SUM(DA11:DR11) -> 0 | DT11: =DS11/DS$9*100 -> #DIV/0!
A12: 3 | B12: 0827CY241003 | C12: ABHIJEET SINGH | D12: =SUM(M12+AJ12+BG12+CJ12+CY12) -> 17 | E12: =(D12)/D$9*100 -> 37.777778 | F12: =IF(E12<50,E12, " ") -> 37.777778 | G12: =IF(E12<30,E12, " ") | M12: =SUM(H12:L12) -> 0 | N12: =M12/M$9*100 -> 0 | X12: 1 | AC12: 1 | AD12: 1 | AE12: 1 | AG12: 1 | AJ12: =SUM(O12:AI12) -> 5 | AK12: =AJ12/AJ$9*100 -> 38.461538 | AM12: 1 | AN12: 1 | AO12: 1 | AP12: 1 | AR12: 1 | AT12: 1 | AU12: 1 | BE12: 1 | BG12: =SUM(AL12:BF12) -> 8 | BH12: =BG12/BG$9*100 -> 57.142857 | BL12: 1 | CG12: 1 | CH12: 1 | CJ12: =SUM(BI12:CI12) -> 3 | CK12: =CJ12/CJ$9*100 -> 27.272727 | CQ12: 1 | CY12: =SUM(CL12:CX12) -> 1 | CZ12: =CY12/CY$9*100 -> 20 | DS12: =SUM(DA12:DR12) -> 0 | DT12: =DS12/DS$9*100 -> #DIV/0!
A13: 4 | B13: 0827CY241004 | C13: ADITI CHOUDHARY | D13: =SUM(M13+AJ13+BG13+CJ13+CY13) -> 22 | E13: =(D13)/D$9*100 -> 48.888889 | F13: =IF(E13<50,E13, " ") -> 48.888889 | G13: =IF(E13<30,E13, " ") | M13: =SUM(H13:L13) -> 0 | N13: =M13/M$9*100 -> 0 | W13: 1 | X13: 1 | Y13: 1 | Z13: 1 | AA13: 1 | AB13: 1 | AH13: 1 | AI13: 1 | AJ13: =SUM(O13:AI13) -> 8 | AK13: =AJ13/AJ$9*100 -> 61.538462 | AM13: 1 | AN13: 1 | AP13: 1 | AQ13: 1 | AT13: 1 | BF13: 1 | BG13: =SUM(AL13:BF13) -> 6 | BH13: =BG13/BG$9*100 -> 42.857143 | BL13: 1 | CA13: 1 | CB13: 1 | CE13: 1 | CF13: 1 | CG13: 1 | CH13: 1 | CJ13: =SUM(BI13:CI13) -> 7 | CK13: =CJ13/CJ$9*100 -> 63.636364 | CQ13: 1 | CY13: =SUM(CL13:CX13) -> 1 | CZ13: =CY13/CY$9*100 -> 20 | DS13: =SUM(DA13:DR13) -> 0 | DT13: =DS13/DS$9*100 -> #DIV/0!
A14: 5 | B14: 0827CY241005 | C14: ADITYA JAUNJAL | D14: =SUM(M14+AJ14+BG14+CJ14+CY14) -> 36 | E14: =(D14)/D$9*100 -> 80 | F14: =IF(E14<50,E14, " ") | G14: =IF(E14<30,E14, " ") | M14: =SUM(H14:L14) -> 0 | N14: =M14/M$9*100 -> 0 | W14: 1 | X14: 1 | Y14: 1 | Z14: 1 | AA14: 1 | AB14: 1 | AC14: 1 | AD14: 1 | AE14: 1 | AF14: 1 | AG14: 1 | AH14: 1 | AI14: 1 | AJ14: =SUM(O14:AI14) -> 13 | AK14: =AJ14/AJ$9*100 -> 100 | AL14: 1 | AM14: 1 | AN14: 1 | AO14: 1 | AP14: 1 | AR14: 1 | AT14: 1 | AU14: 1 | BB14: 1 | BC14: 1 | BG14: =SUM(AL14:BF14) -> 10 | BH14: =BG14/BG$9*100 -> 71.428571 | BX14: 1 | BY14: 1 | CA14: 1 | CB14: 1 | CC14: 1 | CD14: 1 | CG14: 1 | CH14: 1 | CJ14: =SUM(BI14:CI14) -> 8 | CK14: =CJ14/CJ$9*100 -> 72.727273 | CL14: 1 | CM14: 1 | CN14: 1 | CO14: 1 | CQ14: 1 | CY14: =SUM(CL14:CX14) -> 5 | CZ14: =CY14/CY$9*100 -> 100 | DS14: =SUM(DA14:DR14) -> 0 | DT14: =DS14/DS$9*100 -> #DIV/0!
A15: 6 | B15: 0827CY241006 | C15: AMAY NAMDEV | D15: =SUM(M15+AJ15+BG15+CJ15+CY15) -> 19 | E15: =(D15)/D$9*100 -> 42.222222 | F15: =IF(E15<50,E15, " ") -> 42.222222 | G15: =IF(E15<30,E15, " ") | M15: =SUM(H15:L15) -> 0 | N15: =M15/M$9*100 -> 0 | X15: 1 | Z15: 1 | AB15: 1 | AC15: 1 | AE15: 1 | AG15: 1 | AJ15: =SUM(O15:AI15) -> 6 | AK15: =AJ15/AJ$9*100 -> 46.153846 | AM15: 1 | AN15: 1 | AP15: 1 | BB15: 1 | BE15: 1 | BG15: =SUM(AL15:BF15) -> 5 | BH15: =BG15/BG$9*100 -> 35.714286 | BL15: 1 | CC15: 1 | CD15: 1 | CJ15: =SUM(BI15:CI15) -> 3 | CK15: =CJ15/CJ$9*100 -> 27.272727 | CL15: 1 | CM15: 1 | CN15: 1 | CO15: 1 | CQ15: 1 | CY15: =SUM(CL15:CX15) -> 5 | CZ15: =CY15/CY$9*100 -> 100 | DS15: =SUM(DA15:DR15) -> 0 | DT15: =DS15/DS$9*100 -> #DIV/0!
A16: 7 | B16: 0827CY241007 | C16: AMISHA SALVI | D16: =SUM(M16+AJ16+BG16+CJ16+CY16) -> 1 | E16: =(D16)/D$9*100 -> 2.2222222 | F16: =IF(E16<50,E16, " ") -> 2.2222222 | G16: =IF(E16<30,E16, " ") -> 2.2222222 | H16: 1 | M16: =SUM(H16:L16) -> 1 | N16: =M16/M$9*100 -> 50 | AJ16: =SUM(O16:AI16) -> 0 | AK16: =AJ16/AJ$9*100 -> 0 | BG16: =SUM(AL16:BF16) -> 0 | BH16: =BG16/BG$9*100 -> 0 | CJ16: =SUM(BI16:CI16) -> 0 | CK16: =CJ16/CJ$9*100 -> 0 | CY16: =SUM(CL16:CX16) -> 0 | CZ16: =CY16/CY$9*100 -> 0 | DS16: =SUM(DA16:DR16) -> 0 | DT16: =DS16/DS$9*100 -> #DIV/0!
A17: 8 | B17: 0827CY241008 | C17: AMIT GANGWAL | D17: =SUM(M17+AJ17+BG17+CJ17+CY17) -> 0 | E17: =(D17)/D$9*100 -> 0 | F17: =IF(E17<50,E17, " ") -> 0 | G17: =IF(E17<30,E17, " ") -> 0 | M17: =SUM(H17:L17) -> 0 | N17: =M17/M$9*100 -> 0 | AJ17: =SUM(O17:AI17) -> 0 | AK17: =AJ17/AJ$9*100 -> 0 | BG17: =SUM(AL17:BF17) -> 0 | BH17: =BG17/BG$9*100 -> 0 | CJ17: =SUM(BI17:CI17) -> 0 | CK17: =CJ17/CJ$9*100 -> 0 | CY17: =SUM(CL17:CX17) -> 0 | CZ17: =CY17/CY$9*100 -> 0 | DS17: =SUM(DA17:DR17) -> 0 | DT17: =DS17/DS$9*100 -> #DIV/0!
A18: 9 | B18: 0827CY241009 | C18: ANANYA SHARMA | D18: =SUM(M18+AJ18+BG18+CJ18+CY18) -> 30 | E18: =(D18)/D$9*100 -> 66.666667 | F18: =IF(E18<50,E18, " ") | G18: =IF(E18<30,E18, " ") | M18: =SUM(H18:L18) -> 0 | N18: =M18/M$9*100 -> 0 | W18: 1 | X18: 1 | AA18: 1 | AB18: 1 | AC18: 1 | AF18: 1 | AG18: 1 | AH18: 1 | AI18: 1 | AJ18: =SUM(O18:AI18) -> 9 | AK18: =AJ18/AJ$9*100 -> 69.230769 | AL18: 1 | AM18: 1 | AN18: 1 | AO18: 1 | AP18: 1 | AQ18: 1 | AR18: 1 | BB18: 1 | BC18: 1 | BD18: 1 | BF18: 1 | BG18: =SUM(AL18:BF18) -> 11 | BH18: =BG18/BG$9*100 -> 78.571429 | BL18: 1 | BX18: 1 | BY18: 1 | CA18: 1 | CB18: 1 | CE18: 1 | CF18: 1 | CJ18: =SUM(BI18:CI18) -> 7 | CK18: =CJ18/CJ$9*100 -> 63.636364 | CL18: 1 | CM18: 1 | CQ18: 1 | CY18: =SUM(CL18:CX18) -> 3 | CZ18: =CY18/CY$9*100 -> 60 | DS18: =SUM(DA18:DR18) -> 0 | DT18: =DS18/DS$9*100 -> #DIV/0!
A19: 10 | B19: 0827CY241010 | C19: ANIKET PATEL | D19: =SUM(M19+AJ19+BG19+CJ19+CY19) -> 0 | E19: =(D19)/D$9*100 -> 0 | F19: =IF(E19<50,E19, " ") -> 0 | G19: =IF(E19<30,E19, " ") -> 0 | M19: =SUM(H19:L19) -> 0 | N19: =M19/M$9*100 -> 0 | AJ19: =SUM(O19:AI19) -> 0 | AK19: =AJ19/AJ$9*100 -> 0 | BG19: =SUM(AL19:BF19) -> 0 | BH19: =BG19/BG$9*100 -> 0 | CJ19: =SUM(BI19:CI19) -> 0 | CK19: =CJ19/CJ$9*100 -> 0 | CY19: =SUM(CL19:CX19) -> 0 | CZ19: =CY19/CY$9*100 -> 0 | DS19: =SUM(DA19:DR19) -> 0 | DT19: =DS19/DS$9*100 -> #DIV/0!
A20: 11 | B20: 0827CY241011 | C20: ANISHA BAIRAGI | D20: =SUM(M20+AJ20+BG20+CJ20+CY20) -> 43 | E20: =(D20)/D$9*100 -> 95.555556 | F20: =IF(E20<50,E20, " ") | G20: =IF(E20<30,E20, " ") | H20: 1 | M20: =SUM(H20:L20) -> 1 | N20: =M20/M$9*100 -> 50 | W20: 1 | X20: 1 | Y20: 1 | Z20: 1 | AA20: 1 | AB20: 1 | AC20: 1 | AD20: 1 | AE20: 1 | AF20: 1 | AG20: 1 | AH20: 1 | AI20: 1 | AJ20: =SUM(O20:AI20) -> 13 | AK20: =AJ20/AJ$9*100 -> 100 | AL20: 1 | AM20: 1 | AN20: 1 | AO20: 1 | AP20: 1 | AQ20: 1 | AR20: 1 | AT20: 1 | AU20: 1 | BB20: 1 | BC20: 1 | BD20: 1 | BF20: 1 | BG20: =SUM(AL20:BF20) -> 13 | BH20: =BG20/BG$9*100 -> 92.857143 | BL20: 1 | BX20: 1 | BY20: 1 | CA20: 1 | CB20: 1 | CC20: 1 | CD20: 1 | CE20: 1 | CF20: 1 | CG20: 1 | CH20: 1 | CJ20: =SUM(BI20:CI20) -> 11 | CK20: =CJ20/CJ$9*100 -> 100 | CL20: 1 | CM20: 1 | CN20: 1 | CO20: 1 | CQ20: 1 | CY20: =SUM(CL20:CX20) -> 5 | CZ20: =CY20/CY$9*100 -> 100 | DS20: =SUM(DA20:DR20) -> 0 | DT20: =DS20/DS$9*100 -> #DIV/0!
A21: 12 | B21: 0827CY241012 | C21: ANKUSH BAMOTRIYA | D21: =SUM(M21+AJ21+BG21+CJ21+CY21) -> 2 | E21: =(D21)/D$9*100 -> 4.4444444 | F21: =IF(E21<50,E21, " ") -> 4.4444444 | G21: =IF(E21<30,E21, " ") -> 4.4444444 | M21: =SUM(H21:L21) -> 0 | N21: =M21/M$9*100 -> 0 | AJ21: =SUM(O21:AI21) -> 0 | AK21: =AJ21/AJ$9*100 -> 0 | BG21: =SUM(AL21:BF21) -> 0 | BH21: =BG21/BG$9*100 -> 0 | BX21: 1 | BY21: 1 | CJ21: =SUM(BI21:CI21) -> 2 | CK21: =CJ21/CJ$9*100 -> 18.181818 | CY21: =SUM(CL21:CX21) -> 0 | CZ21: =CY21/CY$9*100 -> 0 | DS21: =SUM(DA21:DR21) -> 0 | DT21: =DS21/DS$9*100 -> #DIV/0!
A22: 13 | B22: 0827CY241013 | C22: ANUSHKA SETHIYA | D22: =SUM(M22+AJ22+BG22+CJ22+CY22) -> 11 | E22: =(D22)/D$9*100 -> 24.444444 | F22: =IF(E22<50,E22, " ") -> 24.444444 | G22: =IF(E22<30,E22, " ") -> 24.444444 | M22: =SUM(H22:L22) -> 0 | N22: =M22/M$9*100 -> 0 | W22: 1 | X22: 1 | Y22: 1 | AA22: 1 | AB22: 1 | AC22: 1 | AD22: 1 | AG22: 1 | AI22: 1 | AJ22: =SUM(O22:AI22) -> 9 | AK22: =AJ22/AJ$9*100 -> 69.230769 | AO22: 1 | BB22: 1 | BG22: =SUM(AL22:BF22) -> 2 | BH22: =BG22/BG$9*100 -> 14.285714 | CJ22: =SUM(BI22:CI22) -> 0 | CK22: =CJ22/CJ$9*100 -> 0 | CY22: =SUM(CL22:CX22) -> 0 | CZ22: =CY22/CY$9*100 -> 0 | DS22: =SUM(DA22:DR22) -> 0 | DT22: =DS22/DS$9*100 -> #DIV/0!
A23: 14 | B23: 0827CY241014 | C23: APOORV JAIN | D23: =SUM(M23+AJ23+BG23+CJ23+CY23) -> 11 | E23: =(D23)/D$9*100 -> 24.444444 | F23: =IF(E23<50,E23, " ") -> 24.444444 | G23: =IF(E23<30,E23, " ") -> 24.444444 | M23: =SUM(H23:L23) -> 0 | N23: =M23/M$9*100 -> 0 | AB23: 1 | AG23: 1 | AH23: 1 | AJ23: =SUM(O23:AI23) -> 3 | AK23: =AJ23/AJ$9*100 -> 23.076923 | AO23: 1 | BC23: 1 | BD23: 1 | BF23: 1 | BG23: =SUM(AL23:BF23) -> 4 | BH23: =BG23/BG$9*100 -> 28.571429 | CA23: 1 | CB23: 1 | CE23: 1 | CF23: 1 | CJ23: =SUM(BI23:CI23) -> 4 | CK23: =CJ23/CJ$9*100 -> 36.363636 | CY23: =SUM(CL23:CX23) -> 0 | CZ23: =CY23/CY$9*100 -> 0 | DS23: =SUM(DA23:DR23) -> 0 | DT23: =DS23/DS$9*100 -> #DIV/0!
A24: 15 | B24: 0827CY241015 | C24: ASHMIT YADAV | D24: =SUM(M24+AJ24+BG24+CJ24+CY24) -> 22 | E24: =(D24)/D$9*100 -> 48.888889 | F24: =IF(E24<50,E24, " ") -> 48.888889 | G24: =IF(E24<30,E24, " ") | M24: =SUM(H24:L24) -> 0 | N24: =M24/M$9*100 -> 0 | X24: 1 | Z24: 1 | AC24: 1 | AD24: 1 | AE24: 1 | AJ24: =SUM(O24:AI24) -> 5 | AK24: =AJ24/AJ$9*100 -> 38.461538 | AN24: 1 | AO24: 1 | AP24: 1 | AR24: 1 | AT24: 1 | AU24: 1 | BG24: =SUM(AL24:BF24) -> 6 | BH24: =BG24/BG$9*100 -> 42.857143 | CA24: 1 | CB24: 1 | CC24: 1 | CD24: 1 | CG24: 1 | CH24: 1 | CJ24: =SUM(BI24:CI24) -> 6 | CK24: =CJ24/CJ$9*100 -> 54.545455 | CL24: 1 | CM24: 1 | CN24: 1 | CO24: 1 | CQ24: 1 | CY24: =SUM(CL24:CX24) -> 5 | CZ24: =CY24/CY$9*100 -> 100 | DS24: =SUM(DA24:DR24) -> 0 | DT24: =DS24/DS$9*100 -> #DIV/0!
A25: 16 | B25: 0827CY241016 | C25: ASHWIN PATEL | D25: =SUM(M25+AJ25+BG25+CJ25+CY25) -> 0 | E25: =(D25)/D$9*100 -> 0 | F25: =IF(E25<50,E25, " ") -> 0 | G25: =IF(E25<30,E25, " ") -> 0 | M25: =SUM(H25:L25) -> 0 | N25: =M25/M$9*100 -> 0 | AJ25: =SUM(O25:AI25) -> 0 | AK25: =AJ25/AJ$9*100 -> 0 | BG25: =SUM(AL25:BF25) -> 0 | BH25: =BG25/BG$9*100 -> 0 | CJ25: =SUM(BI25:CI25) -> 0 | CK25: =CJ25/CJ$9*100 -> 0 | CY25: =SUM(CL25:CX25) -> 0 | CZ25: =CY25/CY$9*100 -> 0 | DS25: =SUM(DA25:DR25) -> 0 | DT25: =DS25/DS$9*100 -> #DIV/0!
A26: 17 | B26: 0827CY241017 | C26: AYUSH SETHI | D26: =SUM(M26+AJ26+BG26+CJ26+CY26) -> 21 | E26: =(D26)/D$9*100 -> 46.666667 | F26: =IF(E26<50,E26, " ") -> 46.666667 | G26: =IF(E26<30,E26, " ") | M26: =SUM(H26:L26) -> 0 | N26: =M26/M$9*100 -> 0 | AI26: 1 | AJ26: =SUM(O26:AI26) -> 1 | AK26: =AJ26/AJ$9*100 -> 7.6923077 | AL26: 1 | AN26: 1 | AO26: 1 | AP26: 1 | AR26: 1 | BB26: 1 | BD26: 1 | BE26: 1 | BF26: 1 | BG26: =SUM(AL26:BF26) -> 9 | BH26: =BG26/BG$9*100 -> 64.285714 | BX26: 1 | BY26: 1 | CC26: 1 | CD26: 1 | CE26: 1 | CF26: 1 | CG26: 1 | CH26: 1 | CJ26: =SUM(BI26:CI26) -> 8 | CK26: =CJ26/CJ$9*100 -> 72.727273 | CN26: 1 | CO26: 1 | CQ26: 1 | CY26: =SUM(CL26:CX26) -> 3 | CZ26: =CY26/CY$9*100 -> 60 | DS26: =SUM(DA26:DR26) -> 0 | DT26: =DS26/DS$9*100 -> #DIV/0!
A27: 18 | B27: 0827CY241018 | C27: AYUSHI BAIRAGI | D27: =SUM(M27+AJ27+BG27+CJ27+CY27) -> 6 | E27: =(D27)/D$9*100 -> 13.333333 | F27: =IF(E27<50,E27, " ") -> 13.333333 | G27: =IF(E27<30,E27, " ") -> 13.333333 | H27: 1 | M27: =SUM(H27:L27) -> 1 | N27: =M27/M$9*100 -> 50 | X27: 1 | AJ27: =SUM(O27:AI27) -> 1 | AK27: =AJ27/AJ$9*100 -> 7.6923077 | AL27: 1 | AO27: 1 | BB27: 1 | BF27: 1 | BG27: =SUM(AL27:BF27) -> 4 | BH27: =BG27/BG$9*100 -> 28.571429 | CJ27: =SUM(BI27:CI27) -> 0 | CK27: =CJ27/CJ$9*100 -> 0 | CY27: =SUM(CL27:CX27) -> 0 | CZ27: =CY27/CY$9*100 -> 0 | DS27: =SUM(DA27:DR27) -> 0 | DT27: =DS27/DS$9*100 -> #DIV/0!
A28: 19 | B28: 0827CY241019 | C28: BHUMIKA AMIN | D28: =SUM(M28+AJ28+BG28+CJ28+CY28) -> 27 | E28: =(D28)/D$9*100 -> 60 | F28: =IF(E28<50,E28, " ") | G28: =IF(E28<30,E28, " ") | H28: 1 | M28: =SUM(H28:L28) -> 1 | N28: =M28/M$9*100 -> 50 | W28: 1 | X28: 1 | Z28: 1 | AB28: 1 | AC28: 1 | AD28: 1 | AE28: 1 | AJ28: =SUM(O28:AI28) -> 7 | AK28: =AJ28/AJ$9*100 -> 53.846154 | AL28: 1 | AM28: 1 | AN28: 1 | AO28: 1 | AP28: 1 | AQ28: 1 | AT28: 1 | AU28: 1 | BE28: 1 | BF28: 1 | BG28: =SUM(AL28:BF28) -> 10 | BH28: =BG28/BG$9*100 -> 71.428571 | CA28: 1 | CB28: 1 | CE28: 1 | CF28: 1 | CG28: 1 | CH28: 1 | CJ28: =SUM(BI28:CI28) -> 6 | CK28: =CJ28/CJ$9*100 -> 54.545455 | CL28: 1 | CM28: 1 | CQ28: 1 | CY28: =SUM(CL28:CX28) -> 3 | CZ28: =CY28/CY$9*100 -> 60 | DS28: =SUM(DA28:DR28) -> 0 | DT28: =DS28/DS$9*100 -> #DIV/0!
A29: 20 | B29: 0827CY241020 | C29: CHAITANYA PARKER | D29: =SUM(M29+AJ29+BG29+CJ29+CY29) -> 39 | E29: =(D29)/D$9*100 -> 86.666667 | F29: =IF(E29<50,E29, " ") | G29: =IF(E29<30,E29, " ") | J29: 1 | M29: =SUM(H29:L29) -> 1 | N29: =M29/M$9*100 -> 50 | W29: 1 | X29: 1 | Y29: 1 | AA29: 1 | AB29: 1 | AC29: 1 | AD29: 1 | AE29: 1 | AF29: 1 | AG29: 1 | AH29: 1 | AI29: 1 | AJ29: =SUM(O29:AI29) -> 12 | AK29: =AJ29/AJ$9*100 -> 92.307692 | AL29: 1 | AM29: 1 | AN29: 1 | AO29: 1 | AP29: 1 | AR29: 1 | AT29: 1 | AU29: 1 | BB29: 1 | BC29: 1 | BD29: 1 | BE29: 1 | BG29: =SUM(AL29:BF29) -> 12 | BH29: =BG29/BG$9*100 -> 85.714286 | BL29: 1 | BX29: 1 | BY29: 1 | CA29: 1 | CB29: 1 | CC29: 1 | CD29: 1 | CG29: 1 | CH29: 1 | CJ29: =SUM(BI29:CI29) -> 9 | CK29: =CJ29/CJ$9*100 -> 81.818182 | CL29: 1 | CM29: 1 | CN29: 1 | CO29: 1 | CQ29: 1 | CY29: =SUM(CL29:CX29) -> 5 | CZ29: =CY29/CY$9*100 -> 100 | DS29: =SUM(DA29:DR29) -> 0 | DT29: =DS29/DS$9*100 -> #DIV/0!
A30: 21 | B30: 0827CY241021 | C30: CHIRAG KAMARIYA | D30: =SUM(M30+AJ30+BG30+CJ30+CY30) -> 6 | E30: =(D30)/D$9*100 -> 13.333333 | F30: =IF(E30<50,E30, " ") -> 13.333333 | G30: =IF(E30<30,E30, " ") -> 13.333333 | M30: =SUM(H30:L30) -> 0 | N30: =M30/M$9*100 -> 0 | Y30: 1 | AA30: 1 | AC30: 1 | AG30: 1 | AJ30: =SUM(O30:AI30) -> 4 | AK30: =AJ30/AJ$9*100 -> 30.769231 | AO30: 1 | BD30: 1 | BG30: =SUM(AL30:BF30) -> 2 | BH30: =BG30/BG$9*100 -> 14.285714 | CJ30: =SUM(BI30:CI30) -> 0 | CK30: =CJ30/CJ$9*100 -> 0 | CY30: =SUM(CL30:CX30) -> 0 | CZ30: =CY30/CY$9*100 -> 0 | DS30: =SUM(DA30:DR30) -> 0 | DT30: =DS30/DS$9*100 -> #DIV/0!
A31: 22 | B31: 0827CY241022 | C31: CHIRAYU PATIDAR | D31: =SUM(M31+AJ31+BG31+CJ31+CY31) -> 26 | E31: =(D31)/D$9*100 -> 57.777778 | F31: =IF(E31<50,E31, " ") | G31: =IF(E31<30,E31, " ") | M31: =SUM(H31:L31) -> 0 | N31: =M31/M$9*100 -> 0 | W31: 1 | X31: 1 | Y31: 1 | AA31: 1 | AB31: 1 | AC31: 1 | AD31: 1 | AF31: 1 | AG31: 1 | AH31: 1 | AI31: 1 | AJ31: =SUM(O31:AI31) -> 11 | AK31: =AJ31/AJ$9*100 -> 84.615385 | AM31: 1 | AN31: 1 | AO31: 1 | AP31: 1 | AT31: 1 | AU31: 1 | BG31: =SUM(AL31:BF31) -> 6 | BH31: =BG31/BG$9*100 -> 42.857143 | CA31: 1 | CB31: 1 | CE31: 1 | CF31: 1 | CG31: 1 | CH31: 1 | CJ31: =SUM(BI31:CI31) -> 6 | CK31: =CJ31/CJ$9*100 -> 54.545455 | CN31: 1 | CO31: 1 | CQ31: 1 | CY31: =SUM(CL31:CX31) -> 3 | CZ31: =CY31/CY$9*100 -> 60 | DS31: =SUM(DA31:DR31) -> 0 | DT31: =DS31/DS$9*100 -> #DIV/0!
A32: 23 | B32: 0827CY241023 | C32: DARSH MUNDRA | D32: =SUM(M32+AJ32+BG32+CJ32+CY32) -> 32 | E32: =(D32)/D$9*100 -> 71.111111 | F32: =IF(E32<50,E32, " ") | G32: =IF(E32<30,E32, " ") | M32: =SUM(H32:L32) -> 0 | N32: =M32/M$9*100 -> 0 | W32: 1 | X32: 1 | Y32: 1 | Z32: 1 | AA32: 1 | AB32: 1 | AC32: 1 | AD32: 1 | AG32: 1 | AH32: 1 | AI32: 1 | AJ32: =SUM(O32:AI32) -> 11 | AK32: =AJ32/AJ$9*100 -> 84.615385 | AL32: 1 | AM32: 1 | AN32: 1 | AO32: 1 | AP32: 1 | AR32: 1 | AT32: 1 | BB32: 1 | BC32: 1 | BE32: 1 | BF32: 1 | BG32: =SUM(AL32:BF32) -> 11 | BH32: =BG32/BG$9*100 -> 78.571429 | BL32: 1 | CA32: 1 | CB32: 1 | CC32: 1 | CD32: 1 | CE32: 1 | CF32: 1 | CJ32: =SUM(BI32:CI32) -> 7 | CK32: =CJ32/CJ$9*100 -> 63.636364 | CN32: 1 | CO32: 1 | CQ32: 1 | CY32: =SUM(CL32:CX32) -> 3 | CZ32: =CY32/CY$9*100 -> 60 | DS32: =SUM(DA32:DR32) -> 0 | DT32: =DS32/DS$9*100 -> #DIV/0!
A33: 24 | B33: 0827CY241024 | C33: DIKSHARTH HARDIYA | D33: =SUM(M33+AJ33+BG33+CJ33+CY33) -> 4 | E33: =(D33)/D$9*100 -> 8.8888889 | F33: =IF(E33<50,E33, " ") -> 8.8888889 | G33: =IF(E33<30,E33, " ") -> 8.8888889 | M33: =SUM(H33:L33) -> 0 | N33: =M33/M$9*100 -> 0 | Y33: 1 | AA33: 1 | AJ33: =SUM(O33:AI33) -> 2 | AK33: =AJ33/AJ$9*100 -> 15.384615 | AN33: 1 | AP33: 1 | BG33: =SUM(AL33:BF33) -> 2 | BH33: =BG33/BG$9*100 -> 14.285714 | CJ33: =SUM(BI33:CI33) -> 0 | CK33: =CJ33/CJ$9*100 -> 0 | CY33: =SUM(CL33:CX33) -> 0 | CZ33: =CY33/CY$9*100 -> 0 | DS33: =SUM(DA33:DR33) -> 0 | DT33: =DS33/DS$9*100 -> #DIV/0!
A34: 25 | B34: 0827CY241025 | C34: FARAJ AHMED ANSARI | D34: =SUM(M34+AJ34+BG34+CJ34+CY34) -> 6 | E34: =(D34)/D$9*100 -> 13.333333 | F34: =IF(E34<50,E34, " ") -> 13.333333 | G34: =IF(E34<30,E34, " ") -> 13.333333 | M34: =SUM(H34:L34) -> 0 | N34: =M34/M$9*100 -> 0 | W34: 1 | Y34: 1 | AA34: 1 | AB34: 1 | AH34: 1 | AJ34: =SUM(O34:AI34) -> 5 | AK34: =AJ34/AJ$9*100 -> 38.461538 | AM34: 1 | BG34: =SUM(AL34:BF34) -> 1 | BH34: =BG34/BG$9*100 -> 7.1428571 | CJ34: =SUM(BI34:CI34) -> 0 | CK34: =CJ34/CJ$9*100 -> 0 | CY34: =SUM(CL34:CX34) -> 0 | CZ34: =CY34/CY$9*100 -> 0 | DS34: =SUM(DA34:DR34) -> 0 | DT34: =DS34/DS$9*100 -> #DIV/0!
A35: 26 | B35: 0827CY241026 | C35: HARSH BATHRI | D35: =SUM(M35+AJ35+BG35+CJ35+CY35) -> 24 | E35: =(D35)/D$9*100 -> 53.333333 | F35: =IF(E35<50,E35, " ") | G35: =IF(E35<30,E35, " ") | M35: =SUM(H35:L35) -> 0 | N35: =M35/M$9*100 -> 0 | W35: 1 | X35: 1 | Y35: 1 | Z35: 1 | AA35: 1 | AB35: 1 | AC35: 1 | AG35: 1 | AJ35: =SUM(O35:AI35) -> 8 | AK35: =AJ35/AJ$9*100 -> 61.538462 | AM35: 1 | AN35: 1 | AO35: 1 | AP35: 1 | AR35: 1 | AT35: 1 | BC35: 1 | BE35: 1 | BF35: 1 | BG35: =SUM(AL35:BF35) -> 9 | BH35: =BG35/BG$9*100 -> 64.285714 | BX35: 1 | BY35: 1 | CA35: 1 | CB35: 1 | CJ35: =SUM(BI35:CI35) -> 4 | CK35: =CJ35/CJ$9*100 -> 36.363636 | CN35: 1 | CO35: 1 | CQ35: 1 | CY35: =SUM(CL35:CX35) -> 3 | CZ35: =CY35/CY$9*100 -> 60 | DS35: =SUM(DA35:DR35) -> 0 | DT35: =DS35/DS$9*100 -> #DIV/0!
A36: 27 | B36: 0827CY241027 | C36: HARSH PALIWAL | D36: =SUM(M36+AJ36+BG36+CJ36+CY36) -> 6 | E36: =(D36)/D$9*100 -> 13.333333 | F36: =IF(E36<50,E36, " ") -> 13.333333 | G36: =IF(E36<30,E36, " ") -> 13.333333 | M36: =SUM(H36:L36) -> 0 | N36: =M36/M$9*100 -> 0 | AJ36: =SUM(O36:AI36) -> 0 | AK36: =AJ36/AJ$9*100 -> 0 | AT36: 1 | AU36: 1 | BC36: 1 | BD36: 1 | BG36: =SUM(AL36:BF36) -> 4 | BH36: =BG36/BG$9*100 -> 28.571429 | CG36: 1 | CH36: 1 | CJ36: =SUM(BI36:CI36) -> 2 | CK36: =CJ36/CJ$9*100 -> 18.181818 | CY36: =SUM(CL36:CX36) -> 0 | CZ36: =CY36/CY$9*100 -> 0 | DS36: =SUM(DA36:DR36) -> 0 | DT36: =DS36/DS$9*100 -> #DIV/0!
A37: 28 | B37: 0827CY241028 | C37: HEMANT KUMAR PATIL | D37: =SUM(M37+AJ37+BG37+CJ37+CY37) -> 30 | E37: =(D37)/D$9*100 -> 66.666667 | F37: =IF(E37<50,E37, " ") | G37: =IF(E37<30,E37, " ") | M37: =SUM(H37:L37) -> 0 | N37: =M37/M$9*100 -> 0 | W37: 1 | X37: 1 | Y37: 1 | AA37: 1 | AB37: 1 | AC37: 1 | AD37: 1 | AF37: 1 | AG37: 1 | AH37: 1 | AI37: 1 | AJ37: =SUM(O37:AI37) -> 11 | AK37: =AJ37/AJ$9*100 -> 84.615385 | AM37: 1 | AN37: 1 | AO37: 1 | AP37: 1 | AR37: 1 | AT37: 1 | AU37: 1 | BB37: 1 | BC37: 1 | BF37: 1 | BG37: =SUM(AL37:BF37) -> 10 | BH37: =BG37/BG$9*100 -> 71.428571 | BX37: 1 | BY37: 1 | CC37: 1 | CD37: 1 | CG37: 1 | CH37: 1 | CJ37: =SUM(BI37:CI37) -> 6 | CK37: =CJ37/CJ$9*100 -> 54.545455 | CN37: 1 | CO37: 1 | CQ37: 1 | CY37: =SUM(CL37:CX37) -> 3 | CZ37: =CY37/CY$9*100 -> 60 | DS37: =SUM(DA37:DR37) -> 0 | DT37: =DS37/DS$9*100 -> #DIV/0!
A38: 29 | B38: 0827CY241029 | C38: JANHAVI SINGH | D38: =SUM(M38+AJ38+BG38+CJ38+CY38) -> 17 | E38: =(D38)/D$9*100 -> 37.777778 | F38: =IF(E38<50,E38, " ") -> 37.777778 | G38: =IF(E38<30,E38, " ") | M38: =SUM(H38:L38) -> 0 | N38: =M38/M$9*100 -> 0 | X38: 1 | AB38: 1 | AF38: 1 | AJ38: =SUM(O38:AI38) -> 3 | AK38: =AJ38/AJ$9*100 -> 23.076923 | AM38: 1 | AR38: 1 | AT38: 1 | AU38: 1 | BG38: =SUM(AL38:BF38) -> 4 | BH38: =BG38/BG$9*100 -> 28.571429 | BL38: 1 | BX38: 1 | BY38: 1 | CA38: 1 | CB38: 1 | CJ38: =SUM(BI38:CI38) -> 5 | CK38: =CJ38/CJ$9*100 -> 45.454545 | CL38: 1 | CM38: 1 | CN38: 1 | CO38: 1 | CQ38: 1 | CY38: =SUM(CL38:CX38) -> 5 | CZ38: =CY38/CY$9*100 -> 100 | DS38: =SUM(DA38:DR38) -> 0 | DT38: =DS38/DS$9*100 -> #DIV/0!
A39: 30 | B39: 0827CY241030 | C39: JATIN PAL | D39: =SUM(M39+AJ39+BG39+CJ39+CY39) -> 14 | E39: =(D39)/D$9*100 -> 31.111111 | F39: =IF(E39<50,E39, " ") -> 31.111111 | G39: =IF(E39<30,E39, " ") | M39: =SUM(H39:L39) -> 0 | N39: =M39/M$9*100 -> 0 | W39: 1 | Y39: 1 | AA39: 1 | AB39: 1 | AD39: 1 | AE39: 1 | AF39: 1 | AH39: 1 | AJ39: =SUM(O39:AI39) -> 8 | AK39: =AJ39/AJ$9*100 -> 61.538462 | AM39: 1 | AN39: 1 | AP39: 1 | BG39: =SUM(AL39:BF39) -> 3 | BH39: =BG39/BG$9*100 -> 21.428571 | CE39: 1 | CF39: 1 | CJ39: =SUM(BI39:CI39) -> 2 | CK39: =CJ39/CJ$9*100 -> 18.181818 | CQ39: 1 | CY39: =SUM(CL39:CX39) -> 1 | CZ39: =CY39/CY$9*100 -> 20 | DS39: =SUM(DA39:DR39) -> 0 | DT39: =DS39/DS$9*100 -> #DIV/0!
A40: 31 | B40: 0827CY241031 | C40: JAYSHREE CHOUHAN | D40: =SUM(M40+AJ40+BG40+CJ40+CY40) -> 22 | E40: =(D40)/D$9*100 -> 48.888889 | F40: =IF(E40<50,E40, " ") -> 48.888889 | G40: =IF(E40<30,E40, " ") | M40: =SUM(H40:L40) -> 0 | N40: =M40/M$9*100 -> 0 | AB40: 1 | AC40: 1 | AD40: 1 | AE40: 1 | AF40: 1 | AG40: 1 | AI40: 1 | AJ40: =SUM(O40:AI40) -> 7 | AK40: =AJ40/AJ$9*100 -> 53.846154 | AL40: 1 | AM40: 1 | AN40: 1 | AQ40: 1 | AR40: 1 | AT40: 1 | AU40: 1 | BB40: 1 | BC40: 1 | BE40: 1 | BG40: =SUM(AL40:BF40) -> 10 | BH40: =BG40/BG$9*100 -> 71.428571 | CJ40: =SUM(BI40:CI40) -> 0 | CK40: =CJ40/CJ$9*100 -> 0 | CL40: 1 | CM40: 1 | CN40: 1 | CO40: 1 | CQ40: 1 | CY40: =SUM(CL40:CX40) -> 5 | CZ40: =CY40/CY$9*100 -> 100 | DS40: =SUM(DA40:DR40) -> 0 | DT40: =DS40/DS$9*100 -> #DIV/0!
...

Sheet 402 L
A1: CY-402 L
A2: Faculty Name: | C2: Prof. Nidhi Nigam
A3: Subject Name : | C3: Fundamental of Cyber Security
A4: Subject Code : | C4: CY-402
A5: Start Date | C5: 46104
A6: End Date
H7: 1 | I7: 2 | J7: 3 | L7: 4 | O7: 1 | P7: 2 | Q7: 3 | R7: 4 | S7: 5 | T7: 6 | U7: 7 | V7: 8 | W7: 9 | X7: 10 | Y7: 11 | Z7: 12 | AA7: 13 | AB7: 14 | AC7: 15 | AD7: 16 | AE7: 17 | AF7: 18 | AG7: 19 | AH7: 20 | AI7: 21 | AL7: 1 | AM7: 2 | AN7: 3 | AO7: 4 | AP7: 5 | AQ7: 6 | AR7: 7 | AS7: 8 | AT7: 9 | AU7: 10 | AV7: 11 | AW7: 12 | AX7: 13 | AY7: 14 | AZ7: 15 | BA7: 16 | BB7: 17 | BC7: 18 | BD7: 19 | BE7: 20 | BF7: 21 | BI7: 1 | BJ7: 2 | BK7: 3 | BL7: 4 | BM7: 5 | BN7: 6 | BO7: 7 | BP7: 8 | BQ7: 9 | BR7: 10 | BS7: 11 | BT7: 12 | BU7: 13 | BV7: 14 | BW7: 15 | BX7: 16 | BY7: 17 | BZ7: 18 | CA7: 19 | CB7: 20 | CC7: 21 | CD7: 22 | CG7: 1 | CH7: 2 | CI7: 3 | CJ7: 4 | CK7: 5 | CL7: 6 | CM7: 7 | CN7: 8 | CO7: 9 | CP7: 10 | CQ7: 11 | CT7: 1 | CU7: 2 | CV7: 3 | CW7: 4 | CX7: 5
D8: Total Class | E8: OverAll Att. % | F8: Att. 50% | G8: Att. 30% | H8: 46104 | I8: 46105 | J8: 46106 | K8: 46107 | L8: 46111 | M8: MAR CLASS | N8: MAR % | O8: 46113 | P8: 46114 | Q8: 46115 | R8: 46118 | S8: 46119 | T8: 46120 | U8: 46121 | V8: 46122 | W8: 46125 | X8: 46127 | Y8: 46128 | Z8: 46129 | AA8: 46132 | AB8: 46133 | AC8: 46134 | AD8: 46135 | AE8: 46136 | AF8: 46139 | AG8: 46140 | AH8: 46141 | AI8: 46142 | AJ8: APRIL CLASS | AK8: APRIL % | AL8: 46143 | AM8: 46146 | AN8: 46147 | AO8: 46148 | AP8: 46149 | AQ8: 46150 | AR8: 46153 | AS8: 46154 | AT8: 46155 | AU8: 46156 | AV8: 46157 | AW8: 46160 | AX8: 46161 | AY8: 46162 | AZ8: 46163 | BA8: 46164 | BB8: 46167 | BC8: 46168 | BD8: 46169 | BE8: 46170 | BF8: 46171 | BG8: MAY CLASS | BH8: MAY % | BI8: 46174 | BJ8: 46175 | BK8: 46176 | BL8: 46177 | BM8: 46178 | BN8: 46181 | BO8: 46182 | BP8: 46183 | BQ8: 46184 | BR8: 46185 | BS8: 46188 | BT8: 46189 | BU8: 46190 | BV8: 46191 | BW8: 46192 | BX8: 46195 | BY8: 46196 | BZ8: 46197 | CA8: 46198 | CB8: 46199 | CC8: 46202 | CD8: 46203 | CE8: JUNE CLASS | CF8: JUNE % | CG8: 46209 | CH8: 46210 | CR8: JULY CLASS | CS8: JULY % | CZ8: JAN CLASS | DA8: JAN %
A9: S.No. | B9: Enrollment No. | C9: Student Name | D9: =SUM(M9+AJ9+BG9+CE9+CR9) -> 15 | H9: =SUM(H10:H49) -> 5 | I9: =SUM(I10:I49) -> 6 | J9: =SUM(J10:J49) -> 0 | K9: =SUM(K10:K49) -> 0 | L9: =SUM(L10:L49) -> 0 | M9: =COUNTIF(H9:L9,">0") -> 2 | N9: =COUNTIF(H9:L9,">0") -> 2 | O9: =SUM(O10:O49) -> 0 | P9: =SUM(P10:P49) -> 0 | Q9: =SUM(Q10:Q49) -> 0 | R9: =SUM(R10:R49) -> 0 | S9: =SUM(S10:S49) -> 0 | T9: =SUM(T10:T49) -> 0 | U9: =SUM(U10:U49) -> 0 | V9: =SUM(V10:V49) -> 0 | ... AI9: =SUM(AI10:AI49) -> 0 | AJ9: =COUNTIF(O9:AI9,">0") -> 2 | AK9: =SUM(M9+AJ9) -> 4 | AL9: =SUM(AL10:AL49) -> 0 | AM9: =SUM(AM10:AM49) -> 20 | AN9: =SUM(AN10:AN49) -> 18 | AO9: =SUM(AO10:AO49) -> 0 | AP9: =SUM(AP10:AP49) -> 0 | AQ9: =SUM(AQ10:AQ49) -> 0 | AR9: =SUM(AR10:AR49) -> 0 | AS9: =SUM(AS10:AS49) -> 20 | ... BF9: =SUM(BF10:BF49) -> 0 | BG9: =COUNTIF(AL9:BF9,">0") -> 6 | BH9: =SUM(AK9+BG9) -> 10 | BI9: =SUM(BI10:BI49) -> 0 | BJ9: =SUM(BJ10:BJ49) -> 19 | BK9: =SUM(BK10:BK49) -> 0 | BL9: =SUM(BL10:BL49) -> 0 | BM9: =SUM(BM10:BM49) -> 0 | BN9: =SUM(BN10:BN49) -> 0 | BO9: =SUM(BO10:BO49) -> 0 | BP9: =SUM(BP10:BP49) -> 0 | ... CD9: =SUM(CD10:CD49) -> 19 | CE9: =COUNTIF(BI9:CD9,">0") -> 4 | CF9: =SUM(BH9+CE9) -> 14 | CG9: =sum(CG10:CG49) -> 24 | CH9: =SUM(CH10:CH49) -> 7 | CI9: =SUM(CI10:CI49) -> 0 | CJ9: =SUM(CJ10:CJ49) -> 0 | CK9: =SUM(CK10:CK49) -> 0 | CL9: =SUM(CL10:CL49) -> 0 | CM9: =SUM(CM10:CM49) -> 0 | CN9: =SUM(CN10:CN49) -> 0 | CO9: =SUM(CO10:CO49) -> 0 | ... CQ9: =SUM(CQ10:CQ49) -> 0 | CR9: =COUNTIF(CH9:CQ9,">0") -> 1 | CS9: =SUM(CF9+CR9) -> 15 | CT9: =SUM(CT10:CT49) -> 0 | CU9: =SUM(CU10:CU49) -> 0 | CV9: =SUM(CV10:CV49) -> 0 | CW9: =SUM(CW10:CW49) -> 0 | CX9: =SUM(CX10:CX49) -> 0 | CY9: =SUM(CY10:CY49) -> 0 | CZ9: =COUNTIF(CP9:CY9,">0") -> 2 | DA9: =SUM(CO9+CZ9) -> 2
A10: 1 | B10: 0827CY241001 | C10: AASTHA RATHORE | D10: =SUM(M10+AJ10+BG10+CE10+CR10) -> 13 | E10: =(D10)/D$9*100 -> 86.666667 | F10: =IF(E10<50,E10, " ") | G10: =IF(E10<30,E10, " ") | H10: 1 | I10: 1 | M10: =SUM(H10:L10) -> 2 | N10: =M10/M$9*100 -> 100 | AB10: 1 | AF10: 1 | AJ10: =SUM(O10:AI10) -> 2 | AK10: =AJ10/AJ$9*100 -> 100 | AN10: 1 | AS10: 1 | AV10: 1 | AX10: 1 | BC10: 1 | BG10: =SUM(AL10:BF10) -> 5 | BH10: =BG10/BG$9*100 -> 83.333333 | BJ10: 1 | BX10: 1 | BY10: 1 | CD10: 1 | CE10: =SUM(BI10:CD10) -> 4 | CF10: =CE10/CE$9*100 -> 100 | CG10: 1 | CR10: =SUM(CH10:CQ10) -> 0 | CS10: =CR10/CR$9*100 -> 0 | CZ10: =SUM(CP10:CY10) -> 0 | DA10: =CZ10/CZ$9*100 -> 0
A11: 2 | B11: 0827CY241002 | C11: ABEER JOSHI | D11: =SUM(M11+AJ11+BG11+CE11+CR11) -> 7 | E11: =(D11)/D$9*100 -> 46.666667 | F11: =IF(E11<50,E11, " ") -> 46.666667 | G11: =IF(E11<30,E11, " ") | M11: =SUM(H11:L11) -> 0 | N11: =M11/M$9*100 -> 0 | AB11: 1 | AJ11: =SUM(O11:AI11) -> 1 | AK11: =AJ11/AJ$9*100 -> 50 | AM11: 1 | AN11: 1 | AS11: 1 | AX11: 1 | BG11: =SUM(AL11:BF11) -> 4 | BH11: =BG11/BG$9*100 -> 66.666667 | BX11: 1 | BY11: 1 | CE11: =SUM(BI11:CD11) -> 2 | CF11: =CE11/CE$9*100 -> 50 | CG11: 1 | CR11: =SUM(CH11:CQ11) -> 0 | CS11: =CR11/CR$9*100 -> 0 | CZ11: =SUM(CP11:CY11) -> 0 | DA11: =CZ11/CZ$9*100 -> 0
A12: 3 | B12: 0827CY241003 | C12: ABHIJEET SINGH | D12: =SUM(M12+AJ12+BG12+CE12+CR12) -> 7 | E12: =(D12)/D$9*100 -> 46.666667 | F12: =IF(E12<50,E12, " ") -> 46.666667 | G12: =IF(E12<30,E12, " ") | M12: =SUM(H12:L12) -> 0 | N12: =M12/M$9*100 -> 0 | AJ12: =SUM(O12:AI12) -> 0 | AK12: =AJ12/AJ$9*100 -> 0 | AM12: 1 | AN12: 1 | AS12: 1 | AX12: 1 | BG12: =SUM(AL12:BF12) -> 4 | BH12: =BG12/BG$9*100 -> 66.666667 | BJ12: 1 | BY12: 1 | CD12: 1 | CE12: =SUM(BI12:CD12) -> 3 | CF12: =CE12/CE$9*100 -> 75 | CG12: 1 | CR12: =SUM(CH12:CQ12) -> 0 | CS12: =CR12/CR$9*100 -> 0 | CZ12: =SUM(CP12:CY12) -> 0 | DA12: =CZ12/CZ$9*100 -> 0
A13: 4 | B13: 0827CY241004 | C13: ADITI CHOUDHARY | D13: =SUM(M13+AJ13+BG13+CE13+CR13) -> 6 | E13: =(D13)/D$9*100 -> 40 | F13: =IF(E13<50,E13, " ") -> 40 | G13: =IF(E13<30,E13, " ") | M13: =SUM(H13:L13) -> 0 | N13: =M13/M$9*100 -> 0 | AB13: 1 | AJ13: =SUM(O13:AI13) -> 1 | AK13: =AJ13/AJ$9*100 -> 50 | AM13: 1 | AX13: 1 | BG13: =SUM(AL13:BF13) -> 2 | BH13: =BG13/BG$9*100 -> 33.333333 | BJ13: 1 | BY13: 1 | CD13: 1 | CE13: =SUM(BI13:CD13) -> 3 | CF13: =CE13/CE$9*100 -> 75 | CG13: 1 | CR13: =SUM(CH13:CQ13) -> 0 | CS13: =CR13/CR$9*100 -> 0 | CZ13: =SUM(CP13:CY13) -> 0 | DA13: =CZ13/CZ$9*100 -> 0
A14: 5 | B14: 0827CY241005 | C14: ADITYA JAUNJAL | D14: =SUM(M14+AJ14+BG14+CE14+CR14) -> 11 | E14: =(D14)/D$9*100 -> 73.333333 | F14: =IF(E14<50,E14, " ") | G14: =IF(E14<30,E14, " ") | M14: =SUM(H14:L14) -> 0 | N14: =M14/M$9*100 -> 0 | AB14: 1 | AF14: 1 | AJ14: =SUM(O14:AI14) -> 2 | AK14: =AJ14/AJ$9*100 -> 100 | AM14: 1 | AN14: 1 | AS14: 1 | AV14: 1 | AX14: 1 | BC14: 1 | BG14: =SUM(AL14:BF14) -> 6 | BH14: =BG14/BG$9*100 -> 100 | BX14: 1 | BY14: 1 | CD14: 1 | CE14: =SUM(BI14:CD14) -> 3 | CF14: =CE14/CE$9*100 -> 75 | CG14: 1 | CR14: =SUM(CH14:CQ14) -> 0 | CS14: =CR14/CR$9*100 -> 0 | CZ14: =SUM(CP14:CY14) -> 0 | DA14: =CZ14/CZ$9*100 -> 0
